Workbook

Sheet Comments【归档前删除】
A1: EY Ref. | B1: Tab Ref. | C1: Cell Ref. | D1: Question/Comment | E1: Answer/Comment | F1: Closed?
A2: 1 | B2: C.00 Lead | C2: $B$50 | D2: Dana D Li:_x000D_ 根据项目组CFS修改_x000D_ | E2: Rui R Hu:_x000D_ 已更新_x000D_ | F2: No
A3: 2 | B3: C.00 BKD | C3: $C$39 | D3: Dana D Li:_x000D_ 提醒项目组现金流披露，项目组将受限资金披露为现金及现金等价物（参考招标公司cmts)_x000D_ | F3: No
A4: 3 | B4: C.00b Other classification | C4: $K$34 | D4: Dana D Li:_x000D_ 参考招标的cmts，如果项目组确定要列为现金等价物，才在这里做测试_x000D_ | E4: Rui R Hu:_x000D_ 与客户 确认为履约保证金，已更新_x000D_ | F4: No

Sheet 汇总
A1: V6 SWP
B2: C.00 | C2: C.00 Lead sheet（认定：E、 V 、C） | F2: 程序页 | G2: 执行 | H2: 不执行的原因 | I2: 注意事项
B3: 1 | C3: 我们通过波动分析，识别不符合我们预期的账户设置以及账户余额的变化，并确认这些变化对计划实施的实质性程序的影响。 | F3: C.00 Lead | G3: 是
F4: C.00 BKD | G4: 是
B5: C.01 | C5: C.01 Confirmations（认定：E、 V 、C、R&O、P&D） | F5: 程序页 | G5: 执行 | H5: 不执行的原因 | I5: 注意事项
B6: 1 | C6: 我们对所有性质或金额重大的账户发送询证函，将回函金额核对到银行余额调节表中的银行余额，对于无余额调节项的账户，我们将回函金额直接核对到账面余额。我们审阅回函中的其他信息，我们在<C.01>记录函证跟进工作； 当函证程序不适用时，或回函除金额外的其他信息（如资金归集）需要进一步测试，我们在<C.01b>中记录我们的工作。 | F6: C.01 Confirmations | G6: 是
F7: C.01b 特殊账户程序 | G7: 否 | H7: 经询问及函证测试，被审计单位不存在其他特殊账户及资金池账户。本程序不适用。
B8: C.00b | C8: C.00b Other classification （认定：P&D） | F8: 程序页 | G8: 执行 | H8: 不执行的原因 | I8: 注意事项
B9: 1 | C9: 我们评估管理层对货币资金明细项的分类是否正确，包括其中的受限项目、现金及现金等价物类别的项目。 | F9: C.00b Other classification | G9: 是
B10: C.02 | C10: C.02 Bank reconciliations（认定：E、 V 、C） | F10: 程序页 | G10: 执行 | H10: 不执行的原因 | I10: 注意事项
B11: 1 | C11: 我们通过<C.01>及<C.01b>识别存在余额调节项的银行账户，并获取这些账户的余额调节表。 我们识别并选择了大于TT测试阈值的调节项以及其他被认为异常或预期外的调节项进行测试，我们识别并调查超SAD名义金额的未调节差异。 我们针对选中测试的有调节项的银行账户及识别出存在与调节项完整性相关的重大错报风险的银行账户，获取并复核了期后银行对账单。 | F11: C.02 Bank reconciliations | G11: 是
F12: C.02a外币测算 | G12: 否 | H12: 该企业本期不存在人民币以外的其他外币账户
B13: C.03 | C13: C.03 Cutoff （认定：E、 C） | F13: 程序页 | G13: 执行 | H13: 不执行的原因 | I13: 注意事项
B14: 1 | C14: 此程序涉及被审计单位，在适用函证测试范围内的银行账户，与被审计单位的另一个银行账户（不局限于适用函证测试的银行账户）之间的转账。我们记录了确定截止期间的理由，包含我们在⻛险评估程序中的考虑事项，以及这些事项如何影响我们对截⽌期间和样本量的确定。 IPE 考虑： | F14: C.03 Cutoff | G14: 是 | I14: 根据账户的性质和交易的金额，选取金额以及性质重大的账户进行截止性测试。 中国境内的银行转账业务基本能够实现T+1入账，因此我们往往选择资产负债表日前后1天作为测试期间；但如在期末，存在较多跨境交易和国际账户，则需适当延长测试期间。
B16: C.00 | C16: Supplementary | F16: 文件名称
B17: C.00a | C17: 我们评估管理层对现⾦和现⾦等价物负值余额分类的适当性。 | F17: C.00a Negative cash
B18: C.00c | C18: 我们对现金执行了盘点程序。 | F18: C.00c 现金盘点

Sheet C.00 Lead
A1: 022d804f-8de8-4987-b9ac-42632653fc60 | B1: 标准工作底稿: C SWP 货币资金
B2: 客户名称 | C2: 东风鸿远工程咨询有限公司 | D2: 此工作底稿需要与以下 Canvas PSP guided workflow forms一起使用： • C.00 Cash lead sheet • C.01 Bank confirmations • C.02 Bank reconciliations • C.03 Cash cutoff • Account conclusion
B3: 期末 | C3: 46022
B4: 分析日期 | C4: 46044
B5: 可容忍误差(TE) | C5: 3900000
B6: 名义金额(SAD) | C6: 260000
B7: 适用会计准则 | C7: 企业会计准则
B8: 记账本位币 | C8: CNY
B9: C.00 编制引导表并比较余额
B11: 返回汇总页
D13: Threshold(s) | H13: 安永标记
B14: 认定 | C14: CRA | D14: 各项认定1 | E14: 所有相关认定 2 | H14: TB | I14: 已与科目余额表核对无误
B15: 完整性 (C) | C15: Moderate | D15: =IF(C15="Minimal",$C$5*100%,IF(C15="Low",$C$5*75%,IF(C15="Moderate",$C$5*50%,IF(C15="High",$C$5*25%,IF(C15="N/A","-",))))) -> 1950000 | E15: =MIN($D$15:$D$19) -> 1950000 | H15: PY | I15: 与上年最终审定数核对一致
B16: 存在性 (E) | C16: Moderate | D16: =IF(C16="Minimal",$C$5*100%,IF(C16="Low",$C$5*75%,IF(C16="Moderate",$C$5*50%,IF(C16="High",$C$5*25%,IF(C16="N/A","-",))))) -> 1950000 | H16: A3 | I16: 与未审数、审定数核对一致
B17: 计价（V） | C17: N/A | D17: =IF(C17="Minimal",$C$5*100%,IF(C17="Low",$C$5*75%,IF(C17="Moderate",$C$5*50%,IF(C17="High",$C$5*25%,IF(C17="N/A","-",))))) -> - | H17: A5 | I17: 与审计调整核对一致
B18: 权利和义务（R&O） | C18: Moderate | D18: =IF(C18="Minimal",$C$5*100%,IF(C18="Low",$C$5*75%,IF(C18="Moderate",$C$5*50%,IF(C18="High",$C$5*25%,IF(C18="N/A","-",))))) -> 1950000 | H18: FS | I18: 与FS.0x与财务报表核对无误
B19: 列报和披露（P&D） | C19: Moderate | D19: =IF(C19="Minimal",$C$5*100%,IF(C19="Low",$C$5*75%,IF(C19="Moderate",$C$5*50%,IF(C19="High",$C$5*25%,IF(C19="N/A","-",))))) -> 1950000 | H19: w | I19: 低于SAD的金额——放弃进一步调查
B20: 1 各项认定的测试阈值，是根据EY GAM SUBSTANTIVE DESIGN 2.2.1 | H20: Rx | I20: 重新计算，无异常
B21: 中的示例测试阈值（用占TE的百分比表示）在相应风险等级（CRA）区间的上限计算得出的。 | H21: m | I21: 余额/活动不符合测试范围–无需进一步调查
B22: 除负债/费用类别账户的完整性认定应当使用负债/费用账户表之外，其他类别账户和认定均可使用资产/收入账户表。 | H22: SL | I22: 已与明细账核对无误
B23: 2 所有相关认定的测试阈值，是所有有效认定对应之测试阈值的最小值。我们在 Lead中使用该测试阈值：（a）作为选取总账账户进行测试的起点；（b）作为（需要进一步调查的）金额波动范围的起点。
B25: 在下文中描述我们当期对现金账户余额和相关波动的预期，以及这些预期的依据和理由。
B26: 由于本年被审计单位主营业务无重大变化，EY预计本年货币资金余额较上年相比没有明显变化，根据我们对业务的了解、穿行测试、控制测试、检查现金\银行账户的结果，以及与管理层的沟通，公司在过去的12个月内不存在托管账户，存在开立的履约保证金业务、不存在日常结算所用的微信支付账户。
B30: 波动范围
B31: ="波动范围 ("&C8& "):" -> 波动范围 (CNY): | C31: =E15 -> 1950000
B32: 波动范围（%）： | C32: 0.1
B34: 表1 | F34: |------- TB -------| | K34: |------- PY -------|
F35: ="货币/单位: "&C8 -> 货币/单位: CNY
F36: =C3 -> 46022 | K36: =DATE(YEAR($C$3)-1,12,31) -> 45657 | L36: 本期和上期期末余额 | O36: 基于波动幅度判断，是否进一步调查？ | P36: 基于定性考虑判断，是否进一步调查？
B37: 账套名称/账套编码 | C37: 总账科目编码 | D37: 科目名称 | E37: 索引号 | F37: 期末账面数 | G37: 账表调整数 | H37: 期末未审数 | I37: 审计调整数 | J37: 期末审定数 | K37: 上期末审定数 | L37: 变动金额 | M37: 变动% | N37: Notes
B38: 东风鸿远工程咨询有限公司 | C38: 1002 | D38: 银行存款 | E38: C.00 BKD/ | F38: 5924414.1 | H38: =F38+G38 -> 5924414.1 | J38: =H38+I38 -> 5924414.1 | K38: 4880069.7 | L38: =J38-K38 -> 1044344.5 | M38: =IF(K38<>0,L38/K38,1) -> 0.21400196 | O38: =IF(AND(ABS(L38)>=$C$31,ABS(M38)>=$C$32),"是","否") -> 否 | P38: 否
B39: 东风鸿远工程咨询有限公司福建分公司 | C39: 1002 | D39: 银行存款 | F39: 605.89 | H39: =F39+G39 -> 605.89 | J39: =H39+I39 -> 605.89 | K39: 990.34 | L39: =J39-K39 -> -384.45 | M39: =IF(K39<>0,L39/K39,1) -> -0.38820001 | O39: =IF(AND(ABS(L39)>=$C$31,ABS(M39)>=$C$32),"是","否") -> 否 | P39: 否
B40: 东风鸿远工程咨询有限公司武汉分公司 | C40: 1002 | D40: 银行存款 | F40: 8043.03 | H40: =F40+G40 -> 8043.03 | J40: =H40+I40 -> 8043.03 | K40: 5161.99 | L40: =J40-K40 -> 2881.04 | M40: =IF(K40<>0,L40/K40,1) -> 0.55812584 | O40: =IF(AND(ABS(L40)>=$C$31,ABS(M40)>=$C$32),"是","否") -> 否 | P40: 否
B41: 东风鸿远工程咨询有限公司监理分公司 | C41: 1002 | D41: 银行存款 | F41: 122094.03 | H41: =F41+G41 -> 122094.03 | J41: =H41+I41 -> 122094.03 | K41: 3064.68 | L41: =J41-K41 -> 119029.35 | M41: =IF(K41<>0,L41/K41,1) -> 38.839079 | O41: =IF(AND(ABS(L41)>=$C$31,ABS(M41)>=$C$32),"是","否") -> 否 | P41: 否
E43: 合计 | F43: =SUM(F38:F41) -> 6055157.1 | G43: =SUM(G37:G38) -> 0 | H43: =SUM(H38:H41) -> 6055157.1 | I43: =SUM(I37:I38) -> 0 | J43: =SUM(J38:J42) -> 6055157.1 | K43: =SUM(K38:K41) -> 4889286.7 | L43: =J43-K43 -> 1165870.4 | M43: =IF(K43<>0,L43/K43,1) -> 0.23845409 | N43: [A] | O43: =IF(AND(ABS(L43)>=$C$31,ABS(M43)>=$C$32),"是","否") -> 否 | P43: 否
F44: Rx | G44: Rx | H44: Rx | I44: Rx | J44: Rx | K44: Rx
G46: A3 | H46: =[1]A3!$F$13 -> 6055157.1 | J46: =[1]A3!$H$13 -> 6055157.1 | K46: =[1]A3!$L$13 -> 4889286.7
G47: Diff | H47: =H43-H46 -> 0 | J47: =J43-J46 -> 0 | K47: =K43-K46 -> 0
B49: 波动说明
B50: [A]本期末货币资金余额较上期末增加1,165千元，涨幅23.85%。我们对于变动金额大于TT，且变动比例大于10%的项目进行分析，具体分析如下： 银行余额增加系经营活动现金净流入5,014千元，投资活动现金净流出2,304千元，筹资活动现金净流出1.544千元共同影响所致： ①经营活动：经营活动现金净流入5,014千元，主要系销售商品、提供劳务收到的现金105,458千元，购买商品、接受劳务支付的现金38,755千元，支付给职工以及为职工支付的现金52,418千元； ②投资活动：投资活动现金净流出2,304千元，主要系处置固定资产、无形资产和其他长期资产所收回的现金净额808千元，购建固定资产、无形资产、和其他长期资产所支付的现金3,112千元； ③筹资活动：筹资活动现金净流出1.544千元，主要系借款所收到的现金19,000千元，偿还债务支付的现金19,000千元， 支付的其他与筹资活动有关的现金1,033千元。
...

Sheet C.00 BKD
A1: cd8846d7-01cb-4e39-99f2-dd3fb53a39f3 | B1: 标准工作底稿: C SWP 货币资金
B2: C.00 BKD
B4: 返回汇总页
B6: 全量货币资金明细表
B8: TB | C8: TB | D8: TB | E8: TB | F8: TB | G8: TB | H8: TB | I8: PBC&C.01 | J8: EY Works | K8: EY Works
B9: 公司名称 | C9: 科目名称 | D9: 银行/存款机构名称 | E9: 账号1 | F9: 币种 | G9: 期末账面金额 （原币） | H9: 期末账面金额 （本币） | I9: 货币资金账户的性质和用途 | J9: 是否对账户执行银行函证程序？ | K9: 记录我们判断账户在金额及性质上均不重大的理由和执行的工作，或，在<C.01b>记录我们执行的替代性程序。 | L9: 期初账面金额 （本币） | M9: Notes
B10: 东风鸿远工程咨询有限公司 | C10: 银行存款 | D10: 招商银行股份有限公司襄阳分行营业部 | E10: 127919613710008 | F10: CNY | G10: 1373.84 | H10: =G10 -> 1373.84 | I10: 一般存款账户 | J10: 是 | K10: =IF(J10="是","N/a","") -> N/a | L10: 19628.16
B11: 东风鸿远工程咨询有限公司 | C11: 银行存款 | D11: 中国工商银行股份有限公司襄阳高新技术产业支行 | E11: 1804009019200221562 | F11: CNY | G11: 7000 | H11: =G11 -> 7000 | I11: 一般存款账户 | J11: 是 | K11: =IF(J11="是","N/a","") -> N/a | L11: 107000
B12: 东风鸿远工程咨询有限公司 | C12: 银行存款 | D12: 东风汽车财务有限公司 | E12: 2120010759 | F12: CNY | G12: 5696065.2 | H12: =G12 -> 5696065.2 | I12: 一般存款账户 | J12: 否 | K12: 集团财务公司账户，执行内部对账程序 | L12: 4646459.4 | M12: C.01C内部对账!A1
B13: 东风鸿远工程咨询有限公司 | C13: 银行存款 | D13: 兴业银行股份有限公司襄阳分行 | E13: 419010100100198487 | F13: CNY | G13: 991 | H13: =G13 -> 991 | I13: 协定存款户 | J13: 是 | K13: =IF(J13="是","N/a","") -> N/a | L13: 55.58
B14: 东风鸿远工程咨询有限公司 | C14: 银行存款 | D14: 中国建设银行股份有限公司襄阳樊城支行 | E14: 42001646108050002660 | F14: CNY | G14: 90863.39 | H14: =G14 -> 90863.39 | I14: 基本存款账户 | J14: 是 | K14: =IF(J14="是","N/a","") -> N/a | L14: 29069.09
B15: 东风鸿远工程咨询有限公司 | C15: 银行存款 | D15: 交通银行股份有限公司襄阳分行营业部 | E15: 426426351011000206710 | F15: CNY | G15: 850.22 | H15: =G15 -> 850.22 | I15: 一般存款账户 | J15: 是 | K15: =IF(J15="是","N/a","") -> N/a | L15: 1000
B16: 东风鸿远工程咨询有限公司 | C16: 银行存款 | D16: 中国银行襄阳真武支行 | E16: 559979614041 | F16: CNY | G16: 76892.42 | H16: =G16 -> 76892.42 | I16: 一般存款账户 | J16: 是 | K16: =IF(J16="是","N/a","") -> N/a | L16: 76857.44
B17: 东风鸿远工程咨询有限公司 | C17: 银行存款 | D17: 招商银行股份有限公司襄阳分行营业部 | E17: 12791961377100020 | F17: CNY | G17: 50000 | H17: =G17 -> 50000 | I17: 对公活期保证金账户 | J17: 是 | K17: =IF(J17="是","N/a","") -> N/a | L17: 0
B18: 东风鸿远工程咨询有限公司 | C18: 银行存款 | D18: 中国邮政储蓄银行股份有限公司襄阳市大庆东路支行 | E18: 942068013000809290 | F18: CNY | G18: 378.05 | H18: =G18 -> 378.05 | I18: 一般存款账户 | J18: 是 | K18: =IF(J18="是","N/a","") -> N/a | L18: 0
B19: 东风鸿远工程咨询有限公司福建分公司 | C19: 银行存款 | D19: 中国建设银行股份有限公司泉州洛江支行 | E19: 35050165690700002445 | F19: CNY | G19: 605.89 | H19: =G19 -> 605.89 | I19: 基本存款账户 | J19: 是 | K19: =IF(J19="是","N/a","") -> N/a | L19: 990.34
B20: 东风鸿远工程咨询有限公司武汉分公司 | C20: 银行存款 | D20: 中国建设银行股份有限公司武汉经济技术开发区支行 | E20: 42050125813600001754 | F20: CNY | G20: 8043.03 | H20: =G20 -> 8043.03 | I20: 基本存款账户 | J20: 是 | K20: =IF(J20="是","N/a","") -> N/a | L20: 5161.99
B21: 东风鸿远工程咨询有限公司监理分公司 | C21: 银行存款 | D21: 中国工商银行股份有限公司襄阳高新技术产业支行 | E21: 1804009019200268848 | F21: CNY | G21: 122094.03 | H21: =G21 -> 122094.03 | I21: 一般存款账户 | J21: 是 | K21: =IF(J21="是","N/a","") -> N/a | L21: 995.53
B22: 东风鸿远工程咨询有限公司监理分公司 | C22: 银行存款 | D22: 中国建设银行股份有限公司襄阳铁路支行 | E22: 42050164770800000367 | F22: CNY | G22: 0 | H22: =G22 -> 0 | I22: 基本存款账户 | J22: 是 | K22: =IF(J22="是","N/a","") -> N/a | L22: 2069.15
H24: =SUM(H10:H22) -> 6055157.1 | L24: =SUM(L10:L22) -> 4889286.7
H25: RX
G26: C_Lead | H26: =H24-'C.00 Lead'!F43 -> 0 | L26: =L24-'C.00 Lead'!K43 -> 0
B28: Notes
B29: 货币资金总账与明细账核对一致，无差异
B36: For ref 现金 | C36: =H24-'C.01 Confirmations '!X24 -> 6005157.1
B37: 现金等价物 | C37: 0
B38: CFS现金及现金等价物 | C38: ='[2]CF-主表'!$E$45 -> 6055157.1
B39: diff | C39: =C36+C37-C38 -> -50000

Sheet C.01C内部对账
A3: 东风财务公司是东风集团内部持牌金融机构，主要在集团内部开展吸收存款、公司及经销商贷款、承兑汇票、委存委贷等业务，东风集团下属单位（包含合营公司）本年采用对账的形式替代银行函证，相关对账邮件见：
A5: 存放东财款项
A7: 账面数据 | J7: 东财数据 | S7: 对账差异
A8: 账号名称 | B8: 账号 | C8: 币种 | D8: 利率 | E8: 存款类型 | F8: 账户余额 | G8: 起始日期 | H8: 终止日期 （如无，可填不适用，下同） | I8: 是否属于受限账户 | J8: 账号名称 | K8: 账号 | L8: 币种 | M8: 利率 | N8: 存款类型 | O8: 账户余额 | P8: 起始日期 | Q8: 终止日期 （如无，可填不适用，下同） | R8: 是否属于受限账户 | S8: 是否存在差异 | T8: 对差异的解释
A9: 东风鸿远工程咨询有限公司 | B9: 2120010759 | C9: CNY | D9: 0.1 | E9: 活期存款 | F9: ='C.00 BKD'!G12 -> 5696065.2 | G9: 2024-05-10 | H9: 无 | I9: 否 | J9: 东风鸿远工程咨询有限公司 | K9: 2120010759 | L9: CNY | M9: 0.1 | N9: 活期存款 | O9: 5696065.2 | P9: 2024-05-10 | Q9: 无 | R9: 否 | S9: 否
A15: 【经对账，未见差异】

Sheet SkywindSettingSheet
A1: 0a1351bf-0789-4e2c-8675-482199dfc116
