Workbook

Sheet 汇总
A1: V6 SWP
B2: 该科目涉及OSP底稿可参考此链接 | E2: OSP L1 SWP 开发支出 202YMMDD XYZ公司.xlsx
E3: OSP L1 SWP 无形资产权属检查 202YMMDD XYZ公司.xlsx
E4: OSP L1 SWP 无形资产资本化支出 202YMMDD XYZ公司.xlsx
B6: L1.00 | C6: L1.00 Lead sheet（认定：E、V、C、R&O、P&D） | D6: L.00 Lead sheet | E6: L.00 Lead sheet | F6: 程序页 | G6: 执行 | H6: 不执行的原因
B7: 1 | C7: 获取和编制无形资产两期变动的引导表，并与试算平衡表和上年底稿核对一致。对无形资产变动建立预期并说明理由，对不符合预期的变动以及异常变动进行调查和分析。 | F7: L1.00 Lead sheet | G7: 是
B8: L1.01.1 | C8: L1.01.1 Agree SL to GL（认定：E、V、C、R&O、P&D） | D8: L1.01.1 明细账与总账核对一致 | E8: L1.01.1 明细账与总账核对一致 | F8: 程序页 | G8: 执行 | H8: 不执行的原因
B9: 1 | C9: 获取无形资产后推明细表，并将其与试算平衡表和无形资产清单核对一致。 | F9: L1.01.1 Agree SL to GL | G9: 是
B10: L1.02.1 | C10: L1.02.1 新增测试 &新增清单（认定：E、V、C、R&O、P&D） | F10: 程序页 | G10: 执行 | H10: 不执行的原因
B11: 1 | C11: 获取当期按类别划分的所有无形资产新增清单，并将该列表与无形资产后推核对一致，调查超过SAD名义金额的差额。 | F11: 新增清单
B12: 2 | C12: 对本年新增资产执行关键项目测试和代表性样本测试（如需要）。 | F12: L1.02.1 新增测试
B13: L1.02.2 | C13: L1.02.2 处置测试 & 处置清单（认定：E、V、C、R&O、P&D） | F13: 程序页 | G13: 执行 | H13: 不执行的原因
B14: 1 | C14: 获取当期按类别划分的所有无形资产处置清单，包括记录的处置的损益，并将该列表与无形资产后推核对一致，我们调查超过SAD名义金额的差额。 | F14: 处置清单
B15: 2 | C15: 对本年处置资产执行关键项目测试和代表性样本测试（如需要）。 | F15: L1.02.2 处置测试
B16: L1.03 | C16: L1.03 摊销测试（认定：E、V、C、R&O、P&D） | D16: L1.01.1a IA list & 摊销测试 | E16: L1.01.1a IA list & 摊销测试 | F16: 程序页 | G16: 执行 | H16: 不执行的原因
B17: 1 | C17: 按照公司摊销政策对本年应计提摊销执行重新计算（by item），并与账面进行核对，调查超过SAD名义金额的差额。 检查无形资产各项目的摊销政策是否符合有关规定，是否与上期一致，其是否具有商业合理性。若改变摊销政策，检查其依据是否充分。 | F17: L1.03 摊销测试
B18: L1.04 | C18: L1.04 无形资产的减值（认定：V） | D18: L1.01.1a IA list & 摊销测试 | E18: L1.01.1a IA list & 摊销测试 | F18: 程序页 | G18: 执行 | H18: 不执行的原因
B19: 1 | C19: 验证是否已按照公司的会计政策或适用财务报告框架进行了适当调整，以反映无形资产的账面价值的减值。 | F19: 项目组自行填写底稿索引

Sheet L1.00 Lead sheet
B1: 标准工作底稿: L1 SWP 无形资产
B2: 客户名称 | C2: 东风鸿远工程咨询有限公司
B3: 期末 | C3: 45900
B4: 分析日期 | C4: 45917
B5: 可容忍误差(TE） | C5: 3180000
B6: 名义金额（SAD） | C6: 212000
B7: 公认会计准则（GAAP） | C7: 企业会计准则
B8: 货币/单位 | C8: CNY
B9: L1.00：编制引导表并比较余额
B11: 返回汇总页
D13: Threshold(s) | H13: 安永标记
B14: 认定 | C14: CRA | D14: 各项认定1 | E14: 所有相关认定 2 | H14: TB | I14: 已与科目余额表核对无误
B15: 完整性 (C) | C15: Moderate | D15: =IF(C15="Minimal",$C$5*100%,IF(C15="Low",$C$5*75%,IF(C15="Moderate",$C$5*50%,IF(C15="High",$C$5*25%,IF(C15="N/A","-",))))) -> 1590000 | E15: =MIN($D$15:$D$19) -> 1590000 | H15: PY | I15: 与上年最终审定数核对一致
B16: 存在性 (E) / 发生 (O) | C16: Moderate | D16: =IF(C16="Minimal",$C$5*100%,IF(C16="Low",$C$5*75%,IF(C16="Moderate",$C$5*50%,IF(C16="High",$C$5*25%,IF(C16="N/A","-",))))) -> 1590000 | H16: A3 | I16: 与未审数、审定数核对一致
B17: 计价/计量 (V/M) | C17: Moderate | D17: =IF(C17="Minimal",$C$5*100%,IF(C17="Low",$C$5*75%,IF(C17="Moderate",$C$5*50%,IF(C17="High",$C$5*25%,IF(C17="N/A","-",))))) -> 1590000 | H17: A5 | I17: 与审计调整核对一致
B18: 权利和义务 (R&O) | C18: Moderate | D18: =IF(C18="Minimal",$C$5*100%,IF(C18="Low",$C$5*75%,IF(C18="Moderate",$C$5*50%,IF(C18="High",$C$5*25%,IF(C18="N/A","-",))))) -> 1590000 | H18: FS | I18: 与FS.0x与财务报表核对无误
B19: 列报和披露 (P&D) | C19: N/A | D19: =IF(C19="Minimal",$C$5*100%,IF(C19="Low",$C$5*75%,IF(C19="Moderate",$C$5*50%,IF(C19="High",$C$5*25%,IF(C19="N/A","-",))))) -> - | H19: w | I19: 低于SAD的金额——放弃进一步调查
B20: 1 各项认定的测试阈值，是根据EY GAM SUBSTANTIVE DESIGN 2.2.1 | H20: Rx | I20: 重新计算，无异常
B21: 中的示例测试阈值（用占TE的百分比表示）在相应风险等级（CRA）区间的上限计算得出的。 | H21: m | I21: 余额/活动不符合测试范围–无需进一步调查
B22: 除负债/费用类别账户的完整性认定应当使用负债/费用账户表之外，其他类别账户和认定均可使用资产/收入账户表。 | H22: SL | I22: 已与明细账核对无误
B23: 2 所有相关认定的测试阈值，是所有有效认定对应之测试阈值的最小值。我们在 Lead中使用该测试阈值：（a）作为选取总账账户进行测试的起点；（b）作为（需要进一步调查的）金额波动范围的起点。
B25: 以下描述我们对无形资产的预期，在此期间的相关账户余额和相关波动，以及我们这些预期的依据和理由。（请对无形资产L1.01.1 BKD中表1的变动项分别进行预期，如新增、处置、摊销方法、摊销年限、摊销费用、使用寿命变化等。）
B31: 波动范围
B32: ="波动幅度 ("&C8& "):" -> 波动幅度 (CNY): | C32: =$E$15 -> 1590000
B33: 波动幅度(%): | C33: 0.1
B35: 我们获取或编制了与上期对比的重大账户（无形资产）引导表。我们将本期余额与试算平衡表核对一致，并将上期余额与上期审定数核对一致（如适用）。
B36: 我们将期末余额与上期余额进行对比。调查超出测试阈值（金额和百分比）的波动，以及代表异常或预期外变动或未发生预期中变动的波动，并确定其对我们计划实质性程序的影响（如有）。
E38: |------- TB -------| | J38: |------- PY -------|
E39: ="货币/单位: "&C8 -> 货币/单位: CNY
E40: =C3 -> 45900 | J40: =DATE(YEAR($C$3)-1,12,31) -> 45657 | K40: 本期和上期期末余额 | N40: 基于波动幅度判断，是否进一步调查？ | O40: 基于定性考虑判断，是否进一步调查？
B41: 总账科目编码 | C41: 科目名称 | D41: 索引号 | E41: 期末账面数 | F41: 账表调整数 | G41: 期末未审数 | H41: 审计调整数 | I41: 期末审定数 | J41: 上期末审定数 | K41: 变动金额 | L41: 变动% | M41: Notes
B42: 1801 | C42: 无形资产 | D42: L.01.1 | E42: ='L1.01.1 Agree SL to GL'!T39 -> 0 | G42: =E42+F42 -> 0 | I42: =G42+H42 -> 0 | J42: 10353587 | K42: =I42-J42 -> -10353587 | L42: =IF(J42<>0,K42/J42,1) -> -1 | M42: [A] | N42: =IF(AND(ABS(K42)>=$C$32,ABS(L42)>=$C$33),"是","否") -> 是
B43: 1802 | C43: 累计摊销 | D43: L.01.1 | E43: ='L1.01.1 Agree SL to GL'!T41 -> 0 | G43: =E43+F43 -> 0 | I43: =G43+H43 -> 0 | J43: 1372065.4 | K43: =I43-J43 -> -1372065.4 | L43: =IF(J43<>0,K43/J43,1) -> -1 | N43: =IF(AND(ABS(K43)>=$C$32,ABS(L43)>=$C$33),"是","否") -> 否
C44: 减值准备 | D44: L.01.1 | E44: ='L1.01.1 Agree SL to GL'!T43 -> 0 | G44: =E44+F44 -> 0 | I44: =G44+H44 -> 0 | J44: 0 | K44: =I44-J44 -> 0 | L44: =IF(J44<>0,K44/J44,1) -> 1 | N44: =IF(AND(ABS(K44)>=$C$32,ABS(L44)>=$C$33),"是","否") -> 否
C46: 合计 | E46: =E42-E43-E44 -> 0 | F46: =F42-F43-F44 -> 0 | G46: =G42-G43-G44 -> 0 | H46: =H42-H43-H44 -> 0 | I46: =I42-I43-I44 -> 0 | J46: =J42-J43-J44 -> 8981521.7 | K46: =K42-K43-K44 -> -8981521.7 | L46: =IF(J46<>0,K46/J46,1) -> -1 | N46: =IF(AND(ABS(K46)>=$C$32,ABS(L46)>=$C$33),"是","否") -> 是
C48: check with A3 | J48: =[1]A3!$M$55 -> 8981521.7
C49: Diff | G49: =G48-G46 -> 0 | I49: =I48-I46 -> 0 | J49: =J48-J46 -> 0
B51: 波动说明
B52: [A]
B57: 调整汇总表（如不适用请删除）
...

Sheet L1.01.1 Agree SL to GL
B1: 标准工作底稿: L1 SWP 无形资产 | C1: 标准工作底稿: L1 SWP 无形资产 | D1: 标准工作底稿: L1 SWP 无形资产 | E1: 标准工作底稿: L1 SWP 无形资产 | F1: 标准工作底稿: L1 SWP 无形资产 | G1: 标准工作底稿: L1 SWP 无形资产 | H1: 标准工作底稿: L1 SWP 无形资产 | I1: 标准工作底稿: L1 SWP 无形资产 | J1: 标准工作底稿: L1 SWP 无形资产 | K1: 标准工作底稿: L1 SWP 无形资产 | L1: 标准工作底稿: L1 SWP 无形资产 | M1: 标准工作底稿: L1 SWP 无形资产 | N1: 标准工作底稿: L1 SWP 无形资产 | O1: 标准工作底稿: L1 SWP 无形资产 | P1: 标准工作底稿: L1 SWP 无形资产 | Q1: 标准工作底稿: L1 SWP 无形资产 | R1: 标准工作底稿: L1 SWP 无形资产 | S1: 标准工作底稿: L1 SWP 无形资产 | T1: 标准工作底稿: L1 SWP 无形资产 | U1: 标准工作底稿: L1 SWP 无形资产 | V1: 标准工作底稿: L1 SWP 无形资产
B2: L1.01.1 明细账与总账核对一致
B4: 返回汇总页
B6: 获取上期末至本期末（或中期，如适用）无形资产及相关新增、处置、转让和摊销的后推明细表。（原值、累计摊销、减值均为正数填列，本期减少以负数填列，账表调整、审计调整数据均直接链接至L1.00 Lead sheet。）以下资产类别作为示例，审计团队需按照被审计单位实际情况修改。
B7: 将期初无形资产余额与上期审定数核对一致，将期末无形资产余额与无形资产明细账和试算表核对一致。调查大于SAD的差异。
B8: 我们选择了超过测试阈值的后推活动（如，新增、处置、转移和摊销费用），以执行L1.02和L1.03的实质性程序。对于未包含在本程序表范围内的程序，我们交叉索引至完成该程序的单独程序表。我们评估了无形资产的其他转出和其他调整，以了解调整的性质，并确定是否需要执行额外程序。
B9: 表1
F10: 土地使用权 | I10: 软件 | L10: 商标权 | O10: 专利权 | R10: 特许权 | U10: 合计 | W10: Check
E11: 账面数 | F11: 账表调整/审计调整 | G11: 审定数 | H11: 账面数 | I11: 账表调整/审计调整 | J11: 审定数 | K11: 账面数 | L11: 账表调整/审计调整 | M11: 审定数 | N11: 账面数 | O11: 账表调整/审计调整 | P11: 审定数 | Q11: 账面数 | R11: 账表调整/审计调整 | S11: 审定数 | T11: 账面数 | U11: 账表调整/审计调整 | V11: 审定数
B12: 原值 | C12: 年初余额 | D12: PY | G12: =SUM(E12:F12) -> 0 | J12: =SUM(H12:I12) -> 0 | M12: =SUM(K12:L12) -> 0 | P12: =SUM(N12:O12) -> 0 | S12: =SUM(Q12:R12) -> 0 | T12: =SUM(Q12,N12,K12,H12,E12) -> 0 | U12: =F12+I12+L12+O12+R12 -> 0 | V12: =G12+J12+M12+P12+S12 -> 0 | W12: =V12-'L1.00 Lead sheet'!I42 -> 0
C13: 购置 | D13: L1.02.1 | G13: =SUM(E13:F13) -> 0 | J13: =SUM(H13:I13) -> 0 | M13: =SUM(K13:L13) -> 0 | P13: =SUM(N13:O13) -> 0 | S13: =SUM(Q13:R13) -> 0 | T13: =SUM(Q13,N13,K13,H13,E13) -> 0 | U13: =F13+I13+L13+O13+R13 -> 0 | V13: =G13+J13+M13+P13+S13 -> 0
C14: 合并增加 | J14: =SUM(H14:I14) -> 0
C15: 本年其他新增 | G15: =SUM(E15:F15) -> 0 | J15: =SUM(H15:I15) -> 0 | M15: =SUM(K15:L15) -> 0 | P15: =SUM(N15:O15) -> 0 | S15: =SUM(Q15:R15) -> 0 | T15: =SUM(Q15,N15,K15,H15,E15) -> 0 | U15: =F15+I15+L15+O15+R15 -> 0 | V15: =G15+J15+M15+P15+S15 -> 0
C16: 处置或报废 | D16: L1.02.2 | G16: =SUM(E16:F16) -> 0 | J16: =SUM(H16:I16) -> 0 | M16: =SUM(K16:L16) -> 0 | P16: =SUM(N16:O16) -> 0 | S16: =SUM(Q16:R16) -> 0 | T16: =SUM(Q16,N16,K16,H16,E16) -> 0 | U16: =F16+I16+L16+O16+R16 -> 0 | V16: =G16+J16+M16+P16+S16 -> 0
C17: 本年其他转出 | G17: =SUM(E17:F17) -> 0 | J17: =SUM(H17:I17) -> 0 | M17: =SUM(K17:L17) -> 0 | P17: =SUM(N17:O17) -> 0 | S17: =SUM(Q17:R17) -> 0 | T17: =SUM(Q17,N17,K17,H17,E17) -> 0 | U17: =F17+I17+L17+O17+R17 -> 0 | V17: =G17+J17+M17+P17+S17 -> 0
C18: 年末余额 | D18: Rx | E18: =SUM(E12:E17) -> 0 | F18: =SUM(F12:F17) -> 0 | G18: =SUM(G12:G17) -> 0 | H18: =SUM(H12:H17) -> 0 | I18: =SUM(I12:I17) -> 0 | J18: =SUM(J12:J17) -> 0 | K18: =SUM(K12:K17) -> 0 | L18: =SUM(L12:L17) -> 0 | ... V18: =SUM(V12:V17) -> 0 | W18: =V18-'L1.00 Lead sheet'!I42 -> 0
C19: 年初余额 | D19: PY | G19: =SUM(E19:F19) -> 0 | J19: =SUM(H19:I19) -> 0 | M19: =SUM(K19:L19) -> 0 | P19: =SUM(N19:O19) -> 0 | S19: =SUM(Q19:R19) -> 0 | T19: =SUM(Q19,N19,K19,H19,E19) -> 0 | U19: =F19+I19+L19+O19+R19 -> 0 | V19: =G19+J19+M19+P19+S19 -> 0 | W19: =V19-'L1.00 Lead sheet'!I43 -> 0
C20: 计提 | D20: L1.01.1a | G20: =SUM(E20:F20) -> 0 | J20: =SUM(H20:I20) -> 0 | M20: =SUM(K20:L20) -> 0 | P20: =SUM(N20:O20) -> 0 | S20: =SUM(Q20:R20) -> 0 | T20: =SUM(Q20,N20,K20,H20,E20) -> 0 | U20: =F20+I20+L20+O20+R20 -> 0 | V20: =G20+J20+M20+P20+S20 -> 0 | W20: =V20+'L1.03 摊销测试'!H18 -> 0
C21: 合并增加
B22: 累计摊销 | C22: 处置或报废 | D22: L1.02.2 | G22: =SUM(E22:F22) -> 0 | J22: =SUM(H22:I22) -> 0 | M22: =SUM(K22:L22) -> 0 | P22: =SUM(N22:O22) -> 0 | S22: =SUM(Q22:R22) -> 0 | T22: =SUM(Q22,N22,K22,H22,E22) -> 0 | U22: =F22+I22+L22+O22+R22 -> 0 | V22: =G22+J22+M22+P22+S22 -> 0
C23: 本年其他转出 | G23: =SUM(E23:F23) -> 0 | J23: =SUM(H23:I23) -> 0 | M23: =SUM(K23:L23) -> 0 | P23: =SUM(N23:O23) -> 0 | S23: =SUM(Q23:R23) -> 0 | T23: =SUM(Q23,N23,K23,H23,E23) -> 0 | U23: =F23+I23+L23+O23+R23 -> 0 | V23: =G23+J23+M23+P23+S23 -> 0
C24: =C18 -> 年末余额 | D24: Rx | E24: =SUM(E19:E23) -> 0 | F24: =SUM(F19:F23) -> 0 | G24: =SUM(G19:G23) -> 0 | H24: =SUM(H19:H23) -> 0 | I24: =SUM(I19:I23) -> 0 | J24: =SUM(J19:J23) -> 0 | K24: =SUM(K19:K23) -> 0 | L24: =SUM(L19:L23) -> 0 | ... V24: =SUM(V19:V23) -> 0 | W24: =V24-'L1.00 Lead sheet'!I43 -> 0
C25: 年初余额 | D25: PY | G25: =SUM(E25:F25) -> 0 | J25: =SUM(H25:I25) -> 0 | M25: =SUM(K25:L25) -> 0 | P25: =SUM(N25:O25) -> 0 | S25: =SUM(Q25:R25) -> 0 | T25: =SUM(Q25,N25,K25,H25,E25) -> 0 | U25: =F25+I25+L25+O25+R25 -> 0 | V25: =G25+J25+M25+P25+S25 -> 0 | W25: =V25-'L1.00 Lead sheet'!J44 -> 0
C26: 计提 | D26: SWP减值 | G26: =SUM(E26:F26) -> 0 | J26: =SUM(H26:I26) -> 0 | M26: =SUM(K26:L26) -> 0 | P26: =SUM(N26:O26) -> 0 | S26: =SUM(Q26:R26) -> 0 | T26: =SUM(Q26,N26,K26,H26,E26) -> 0 | U26: =F26+I26+L26+O26+R26 -> 0 | V26: =G26+J26+M26+P26+S26 -> 0
B27: 减值准备 | C27: 处置或报废 | D27: L1.02.2 | G27: =SUM(E27:F27) -> 0 | J27: =SUM(H27:I27) -> 0 | M27: =SUM(K27:L27) -> 0 | P27: =SUM(N27:O27) -> 0 | S27: =SUM(Q27:R27) -> 0 | T27: =SUM(Q27,N27,K27,H27,E27) -> 0 | U27: =F27+I27+L27+O27+R27 -> 0 | V27: =G27+J27+M27+P27+S27 -> 0
C28: 本年其他转出 | D28: SWP减值 | G28: =SUM(E28:F28) -> 0 | J28: =SUM(H28:I28) -> 0 | M28: =SUM(K28:L28) -> 0 | P28: =SUM(N28:O28) -> 0 | S28: =SUM(Q28:R28) -> 0 | T28: =SUM(Q28,N28,K28,H28,E28) -> 0 | U28: =F28+I28+L28+O28+R28 -> 0 | V28: =G28+J28+M28+P28+S28 -> 0
C29: =C18 -> 年末余额 | D29: Rx | E29: =SUM(E25:E28) -> 0 | F29: =SUM(F25:F28) -> 0 | G29: =SUM(G25:G28) -> 0 | H29: =SUM(H25:H28) -> 0 | I29: =SUM(I25:I28) -> 0 | J29: =SUM(J25:J28) -> 0 | K29: =SUM(K25:K28) -> 0 | L29: =SUM(L25:L28) -> 0 | ... V29: =SUM(V25:V28) -> 0 | W29: =V29-'L1.00 Lead sheet'!I44 -> 0
B30: 净值 (NBV) | C30: =C18 -> 年末余额 | D30: Rx | E30: =E18-E24-E29 -> 0 | F30: =F18-F24-F29 -> 0 | G30: =G18-G24-G29 -> 0 | H30: =H18-H24-H29 -> 0 | I30: =I18-I24-I29 -> 0 | J30: =J18-J24-J29 -> 0 | K30: =K18-K24-K29 -> 0 | L30: =L18-L24-L29 -> 0 | ... S30: =S18-S24-S29 -> 0 | T30: =SUM(S30,N30,K30,H30,E30) -> 0 | U30: =F30+I30+L30+O30+R30 -> 0 | V30: =G30+J30+M30+P30+S30 -> 0 | W30: =V30-'L1.00 Lead sheet'!I48 -> 0
C31: =C12 -> 年初余额 | D31: Rx | E31: =E12-E19-E25 -> 0 | F31: =F12-F19-F25 -> 0 | G31: =G12-G19-G25 -> 0 | H31: =H12-H19-H25 -> 0 | I31: =I12-I19-I25 -> 0 | J31: =J12-J19-J25 -> 0 | K31: =K12-K19-K25 -> 0 | L31: =L12-L19-L25 -> 0 | ... S31: =S12-S19-S25 -> 0 | T31: =SUM(S31,N31,K31,H31,E31) -> 0 | U31: =F31+I31+L31+O31+R31 -> 0 | V31: =G31+J31+M31+P31+S31 -> 0 | W31: =V31-'L1.00 Lead sheet'!I48 -> 0
B32: 变动 | C32: 原值变动金额 | D32: 本年VS上年 | E32: =E18-E12 -> 0 | F32: =F18-F12 -> 0 | G32: =G18-G12 -> 0 | H32: =H18-H12 -> 0 | I32: =I18-I12 -> 0 | J32: =J18-J12 -> 0 | K32: =K18-K12 -> 0 | L32: =L18-L12 -> 0 | ... V32: =V18-V12 -> 0
C33: 原值变动比例 | D33: % | E33: =IFERROR(E32/E12,1) -> 1 | G33: =IFERROR(G32/G12,1) -> 1 | H33: =IFERROR(H32/H12,1) -> 1 | J33: =IFERROR(J32/J12,1) -> 1 | K33: =IFERROR(K32/K12,1) -> 1 | M33: =IFERROR(M32/M12,1) -> 1 | N33: =IFERROR(N32/N12,1) -> 1 | P33: =IFERROR(P32/P12,1) -> 1 | Q33: =IFERROR(Q32/Q12,1) -> 1 | S33: =IFERROR(S32/S12,1) -> 1 | T33: =IFERROR(T32/T12,1) -> 1 | V33: =IFERROR(V32/V12,1) -> 1
C34: 累计摊销变动金额 | D34: 本年VS上年 | E34: =E24-E19 -> 0 | G34: =G24-G19 -> 0 | H34: =H24-H19 -> 0 | J34: =J24-J19 -> 0 | K34: =K24-K19 -> 0 | M34: =M24-M19 -> 0 | N34: =N24-N19 -> 0 | P34: =P24-P19 -> 0 | Q34: =Q24-Q19 -> 0 | S34: =S24-S19 -> 0 | T34: =T24-T19 -> 0 | V34: =V24-V19 -> 0
C35: 累计摊销变动比例 | D35: % | E35: =IFERROR(E34/E19,1) -> 1 | G35: =IFERROR(G34/G19,1) -> 1 | H35: =IFERROR(H34/H19,1) -> 1 | J35: =IFERROR(J34/J19,1) -> 1 | K35: =IFERROR(K34/K19,1) -> 1 | M35: =IFERROR(M34/M19,1) -> 1 | N35: =IFERROR(N34/N19,1) -> 1 | P35: =IFERROR(P34/P19,1) -> 1 | Q35: =IFERROR(Q34/Q19,1) -> 1 | S35: =IFERROR(S34/S19,1) -> 1 | T35: =IFERROR(T34/T19,1) -> 1 | V35: =IFERROR(V34/V19,1) -> 1
C36: 减值准备变动金额 | D36: 本年VS上年 | E36: =E29-E25 -> 0 | G36: =G29-G25 -> 0 | H36: =H29-H25 -> 0 | J36: =J29-J25 -> 0 | K36: =K29-K25 -> 0 | M36: =M29-M25 -> 0 | N36: =N29-N25 -> 0 | P36: =P29-P25 -> 0 | Q36: =Q29-Q25 -> 0 | S36: =S29-S25 -> 0 | T36: =T29-T25 -> 0 | V36: =V29-V25 -> 0
C37: 减值准备变动比例 | D37: % | E37: =IFERROR(E36/E25,1) -> 1 | G37: =IFERROR(G36/G25,1) -> 1 | H37: =IFERROR(H36/H25,1) -> 1 | J37: =IFERROR(J36/J25,1) -> 1 | K37: =IFERROR(K36/K25,1) -> 1 | M37: =IFERROR(M36/M25,1) -> 1 | N37: =IFERROR(N36/N25,1) -> 1 | P37: =IFERROR(P36/P25,1) -> 1 | Q37: =IFERROR(Q36/Q25,1) -> 1 | S37: =IFERROR(S36/S25,1) -> 1 | T37: =IFERROR(T36/T25,1) -> 1 | V37: =IFERROR(V36/V25,1) -> 1
B39: TB-原值 | T39: =E39+H39+K39+N39+Q39 -> 0
B40: 差异 | E40: =E39-E18 -> 0 | H40: =H39-H18 -> 0 | K40: =K39-K18 -> 0 | N40: =N39-N18 -> 0 | Q40: =Q39-Q18 -> 0 | T40: =T39-T18 -> 0
B41: TB-累计摊销 | T41: =E41+H41+K41+N41+Q41 -> 0
B42: 差异 | E42: =E41-E24 -> 0 | H42: =H41-H24 -> 0 | K42: =K41-K24 -> 0 | N42: =N41-N24 -> 0 | Q42: =Q41-Q24 -> 0 | T42: =T41-T24 -> 0
B43: TB-减值准备 | T43: =E43+H43+K43+N43+Q43 -> 0
...

Sheet L1.01.1 Agree SL to GL(241231)
B1: 标准工作底稿: L1 SWP 无形资产 | C1: 标准工作底稿: L1 SWP 无形资产 | D1: 标准工作底稿: L1 SWP 无形资产 | E1: 标准工作底稿: L1 SWP 无形资产 | F1: 标准工作底稿: L1 SWP 无形资产 | G1: 标准工作底稿: L1 SWP 无形资产 | H1: 标准工作底稿: L1 SWP 无形资产 | I1: 标准工作底稿: L1 SWP 无形资产 | J1: 标准工作底稿: L1 SWP 无形资产 | K1: 标准工作底稿: L1 SWP 无形资产 | L1: 标准工作底稿: L1 SWP 无形资产 | M1: 标准工作底稿: L1 SWP 无形资产 | N1: 标准工作底稿: L1 SWP 无形资产 | O1: 标准工作底稿: L1 SWP 无形资产 | P1: 标准工作底稿: L1 SWP 无形资产 | Q1: 标准工作底稿: L1 SWP 无形资产 | R1: 标准工作底稿: L1 SWP 无形资产 | S1: 标准工作底稿: L1 SWP 无形资产 | T1: 标准工作底稿: L1 SWP 无形资产 | U1: 标准工作底稿: L1 SWP 无形资产 | V1: 标准工作底稿: L1 SWP 无形资产
B2: L1.01.1 明细账与总账核对一致
B4: 返回汇总页
B6: 获取上期末至本期末（或中期，如适用）无形资产及相关新增、处置、转让和摊销的后推明细表。（原值、累计摊销、减值均为正数填列，本期减少以负数填列，账表调整、审计调整数据均直接链接至L1.00 Lead sheet。）以下资产类别作为示例，审计团队需按照被审计单位实际情况修改。
B7: 将期初无形资产余额与上期审定数核对一致，将期末无形资产余额与无形资产明细账和试算表核对一致。调查大于SAD的差异。
B8: 我们选择了超过测试阈值的后推活动（如，新增、处置、转移和摊销费用），以执行L1.02和L1.03的实质性程序。对于未包含在本程序表范围内的程序，我们交叉索引至完成该程序的单独程序表。我们评估了无形资产的其他转出和其他调整，以了解调整的性质，并确定是否需要执行额外程序。
B9: 表1
F10: 土地使用权 | I10: 软件 | L10: 商标权 | O10: 专利权 | R10: 特许权 | U10: 合计 | W10: Check
E11: 账面数 | F11: 账表调整/审计调整 | G11: 审定数 | H11: 账面数 | I11: 账表调整/审计调整 | J11: 审定数 | K11: 账面数 | L11: 账表调整/审计调整 | M11: 审定数 | N11: 账面数 | O11: 账表调整/审计调整 | P11: 审定数 | Q11: 账面数 | R11: 账表调整/审计调整 | S11: 审定数 | T11: 账面数 | U11: 账表调整/审计调整 | V11: 审定数
B12: 原值 | C12: 年初余额 | D12: PY | E12: 0 | G12: =SUM(E12:F12) -> 0 | H12: 0 | J12: =SUM(H12:I12) -> 0 | K12: 0 | M12: =SUM(K12:L12) -> 0 | N12: 0 | P12: =SUM(N12:O12) -> 0 | Q12: 0 | S12: =SUM(Q12:R12) -> 0 | T12: =SUM(Q12,N12,K12,H12,E12) -> 0 | U12: =F12+I12+L12+O12+R12 -> 0 | V12: =G12+J12+M12+P12+S12 -> 0
C13: 购置 | D13: L1.02.1 | E13: 0 | G13: =SUM(E13:F13) -> 0 | H13: 184955.76 | J13: =SUM(H13:I13) -> 184955.76 | K13: 0 | M13: =SUM(K13:L13) -> 0 | N13: 0 | P13: =SUM(N13:O13) -> 0 | Q13: 0 | S13: =SUM(Q13:R13) -> 0 | T13: =SUM(Q13,N13,K13,H13,E13) -> 184955.76 | U13: =F13+I13+L13+O13+R13 -> 0 | V13: =G13+J13+M13+P13+S13 -> 184955.76
C14: 合并增加 | E14: 8736666 | G14: =SUM(E14:F14) -> 8736666 | H14: 1431965.4 | J14: =SUM(H14:I14) -> 1431965.4 | K14: 0 | N14: 0 | Q14: 0 | T14: =SUM(Q14,N14,K14,H14,E14) -> 10168631 | V14: =G14+J14+M14+P14+S14 -> 10168631
C15: 本年其他新增 | E15: 0 | G15: =SUM(E15:F15) -> 0 | H15: 0 | J15: =SUM(H15:I15) -> 0 | K15: 0 | M15: =SUM(K15:L15) -> 0 | N15: 0 | P15: =SUM(N15:O15) -> 0 | Q15: 0 | S15: =SUM(Q15:R15) -> 0 | T15: =SUM(Q15,N15,K15,H15,E15) -> 0 | U15: =F15+I15+L15+O15+R15 -> 0 | V15: =G15+J15+M15+P15+S15 -> 0
C16: 处置或报废 | D16: L1.02.2 | E16: 0 | G16: =SUM(E16:F16) -> 0 | H16: 0 | J16: =SUM(H16:I16) -> 0 | K16: 0 | M16: =SUM(K16:L16) -> 0 | N16: 0 | P16: =SUM(N16:O16) -> 0 | Q16: 0 | S16: =SUM(Q16:R16) -> 0 | T16: =SUM(Q16,N16,K16,H16,E16) -> 0 | U16: =F16+I16+L16+O16+R16 -> 0 | V16: =G16+J16+M16+P16+S16 -> 0
C17: 本年其他转出 | E17: 0 | G17: =SUM(E17:F17) -> 0 | H17: 0 | J17: =SUM(H17:I17) -> 0 | K17: 0 | M17: =SUM(K17:L17) -> 0 | N17: 0 | P17: =SUM(N17:O17) -> 0 | Q17: 0 | S17: =SUM(Q17:R17) -> 0 | T17: =SUM(Q17,N17,K17,H17,E17) -> 0 | U17: =F17+I17+L17+O17+R17 -> 0 | V17: =G17+J17+M17+P17+S17 -> 0
C18: 年末余额 | D18: Rx | E18: =SUM(E12:E17) -> 8736666 | F18: =SUM(F12:F17) -> 0 | G18: =SUM(G12:G17) -> 8736666 | H18: =SUM(H12:H17) -> 1616921.2 | I18: =SUM(I12:I17) -> 0 | J18: =SUM(J12:J17) -> 1616921.2 | K18: =SUM(K12:K17) -> 0 | L18: =SUM(L12:L17) -> 0 | ... V18: =SUM(V12:V17) -> 10353587 | W18: =V18-'L1.00 Lead sheet'!J42 -> 0
C19: 年初余额 | D19: PY | E19: 0 | G19: =SUM(E19:F19) -> 0 | H19: 0 | J19: =SUM(H19:I19) -> 0 | K19: 0 | M19: =SUM(K19:L19) -> 0 | N19: 0 | P19: =SUM(N19:O19) -> 0 | Q19: 0 | S19: =SUM(Q19:R19) -> 0 | T19: =SUM(Q19,N19,K19,H19,E19) -> 0 | U19: =F19+I19+L19+O19+R19 -> 0 | V19: =G19+J19+M19+P19+S19 -> 0
C20: 计提 | D20: L1.01.1a | E20: 218416.68 | G20: =SUM(E20:F20) -> 218416.68 | H20: 179240.11 | J20: =SUM(H20:I20) -> 179240.11 | K20: 0 | M20: =SUM(K20:L20) -> 0 | N20: 0 | P20: =SUM(N20:O20) -> 0 | Q20: 0 | S20: =SUM(Q20:R20) -> 0 | T20: =SUM(Q20,N20,K20,H20,E20) -> 397656.79 | U20: =F20+I20+L20+O20+R20 -> 0 | V20: =G20+J20+M20+P20+S20 -> 397656.79
C21: 合并增加 | E21: 691331.7 | G21: =SUM(E21:F21) -> 691331.7 | H21: 283076.95 | J21: =SUM(H21:I21) -> 283076.95 | K21: 0 | M21: =SUM(K21:L21) -> 0 | N21: 0 | P21: =SUM(N21:O21) -> 0 | Q21: 0 | S21: =SUM(Q21:R21) -> 0 | T21: =SUM(Q21,N21,K21,H21,E21) -> 974408.65 | U21: =F21+I21+L21+O21+R21 -> 0 | V21: =G21+J21+M21+P21+S21 -> 974408.65
B22: 累计摊销 | C22: 处置或报废 | D22: L1.02.2 | E22: 0 | G22: =SUM(E22:F22) -> 0 | H22: 0 | J22: =SUM(H22:I22) -> 0 | K22: 0 | M22: =SUM(K22:L22) -> 0 | N22: 0 | P22: =SUM(N22:O22) -> 0 | Q22: 0 | S22: =SUM(Q22:R22) -> 0 | T22: =SUM(Q22,N22,K22,H22,E22) -> 0 | U22: =F22+I22+L22+O22+R22 -> 0 | V22: =G22+J22+M22+P22+S22 -> 0 | W22: =V22+'L1.03 摊销测试'!H20 -> 0
C23: 本年其他转出 | E23: 0 | G23: =SUM(E23:F23) -> 0 | H23: 0 | J23: =SUM(H23:I23) -> 0 | K23: 0 | M23: =SUM(K23:L23) -> 0 | N23: 0 | P23: =SUM(N23:O23) -> 0 | Q23: 0 | S23: =SUM(Q23:R23) -> 0 | T23: =SUM(Q23,N23,K23,H23,E23) -> 0 | U23: =F23+I23+L23+O23+R23 -> 0 | V23: =G23+J23+M23+P23+S23 -> 0
C24: =C18 -> 年末余额 | D24: Rx | E24: =SUM(E19:E23) -> 909748.38 | F24: =SUM(F19:F23) -> 0 | G24: =SUM(G19:G23) -> 909748.38 | H24: =SUM(H19:H23) -> 462317.06 | I24: =SUM(I19:I23) -> 0 | J24: =SUM(J19:J23) -> 462317.06 | K24: =SUM(K19:K23) -> 0 | L24: =SUM(L19:L23) -> 0 | ... V24: =SUM(V19:V23) -> 1372065.4 | W24: =V24-'L1.00 Lead sheet'!J43 -> 0
C25: 年初余额 | D25: PY | E25: 0 | G25: =SUM(E25:F25) -> 0 | H25: 0 | J25: =SUM(H25:I25) -> 0 | K25: 0 | M25: =SUM(K25:L25) -> 0 | N25: 0 | P25: =SUM(N25:O25) -> 0 | Q25: 0 | S25: =SUM(Q25:R25) -> 0 | T25: =SUM(Q25,N25,K25,H25,E25) -> 0 | U25: =F25+I25+L25+O25+R25 -> 0 | V25: =G25+J25+M25+P25+S25 -> 0 | W25: =V25-'L1.00 Lead sheet'!J44 -> 0
C26: 计提 | D26: SWP减值 | E26: 0 | G26: =SUM(E26:F26) -> 0 | H26: 0 | J26: =SUM(H26:I26) -> 0 | K26: 0 | M26: =SUM(K26:L26) -> 0 | N26: 0 | P26: =SUM(N26:O26) -> 0 | Q26: 0 | S26: =SUM(Q26:R26) -> 0 | T26: =SUM(Q26,N26,K26,H26,E26) -> 0 | U26: =F26+I26+L26+O26+R26 -> 0 | V26: =G26+J26+M26+P26+S26 -> 0
B27: 减值准备 | C27: 处置或报废 | D27: L1.02.2 | E27: 0 | G27: =SUM(E27:F27) -> 0 | H27: 0 | J27: =SUM(H27:I27) -> 0 | K27: 0 | M27: =SUM(K27:L27) -> 0 | N27: 0 | P27: =SUM(N27:O27) -> 0 | Q27: 0 | S27: =SUM(Q27:R27) -> 0 | T27: =SUM(Q27,N27,K27,H27,E27) -> 0 | U27: =F27+I27+L27+O27+R27 -> 0 | V27: =G27+J27+M27+P27+S27 -> 0
C28: 本年其他转出 | D28: SWP减值 | E28: 0 | G28: =SUM(E28:F28) -> 0 | H28: 0 | J28: =SUM(H28:I28) -> 0 | K28: 0 | M28: =SUM(K28:L28) -> 0 | N28: 0 | P28: =SUM(N28:O28) -> 0 | Q28: 0 | S28: =SUM(Q28:R28) -> 0 | T28: =SUM(Q28,N28,K28,H28,E28) -> 0 | U28: =F28+I28+L28+O28+R28 -> 0 | V28: =G28+J28+M28+P28+S28 -> 0
C29: =C18 -> 年末余额 | D29: Rx | E29: =SUM(E25:E28) -> 0 | F29: =SUM(F25:F28) -> 0 | G29: =SUM(G25:G28) -> 0 | H29: =SUM(H25:H28) -> 0 | I29: =SUM(I25:I28) -> 0 | J29: =SUM(J25:J28) -> 0 | K29: =SUM(K25:K28) -> 0 | L29: =SUM(L25:L28) -> 0 | ... V29: =SUM(V25:V28) -> 0 | W29: =V29-'L1.00 Lead sheet'!I44 -> 0
B30: 净值 (NBV) | C30: =C18 -> 年末余额 | D30: Rx | E30: =E18-E24-E29 -> 7826917.6 | F30: =F18-F24-F29 -> 0 | G30: =G18-G24-G29 -> 7826917.6 | H30: =H18-H24-H29 -> 1154604.1 | I30: =I18-I24-I29 -> 0 | J30: =J18-J24-J29 -> 1154604.1 | K30: =K18-K24-K29 -> 0 | L30: =L18-L24-L29 -> 0 | ... S30: =S18-S24-S29 -> 0 | T30: =SUM(S30,N30,K30,H30,E30) -> 8981521.7 | U30: =F30+I30+L30+O30+R30 -> 0 | V30: =G30+J30+M30+P30+S30 -> 8981521.7 | W30: =V30-'L1.00 Lead sheet'!J46 -> 0
C31: =C12 -> 年初余额 | D31: Rx | E31: =E12-E19-E25 -> 0 | F31: =F12-F19-F25 -> 0 | G31: =G12-G19-G25 -> 0 | H31: =H12-H19-H25 -> 0 | I31: =I12-I19-I25 -> 0 | J31: =J12-J19-J25 -> 0 | K31: =K12-K19-K25 -> 0 | L31: =L12-L19-L25 -> 0 | ... S31: =S12-S19-S25 -> 0 | T31: =SUM(S31,N31,K31,H31,E31) -> 0 | U31: =F31+I31+L31+O31+R31 -> 0 | V31: =G31+J31+M31+P31+S31 -> 0
B32: 变动 | C32: 原值变动金额 | D32: 本年VS上年 | E32: =E18-E12 -> 8736666 | F32: =F18-F12 -> 0 | G32: =G18-G12 -> 8736666 | H32: =H18-H12 -> 1616921.2 | I32: =I18-I12 -> 0 | J32: =J18-J12 -> 1616921.2 | K32: =K18-K12 -> 0 | L32: =L18-L12 -> 0 | ... V32: =V18-V12 -> 10353587
C33: 原值变动比例 | D33: % | E33: =IFERROR(E32/E12,1) -> 1 | G33: =IFERROR(G32/G12,1) -> 1 | H33: =IFERROR(H32/H12,1) -> 1 | J33: =IFERROR(J32/J12,1) -> 1 | K33: =IFERROR(K32/K12,1) -> 1 | M33: =IFERROR(M32/M12,1) -> 1 | N33: =IFERROR(N32/N12,1) -> 1 | P33: =IFERROR(P32/P12,1) -> 1 | Q33: =IFERROR(Q32/Q12,1) -> 1 | S33: =IFERROR(S32/S12,1) -> 1 | T33: =IFERROR(T32/T12,1) -> 1 | V33: =IFERROR(V32/V12,1) -> 1
C34: 累计摊销变动金额 | D34: 本年VS上年 | E34: =E24-E19 -> 909748.38 | G34: =G24-G19 -> 909748.38 | H34: =H24-H19 -> 462317.06 | J34: =J24-J19 -> 462317.06 | K34: =K24-K19 -> 0 | M34: =M24-M19 -> 0 | N34: =N24-N19 -> 0 | P34: =P24-P19 -> 0 | Q34: =Q24-Q19 -> 0 | S34: =S24-S19 -> 0 | T34: =T24-T19 -> 1372065.4 | V34: =V24-V19 -> 1372065.4
C35: 累计摊销变动比例 | D35: % | E35: =IFERROR(E34/E19,1) -> 1 | G35: =IFERROR(G34/G19,1) -> 1 | H35: =IFERROR(H34/H19,1) -> 1 | J35: =IFERROR(J34/J19,1) -> 1 | K35: =IFERROR(K34/K19,1) -> 1 | M35: =IFERROR(M34/M19,1) -> 1 | N35: =IFERROR(N34/N19,1) -> 1 | P35: =IFERROR(P34/P19,1) -> 1 | Q35: =IFERROR(Q34/Q19,1) -> 1 | S35: =IFERROR(S34/S19,1) -> 1 | T35: =IFERROR(T34/T19,1) -> 1 | V35: =IFERROR(V34/V19,1) -> 1
C36: 减值准备变动金额 | D36: 本年VS上年 | E36: =E29-E25 -> 0 | G36: =G29-G25 -> 0 | H36: =H29-H25 -> 0 | J36: =J29-J25 -> 0 | K36: =K29-K25 -> 0 | M36: =M29-M25 -> 0 | N36: =N29-N25 -> 0 | P36: =P29-P25 -> 0 | Q36: =Q29-Q25 -> 0 | S36: =S29-S25 -> 0 | T36: =T29-T25 -> 0 | V36: =V29-V25 -> 0
C37: 减值准备变动比例 | D37: % | E37: =IFERROR(E36/E25,1) -> 1 | G37: =IFERROR(G36/G25,1) -> 1 | H37: =IFERROR(H36/H25,1) -> 1 | J37: =IFERROR(J36/J25,1) -> 1 | K37: =IFERROR(K36/K25,1) -> 1 | M37: =IFERROR(M36/M25,1) -> 1 | N37: =IFERROR(N36/N25,1) -> 1 | P37: =IFERROR(P36/P25,1) -> 1 | Q37: =IFERROR(Q36/Q25,1) -> 1 | S37: =IFERROR(S36/S25,1) -> 1 | T37: =IFERROR(T36/T25,1) -> 1 | V37: =IFERROR(V36/V25,1) -> 1
B39: TB-原值 | E39: =[2]新的工作表!$I$67 -> 8,736,665.96 | H39: =[2]新的工作表!$I$68+[3]新的工作表!$I$17 -> 1616921.2 | I39: 鸿远本部+武汉分公司 | K39: 0 | N39: 0 | Q39: 0 | T39: =E39+H39+K39+N39+Q39 -> 10353587
B40: 差异 | E40: =E39-E18 -> 0 | H40: =H39-H18 -> 0 | K40: =K39-K18 -> 0 | N40: =N39-N18 -> 0 | Q40: =Q39-Q18 -> 0 | T40: =T39-T18 -> 0
B41: TB-累计摊销 | E41: =[2]新的工作表!$J$70 -> 909,748.38 | H41: =[2]新的工作表!$J$71+[3]新的工作表!$I$18 -> 462317.06 | K41: 0 | N41: 0 | Q41: 0 | T41: =E41+H41+K41+N41+Q41 -> 1372065.4
B42: 差异 | E42: =E41-E24 -> 0 | H42: =H41-H24 -> 0 | K42: =K41-K24 -> 0 | N42: =N41-N24 -> 0 | Q42: =Q41-Q24 -> 0 | T42: =T41-T24 -> 0
B43: TB-减值准备 | E43: 0 | H43: 0 | K43: 0 | N43: 0 | Q43: 0 | T43: =E43+H43+K43+N43+Q43 -> 0
...

Sheet L1.02.1 新增测试
B1: 标准工作底稿: L1 SWP 无形资产
B2: L1.02.1：详细测试 (新增)
B4: 返回汇总页
B6: 记录我们的详细测试所涵盖的总体（指引：纳入充分的描述，以使经验丰富且之前与该项审计无关的审计师能够理解样本是如何选择的，例如，总体的分类或筛选。）
B12: 购置总金额
B13: Breakdown中购置金额 | E13: ='L1.01.1 Agree SL to GL'!T13 -> 0 | F13: L1.01.1
B14: 差异 | E14: =E12-E13 -> 0 | F14: Rx | G14: 差异是否需要进一步调查？ | J14: =IF(ABS(E14)>'L1.00 Lead sheet'!$C$6, "Yes", "No") -> No
B16: 减：测试的关键项目
B17: 进行代表性抽样的剩余总体 | E17: =E12-E16 -> 0
B19: 在下方描述选择关键项目的理由（请参阅Canvas指导工作流程的“关键项目”部分，包括信息图标）
B25: EY 测试属性解释:
B26: 对于每个被选中进行测试的项目，我们检查了相关的第三方证据以及相关的会计分录，并确定：
B27: 1) 测试样本于恰当的日期被正确资本化为无形资产（即，不应该费用化）。
B28: 2) 历史成本已根据适用的财务报告框架进行记录。
B29: 3) 管理层对测试项目采用的使用寿命和摊销方法是适当的（符合实体的会计政策和适用的财务报告框架）。
B30: 4) 该资产已被归入适当的无形资产类别。
O31: |------- Rx -------| | P31: EY Works
B32: 样本序号 | C32: 样本类型 | D32: 无形资产类别 | E32: 总账账户代码 | F32: 无形资产编号 | G32: 无形资产名称 | H32: 资产原价 | I32: 资本化日期 | J32: 使用寿命 (月) | K32: 残值率 | L32: 摊销政策 | M32: 资产原价（通过审计证据/支持性文件取得） | N32: 获得的证据/支持的描述（例如，我们检查的控制权转移时点的单据/销售发票/合同/订单等） | O32: 资产原价差异 | P32: 1 | Q32: 2 | R32: 3 | S32: 4
B33: 1 | O33: =M33-H33 -> 0
B34: 2 | O34: =M34-H34 -> 0
B35: 3 | O35: =M35-H35 -> 0
B36: 4 | O36: =M36-H36 -> 0
B37: 5 | O37: =M37-H37 -> 0
B39: 标记图例: 记录已识别的异常情况以及如何解决这些异常情况的详细信息，包括执行的其他实质性程序（指南：包括足够的描述，以使之前与审计无关的经验丰富的审计师能够理解执行的程序）。

Sheet L1.02.1a 选样输出
B2: 注：样本新增测试请与L1.02.1 新增（本年购置）测试金额核对一致。 | N2: 返回汇总页

Sheet 新增清单
O2: 返回汇总页
B3: 获取当期按类别划分的所有无形资产新增清单，并将该列表与无形资产后推核对一致。调查超过SAD名义金额的差额（例如，新增清单和后推明细表之间没被解释的差额）。
B5: 注：项目组可以自定义无形资产新增清单表格，也可直接使用系统导出的无形资产新增清单，但必须确保必需字段（无形资产类别、编号、名称、入账开始日期、使用寿命、残值率、原值、新增方式）完整。

Sheet L1.02.2 处置测试
B1: 标准工作底稿: L1 SWP 无形资产
B2: L1.02.2：详细测试 (处置)
B4: 返回汇总页
B6: 记录我们的详细测试所涵盖的总体（指引：纳入充分的描述，以使经验丰富且之前与该项审计无关的审计师能够理解样本是如何选择的，例如，总体的分类或筛选。）
E12: |------- Rx -------|
E13: 账面价值 | G13: 原价 | I13: 累计摊销 | K13: 减值准备
B14: 减少总金额 | E14: =G14-I14-K14 -> 0
B15: Breakdown中减少金额 | E15: =G15-I15-K15 -> 0 | F15: L1.01.1 | G15: =-('L1.01.1 Agree SL to GL'!T16) -> 0 | H15: L1.01.1 | I15: =-('L1.01.1 Agree SL to GL'!T22) -> 0 | J15: L1.01.1 | K15: =-('L1.01.1 Agree SL to GL'!T27) -> 0 | L15: L1.01.1
B16: 差异 | E16: =E14-E15 -> 0 | F16: Rx | G16: =G14-G15 -> 0 | H16: Rx | I16: =I14-I15 -> 0 | J16: Rx | K16: =K14-K15 -> 0 | L16: Rx
B17: 差异是否需要进一步调查？ | E17: =IF(ABS(E16)>'L1.00 Lead sheet'!$C$6, "Yes", "No") -> No | G17: =IF(ABS(G16)>'L1.00 Lead sheet'!$C$6, "Yes", "No") -> No | I17: =IF(ABS(I16)>'L1.00 Lead sheet'!$C$6, "Yes", "No") -> No | K17: =IF(ABS(K16)>'L1.00 Lead sheet'!$C$6, "Yes", "No") -> No
B19: 减：测试的关键项目
B20: 进行代表性抽样的剩余总体 | E20: =E14-E19 -> 0
B22: 在下方描述选择关键项目的理由（请参阅Canvas指导工作流程的“关键项目”部分，包括信息图标）
B28: EY 测试属性解释:
B29: 对于每个被选中进行测试的项目，我们检查了相关的第三方证据以及相关的会计分录，并确定：
B30: 1) 测试样本（原值和累计摊销余额）已从无形资产明细账和总账中正确移除。
B31: 2) 重新计算资产处置时点的账面净值，并计算处置损益。确认处置损益已按照适用的财务报告框架正确记录和分类。
B32: 3)如果适用，正确记录处置收入金额。如果资产被出售（即收到收益），则获得发票或付款证明等，并确认与日记账分录中记录的收益金额一致。
L34: |------- Rx -------| | O34: |------- Rx -------| | Q34: |------- Rx -------| | S34: EY Works
B35: 样本序号 | C35: 样本类型 | D35: 无形资产类别 | E35: 总账账户代码 | F35: 无形资产编号 | G35: 无形资产名称 | H35: 处置/报废日 | I35: 原价 | J35: 累计摊销 | K35: 减值准备 | L35: 账面价值 | M35: 出售价格 | N35: 处置交易凭证号 | O35: 处置损益 | P35: 出售价格（通过审计证据/支持性文件取得） | Q35: 出售价格差异 | R35: 获得的证据/支持的描述（例如，我们检查的具体销售发票/合同/订单/审批文件等） | S35: 1 | T35: 2 | U35: 3
B36: 1 | L36: =SUM(I36:K36) -> 0 | O36: =M36-L36 -> 0 | Q36: =P36-M36 -> 0
B37: 2 | L37: =SUM(I37:K37) -> 0 | O37: =M37-L37 -> 0 | Q37: =P37-M37 -> 0
B38: 3 | L38: =SUM(I38:K38) -> 0 | O38: =M38-L38 -> 0 | Q38: =P38-M38 -> 0
B39: 4 | L39: =SUM(I39:K39) -> 0 | O39: =M39-L39 -> 0 | Q39: =P39-M39 -> 0
B40: 5 | L40: =SUM(I40:K40) -> 0 | O40: =M40-L40 -> 0 | Q40: =P40-M40 -> 0
B42: 标记图例: 记录已识别的异常情况以及如何解决这些异常情况的详细信息，包括执行的其他实质性程序（指南：包括足够的描述，以使之前与审计无关的经验丰富的审计师能够理解执行的程序）。

Sheet 处置清单
N2: 返回汇总页
B3: 获取当期按类别划分的所有无形资产处置清单，包括记录的处置的损益，并将该列表与无形资产后推核对一致。我们调查超过SAD名义金额的差额（例如，处置清单和后推明细表之间没被解释的差额）。我们考虑了实体经营的任何重大变化是否导致资产报废和/或处置，如果是，我们确保这些资产计入当期处置。
B6: 注：项目组可以自定义无形资产处置清单表格，也可直接使用系统导出的无形资产处置清单，但必须确保必需字段（无形资产类别、编号、名称、原值、累计折旧、减值、净值、处置日期、减少方式）完整。

Sheet L1.02.2a 选样输出
B2: 注：样本处置测试请与L1.02.2 处置（处置及报废）测试金额核对一致。 | N2: 返回汇总页

Sheet L1.03 摊销测试
B1: 标准工作底稿: L1 SWP 无形资产
B2: L1.03：详细测试 (摊销)
B4: 注：1.如果下列表格不适用，项目组可以自定义下方无形资产清单表格，也可直接使用系统导出的无形资产清单，但必须确保必需字段完整。
B5: 2.无形资产的类别：请使用被审计单位的台账，无需对资产的类别添加自己的重分类修改，资产类别应当与L1.01.1中列示的类别匹配。
B7: 返回汇总页
B9: 按公司的摊销政策重新计算本年应计提的摊销费用并与账面本年摊销费用比对。重新计算摊销出现差异的，我们进行进一步核查以得出结论。
B10: |-------------------------------------------------------------------------------------------------------------------------------------------------必需字段*----------------------------------------------------------------------------------------------------------------------------------------------------------|
B11: 表1 无形资产明细清单 | N11: 若处置或报废，须填写 | P11: EY Works
B12: 无形资产编号 | C12: 无形资产名称 | D12: 无形资产类别 | E12: 入账开始日期 | F12: 残值率 | G12: 使用寿命(月) | H12: 本期摊销 | I12: 本期计提减值准备 | J12: 期末原值 | K12: 期末累计摊销 | L12: 期末减值准备 | M12: 期末净值 | N12: 处置日期 | O12: 原值减少金额 | P12: 提足折旧时间 | Q12: 本期应摊销月数 | R12: 本期应摊销金额 | S12: 本期差异 | T12: 标记
P13: =IFERROR(EOMONTH(E13,G13-MONTH(1)),"") | Q13: {=IFERROR(IF(N13="",_xlfn.IFS(YEAR(E13)<YEAR('L1.00 Lead sheet'!$C$3),_xlfn.IFS(YEAR(P13)>YEAR('L1.00 Lead sheet'!$C$3),MONTH('L1.00 Lead sheet'!$C$3),YEAR(P13)=YEAR('L1.00 Lead sheet'!$C$3),IF(MONTH(P13)>=MONTH('L1.00 Lead sheet'!$C$3),MONTH('L1.00 Lead sheet'!$C$3),MONTH(P13)),YEAR(P13)<YEAR('L1.00 Lead sheet'!$C$3),0),(YEAR(E13)=YEAR('L1.00 Lead sheet'!$C$3)),MONTH('L1.00 Lead sheet'!$C$3)+1-(MONTH(E13)),YEAR(E13)>YEAR('L1.00 Lead sheet'!$C$3),0),_xlfn.IFS(EOMONTH(E13,G13-1)<DATE(YEAR('L1.00 Lead sheet'!$C$3),1,1),0,AND(DATE(YEAR('L1.00 Lead sheet'!$C$3),1,1)<EOMONTH(E13,G13-1),EOMONTH(E13,G13-1)<DATE(YEAR('L1.00 Lead sheet'!$C$3),MONTH('L1.00 Lead sheet'!$C$3),DAY('L1.00 Lead sheet'!$C$3))),IF(DATE(YEAR(N13),MONTH(N13),DAY(N13))<EOMONTH(E13,G13-1),MONTH(N13)-1,MONTH(EOMONTH(E13,G13-1))),EOMONTH(E13,G13-1)=DATE(YEAR('L1.00 Lead sheet'!$C$3),MONTH('L1.00 Lead sheet'!$C$3),DAY('L1.00 Lead sheet'!$C$3)),IF(DATE(YEAR(N13),MONTH(N13),DAY(N13))>EOMONTH(E13,G13-1),MONTH(EOMONTH(E13,G13-1)),MONTH(N13)-1),EOMONTH(E13,G13-1)>DATE(YEAR('L1.00 Lead sheet'!$C$3),MONTH('L1.00 Lead sheet'!$C$3),DAY('L1.00 Lead sheet'!$C$3)),IF(YEAR(E13)>YEAR('L1.00 Lead sheet'!$C$3),0,IF(YEAR(E13)=YEAR('L1.00 Lead sheet'!$C$3),IF(YEAR(N13)>YEAR('L1.00 Lead sheet'!$C$3),MONTH('L1.00 Lead sheet'!$C$3)-MONTH(E13)+1,MONTH(N13)-MONTH(E13)+1),_xlfn.IFS(YEAR(N13)>YEAR('L1.00 Lead sheet'!$C$3),MONTH('L1.00 Lead sheet'!$C$3),YEAR(N13)=YEAR('L1.00 Lead sheet'!$C$3),MONTH(N13)-1,YEAR(N13)<YEAR('L1.00 Lead sheet'!$C$3),0))))),0)} -> 0 | R13: =-(IFERROR(IF(J13=0,(O13*(1-F13))/G13*Q13,(J13*(1-F13))/G13*Q13),0)) -> 0 | S13: =R13-H13 -> 0 | T13: =IF(ABS(S13)>'L1.00 Lead sheet'!$C$6,"Note","w") -> w
P14: =IFERROR(EOMONTH(E14,G14-MONTH(1)),"") | Q14: {=IFERROR(IF(N14="",_xlfn.IFS(YEAR(E14)<YEAR('L1.00 Lead sheet'!$C$3),_xlfn.IFS(YEAR(P14)>YEAR('L1.00 Lead sheet'!$C$3),MONTH('L1.00 Lead sheet'!$C$3),YEAR(P14)=YEAR('L1.00 Lead sheet'!$C$3),IF(MONTH(P14)>=MONTH('L1.00 Lead sheet'!$C$3),MONTH('L1.00 Lead sheet'!$C$3),MONTH(P14)),YEAR(P14)<YEAR('L1.00 Lead sheet'!$C$3),0),(YEAR(E14)=YEAR('L1.00 Lead sheet'!$C$3)),MONTH('L1.00 Lead sheet'!$C$3)+1-(MONTH(E14)),YEAR(E14)>YEAR('L1.00 Lead sheet'!$C$3),0),_xlfn.IFS(EOMONTH(E14,G14-1)<DATE(YEAR('L1.00 Lead sheet'!$C$3),1,1),0,AND(DATE(YEAR('L1.00 Lead sheet'!$C$3),1,1)<EOMONTH(E14,G14-1),EOMONTH(E14,G14-1)<DATE(YEAR('L1.00 Lead sheet'!$C$3),MONTH('L1.00 Lead sheet'!$C$3),DAY('L1.00 Lead sheet'!$C$3))),IF(DATE(YEAR(N14),MONTH(N14),DAY(N14))<EOMONTH(E14,G14-1),MONTH(N14)-1,MONTH(EOMONTH(E14,G14-1))),EOMONTH(E14,G14-1)=DATE(YEAR('L1.00 Lead sheet'!$C$3),MONTH('L1.00 Lead sheet'!$C$3),DAY('L1.00 Lead sheet'!$C$3)),IF(DATE(YEAR(N14),MONTH(N14),DAY(N14))>EOMONTH(E14,G14-1),MONTH(EOMONTH(E14,G14-1)),MONTH(N14)-1),EOMONTH(E14,G14-1)>DATE(YEAR('L1.00 Lead sheet'!$C$3),MONTH('L1.00 Lead sheet'!$C$3),DAY('L1.00 Lead sheet'!$C$3)),IF(YEAR(E14)>YEAR('L1.00 Lead sheet'!$C$3),0,IF(YEAR(E14)=YEAR('L1.00 Lead sheet'!$C$3),IF(YEAR(N14)>YEAR('L1.00 Lead sheet'!$C$3),MONTH('L1.00 Lead sheet'!$C$3)-MONTH(E14)+1,MONTH(N14)-MONTH(E14)+1),_xlfn.IFS(YEAR(N14)>YEAR('L1.00 Lead sheet'!$C$3),MONTH('L1.00 Lead sheet'!$C$3),YEAR(N14)=YEAR('L1.00 Lead sheet'!$C$3),MONTH(N14)-1,YEAR(N14)<YEAR('L1.00 Lead sheet'!$C$3),0))))),0)} -> 0 | R14: =-(IFERROR(IF(J14=0,(O14*(1-F14))/G14*Q14,(J14*(1-F14))/G14*Q14),0)) -> 0 | S14: =R14-H14 -> 0 | T14: =IF(ABS(S14)>'L1.00 Lead sheet'!$C$6,"Note","w") -> w
P15: =IFERROR(EOMONTH(E15,G15-MONTH(1)),"") | Q15: {=IFERROR(IF(N15="",_xlfn.IFS(YEAR(E15)<YEAR('L1.00 Lead sheet'!$C$3),_xlfn.IFS(YEAR(P15)>YEAR('L1.00 Lead sheet'!$C$3),MONTH('L1.00 Lead sheet'!$C$3),YEAR(P15)=YEAR('L1.00 Lead sheet'!$C$3),IF(MONTH(P15)>=MONTH('L1.00 Lead sheet'!$C$3),MONTH('L1.00 Lead sheet'!$C$3),MONTH(P15)),YEAR(P15)<YEAR('L1.00 Lead sheet'!$C$3),0),(YEAR(E15)=YEAR('L1.00 Lead sheet'!$C$3)),MONTH('L1.00 Lead sheet'!$C$3)+1-(MONTH(E15)),YEAR(E15)>YEAR('L1.00 Lead sheet'!$C$3),0),_xlfn.IFS(EOMONTH(E15,G15-1)<DATE(YEAR('L1.00 Lead sheet'!$C$3),1,1),0,AND(DATE(YEAR('L1.00 Lead sheet'!$C$3),1,1)<EOMONTH(E15,G15-1),EOMONTH(E15,G15-1)<DATE(YEAR('L1.00 Lead sheet'!$C$3),MONTH('L1.00 Lead sheet'!$C$3),DAY('L1.00 Lead sheet'!$C$3))),IF(DATE(YEAR(N15),MONTH(N15),DAY(N15))<EOMONTH(E15,G15-1),MONTH(N15)-1,MONTH(EOMONTH(E15,G15-1))),EOMONTH(E15,G15-1)=DATE(YEAR('L1.00 Lead sheet'!$C$3),MONTH('L1.00 Lead sheet'!$C$3),DAY('L1.00 Lead sheet'!$C$3)),IF(DATE(YEAR(N15),MONTH(N15),DAY(N15))>EOMONTH(E15,G15-1),MONTH(EOMONTH(E15,G15-1)),MONTH(N15)-1),EOMONTH(E15,G15-1)>DATE(YEAR('L1.00 Lead sheet'!$C$3),MONTH('L1.00 Lead sheet'!$C$3),DAY('L1.00 Lead sheet'!$C$3)),IF(YEAR(E15)>YEAR('L1.00 Lead sheet'!$C$3),0,IF(YEAR(E15)=YEAR('L1.00 Lead sheet'!$C$3),IF(YEAR(N15)>YEAR('L1.00 Lead sheet'!$C$3),MONTH('L1.00 Lead sheet'!$C$3)-MONTH(E15)+1,MONTH(N15)-MONTH(E15)+1),_xlfn.IFS(YEAR(N15)>YEAR('L1.00 Lead sheet'!$C$3),MONTH('L1.00 Lead sheet'!$C$3),YEAR(N15)=YEAR('L1.00 Lead sheet'!$C$3),MONTH(N15)-1,YEAR(N15)<YEAR('L1.00 Lead sheet'!$C$3),0))))),0)} -> 0 | R15: =-(IFERROR(IF(J15=0,(O15*(1-F15))/G15*Q15,(J15*(1-F15))/G15*Q15),0)) -> 0 | S15: =R15-H15 -> 0 | T15: =IF(ABS(S15)>'L1.00 Lead sheet'!$C$6,"Note","w") -> w
P16: =IFERROR(EOMONTH(E16,G16-MONTH(1)),"") | Q16: {=IFERROR(IF(N16="",_xlfn.IFS(YEAR(E16)<YEAR('L1.00 Lead sheet'!$C$3),_xlfn.IFS(YEAR(P16)>YEAR('L1.00 Lead sheet'!$C$3),MONTH('L1.00 Lead sheet'!$C$3),YEAR(P16)=YEAR('L1.00 Lead sheet'!$C$3),IF(MONTH(P16)>=MONTH('L1.00 Lead sheet'!$C$3),MONTH('L1.00 Lead sheet'!$C$3),MONTH(P16)),YEAR(P16)<YEAR('L1.00 Lead sheet'!$C$3),0),(YEAR(E16)=YEAR('L1.00 Lead sheet'!$C$3)),MONTH('L1.00 Lead sheet'!$C$3)+1-(MONTH(E16)),YEAR(E16)>YEAR('L1.00 Lead sheet'!$C$3),0),_xlfn.IFS(EOMONTH(E16,G16-1)<DATE(YEAR('L1.00 Lead sheet'!$C$3),1,1),0,AND(DATE(YEAR('L1.00 Lead sheet'!$C$3),1,1)<EOMONTH(E16,G16-1),EOMONTH(E16,G16-1)<DATE(YEAR('L1.00 Lead sheet'!$C$3),MONTH('L1.00 Lead sheet'!$C$3),DAY('L1.00 Lead sheet'!$C$3))),IF(DATE(YEAR(N16),MONTH(N16),DAY(N16))<EOMONTH(E16,G16-1),MONTH(N16)-1,MONTH(EOMONTH(E16,G16-1))),EOMONTH(E16,G16-1)=DATE(YEAR('L1.00 Lead sheet'!$C$3),MONTH('L1.00 Lead sheet'!$C$3),DAY('L1.00 Lead sheet'!$C$3)),IF(DATE(YEAR(N16),MONTH(N16),DAY(N16))>EOMONTH(E16,G16-1),MONTH(EOMONTH(E16,G16-1)),MONTH(N16)-1),EOMONTH(E16,G16-1)>DATE(YEAR('L1.00 Lead sheet'!$C$3),MONTH('L1.00 Lead sheet'!$C$3),DAY('L1.00 Lead sheet'!$C$3)),IF(YEAR(E16)>YEAR('L1.00 Lead sheet'!$C$3),0,IF(YEAR(E16)=YEAR('L1.00 Lead sheet'!$C$3),IF(YEAR(N16)>YEAR('L1.00 Lead sheet'!$C$3),MONTH('L1.00 Lead sheet'!$C$3)-MONTH(E16)+1,MONTH(N16)-MONTH(E16)+1),_xlfn.IFS(YEAR(N16)>YEAR('L1.00 Lead sheet'!$C$3),MONTH('L1.00 Lead sheet'!$C$3),YEAR(N16)=YEAR('L1.00 Lead sheet'!$C$3),MONTH(N16)-1,YEAR(N16)<YEAR('L1.00 Lead sheet'!$C$3),0))))),0)} -> 0 | R16: =-(IFERROR(IF(J16=0,(O16*(1-F16))/G16*Q16,(J16*(1-F16))/G16*Q16),0)) -> 0 | S16: =R16-H16 -> 0 | T16: =IF(ABS(S16)>'L1.00 Lead sheet'!$C$6,"Note","w") -> w
P17: =IFERROR(EOMONTH(E17,G17-MONTH(1)),"") | Q17: {=IFERROR(IF(N17="",_xlfn.IFS(YEAR(E17)<YEAR('L1.00 Lead sheet'!$C$3),_xlfn.IFS(YEAR(P17)>YEAR('L1.00 Lead sheet'!$C$3),MONTH('L1.00 Lead sheet'!$C$3),YEAR(P17)=YEAR('L1.00 Lead sheet'!$C$3),IF(MONTH(P17)>=MONTH('L1.00 Lead sheet'!$C$3),MONTH('L1.00 Lead sheet'!$C$3),MONTH(P17)),YEAR(P17)<YEAR('L1.00 Lead sheet'!$C$3),0),(YEAR(E17)=YEAR('L1.00 Lead sheet'!$C$3)),MONTH('L1.00 Lead sheet'!$C$3)+1-(MONTH(E17)),YEAR(E17)>YEAR('L1.00 Lead sheet'!$C$3),0),_xlfn.IFS(EOMONTH(E17,G17-1)<DATE(YEAR('L1.00 Lead sheet'!$C$3),1,1),0,AND(DATE(YEAR('L1.00 Lead sheet'!$C$3),1,1)<EOMONTH(E17,G17-1),EOMONTH(E17,G17-1)<DATE(YEAR('L1.00 Lead sheet'!$C$3),MONTH('L1.00 Lead sheet'!$C$3),DAY('L1.00 Lead sheet'!$C$3))),IF(DATE(YEAR(N17),MONTH(N17),DAY(N17))<EOMONTH(E17,G17-1),MONTH(N17)-1,MONTH(EOMONTH(E17,G17-1))),EOMONTH(E17,G17-1)=DATE(YEAR('L1.00 Lead sheet'!$C$3),MONTH('L1.00 Lead sheet'!$C$3),DAY('L1.00 Lead sheet'!$C$3)),IF(DATE(YEAR(N17),MONTH(N17),DAY(N17))>EOMONTH(E17,G17-1),MONTH(EOMONTH(E17,G17-1)),MONTH(N17)-1),EOMONTH(E17,G17-1)>DATE(YEAR('L1.00 Lead sheet'!$C$3),MONTH('L1.00 Lead sheet'!$C$3),DAY('L1.00 Lead sheet'!$C$3)),IF(YEAR(E17)>YEAR('L1.00 Lead sheet'!$C$3),0,IF(YEAR(E17)=YEAR('L1.00 Lead sheet'!$C$3),IF(YEAR(N17)>YEAR('L1.00 Lead sheet'!$C$3),MONTH('L1.00 Lead sheet'!$C$3)-MONTH(E17)+1,MONTH(N17)-MONTH(E17)+1),_xlfn.IFS(YEAR(N17)>YEAR('L1.00 Lead sheet'!$C$3),MONTH('L1.00 Lead sheet'!$C$3),YEAR(N17)=YEAR('L1.00 Lead sheet'!$C$3),MONTH(N17)-1,YEAR(N17)<YEAR('L1.00 Lead sheet'!$C$3),0))))),0)} -> 0 | R17: =-(IFERROR(IF(J17=0,(O17*(1-F17))/G17*Q17,(J17*(1-F17))/G17*Q17),0)) -> 0 | S17: =R17-H17 -> 0 | T17: =IF(ABS(S17)>'L1.00 Lead sheet'!$C$6,"Note","w") -> w
D18: 合计 | H18: =SUM(H12:H17) -> 0 | I18: =SUM(I12:I17) -> 0 | J18: =SUM(J12:J17) -> 0 | K18: =SUM(K12:K17) -> 0 | L18: =SUM(L12:L17) -> 0 | M18: =SUM(M12:M17) -> 0 | O18: =SUM(O12:O17) -> 0 | R18: =SUM(R12:R17) -> 0 | S18: =SUM(S12:S17) -> 0 | T18: =IF(ABS(S18)>'L1.00 Lead sheet'!$C$6,"Note","w") -> w
H19: Rx | I19: Rx | J19: Rx | K19: Rx | L19: Rx | M19: Rx | O19: Rx | R19: Rx
B21: 检查无形资产各项目的摊销政策是否符合有关规定，是否与上期一致，其是否具有商业合理性。若改变摊销政策，检查其依据是否充分。
B22: 表2 公司摊销政策复核表
B23: 资产类别 | C23: =YEAR('L1.00 Lead sheet'!C3)&"年度" -> 2025年度 | D23: =YEAR('L1.00 Lead sheet'!C3)-1&"年度" -> 2024年度 | E23: 差异 | F23: 差异说明 | G23: 使用寿命的
C24: 使用寿命 | D24: 使用寿命 | G24: 商业合理性分析
B25: ='L1.01.1 Agree SL to GL'!F10 -> 土地使用权 | E25: =C25=D25 -> TRUE
B26: ='L1.01.1 Agree SL to GL'!I10 -> 软件 | E26: =C26=D26 -> TRUE
B27: ='L1.01.1 Agree SL to GL'!L10 -> 商标权 | E27: =C27=D27 -> TRUE
B28: ='L1.01.1 Agree SL to GL'!O10 -> 专利权 | E28: =C28=D28 -> TRUE
B29: ='L1.01.1 Agree SL to GL'!R10 -> 特许权 | E29: =C29=D29 -> TRUE

Sheet L1.03 摊销测试 (20241231)
B1: 标准工作底稿: L1 SWP 无形资产
B2: L1.03：详细测试 (摊销)
B4: 注：1.如果下列表格不适用，项目组可以自定义下方无形资产清单表格，也可直接使用系统导出的无形资产清单，但必须确保必需字段完整。
B5: 2.无形资产的类别：请使用被审计单位的台账，无需对资产的类别添加自己的重分类修改，资产类别应当与L1.01.1中列示的类别匹配。
B7: 返回汇总页
B9: 按公司的摊销政策重新计算本年应计提的摊销费用并与账面本年摊销费用比对。重新计算摊销出现差异的，我们进行进一步核查以得出结论。
B10: |-------------------------------------------------------------------------------------------------------------------------------------------------必需字段*----------------------------------------------------------------------------------------------------------------------------------------------------------|
B11: 表1 无形资产明细清单 | N11: 若处置或报废，须填写 | P11: EY Works
A12: 公司主体 | B12: 无形资产编号 | C12: 无形资产名称 | D12: 无形资产类别 | E12: 入账开始日期 | F12: 残值率 | G12: 使用寿命(月) | H12: 本期摊销 | I12: 本期计提减值准备 | J12: 期末原值 | K12: 期末累计摊销 | L12: 期末减值准备 | M12: 期末净值 | N12: 处置日期 | O12: 原值减少金额 | P12: 提足折旧时间 | Q12: 本期应摊销月数 | R12: 本期应摊销金额 | S12: 本期差异 | T12: 标记
A13: 东风鸿远工程咨询有限公司 | B13: SJY0067 | C13: 设计院土地使用权 | D13: 土地使用权 | E13: 44113 | F13: 0 | G13: 480 | H13: 145611.12 | I13: 0 | J13: 8736666 | K13: 1055359.5 | L13: 0 | M13: =J13-K13-L13 -> 7681306.5 | N13: NA | O13: NA | P13: =IFERROR(EOMONTH(E13,G13-MONTH(1)),"") -> 58714 | Q13: 8 | R13: =-(IFERROR(IF(J13=0,(O13*(1-F13))/G13*Q13,(J13*(1-F13))/G13*Q13),0)) -> -145611.1 | S13: =R13+H13 -> 0.020666667 | T13: =IF(ABS(S13)>'L1.00 Lead sheet'!$C$6,"Note","w") -> w
A14: 东风鸿远工程咨询有限公司 | B14: SJY0068 | C14: 勘察设计软件 | D14: 软件 | E14: 43175 | F14: 0 | G14: 60 | H14: 0 | I14: 0 | J14: 50943.4 | K14: 50943.4 | L14: 0 | M14: =J14-K14-L14 -> 0 | N14: NA | O14: NA | P14: =IFERROR(EOMONTH(E14,G14-MONTH(1)),"") -> 44985 | Q14: {=IFERROR(IF(N14="",_xlfn.IFS(YEAR(E14)<YEAR('L1.00 Lead sheet'!$C$3),_xlfn.IFS(YEAR(P14)>YEAR('L1.00 Lead sheet'!$C$3),MONTH('L1.00 Lead sheet'!$C$3),YEAR(P14)=YEAR('L1.00 Lead sheet'!$C$3),IF(MONTH(P14)>=MONTH('L1.00 Lead sheet'!$C$3),MONTH('L1.00 Lead sheet'!$C$3),MONTH(P14)),YEAR(P14)<YEAR('L1.00 Lead sheet'!$C$3),0),(YEAR(E14)=YEAR('L1.00 Lead sheet'!$C$3)),MONTH('L1.00 Lead sheet'!$C$3)+1-(MONTH(E14)),YEAR(E14)>YEAR('L1.00 Lead sheet'!$C$3),0),_xlfn.IFS(EOMONTH(E14,G14-1)<DATE(YEAR('L1.00 Lead sheet'!$C$3),1,1),0,AND(DATE(YEAR('L1.00 Lead sheet'!$C$3),1,1)<EOMONTH(E14,G14-1),EOMONTH(E14,G14-1)<DATE(YEAR('L1.00 Lead sheet'!$C$3),MONTH('L1.00 Lead sheet'!$C$3),DAY('L1.00 Lead sheet'!$C$3))),IF(DATE(YEAR(N14),MONTH(N14),DAY(N14))<EOMONTH(E14,G14-1),MONTH(N14)-1,MONTH(EOMONTH(E14,G14-1))),EOMONTH(E14,G14-1)=DATE(YEAR('L1.00 Lead sheet'!$C$3),MONTH('L1.00 Lead sheet'!$C$3),DAY('L1.00 Lead sheet'!$C$3)),IF(DATE(YEAR(N14),MONTH(N14),DAY(N14))>EOMONTH(E14,G14-1),MONTH(EOMONTH(E14,G14-1)),MONTH(N14)-1),EOMONTH(E14,G14-1)>DATE(YEAR('L1.00 Lead sheet'!$C$3),MONTH('L1.00 Lead sheet'!$C$3),DAY('L1.00 Lead sheet'!$C$3)),IF(YEAR(E14)>YEAR('L1.00 Lead sheet'!$C$3),0,IF(YEAR(E14)=YEAR('L1.00 Lead sheet'!$C$3),IF(YEAR(N14)>YEAR('L1.00 Lead sheet'!$C$3),MONTH('L1.00 Lead sheet'!$C$3)-MONTH(E14)+1,MONTH(N14)-MONTH(E14)+1),_xlfn.IFS(YEAR(N14)>YEAR('L1.00 Lead sheet'!$C$3),MONTH('L1.00 Lead sheet'!$C$3),YEAR(N14)=YEAR('L1.00 Lead sheet'!$C$3),MONTH(N14)-1,YEAR(N14)<YEAR('L1.00 Lead sheet'!$C$3),0))))),0)} -> 0 | R14: =-(IFERROR(IF(J14=0,(O14*(1-F14))/G14*Q14,(J14*(1-F14))/G14*Q14),0)) -> 0 | S14: =R14-H14 -> 0 | T14: =IF(ABS(S14)>'L1.00 Lead sheet'!$C$6,"Note","w") -> w
A15: 东风鸿远工程咨询有限公司 | B15: SJY0069 | C15: 挡土墙设计软件 | D15: 软件 | E15: 43255 | F15: 0 | G15: 60 | H15: 0 | I15: 0 | J15: 21551.72 | K15: 21551.72 | L15: 0 | M15: =J15-K15-L15 -> 0 | N15: NA | O15: NA | P15: =IFERROR(EOMONTH(E15,G15-MONTH(1)),"") -> 45077 | Q15: {=IFERROR(IF(N15="",_xlfn.IFS(YEAR(E15)<YEAR('L1.00 Lead sheet'!$C$3),_xlfn.IFS(YEAR(P15)>YEAR('L1.00 Lead sheet'!$C$3),MONTH('L1.00 Lead sheet'!$C$3),YEAR(P15)=YEAR('L1.00 Lead sheet'!$C$3),IF(MONTH(P15)>=MONTH('L1.00 Lead sheet'!$C$3),MONTH('L1.00 Lead sheet'!$C$3),MONTH(P15)),YEAR(P15)<YEAR('L1.00 Lead sheet'!$C$3),0),(YEAR(E15)=YEAR('L1.00 Lead sheet'!$C$3)),MONTH('L1.00 Lead sheet'!$C$3)+1-(MONTH(E15)),YEAR(E15)>YEAR('L1.00 Lead sheet'!$C$3),0),_xlfn.IFS(EOMONTH(E15,G15-1)<DATE(YEAR('L1.00 Lead sheet'!$C$3),1,1),0,AND(DATE(YEAR('L1.00 Lead sheet'!$C$3),1,1)<EOMONTH(E15,G15-1),EOMONTH(E15,G15-1)<DATE(YEAR('L1.00 Lead sheet'!$C$3),MONTH('L1.00 Lead sheet'!$C$3),DAY('L1.00 Lead sheet'!$C$3))),IF(DATE(YEAR(N15),MONTH(N15),DAY(N15))<EOMONTH(E15,G15-1),MONTH(N15)-1,MONTH(EOMONTH(E15,G15-1))),EOMONTH(E15,G15-1)=DATE(YEAR('L1.00 Lead sheet'!$C$3),MONTH('L1.00 Lead sheet'!$C$3),DAY('L1.00 Lead sheet'!$C$3)),IF(DATE(YEAR(N15),MONTH(N15),DAY(N15))>EOMONTH(E15,G15-1),MONTH(EOMONTH(E15,G15-1)),MONTH(N15)-1),EOMONTH(E15,G15-1)>DATE(YEAR('L1.00 Lead sheet'!$C$3),MONTH('L1.00 Lead sheet'!$C$3),DAY('L1.00 Lead sheet'!$C$3)),IF(YEAR(E15)>YEAR('L1.00 Lead sheet'!$C$3),0,IF(YEAR(E15)=YEAR('L1.00 Lead sheet'!$C$3),IF(YEAR(N15)>YEAR('L1.00 Lead sheet'!$C$3),MONTH('L1.00 Lead sheet'!$C$3)-MONTH(E15)+1,MONTH(N15)-MONTH(E15)+1),_xlfn.IFS(YEAR(N15)>YEAR('L1.00 Lead sheet'!$C$3),MONTH('L1.00 Lead sheet'!$C$3),YEAR(N15)=YEAR('L1.00 Lead sheet'!$C$3),MONTH(N15)-1,YEAR(N15)<YEAR('L1.00 Lead sheet'!$C$3),0))))),0)} -> 0 | R15: =-(IFERROR(IF(J15=0,(O15*(1-F15))/G15*Q15,(J15*(1-F15))/G15*Q15),0)) -> 0 | S15: =R15-H15 -> 0 | T15: =IF(ABS(S15)>'L1.00 Lead sheet'!$C$6,"Note","w") -> w
A16: 东风鸿远工程咨询有限公司 | B16: SJY0144 | C16: 金慧综合管理系统 | D16: 软件 | E16: 44575 | F16: 0 | G16: 120 | H16: 88014 | I16: 0 | J16: 1251527.8 | K16: 404392.79 | L16: 0 | M16: =J16-K16-L16 -> 847135.05 | N16: NA | O16: NA | P16: =IFERROR(EOMONTH(E16,G16-MONTH(1)),"") -> 48213 | Q16: 8 | R16: =-(IFERROR(IF(J16=0,(O16*(1-F16))/G16*Q16,(J16*(1-F16))/G16*Q16),0)) -> -83435.189 | S16: =R16+H16 -> 4578.8107 | T16: =IF(ABS(S16)>'L1.00 Lead sheet'!$C$6,"Note","w") -> w
A17: 东风鸿远工程咨询有限公司 | B17: ZCLB0716 | C17: “多测合一”生产软件（SISS）V1.0 | D17: 软件 | E17: 45302 | F17: 0 | G17: 60 | H17: 12389.36 | I17: 0 | J17: 92920.36 | K17: 24778.72 | L17: 0 | M17: =J17-K17-L17 -> 68141.64 | N17: NA | O17: NA | P17: =IFERROR(EOMONTH(E17,G17-MONTH(1)),"") -> 47118 | Q17: 8 | R17: =-(IFERROR(IF(J17=0,(O17*(1-F17))/G17*Q17,(J17*(1-F17))/G17*Q17),0)) -> -12389.381 | S17: =R17+H17 -> -0.021333333 | T17: =IF(ABS(S17)>'L1.00 Lead sheet'!$C$6,"Note","w") -> w
A18: 东风鸿远工程咨询有限公司 | B18: ZCLB0718 | C18: 大疆智图永久版、LiDAR360软件 | D18: 软件 | E18: 45392 | F18: 0 | G18: 60 | H18: 7551.6 | I18: 0 | J18: 56637.17 | K18: 16047.17 | L18: 0 | M18: =J18-K18-L18 -> 40590 | N18: NA | O18: NA | P18: =IFERROR(EOMONTH(E18,G18-MONTH(1)),"") -> 47208 | Q18: 8 | R18: =-(IFERROR(IF(J18=0,(O18*(1-F18))/G18*Q18,(J18*(1-F18))/G18*Q18),0)) -> -7551.6227 | S18: =R18+H18 -> -0.022666667 | T18: =IF(ABS(S18)>'L1.00 Lead sheet'!$C$6,"Note","w") -> w
A19: 东风鸿远工程咨询有限公司武汉分公司 | B19: 1 | C19: IT软件 | D19: IT软件 | E19: 44958 | F19: 0 | G19: 60 | H19: 28668.12 | I19: 0 | J19: 143340.7 | K19: 52558.22 | L19: 0 | M19: =J19-K19-L19 -> 90782.48 | N19: NA | O19: NA | P19: =IFERROR(EOMONTH(E19,G19-MONTH(1)),"") -> 46783 | Q19: 12 | R19: =-(IFERROR(IF(J19=0,(O19*(1-F19))/G19*Q19,(J19*(1-F19))/G19*Q19),0)) -> -28668.14 | S19: =R19+H19 -> -0.02 | T19: =IF(ABS(S19)>'L1.00 Lead sheet'!$C$6,"Note","w") -> w
P20: =IFERROR(EOMONTH(E20,G20-MONTH(1)),"") | Q20: {=IFERROR(IF(N20="",_xlfn.IFS(YEAR(E20)<YEAR('L1.00 Lead sheet'!$C$3),_xlfn.IFS(YEAR(P20)>YEAR('L1.00 Lead sheet'!$C$3),MONTH('L1.00 Lead sheet'!$C$3),YEAR(P20)=YEAR('L1.00 Lead sheet'!$C$3),IF(MONTH(P20)>=MONTH('L1.00 Lead sheet'!$C$3),MONTH('L1.00 Lead sheet'!$C$3),MONTH(P20)),YEAR(P20)<YEAR('L1.00 Lead sheet'!$C$3),0),(YEAR(E20)=YEAR('L1.00 Lead sheet'!$C$3)),MONTH('L1.00 Lead sheet'!$C$3)+1-(MONTH(E20)),YEAR(E20)>YEAR('L1.00 Lead sheet'!$C$3),0),_xlfn.IFS(EOMONTH(E20,G20-1)<DATE(YEAR('L1.00 Lead sheet'!$C$3),1,1),0,AND(DATE(YEAR('L1.00 Lead sheet'!$C$3),1,1)<EOMONTH(E20,G20-1),EOMONTH(E20,G20-1)<DATE(YEAR('L1.00 Lead sheet'!$C$3),MONTH('L1.00 Lead sheet'!$C$3),DAY('L1.00 Lead sheet'!$C$3))),IF(DATE(YEAR(N20),MONTH(N20),DAY(N20))<EOMONTH(E20,G20-1),MONTH(N20)-1,MONTH(EOMONTH(E20,G20-1))),EOMONTH(E20,G20-1)=DATE(YEAR('L1.00 Lead sheet'!$C$3),MONTH('L1.00 Lead sheet'!$C$3),DAY('L1.00 Lead sheet'!$C$3)),IF(DATE(YEAR(N20),MONTH(N20),DAY(N20))>EOMONTH(E20,G20-1),MONTH(EOMONTH(E20,G20-1)),MONTH(N20)-1),EOMONTH(E20,G20-1)>DATE(YEAR('L1.00 Lead sheet'!$C$3),MONTH('L1.00 Lead sheet'!$C$3),DAY('L1.00 Lead sheet'!$C$3)),IF(YEAR(E20)>YEAR('L1.00 Lead sheet'!$C$3),0,IF(YEAR(E20)=YEAR('L1.00 Lead sheet'!$C$3),IF(YEAR(N20)>YEAR('L1.00 Lead sheet'!$C$3),MONTH('L1.00 Lead sheet'!$C$3)-MONTH(E20)+1,MONTH(N20)-MONTH(E20)+1),_xlfn.IFS(YEAR(N20)>YEAR('L1.00 Lead sheet'!$C$3),MONTH('L1.00 Lead sheet'!$C$3),YEAR(N20)=YEAR('L1.00 Lead sheet'!$C$3),MONTH(N20)-1,YEAR(N20)<YEAR('L1.00 Lead sheet'!$C$3),0))))),0)} -> 0 | R20: =-(IFERROR(IF(J20=0,(O20*(1-F20))/G20*Q20,(J20*(1-F20))/G20*Q20),0)) -> 0 | S20: =R20-H20 -> 0 | T20: =IF(ABS(S20)>'L1.00 Lead sheet'!$C$6,"Note","w") -> w
P21: =IFERROR(EOMONTH(E21,G21-MONTH(1)),"") | Q21: {=IFERROR(IF(N21="",_xlfn.IFS(YEAR(E21)<YEAR('L1.00 Lead sheet'!$C$3),_xlfn.IFS(YEAR(P21)>YEAR('L1.00 Lead sheet'!$C$3),MONTH('L1.00 Lead sheet'!$C$3),YEAR(P21)=YEAR('L1.00 Lead sheet'!$C$3),IF(MONTH(P21)>=MONTH('L1.00 Lead sheet'!$C$3),MONTH('L1.00 Lead sheet'!$C$3),MONTH(P21)),YEAR(P21)<YEAR('L1.00 Lead sheet'!$C$3),0),(YEAR(E21)=YEAR('L1.00 Lead sheet'!$C$3)),MONTH('L1.00 Lead sheet'!$C$3)+1-(MONTH(E21)),YEAR(E21)>YEAR('L1.00 Lead sheet'!$C$3),0),_xlfn.IFS(EOMONTH(E21,G21-1)<DATE(YEAR('L1.00 Lead sheet'!$C$3),1,1),0,AND(DATE(YEAR('L1.00 Lead sheet'!$C$3),1,1)<EOMONTH(E21,G21-1),EOMONTH(E21,G21-1)<DATE(YEAR('L1.00 Lead sheet'!$C$3),MONTH('L1.00 Lead sheet'!$C$3),DAY('L1.00 Lead sheet'!$C$3))),IF(DATE(YEAR(N21),MONTH(N21),DAY(N21))<EOMONTH(E21,G21-1),MONTH(N21)-1,MONTH(EOMONTH(E21,G21-1))),EOMONTH(E21,G21-1)=DATE(YEAR('L1.00 Lead sheet'!$C$3),MONTH('L1.00 Lead sheet'!$C$3),DAY('L1.00 Lead sheet'!$C$3)),IF(DATE(YEAR(N21),MONTH(N21),DAY(N21))>EOMONTH(E21,G21-1),MONTH(EOMONTH(E21,G21-1)),MONTH(N21)-1),EOMONTH(E21,G21-1)>DATE(YEAR('L1.00 Lead sheet'!$C$3),MONTH('L1.00 Lead sheet'!$C$3),DAY('L1.00 Lead sheet'!$C$3)),IF(YEAR(E21)>YEAR('L1.00 Lead sheet'!$C$3),0,IF(YEAR(E21)=YEAR('L1.00 Lead sheet'!$C$3),IF(YEAR(N21)>YEAR('L1.00 Lead sheet'!$C$3),MONTH('L1.00 Lead sheet'!$C$3)-MONTH(E21)+1,MONTH(N21)-MONTH(E21)+1),_xlfn.IFS(YEAR(N21)>YEAR('L1.00 Lead sheet'!$C$3),MONTH('L1.00 Lead sheet'!$C$3),YEAR(N21)=YEAR('L1.00 Lead sheet'!$C$3),MONTH(N21)-1,YEAR(N21)<YEAR('L1.00 Lead sheet'!$C$3),0))))),0)} -> 0 | R21: =-(IFERROR(IF(J21=0,(O21*(1-F21))/G21*Q21,(J21*(1-F21))/G21*Q21),0)) -> 0 | S21: =R21-H21 -> 0 | T21: =IF(ABS(S21)>'L1.00 Lead sheet'!$C$6,"Note","w") -> w
P22: =IFERROR(EOMONTH(E22,G22-MONTH(1)),"") | Q22: {=IFERROR(IF(N22="",_xlfn.IFS(YEAR(E22)<YEAR('L1.00 Lead sheet'!$C$3),_xlfn.IFS(YEAR(P22)>YEAR('L1.00 Lead sheet'!$C$3),MONTH('L1.00 Lead sheet'!$C$3),YEAR(P22)=YEAR('L1.00 Lead sheet'!$C$3),IF(MONTH(P22)>=MONTH('L1.00 Lead sheet'!$C$3),MONTH('L1.00 Lead sheet'!$C$3),MONTH(P22)),YEAR(P22)<YEAR('L1.00 Lead sheet'!$C$3),0),(YEAR(E22)=YEAR('L1.00 Lead sheet'!$C$3)),MONTH('L1.00 Lead sheet'!$C$3)+1-(MONTH(E22)),YEAR(E22)>YEAR('L1.00 Lead sheet'!$C$3),0),_xlfn.IFS(EOMONTH(E22,G22-1)<DATE(YEAR('L1.00 Lead sheet'!$C$3),1,1),0,AND(DATE(YEAR('L1.00 Lead sheet'!$C$3),1,1)<EOMONTH(E22,G22-1),EOMONTH(E22,G22-1)<DATE(YEAR('L1.00 Lead sheet'!$C$3),MONTH('L1.00 Lead sheet'!$C$3),DAY('L1.00 Lead sheet'!$C$3))),IF(DATE(YEAR(N22),MONTH(N22),DAY(N22))<EOMONTH(E22,G22-1),MONTH(N22)-1,MONTH(EOMONTH(E22,G22-1))),EOMONTH(E22,G22-1)=DATE(YEAR('L1.00 Lead sheet'!$C$3),MONTH('L1.00 Lead sheet'!$C$3),DAY('L1.00 Lead sheet'!$C$3)),IF(DATE(YEAR(N22),MONTH(N22),DAY(N22))>EOMONTH(E22,G22-1),MONTH(EOMONTH(E22,G22-1)),MONTH(N22)-1),EOMONTH(E22,G22-1)>DATE(YEAR('L1.00 Lead sheet'!$C$3),MONTH('L1.00 Lead sheet'!$C$3),DAY('L1.00 Lead sheet'!$C$3)),IF(YEAR(E22)>YEAR('L1.00 Lead sheet'!$C$3),0,IF(YEAR(E22)=YEAR('L1.00 Lead sheet'!$C$3),IF(YEAR(N22)>YEAR('L1.00 Lead sheet'!$C$3),MONTH('L1.00 Lead sheet'!$C$3)-MONTH(E22)+1,MONTH(N22)-MONTH(E22)+1),_xlfn.IFS(YEAR(N22)>YEAR('L1.00 Lead sheet'!$C$3),MONTH('L1.00 Lead sheet'!$C$3),YEAR(N22)=YEAR('L1.00 Lead sheet'!$C$3),MONTH(N22)-1,YEAR(N22)<YEAR('L1.00 Lead sheet'!$C$3),0))))),0)} -> 0 | R22: =-(IFERROR(IF(J22=0,(O22*(1-F22))/G22*Q22,(J22*(1-F22))/G22*Q22),0)) -> 0 | S22: =R22-H22 -> 0 | T22: =IF(ABS(S22)>'L1.00 Lead sheet'!$C$6,"Note","w") -> w
D23: 合计 | H23: =SUM(H12:H22) -> 282234.2 | I23: =SUM(I12:I22) -> 0 | J23: =SUM(J12:J22) -> 10353587 | K23: =SUM(K12:K22) -> 1625631.5 | L23: =SUM(L12:L22) -> 0 | M23: =SUM(M12:M22) -> 8727955.6 | O23: =SUM(O12:O22) -> 0 | R23: =SUM(R12:R22) -> -277655.43 | S23: =SUM(S12:S22) -> 4578.7673 | T23: =IF(ABS(S23)>'L1.00 Lead sheet'!$C$6,"Note","w") -> w
H24: Rx | I24: Rx | J24: Rx | K24: Rx | L24: Rx | M24: Rx | O24: Rx | R24: Rx
B26: 检查无形资产各项目的摊销政策是否符合有关规定，是否与上期一致，其是否具有商业合理性。若改变摊销政策，检查其依据是否充分。
B27: 表2 公司摊销政策复核表
B28: 资产类别 | C28: =YEAR('L1.00 Lead sheet'!C3)-1&"年度" -> 2024年度 | D28: =YEAR('L1.00 Lead sheet'!C3)-1-1&"年度" -> 2023年度 | E28: 差异 | F28: 差异说明 | G28: 使用寿命的
C29: 使用寿命 | D29: 使用寿命 | G29: 商业合理性分析
B30: ='L1.01.1 Agree SL to GL'!F10 -> 土地使用权 | C30: 30-50年 | D30: 30-50年 | E30: =C30=D30 -> TRUE | F30: NA | G30: 是
B31: ='L1.01.1 Agree SL to GL'!I10 -> 软件 | C31: 5年 | D31: 5年 | E31: =C31=D31 -> TRUE | F31: NA | G31: 是
B32: ='L1.01.1 Agree SL to GL'!L10 -> 商标权 | C32: NA | D32: NA | E32: =C32=D32 -> TRUE | F32: NA | G32: NA
B33: ='L1.01.1 Agree SL to GL'!O10 -> 专利权 | C33: NA | D33: NA | E33: =C33=D33 -> TRUE | F33: NA | G33: NA
B34: ='L1.01.1 Agree SL to GL'!R10 -> 特许权 | C34: NA | D34: NA | E34: =C34=D34 -> TRUE | F34: NA | G34: NA

Sheet SkywindSettingSheet
A1: b8e777cf-a974-4dca-af89-7da1caee1666
