Workbook
Name balanceofAS: [1]C_100Breakdown!$O$37:$O$47110
Name balanceofDep: [1]C_110函证控制表!$S$32:$S$64073
Name balanceofGua: [1]C_110函证控制表!$AW$32:$AW$64073
Name balanceofLC: [1]C_110函证控制表!$CB$32:$CB$64073
Name balanceofLoan: [1]C_110函证控制表!$AA$32:$AA$64073
Name commercialBill: [1]C_110函证控制表!$BW$32:$BW$64073
Name creditorLoan: [1]C_110函证控制表!$AL$32:$AL$64073
Name CurrencyCodes: #REF!
Name currencyT: [1]C_100Breakdown!$K$37:$K$47110
Name CurrentLanguage: #REF!
Name debtorLoan: [1]C_110函证控制表!$AR$32:$AR$64073
Name EYCanvasAnswer: #REF!
Name FEtradingContract: [1]C_110函证控制表!$CI$32:$CI$64073
Name guaranteebyBank: [1]C_110函证控制表!$BC$32:$BC$64073
Name inCurrencyCode: #REF!
Name inFinalDol: #REF!
Name inOverallEval: #REF!
Name inPeriod: #REF!
Name inPlannedLevel: #REF!
Name inTolerableError: #REF!
Name isCancelled: [1]C_100Breakdown!$V$37:$V$47110
Name numberofAccCancelled: [1]C_110函证控制表!$AG$32:$AG$64073
Name otherpropertyDocs: [1]C_110函证控制表!$CO$32:$CO$64073
Name ScopeCompany: #REF!
Name sd_format: "yyyy/m/d"
Name sdt_format: "yyyy/m/d hh:mm"
Name TypeofCur: [1]C_110函证控制表!$O$32:$O$64073
Name unduecommercialBill: [1]C_110函证控制表!$BO$32:$BO$64073
Name unduefinancialM: [1]C_110函证控制表!$CS$32:$CS$64073
Name uppaidacceptanceBill: [1]C_110函证控制表!$BI$32:$BI$64073

Sheet 后推明细表
C2: 固定资产类别 | E2: 非专利技术 | H2: 其他 | K2: 软件 | N2: 土地使用权 | Q2: 专利权 | T2: 其他 | W2: 合计
D3: 账面数 | E3: 账表调整/审计调整 | F3: 审定数 | G3: 账面数 | H3: 账表调整/审计调整 | I3: 审定数 | J3: 账面数 | K3: 账表调整/审计调整 | L3: 审定数 | M3: 账面数 | O3: 审定数 | P3: 账面数 | R3: 审定数 | S3: 账面数 | U3: 审定数 | V3: 账面数 | W3: 账表调整/审计调整 | X3: 审定数 | Y3: A3 | Z3: check
C4: 年初余额 | D4: 3.0883473e+09 | F4: 3.0883473e+09 | G4: 4.1174757e+09 | I4: 4.1174757e+09 | J4: 6.6513516e+08 | L4: 6.6513516e+08 | M4: 2.894701e+08 | N4: 211 | O4: 2.894701e+08 | P4: 5.8486655e+09 | R4: 5.8486655e+09 | V4: =SUM(D4,G4,M4,J4,S4,P4) -> 1.4009094e+10 | W4: =SUM(E4,H4,K4,N4,T4) -> 211 | X4: =SUM(F4,I4,L4,O4,U4,R4) -> 1.4009094e+10
C5: 购置 | D5: 57749.96 | F5: =SUM(D5:E5) -> 57749.96 | G5: 1200445.2 | I5: =SUM(G5:H5) -> 1200445.2 | J5: 0 | L5: =SUM(J5:K5) -> 0 | M5: 0 | O5: =SUM(M5:N5) -> 0 | P5: 184433.97 | R5: =SUM(P5:Q5) -> 184433.97 | V5: =SUM(D5,G5,M5,J5,S5,P5) -> 1442629.1 | W5: =SUM(E5,H5,K5,N5,T5) -> 0 | X5: =SUM(F5,I5,L5,O5,U5,R5) -> 1442629.1
C6: 在建工程转入 | D6: 6357331.2 | F6: =SUM(D6:E6) -> 6357331.2 | G6: 8381434.1 | I6: =SUM(G6:H6) -> 8381434.1 | J6: 11075453 | L6: =SUM(J6:K6) -> 11075453 | M6: 0 | O6: =SUM(M6:N6) -> 0 | P6: 5572619.2 | R6: =SUM(P6:Q6) -> 5572619.2 | V6: =SUM(D6,G6,J6,M6,S6,P6) -> 31386837 | W6: =SUM(E6,H6,K6,N6,T6) -> 0 | X6: =SUM(F6,I6,L6,O6,U6,R6) -> 31386837
B7: 原值 | C7: 处置或报废 | D7: 0 | F7: =SUM(D7:E7) -> 0 | G7: 0 | I7: =SUM(G7:H7) -> 0 | J7: 0 | L7: =SUM(J7:K7) -> 0 | M7: 0 | O7: =SUM(M7:N7) -> 0 | P7: 0 | R7: =SUM(P7:Q7) -> 0 | V7: =SUM(D7,G7,J7,M7,S7,P7) -> 0 | W7: =SUM(E7,H7,K7,N7,T7) -> 0 | X7: =SUM(F7,I7,L7,O7,U7,R7) -> 0
C8: 合并范围变动 | D8: 0 | F8: =SUM(D8:E8) -> 0 | G8: 0 | I8: =SUM(G8:H8) -> 0 | J8: 0 | L8: =SUM(J8:K8) -> 0 | M8: 0 | O8: =SUM(M8:N8) -> 0 | P8: 0 | R8: =SUM(P8:Q8) -> 0 | V8: =SUM(后推明细表!D8,后推明细表!G8,后推明细表!J8,后推明细表!M8,后推明细表!S8,P8) -> 0 | X8: =SUM(F8,I8,L8,O8,U8,R8) -> 0
C9: 其他增加或减少 | D9: 0 | F9: =SUM(D9:E9) -> 0 | G9: 0 | I9: =SUM(G9:H9) -> 0 | J9: 0 | L9: =SUM(J9:K9) -> 0 | M9: 0 | O9: =SUM(M9:N9) -> 0 | P9: 0 | R9: =SUM(P9:Q9) -> 0 | V9: =SUM(后推明细表!D9,后推明细表!G9,后推明细表!J9,后推明细表!M9,后推明细表!S9,P9) -> 0 | X9: =SUM(F9,I9,L9,O9,U9,R9) -> 0
C10: 年末余额 | D10: =SUM(D4:D9) -> 3.0947623e+09 | E10: =E4+E5+E6+E7 -> 0 | F10: =SUM(F4:F9) -> 3.0947623e+09 | G10: =SUM(G4:G9) -> 4.1270576e+09 | H10: =H4+H5+H6+H7 -> 0 | I10: =I4+I5+I6+I7+I8+I9 -> 4.1270576e+09 | J10: =SUM(J4:J9) -> 6.7621062e+08 | K10: =K4+K5+K6+K7 -> 0 | L10: =SUM(L4:L9) -> 6.7621062e+08 | M10: =SUM(M4:M9) -> 2.894701e+08 | N10: =N4+N5+N6+N7 -> 211 | O10: =SUM(后推明细表!O4:O9) -> 2.894701e+08 | P10: =SUM(P4:P9) -> 5.8544226e+09 | Q10: =Q4+Q5+Q6+Q7 -> 0 | R10: =SUM(R4:R9) -> 5.8544226e+09 | S10: =SUM(S4:S9) -> 0 | T10: =T4+T5+T6+T7 -> 0 | U10: =SUM(U4:U9) -> 0 | V10: =SUM(V4:V9) -> 1.4041923e+10 | W10: =W4+W5+W6+W7 -> 211 | X10: =X4+X5+X6+X7+X8+X9 -> 1.4041923e+10
C11: 年初余额 | D11: 2.5279441e+09 | E11: 0 | F11: 2.5279441e+09 | G11: 2.4984791e+09 | H11: 0 | I11: 2.4984791e+09 | J11: 5.1606927e+08 | K11: 0 | L11: 5.1606927e+08 | M11: 54641282 | N11: 0 | O11: 54641282 | P11: 3.1835546e+09 | Q11: 0 | R11: 3.1835546e+09 | V11: =SUM(D11,G11,J11,M11,S11,P11) -> 8.7806883e+09 | W11: =SUM(E11,H11,K11,N11,T11) -> 0 | X11: =SUM(F11,I11,L11,O11,U11,R11) -> 8.7806883e+09
C12: 计提 | D12: 29426802 | F12: =SUM(D12:E12) -> 29426802 | G12: 2.6845023e+08 | I12: =SUM(G12:H12) -> 2.6845023e+08 | J12: 37906013 | L12: =SUM(J12:K12) -> 37906013 | M12: 5800506 | O12: =SUM(M12:N12) -> 5800506 | P12: 1.4099475e+08 | R12: =SUM(P12:Q12) -> 1.4099475e+08 | V12: =SUM(D12,G12,J12,M12,S12,P12) -> 4.8257831e+08 | W12: =SUM(E12,H12,K12,N12,T12) -> 0 | X12: =SUM(F12,I12,L12,O12,U12,R12) -> 4.8257831e+08
B13: 累计折旧 | C13: 处置或报废 | D13: 0 | F13: =SUM(D13:E13) -> 0 | I13: =SUM(G13:H13) -> 0 | J13: 0 | L13: =SUM(J13:K13) -> 0 | M13: 0 | O13: =SUM(M13:N13) -> 0 | P13: 0 | R13: =SUM(P13:Q13) -> 0 | V13: =SUM(D13,G13,J13,M13,S13,P13,) -> 0 | W13: =SUM(E13,H13,K13,N13,T13) -> 0 | X13: =SUM(F13,I13,L13,O13,U13,R13) -> 0
C14: 合并范围变动 | D14: 0 | F14: =SUM(D14:E14) -> 0 | G14: 0 | I14: =SUM(G14:H14) -> 0 | J14: 0 | L14: =SUM(J14:K14) -> 0 | M14: 0 | O14: =SUM(M14:N14) -> 0 | P14: 0 | R14: =SUM(P14:Q14) -> 0 | V14: =SUM(D14,G14,J14,M14,M14,S14,P14) -> 0 | X14: =SUM(F14,I14,L14,O14,U14,R14) -> 0
C15: 其他增加或减少 | D15: 0 | F15: =SUM(D15:E15) -> 0 | G15: 0 | I15: =SUM(G15:H15) -> 0 | J15: 0 | L15: =SUM(J15:K15) -> 0 | M15: 0 | O15: =SUM(M15:N15) -> 0 | P15: 0 | R15: =SUM(P15:Q15) -> 0 | V15: =SUM(D15,G15,J15,M15,M15,S15,P15) -> 0 | X15: =SUM(F15,I15,L15,O15,U15,R15) -> 0
C16: 年末余额 | D16: =SUM(D11:D15) -> 2.5573709e+09 | E16: =E11+E12+E13 -> 0 | F16: =F11+F12+F13+F14+F15 -> 2.5573709e+09 | G16: =G11+G12+G13+G14+G15 -> 2.7669293e+09 | H16: =H11+H12+H13 -> 0 | I16: =I11+I12+I13+I14+I15 -> 2.7669293e+09 | J16: =SUM(J11:J15) -> 5.5397529e+08 | K16: =K11+K12+K13 -> 0 | L16: =SUM(L11:L15) -> 5.5397529e+08 | M16: =SUM(M11:M15) -> 60441788 | N16: =N11+N12+N13 -> 0 | O16: =SUM(O11:O15) -> 60441788 | P16: =SUM(P11:P15) -> 3.3245493e+09 | Q16: =Q11+Q12+Q13 -> 0 | R16: =SUM(后推明细表!R11:R15) -> 3.3245493e+09 | S16: =SUM(S11:S15) -> 0 | T16: =T11+T12+T13 -> 0 | U16: =SUM(后推明细表!U11:U15) -> 0 | V16: =SUM(V11:V15) -> 9.2632666e+09 | W16: =W11+W12+W13 -> 0 | X16: =X11+X12+X13+X14+X15 -> 9.2632666e+09
C17: 年初余额 | D17: 4.1652613e+08 | E17: 0 | F17: 4.1652613e+08 | G17: 4.563558e+08 | H17: 0 | I17: 4.563558e+08 | J17: 5406999.2 | K17: 0 | L17: 5406999.2 | M17: 0 | N17: 0 | O17: 0 | P17: 1.988968e+09 | Q17: 0 | R17: 1.988968e+09 | V17: =SUM(D17,G17,J17,M17,S17,P17) -> 2.867257e+09 | W17: =SUM(E17,H17,K17,N17,T17) -> 0 | X17: =SUM(F17,I17,L17,O17,U17,R17) -> 2.867257e+09
C18: 计提 | D18: 0 | F18: =SUM(D18:E18) -> 0 | G18: 1138128 | I18: =SUM(G18:H18) -> 1138128 | J18: 0 | L18: =SUM(J18:K18) -> 0 | M18: 0 | O18: =SUM(M18:N18) -> 0 | P18: 19841 | R18: =SUM(P18:Q18) -> 19841 | V18: =SUM(D18,G18,J18,M18,S18,P18) -> 1157969 | W18: =SUM(E18,H18,K18,N18,T18) -> 0 | X18: =SUM(F18,I18,L18,O18,U18,R18) -> 1157969
B19: 减值准备 | C19: 处置或报废 | D19: 0 | F19: =SUM(D19:E19) -> 0 | G19: 0 | I19: =SUM(G19:H19) -> 0 | J19: 0 | L19: =SUM(J19:K19) -> 0 | M19: 0 | O19: =SUM(M19:N19) -> 0 | P19: 0 | R19: =SUM(P19:Q19) -> 0 | V19: =SUM(D19,G19,J19,M19,S19) -> 0 | W19: =SUM(E19,H19,K19,N19,T19) -> 0 | X19: =SUM(F19,I19,L19,O19,U19,R19) -> 0
C20: 其他增加或减少 | D20: 0 | F20: =SUM(D20:E20) -> 0 | G20: 0 | I20: =SUM(G20:H20) -> 0 | J20: 0 | L20: =SUM(J20:K20) -> 0 | M20: 0 | O20: =SUM(M20:N20) -> 0 | P20: 0 | R20: =SUM(P20:Q20) -> 0 | V20: =SUM(D20,G20,J20,M20,S20,P20) -> 0 | X20: =SUM(F20,I20,L20,O20,U20,R20) -> 0
C21: 合并范围变动 | D21: 0 | F21: =SUM(D21:E21) -> 0 | G21: 0 | I21: =SUM(G21:H21) -> 0 | J21: 0 | L21: =SUM(J21:K21) -> 0 | M21: 0 | O21: =SUM(M21:N21) -> 0 | P21: 0 | R21: =SUM(P21:Q21) -> 0 | V21: =SUM(D21,G21,J21,M21,S21,P21) -> 0 | X21: =SUM(F21,I21,L21,O21,U21,R21) -> 0
C22: 年末余额 | D22: =D17+D18+D19+D20+D21 -> 4.1652613e+08 | E22: =E17+E18+E19 -> 0 | F22: =F17+F18+F19+F20+F21 -> 4.1652613e+08 | G22: =G17+G18+G19+G20+G21 -> 4.5749393e+08 | H22: =H17+H18+H19 -> 0 | I22: =I17+I18+I19+I20+I21 -> 4.5749393e+08 | J22: =SUM(J17:J21) -> 5406999.2 | K22: =K17+K18+K19 -> 0 | L22: =SUM(L17:L21) -> 5406999.2 | M22: =SUM(M17:M21) -> 0 | N22: =N17+N18+N19 -> 0 | O22: =SUM(O17:O21) -> 0 | P22: =SUM(P17:P21) -> 1.9889879e+09 | Q22: =Q17+Q18+Q19 -> 0 | R22: =SUM(R17:R21) -> 1.9889879e+09 | S22: =SUM(S17:S21) -> 0 | T22: =T17+T18+T19 -> 0 | U22: =SUM(U17:U21) -> 0 | V22: =SUM(V17:V21) -> 2.8684149e+09 | W22: =W17+W18+W19 -> 0 | X22: =X17+X18+X19+X20+X21 -> 2.8684149e+09
B23: 净值 (NBV) | C23: 年初余额 | D23: =D4-D11-D17 -> 1.4387705e+08 | E23: =E4-E11-E17 -> 0 | F23: =F4-F11-F17 -> 1.4387705e+08 | G23: =G4-G11-G17 -> 1.1626408e+09 | H23: =H4-H11-H17 -> 0 | I23: =I4-I11-I17 -> 1.1626408e+09 | J23: =M4-J11-J17 -> -2.3200618e+08 | K23: =K4-K11-K17 -> 0 | L23: =L4-L11-L17 -> 1.4365889e+08 | M23: =M4-M11-M17 -> 234828814 | N23: =N4-N11-N17 -> 211 | O23: =O4-O11-O17 -> 234828814 | P23: =P4-P11-P17 -> 6.7614294e+08 | Q23: =Q4-Q11-Q17 -> 0 | R23: =R4-R11-R17 -> 6.7614294e+08 | ... X23: =X4-X11-X17 -> 2.3611485e+09 | Y23: =[2]A3_单体报表审定数!$DN$55 -> 2.3611485e+09 | Z23: =X23-Y23 -> -5.2452087e-06
C24: 年末余额 | D24: =D10-D16-D22 -> 1.2086533e+08 | E24: =E10-E16-E22 -> 0 | F24: =F10-F16-F22 -> 1.2086533e+08 | G24: =G10-G16-G22 -> 9.0263434e+08 | H24: =H10-H16-H22 -> 0 | I24: =I10-I16-I22 -> 9.0263434e+08 | J24: =J10-J16-J22 -> 1.1682833e+08 | K24: =K10-K16-K22 -> 0 | ... X24: =X10-X16-X22 -> 1.9102417e+09 | Y24: =[2]A3_单体报表审定数!$F$55 -> 1.9102417e+09 | Z24: =X24-Y24 -> -4.0531158e-06
B27: Notes
B28: 其他类无形资产，主要包括通用资产研发支出3,607,399千元，调整车型技术改造项目2,945千元，M44RR造型及结构设计项目7,196千元。

Sheet LRA_无形资产&摊销费用
C2: 客户名称 | D2: 神龙汽车有限公司 | F2: 重要性水平(PM) | G2: 449080000
C4: 年度 | D4: 46022 | F4: 可容忍误差(TE) | G4: 337000000
C6: 记账本位币 | D6: CNY | F6: 测试阈值(TT) | G6: =G4 -> 337000000
F8: 名义金额(SAD) | G8: 16750000
C11: 目标
C12: 验证财务报表的固定资产以及计入利润表中的折旧费用金额是否合理列示。
A14: 一、摊销测试 | C14: 所执行程序——摊销费用
B15: 1. | C15: 建立预期并确定预期的精确度
C17: 我们对管理层进行询问，了解到本年度和上年度没有发生重大的资产出售或处置，资产规模稳定，处于在用状态。基于我们对公司业务的了解，公司未面临资产技术过时的风险，距离提足摊销尚有一定年限。因此管理层的描述与我们对资产出售或处置的预期相符。 财务系统的无形资产模块根据公司的无形资产政策设定使用寿命，摊销费用每月按直线法计算和记录。根据公司的会计政策，每个资产类别都有单独的使用寿命。我们获取了公司最新的会计政策，有关无形资产和摊销的相关政策，本年未发生任何修改。
C19: 鉴于上述分析，我们预期当期摊销费用占资产原值的比例与上年保持一致，计划以上年摊销率和本期末资产原值预期本年摊销费用发生额，与实际摊销费用进行比较。
C21: 我们基于以下四个维度，对无形资产摊销预期的精确度进行评估： 1）预测精确度：我们通过计算上一年摊销费用占上一年资产类别原值的百分比。我们将该百分比乘以当期平均资产类别余额，得出我们的预期当年摊销费用。模型细分度中等。 2）数据可分解性：ERP系统提供健全的无形资产数据，支持按资产类别分组，匹配模型需求。 3）数据可用性：模型输入数据均来自可靠财务信息。 4）信息的可靠性：所有数据均经审计验证。 综上，我们认为所建立的预期总体精确度达到中等。
B23: 2. | C23: 确定偏差阈值
C24: 根据GAM的要求，对于有限风险账户，我们需要通过实质性程序取得“一些”程度的证据。 根据GAM对SAP要求，在预期精度为中等的情况下，如需取得“一些”程度的证据水平，需要采用的偏差阈值区间在2.5-4倍TE间。 但有限风险账户的偏差阈值只能限定在1倍TE，因此我们采用1倍TE作为折旧测试的偏差阈值，即人民币337,000,000元。 对于各资产类别，我们按其占固定资产原值的比例分配偏差阈值。
B27: 3. | C27: 执行固定资产折旧的分析性复核程序
C28: 我们计算了上一年折旧费用占上一年资产类别原值的百分比。我们将该百分比乘以当期平均资产类别余额，得出我们的预期当年折旧费用。
D29: =后推明细表!E2 -> 非专利技术 | E29: =后推明细表!H2 -> 其他 | F29: =后推明细表!K2 -> 软件 | G29: =后推明细表!N2 -> 土地使用权 | H29: =后推明细表!Q2 -> 专利权 | J29: total | K29: A3 | L29: check
C30: 2023年固定资产原值余额 (2023/12/31)a1 | D30: ='[3]L1.01.1 BKD'!$L$18 -> 3081651866 | E30: ='[3]L1.01.1 BKD'!$R$18 -> 4.0569247e+09 | F30: ='[3]L1.01.1 BKD'!$O$18 -> 6.3877494e+08 | G30: ='[3]L1.01.1 BKD'!$F$18 -> 2.894701e+08 | H30: ='[3]L1.01.1 BKD'!$I$18 -> 5.8027865e+09 | J30: =SUM(D30:I30) -> 1.3869608e+10 | K30: ='[3]L1.00 Lead'!$K$27 -> 1.3869608e+10 | L30: =J30-K30 -> 0
C31: 2024年固定资产原值余额 (2024/12/31)a2 | D31: =后推明细表!D4 -> 3.0883473e+09 | E31: =后推明细表!G4 -> 4.1174757e+09 | F31: =后推明细表!J4 -> 6.6513516e+08 | G31: =后推明细表!M4 -> 2.894701e+08 | H31: =后推明细表!P4 -> 5.8486655e+09 | I31: =后推明细表!S4 -> 0 | J31: =SUM(D31:I31) -> 1.4009094e+10 | K31: <后推明细表>
C32: 账户上年原值平均余额a=(a1+a2)/2 | D32: =AVERAGE(D30:D31) -> 3.0849996e+09 | E32: =AVERAGE(E30:E31) -> 4.0872002e+09 | F32: =AVERAGE(F30:F31) -> 6.5195505e+08 | G32: =AVERAGE(G30:G31) -> 2.894701e+08 | H32: =AVERAGE(H30:H31) -> 5.825726e+09 | I32: =AVERAGE(I30:I31) -> 0 | J32: =SUM(D32:I32) -> 1.3939351e+10
C33: 本年固定资产原值账户余额 (2025/12/31)b | D33: =后推明细表!D10 -> 3.0947623e+09 | E33: =后推明细表!G10 -> 4.1270576e+09 | F33: =后推明细表!J10 -> 6.7621062e+08 | G33: =后推明细表!M10 -> 2.894701e+08 | H33: =后推明细表!P10 -> 5.8544226e+09 | I33: =后推明细表!S10 -> 0 | J33: =SUM(D33:I33) -> 1.4041923e+10 | K33: <后推明细表>
C34: 账户平均原值余额(a+b)/2 | D34: =AVERAGE(D31,D33) -> 3.0915548e+09 | E34: =AVERAGE(E31,E33) -> 4.1222666e+09 | F34: =AVERAGE(F31,F33) -> 6.7067289e+08 | G34: =AVERAGE(G31,G33) -> 2.894701e+08 | H34: =AVERAGE(H31,H33) -> 5.8515441e+09 | I34: =AVERAGE(I31,I33) -> 0 | J34: =SUM(D34:I34) -> 1.4025509e+10
C36: 偏差阈值c | D36: =$G$4/J34*D34 -> 74282795 | E36: =$G$4/$J$34*E34 -> 99048377 | F36: =$G$4/$J$34*F34 -> 16114693 | G36: =$G$4/$J$34*G34 -> 6955285.9 | H36: =$G$4/$J$34*H34 -> 1.4059885e+08 | I36: =$G$4/$J$34*I34 -> 0 | J36: =SUM(D36:I36) -> 337000000
C38: 上年折旧费用(2024)d | D38: ='[3]L1.01.1 BKD'!$L$30 -> 31960494 | E38: ='[3]L1.01.1 BKD'!$R$30 -> 2.792863e+08 | F38: ='[3]L1.01.1 BKD'!$O$30 -> 41172044 | G38: ='[3]L1.01.1 BKD'!$F$30 -> 5800508 | H38: ='[3]L1.01.1 BKD'!$I$30 -> 1.3680056e+08 | J38: =SUM(D38:I38) -> 4.950199e+08
C39: 折旧费用占成本的%e=d/a | D39: =D38/D32 -> 0.010359967 | E39: =E38/E32 -> 0.068331935 | F39: =F38/F32 -> 0.06315166 | G39: =G38/G32 -> 0.020038367 | H39: =H38/H32 -> 0.023482148 | I39: 0 | J39: =J38/J32 -> 0.035512407
C41: 预期折旧费用(2025)f | D41: =D39*D34 -> 32028406 | E41: =E39*E34 -> 2.8168246e+08 | F41: =F39*F34 -> 42354106 | G41: =G39*G34 -> 5800508 | H41: =H39*H34 -> 1.3740682e+08 | I41: =I39*I34/12*9 -> 0 | J41: =SUM(D41:I41) -> 4.992723e+08
C42: 实际折旧费用(2025)g | D42: =后推明细表!D12 -> 29426802 | E42: =后推明细表!G12 -> 2.6845023e+08 | F42: =后推明细表!J12 -> 37906013 | G42: =后推明细表!M12 -> 5800506 | H42: =后推明细表!P12 -> 1.4099475e+08 | I42: =后推明细表!S12 -> 0 | J42: =SUM(D42:I42) -> 4.8257831e+08 | K42: <后推明细表>
C43: 偏差金额h=g-f | D43: =D42-D41 -> -2601603.7 | E43: =E42-E41 -> -13232223 | F43: =F42-F41 -> -4448092.8 | G43: =G42-G41 -> -2 | H43: =H42-H41 -> 3587928.9 | I43: =I42-I41 -> 0 | J43: =SUM(D43:I43) -> -16693993
C45: 偏差是否超过阈值？h vs. c | D45: =IF(ABS(D43)>D36,"Yes","No") -> No | E45: =IF(ABS(E43)>E36,"Yes","No") -> No | F45: =IF(ABS(F43)>F36,"Yes","No") -> No | G45: =IF(ABS(G43)>G36,"Yes","No") -> No | H45: =IF(ABS(H43)>H36,"Yes","No") -> No | I45: =IF(ABS(I43)>I36,"Yes","No") -> No | J45: =IF(ABS(J43)>J36,"Yes","No") -> No
B48: NB1 | C48: X-ref
C49: 制造费用 | D49: 3.2256042e+08
C50: 管理费用 | D50: 20019963
C51: 销售费用 | D51: 9981
C52: 研发费用 | D52: 1.3980688e+08
C54: 账面费用 | D54: ='LRA_无形资产&摊销费用'!J42 -> 4.8257831e+08
C55: 差异 | D55: =D54-D49-D50-D51-D52 -> 181069 | E55: m
B58: NB2 | C58: 我们对固定资产折旧执行了实质性分析程序，各类资产及固定资产总体折旧费用的预期与实际偏差均小于偏差阈值。 综上，通过该测试已取得计划的证据水平（“一些”）。
A63: 二、原值测试 | C63: 所执行程序——固定资产
A64: (如不适用可删除)
C65: 1.对固定资产新增/处置执行关键项测试
C66: 本期无形资产新增与处置金额均远低于TT，不再进一步执行测试。
...
