Workbook
Name CurrencyCodes: #REF!
Name CurrencyCodes: #REF!
Name CurrentLanguage: #REF!
Name CurrentLanguage: #REF!
Name EYCanvasAnswer: #REF!
Name EYCanvasAnswer: #REF!
Name inCurrencyCode: #REF!
Name inCurrencyCode: #REF!
Name inFinalDol: #REF!
Name inFinalDol: #REF!
Name inOverallEval: #REF!
Name inOverallEval: #REF!
Name inPeriod: #REF!
Name inPeriod: #REF!
Name inPlannedLevel: #REF!
Name inPlannedLevel: #REF!
Name inTolerableError: #REF!
Name inTolerableError: #REF!
Name ScopeCompany: #REF!
Name ScopeCompany: #REF!
Name sd_format: "yyyy/m/d"
Name sdt_format: "yyyy/m/d hh:mm"

Sheet 使用指引
B1: 本SOP仅针对Non-PCAOB的项目参考使用。
B3: 有限风险帐户认定场景示例
B5: 1. 无形资产涉及减值但不存在重大错报风险，如国家法规变化导致技术无法再使用，全额进行减值
B6: 2. 无摊销年限，摊销方法等会计估计变更
B7: 3. 无使用寿命不确定的无形资产
B8: 4. 内部研发资本化形成的无形资产金额不重大
B9: 5. 本年新增/处置无形资产金额较小；或，虽然本年新增/处置无形资产的金额较大，但数量较少，易于通过实质性程序验证
B11: 基于我们对实体及该账户的了解，我们认为该账户符合有限风险账户认定的全部标准，设计并执行如下程序：
B13: 序号 | C13: 报表科目 | D13: 执行的程序 | E13: 程序描述 | F13: 执行团队 | G13: 底稿索引
B14: 1 | C14: 无形资产及摊销费用 | D14: 有限风险账户canvas workflow填写 | E14: 有限风险账户的判断及记录 | F14: 项目组 | G14: 有限风险账户判断及记录示例及实质性程序指引
B15: 2 | C15: 无形资产摊销费用 | D15: 实质性分析程序 | E15: 对本期无形资产摊销费用建立预期，并分析实际摊销费用是否符合预期 | F15: WP COE | G15: 所执行程序——摊销费用
B16: 3 | C16: 无形资产原值 | D16: 对无形资产新增和处置执行细节测试（如新增/处置发生额重大） | E16: 对金额超过测试阈值的本年新增/处置资产进行抽凭，验证相关支撑性资料 | F16: WP COE | G16: ='LRA_无形资产&摊销费用'!C69 -> 所执行程序——无形资产

Sheet 后推明细表
C2: 无形资产类别 | E2: 土地使用权 | H2: 计算机软件 | K2: 专利权 | N2: 合计
D3: 账面数 | E3: 账表调整/审计调整 | F3: 审定数 | G3: 账面数 | H3: 账表调整/审计调整 | I3: 审定数 | J3: 账面数 | K3: 账表调整/审计调整 | L3: 审定数 | M3: 账面数 | N3: 账表调整/审计调整 | O3: 审定数 | P3: A3 | Q3: check
C4: 年初余额 | D4: 89898868 | F4: =SUM(D4:E4) -> 89898868 | G4: 5804877.6 | I4: =SUM(G4:H4) -> 5804877.6 | J4: 41872990 | L4: =SUM(J4:K4) -> 41872990 | M4: =SUM(D4,G4,J4) -> 1.3757674e+08 | N4: =SUM(E4,H4,K4) -> 0 | O4: =SUM(F4,I4,L4) -> 1.3757674e+08
C5: 购置 | D5: 0 | F5: =SUM(D5:E5) -> 0 | G5: 0 | I5: =SUM(G5:H5) -> 0 | J5: 8685893.8 | L5: =SUM(J5:K5) -> 8685893.8 | M5: =SUM(D5,G5,J5) -> 8685893.8 | N5: =SUM(E5,H5,K5) -> 0 | O5: =SUM(F5,I5,L5) -> 8685893.8
B6: 原值 | C6: 处置或报废 | D6: 0 | F6: =SUM(D6:E6) -> 0 | G6: 0 | I6: =SUM(G6:H6) -> 0 | J6: 0 | L6: =SUM(J6:K6) -> 0 | M6: =SUM(D6,G6,J6) -> 0 | N6: =SUM(E6,H6,K6) -> 0 | O6: =SUM(F6,I6,L6) -> 0
C7: 年末余额 | D7: =D4+D5+D6 -> 89898868 | E7: =E4+E5+E6 -> 0 | F7: =F4+F5+F6 -> 89898868 | G7: =G4+G5+G6 -> 5804877.6 | H7: =H4+H5+H6 -> 0 | I7: =I4+I5+I6 -> 5804877.6 | J7: =J4+J5+J6 -> 50558884 | K7: =K4+K5+K6 -> 0 | L7: =L4+L5+L6 -> 50558884 | M7: =SUM(D7,G7,J7) -> 1.4626263e+08 | N7: =SUM(E7,H7,K7) -> 0 | O7: =SUM(F7,I7,L7) -> 1.4626263e+08
C8: 年初余额 | D8: 17979774 | F8: =SUM(D8:E8) -> 17979774 | G8: 5247542.5 | I8: =SUM(G8:H8) -> 5247542.5 | J8: 41872990 | L8: =SUM(J8:K8) -> 41872990 | M8: =SUM(D8,G8,J8) -> 65100307 | N8: =SUM(E8,H8,K8) -> 0 | O8: =SUM(F8,I8,L8) -> 65100307
C9: 计提 | D9: 1348483.1 | F9: =SUM(D9:E9) -> 1348483.1 | G9: 144221.39 | I9: =SUM(G9:H9) -> 144221.39 | J9: 290897.71 | L9: =SUM(J9:K9) -> 290897.71 | M9: =SUM(D9,G9,J9) -> 1783602.1 | N9: =SUM(E9,H9,K9) -> 0 | O9: =SUM(F9,I9,L9) -> 1783602.1
B10: 累计摊销 | C10: 处置或报废 | D10: 0 | F10: =SUM(D10:E10) -> 0 | G10: 0 | I10: =SUM(G10:H10) -> 0 | J10: 0 | L10: =SUM(J10:K10) -> 0 | M10: =SUM(D10,G10,J10) -> 0 | N10: =SUM(E10,H10,K10) -> 0 | O10: =SUM(F10,I10,L10) -> 0
C11: 年末余额 | D11: =D8+D9+D10 -> 19328257 | E11: =E8+E9+E10 -> 0 | F11: =F8+F9+F10 -> 19328257 | G11: =G8+G9+G10 -> 5391763.8 | H11: =H8+H9+H10 -> 0 | I11: =I8+I9+I10 -> 5391763.8 | J11: =J8+J9+J10 -> 42163888 | K11: =K8+K9+K10 -> 0 | L11: =L8+L9+L10 -> 42163888 | M11: =SUM(D11,G11,J11) -> 66883909 | N11: =SUM(E11,H11,K11) -> 0 | O11: =SUM(F11,I11,L11) -> 66883909
C12: 年初余额 | D12: 0 | F12: =SUM(D12:E12) -> 0 | G12: 0 | I12: =SUM(G12:H12) -> 0 | J12: 0 | L12: =SUM(J12:K12) -> 0 | M12: =SUM(D12,G12,J12) -> 0 | N12: =SUM(E12,H12,K12) -> 0 | O12: =SUM(F12,I12,L12) -> 0
C13: 计提 | D13: 0 | F13: =SUM(D13:E13) -> 0 | G13: 0 | I13: =SUM(G13:H13) -> 0 | J13: 0 | L13: =SUM(J13:K13) -> 0 | M13: =SUM(D13,G13,J13) -> 0 | N13: =SUM(E13,H13,K13) -> 0 | O13: =SUM(F13,I13,L13) -> 0
B14: 减值准备 | C14: 处置或报废 | D14: 0 | F14: =SUM(D14:E14) -> 0 | G14: 0 | I14: =SUM(G14:H14) -> 0 | J14: 0 | L14: =SUM(J14:K14) -> 0 | M14: =SUM(D14,G14,J14) -> 0 | N14: =SUM(E14,H14,K14) -> 0 | O14: =SUM(F14,I14,L14) -> 0
C15: 年末余额 | D15: =D12+D13+D14 -> 0 | E15: =E12+E13+E14 -> 0 | F15: =F12+F13+F14 -> 0 | G15: =G12+G13+G14 -> 0 | H15: =H12+H13+H14 -> 0 | I15: =I12+I13+I14 -> 0 | J15: =J12+J13+J14 -> 0 | K15: =K12+K13+K14 -> 0 | L15: =L12+L13+L14 -> 0 | M15: =SUM(D15,G15,J15) -> 0 | N15: =SUM(E15,H15,K15) -> 0 | O15: =SUM(F15,I15,L15) -> 0
B16: 净值 (NBV) | C16: 年初余额 | D16: =D4-D8-D12 -> 71919094 | E16: =E4-E8-E12 -> 0 | F16: =F4-F8-F12 -> 71919094 | G16: =G4-G8-G12 -> 557335.11 | H16: =H4-H8-H12 -> 0 | I16: =I4-I8-I12 -> 557335.11 | J16: =J4-J8-J12 -> 0 | K16: =K4-K8-K12 -> 0 | ... O16: =O4-O8-O12 -> 72476429 | P16: =[1]A3!$J$55 -> 72476429 | Q16: =O16-P16 -> 0
C17: 年末余额 | D17: =D7-D11-D15 -> 70570611 | E17: =E7-E11-E15 -> 0 | F17: =F7-F11-F15 -> 70570611 | G17: =G7-G11-G15 -> 413113.72 | H17: =H7-H11-H15 -> 0 | I17: =I7-I11-I15 -> 413113.72 | J17: =J7-J11-J15 -> 8394996.1 | K17: =K7-K11-K15 -> 0 | ... O17: =O7-O11-O15 -> 79378721 | P17: =[1]A3!$F$55 -> 79378721 | Q17: =O17-P17 -> 0

Sheet LRA_无形资产&摊销费用
C2: 客户名称 | D2: 东风井关农业机械有限公司本部 | F2: 重要性水平(PM) | G2: 12530000 | M2: LRA -基础操作指引-【01】 | O2: LRA -进阶实操提示-【01】 | Q2: LRA -易错点-【01】
M3: 填列基本信息： 1、年度：填列资产负债表日，若为一般年度法定审计项目，填写202X-12-31；若为IPO审计服务等对某个特定会计期间进行审计，应填写期末时间。 2、记账本位币：填列记账本位币。企业通常应选择人民币作为记账本位币，业务收支以人民币以外的货币为主的企业，可以按规定选定其中一种货币作为记账本位币。 3、重要性水平（PM）、可容忍误差（TE）、名义金额（SAD）:以Canvas中相关底稿为准进行填列，具体位置请与项目FIC/EIC沟通确认。请确保底稿内实际使用的PM\TE\SAD与最终版一致。 4、测试阈值（TT）：当审计项目组判断需要执行关键项测试时，需要评估测试阈值。有限风险账户没有综合风险评估（CRA），测试阈值的确定依赖职业判断。（如参考CRA minimal的资产账户，按TE的100%确定为TT） | O3: 填列基本信息： ●TE和SAD： 我们在制定审计策略时，要确定两个层面的重要性水平： ·财务报表整体层面——计划重要性水平（PM） ·个别账户或余额层面——可容忍误差（TE） 我们设定TE是为了将未更正和未发现错报的汇总数超过PM的可能性降到适当的低水平（即应对汇总风险）。当我们就未更正错报作出结论时，也应使用TE作为财务报表内未发现错报的估计值。 除了确定PM和TE外，我们还要确定一个金额，将已识别的低于该金额的错报视为明显微不足道。我们将其称为审计差异汇总（SAD）名义金额。当错报低于这个金额时，无论是单独还是与其它错报累计在一起，都不会对财务报表产生重大影响。换言之，从规模、性质或情况判断，低于SAD名义金额的金额均明显微不足道，并且在我们对错报进行整体评估时，也不会考虑这些金额的总和。 | Q3: 填列基本信息： 1、TE/SAD使用错误或未更新，导致审计证据不恰当（多余或不足），审计结论不正确。 2、客户名称、期末、货币/单位等基础信息未更新。
C4: 年度 | D4: 45930 | F4: 可容忍误差(TE) | G4: 8707500
C6: 记账本位币 | D6: CNY | F6: 测试阈值(TT) | G6: =G4 -> 8707500
F8: 名义金额(SAD) | G8: 580500
C11: 目标
C12: 验证财务报表的无形资产以及计入利润表中的摊销费用金额是否合理列示。 | M12: LRA -基础操作指引-【02】 | O12: LRA -进阶实操提示-【02】 | Q12: LRA -易错点-【02】
M13: 摊销测试 - 建立预期并确定预期的精确度： 1、选择测试方法：对于有限风险账户，足够的证据级别为“一些”，应当对摊销费用执行实质性分析程序（SAP），我们根据既定的证据级别倒推建立预期及确定预期的精确度，预期的精确度只需要达到“中等”水平。 2、建立预期的底稿记录：我们以对被审计单位实体及其行业的了解（如对实体预算中计划的资本化支出、新增及处置安排、在用无形资产的状态等）、以对会计关系和重大交易类别的了解（如了解实体摊销政策，包括摊销方法、摊销年限和残值率等，从而预期本年摊销费用或比率）、以对审计经验、可用信息来源以及职业判断的运用（如在用无形资产距离提足摊销的时间，是否面临技术过时风险等）对当期应计提的无形资产摊销费用形成预期。 3、预期精确度的底稿记录：底稿记录需结合预测预期结果的精确度、数据可分解的程度、数据的可用性以及信息的可靠性四个考虑因素描述被审计单位能够满足中等精确度的理由。 预期应与测算时使用模型的逻辑一致，本案例中测算模型采用”本年摊销费用=本年资产原值余额*上年摊销率“的方式，对应的预期是本年及上年的摊销率一致。 本SOP中展示的示例预期精确度已达到“中等”。 | O13: 摊销测试 - 建立预期并确定预期的精确度： 当我们认为我们的预期精确度很高时，分析的结果很可能将提供可靠的审计证据。更高的精确度产生更高质量的审计证据。随着我们预期的精确度下降，最终证据的质量下降，其他实质性程序所需的证据范围增加。 影响我们的预期精确度的因素包括： 1）预测实质性分析程序预期结果的精确度 —— 模型中我们通过不同类别资产上年的摊销率预测本年的摊销费用，是一种比较简单的预测模型，若我们希望提高预测的精确度，我们可以考虑更多要素去细化预测模型，如同一资产类别下可能有不同摊销年限、如要考虑本年新增、处置、提足摊销资产，本年计提摊销的月数对摊销费的影响等。 2）信息可以分解的程度 —— 当我们可以达到一定程度的分解，以使我们可以识别和了解因素和金额、比率或趋势之间更为简单和稳定的关系，那么我们通常会有一个更精确的预期。 3）财务与非财务信息的可用性 —— 财务信息（如预算或预测）和非财务信息（如生产或销售的单位量）可以提高预期的精确度。 4）我们作出预期的依据的可靠性 —— 我们用于形成预期的信息的可靠性会影响预期的精确度。高精确度不能依靠有限的信息（例如，数月或数季度的未经测试的会计账户信息）或由实体生成的我们未建立信赖基础的信息，包括仅经过分析性复核程序的信息。 | Q13: 摊销测试 - 建立预期并确定预期的精确度： 1、未建立预期； 2、未描述确定预期精确度的理由。
A14: 一、摊销测试 | C14: 所执行程序——摊销费用
B15: 1. | C15: 建立预期并确定预期的精确度
C17: 我们对管理层进行询问，了解到本年度和上年度没有发生重大的资产出售或处置，资产规模稳定，处于在用状态。基于我们对公司业务的了解，公司未面临资产技术过时的风险，距离提足摊销尚有一定年限。因此管理层的描述与我们对资产出售或处置的预期相符。 财务系统的无形资产模块根据公司的无形资产政策设定使用寿命，摊销费用每月按直线法计算和记录。根据公司的会计政策，每个资产类别都有单独的使用寿命。我们获取了公司最新的会计政策，有关无形资产和摊销的相关政策，本年未发生任何修改。
C19: 鉴于上述分析，我们预期当期摊销费用占资产原值的比例与上年保持一致，计划以上年摊销率和本期末资产原值预期本年摊销费用发生额，与实际摊销费用进行比较。
C21: 我们基于以下四个维度，对无形资产摊销预期的精确度进行评估： 1）预测精确度：我们通过计算上一年摊销费用占上一年资产类别原值的百分比。我们将该百分比乘以当期平均资产类别余额，得出我们的预期当年摊销费用。模型细分度中等。 2）数据可分解性：ERP系统提供健全的无形资产数据，支持按资产类别分组，匹配模型需求。 3）数据可用性：模型输入数据均来自可靠财务信息。 4）信息的可靠性：所有数据均经审计验证。 综上，我们认为所建立的预期总体精确度达到中等。
B23: 2. | C23: 确定偏差阈值 | M23: LRA -基础操作指引-【03】 | O23: LRA -进阶实操提示-【03】
C24: 根据GAM的要求，对于有限风险账户，我们需要通过实质性程序取得“一些”程度的证据。 根据GAM对SAP要求，在预期精度为中等的情况下，如需取得“一些”程度的证据水平，需要采用的偏差阈值区间在2.5-4倍TE间。 但有限风险账户的偏差阈值只能限定在1倍TE，因此我们采用1倍TE作为摊销测试的偏差阈值，即人民币8707500元。 对于各资产类别，我们按其占无形资产原值的比例分配偏差阈值。 | M24: 摊销测试 - 确定偏差阈值： 1、偏差阈值：有限风险账户执行SAP程序，偏差阈值应当设定为TE。 2、分配偏差阈值：根据各自从类别原值的占比，对偏差阈值进行分解。各类别资产分解后的偏差阈值参见36行。 | O24: 摊销测试 - 确定偏差阈值： 1、关于偏差阈值 ●我们的⽬标是设计⼀个实质性分析程序，其产⽣的结果在偏差阈值内，以提供所需的证据⽔平。 ●图中⼼的X代表我们的预期⾦额。 ●左、右箭头代表记录⾦额和我们的预期之间的可接受的偏差范围。如果记录⾦额在此范围之内，则我们通过实质性分析程序获得了预期的证据。如果记录⾦额在此范围之外，这可能表明账⼾余额有潜在错报。我们会调查原因，如果我们⽆法对偏差原因作出结论，我们会实施替代程序以确定是否发⽣了错报。 2、有限风险账户偏差阈值的设定 我们通过在账户层面（而非认定层面）执行必要的实质性程序对有限风险账户的账户余额进行测试，以确认所记录余额的适当性并获得“一些”水平的审计证据。当我们的实质性程序提供账户没有超过可容忍错误的错报的有限保证时，我们获得“一些”水平的审计证据。（GAM 实质性设计：设计实质性程序 6.1 有限风险账户） 3、对分解⽚段的分析 我们通过分解数据来提⾼ 实质性分析程序 的有效性。分解的形式可以是： ●分离产品线或业务线 ●将财务报表的⼀级科⽬分解为⼆级或更末级的汇总性⼦科⽬ ●按⽉或季度分解数据 我们根据分解⽚段的数量将部分偏差阈值分配给各分解⽚段。在分配偏差阈值时，我们也会考虑该⽚段预期⼤⼩相对于账⼾总余额的⽐例。分配给分解⽚段的偏差阈值总和将等于对账⼾余额整体设定的偏差阈值。
B27: 3. | C27: 执行无形资产摊销的分析性复核程序
C28: 我们计算了上一年摊销费用占上一年资产类别原值平均余额的百分比。我们将该百分比乘以当期平均资产类别余额，得出我们的预期当年摊销费用。
D29: 土地使用权 | E29: 计算机软件 | F29: 专利权 | G29: total | H29: A3 | I29: check
C30: 2023年无形资产原值余额 (2023/12/31)a1 | D30: 73717071 | E30: 410066.48 | F30: 0 | G30: =SUM(D30:F30) -> 74127138 | H30: 74127138 | I30: =G30-H30 -> 0
C31: 2024年无形资产原值余额 (202412/31)a2 | D31: =后推明细表!D4 -> 89898868 | E31: =后推明细表!G4 -> 5804877.6 | F31: =后推明细表!J4 -> 41872990 | G31: =SUM(D31:F31) -> 1.3757674e+08 | H31: <后推明细表>
C32: 账户上年原值平均余额a=(a1+a2)/2 | D32: =AVERAGE(D30:D31) -> 81807969 | E32: =AVERAGE(E30:E31) -> 3107472 | F32: =AVERAGE(F30:F31) -> 20936495 | G32: =AVERAGE(G30:G31) -> 1.0585194e+08
C33: 本年无形资产原值账户余额 (2025/9/30)b | D33: =后推明细表!D7 -> 89898868 | E33: =后推明细表!G7 -> 5804877.6 | F33: =后推明细表!J7 -> 50558884 | G33: =SUM(D33:F33) -> 1.4626263e+08 | H33: <后推明细表>
C34: 账户平均原值余额(a+b)/2 | D34: =AVERAGE(D31,D33) -> 89898868 | E34: =AVERAGE(E31,E33) -> 5804877.6 | F34: =AVERAGE(F31,F33) -> 46215937 | G34: =SUM(D34:F34) -> 1.4191968e+08
C36: 偏差阈值c | D36: =$G$36/$G$42*D42 -> 6583259.7 | E36: =$G$36/$G$42*E42 -> 704085.13 | F36: =$G$36/$G$42*F42 -> 1420155.2 | G36: =G6 -> 8707500
C38: 上年摊销费用(2024)d | D38: 1797977.4 | E38: 374020.57 | F38: 0 | G38: =SUM(D38:F38) -> 2171998
C39: 摊销费用占成本的%e=d/a | D39: =D38/D32 -> 0.021978023 | E39: =E38/E32 -> 0.12036169 | F39: =F38/F32 -> 0 | G39: =G38/G32 -> 0.020519209
C41: 预期摊销费用(2025)f | D41: =D39*D34/12*9 -> 1481849.5 | E41: =E39*E34/12*9 -> 524013.64 | F41: =F39*F34/12*9 -> 0 | G41: =SUM(D41:F41) -> 2005863.1
C42: 实际摊销费用(2025)g | D42: =后推明细表!D9 -> 1348483.1 | E42: =后推明细表!G9 -> 144221.39 | F42: =后推明细表!J9 -> 290897.71 | G42: =SUM(D42:F42) -> 1783602.1 | H42: <后推明细表>
C43: 偏差金额h=g-f | D43: =D42-D41 -> -133366.46 | E43: =E42-E41 -> -379792.25 | F43: =F42-F41 -> 290897.71 | G43: =SUM(D43:F43) -> -222260.99
C45: 偏差是否超过阈值？h vs. c | D45: =IF(ABS(D43)>D36,"Yes","No") -> No | E45: =IF(ABS(E43)>E36,"Yes","No") -> No | F45: =IF(ABS(F43)>F36,"Yes","No") -> No | G45: =IF(ABS(G43)>G36,"Yes","No") -> No | M45: LRA -基础操作指引-【04】 | O45: LRA -进阶实操提示-【04】 | Q45: LRA -易错点-【03】
M46: 摊销测试 - 执行无形资产摊销的分析性复核程序： Step1：填写上年年初、上年年末各资产类别的原值余额，以计算年初无形资产原值的平均余额a; Step2：填写本年末各资产类别的原值余额b，以计算无形资产平均原值余额(a+b)/2； Step3：按各资产类别的平均原值余额占无形资产原值的比例分配偏差阈值c； Step4：填写上年各资产类别的摊销费用d，以计算上年各资产类别摊销费用占上年原值余额的比例e； Step5：按上年各资产类别摊销费用占上年各资产类别原值的百分比e，乘以当期各资产类别的平均原值余额，以得出我们预期的当年摊销费用f。 Step6：计算各资产类别的预期摊销费用f与实际摊销费用g的偏差金额h。 Step7：评价偏差金额并形成结论： ①若所有资产类别的偏差、合计的偏差均未超过偏差阈值，则已取得计划的证据水平（“一些”），无需执行进一步程序。 ②若存在某个或多个资产类别的偏差超过阈值的情况，则需对不符合我们预期和超出我们偏差阈值的任何结果进行跟进。我们的跟进工作可能包括进一步调查数据、调查相关交易，以及询问管理层。我们评估并核实管理层给出的解释，考虑我们其它调查的结果，并对已通过这些程序获得适当支持的偏差部分进行量化。同时我们需要核实询问结果，包括通过其它必要的⽀持性证据进⾏核实，并相应记录。 基于调查结果，形成两种不同的跟进措施： a.如果调查结果未发现错报，则已取得计划的证据水平（“一些”），无需执行进一步程序。 b.如果调查结果发现了错报，则需执行错报调查和评估工作。 注意，以上填列的上年年末无形资产原值余额a2、本年无形资产原值账户余额b来源于<后推明细表>，最终与A3核对一致；实际摊销费用g来源于<后推明细表>，应当与对应利润表科目/在建工程/存货的摊销费用核对一致。 | O46: 摊销测试 - 执行无形资产摊销的分析性复核程序： 1、预期模型 本SOP中以各类资产上年摊销率为基础建立对本年摊销费用的预期，与实际摊销费用进行比较。项目组可参考实例执行，也可以自行设计其他达到中等精确度的预期模型进行测试（请确保“1、建立预期并确定预期的精确度中”的记录与实际执行的预期模型相匹配）。 2、常见的偏差超过偏差阈值的原因： 1）若预期摊销费用>实际摊销费用导致的偏差超过阈值，可能的原因是：本年的新增资产多集中于年中或年末发生。 如调查的原因如上，可对年中新增的资产单独计算摊销，评估对SAP差异的影响。 2）若预期摊销费用<实际摊销费用导致的偏差超过阈值，可能的原因是：上年的新增资产多集中于年中或年末发生。 如调查的原因如上，可对上年年中新增的资产单独计算摊销，评估对SAP差异的影响。 3）确实存在错报。 如果调查后发现确实存在错报，我们需对所有超过SAD的错报进行记录和汇总，并考虑该错报是否表明被审计单位存在一个普遍性的问题?是否表明该内控的失效？是否意味着我们之前计划的审计程序可能不够充分，无法发现所有重大错报。基于上述考虑，项目组可能需要修改原定审计计划。 | Q46: 摊销测试 - 执行无形资产摊销的分析性复核程序： 1、存在偏差超过偏差阈值的情况但未继续调查原因； 2、原因调查有误或不充分，未检查相应的支持性文件； 3、上年年末无形资产原值余额、本年无形资产原值账户余额未与TB核对一致，实际摊销费用未与相应利润表科目摊销费用核对一致。
B48: NB1 | C48: X-ref
C49: per 成本&费用 | D49: 1783602.1
C50: 账面费用 | D50: =G42 -> 1783602.1
C51: 差异 | D51: =D49-D50 -> 0
B53: NB2 | C53: 我们对无形资产摊销执行了实质性分析程序，各类资产及无形资产总体摊销费用的预期与实际偏差均小于偏差阈值，通过该测试已取得计划的证据水平（“一些”）。
A69: 二、原值测试 | C69: 所执行程序——无形资产
A70: (如不适用可删除) | M70: LRA -基础操作指引-【05】 | O70: LRA -进阶实操提示-【05】 | Q70: LRA -易错点-【04】
C71: 1.对无形资产新增/处置执行关键项测试 | M71: 原值测试 - 对无形资产新增/处置执行测试： 1、判断是否需要对无形资产原值新增和处置执行测试：结合<后推明细表>列示情况，如本年新增或本年处置发生额大于TE，则应当对新增或处置执行测试；如无需执行测试，原值测试程序不适用。 2、选择测试方法：审计项目组可以结合实际情况选择实质分析性复核程序或有限详细测试（关键项）。本SOP以关键项测试为例进行指引。 3、确定关键项定量标准，并完成记录：有限风险账户没有综合风险评估（CRA），测试阈值的确定依赖职业判断。（如参考CRA minimal的资产账户，按TE的100%确定为TT） 4、确定关键项定性标准，并完成记录：符合表明其单独而言或汇总而言更有可能包含重大错报的定性标准。例如，基于我们对实体业务的了解、我们对固有风险和控制风险的评估以及被测试总体的特征，这些交易或余额是可疑的、异常的、具有较高重大错报风险或过去发生过错报。 （如果在识别定性关键项时识别到实体正常经营过程之外的交易/活动等导致有限风险账户识别条件不成立的，应重新评估作为有限风险账户的合理性。） 5、对选定的关键项执行细节测试：获取支持性文件，参考标准底稿新增/处置测试的测试属性进行检查。 | O71: 原值测试 - 对无形资产新增/处置执行测试： ●选择测试方法： 1、根据GAM要求，针对有限风险账户执行的实质性程序可能包括实质分析性复核程序（SAP）或有限详细测试（适当时），其中有限详细测试可能限于选取对账户余额单独具有（由规模或某种定量特征导致的）重要影响的关键项目。 2、程序选择考虑： ①可以有效建立预期，并能够恰当确定预期的精确度的情况下，可以采用SAP。 ②无法建立预期，或预期精确度不够的情况下，采用关键项测试程序。比如：公司没有规范的资本性支出预算等信息，导致无法建立预期；或SAP模型过于粗糙，预期结果的精确度较差，偏差超过阈值，解释成本很高。 ③直接选择执行关键项测试时，如果样本分布均匀导致无关键项的情况下，建议重新评估采用SAP。 ●关键项目的确定： 1、关键项是指如下交易或余额： ①符合表明其单独而言或汇总而言更有可能包含重大错报的定性标准。例如，基于我们对实体业务的了解、我们对固有风险和控制风险的评估以及被测试总体的特征，这些交易或余额是可疑的、异常的、具有较高重大错报风险或过去发生过错报（有关更多指引和示例，请参阅实质性详细测试 2.2.1），或 ②由于与总体中其他项目相比规模较大，因此单独而言具有重要性； 2、如果我们确定应基于定量阈值识别关键项，则将基于综合风险评估的测试阈值作为起点。（有限风险账户没有综合风险评估，测试阈值的确定依赖职业判断。） 3、如果识别出非常多的关键项，则通常表明定量阈值太低，并且与以至于和总体中的其他项目相比，这些项目可能不够不同，无法被认为是关键项。 | Q71: 原值测试 - 对无形资产新增/处置执行测试： 1、未对大于TE的新增或处置交易执行测试； 2、程序选择不恰当； 3、关键项目测试的选择标准和理由或未恰当记录。
C73: 本年无形资产原值本期新增8685893.84元，小于TE，不再执行关键项测试。未发生原值处置，不计划执行测试。 在识别关键项时，我们考虑以下两个因素： 1、定量：我们计划将新增发生额超过人民币8707500（1倍TE）的资产设定为关键项。 2、定性：我们将本年新增样本性质异常的单项资产，设定为关键项。
...
