Workbook
Name \0: #REF!
Name \a: #REF!
Name \b: #REF!
Name \c: #REF!
Name \d: #REF!
Name \e: #REF!
Name \f: #N/A
Name \g: #N/A
Name \h: #N/A
Name \L: #REF!
Name \p: #N/A
Name \q: #N/A
Name \r: #N/A
Name \s: #REF!
Name \t: #REF!
Name \u: #REF!
Name \v: #REF!
Name \w: #REF!
Name _: #REF!
Name _.xls: #REF!
Name _??????: #N/A
Name __ŠUŠÇ__: NA()
Name _001年其他业务利润: #REF!
Name _001预提费用: #REF!
Name _002: #REF!
Name _002辅助类: #REF!
Name _002年股份: #REF!
Name _002年其他业务利润: #REF!
Name _002年预提费用: #REF!
Name _003: #REF!
Name _003固定资产: #REF!
Name _003固定资产明细帐: #REF!
Name _003累计折旧明细帐: #REF!
Name _003年固定资产: #REF!
Name _003年其他业务利润: #REF!
Name _01.xls: #REF!
Name _014gs: #REF!
Name _014hf: #REF!
Name _02: #REF!
Name _02.xls: #REF!
Name _03.xls: #REF!
Name _1: #REF!
Name _11.xls: #REF!
Name _12.xls: #REF!
Name _121.dbf: #REF!
Name _1212002.dbf: #REF!
Name _133999.dbf: #REF!
Name _17103.dbf: #REF!
Name _171032002.dbf: #REF!
Name _1H02_ADJ: #REF!
Name _1H03_ADJ: #REF!
Name _1H04_ADJ: #REF!
Name _1H05_ADJ: #REF!
Name _1H06_ADJ: #REF!
Name _1其他资产_开办费除外_明细表: #REF!
Name _2: #REF!
Name _23: #REF!
Name _2H02_ADJ: #REF!
Name _2H03_ADJ: #REF!
Name _2H04_ADJ: #REF!

Sheet Comments【归档前删除】
A1: EY Ref. | B1: Tab Ref. | C1: Cell Ref. | D1: Question/Comment | E1: Answer/Comment | F1: Closed?
A2: 1 | B2: M.01 银承BKD | C2: $B$31 | D2: Dana D Li:_x000D_ 这里要写选样的策略，如果没有符合标准的样本，记录在第38行的表里_x000D_ | E2: Jayla Zhang:_x000D_ 已修改_x000D_ Dana D Li:_x000D_ 参考SOP写 公司的银行承兑汇票主要用于货款结算，公司已统一使用了集团公司的资金管理系统，对包括银行承兑汇票在内资金业务统一核算管理；根据连续审计，未发现公司存在应付票据的错报，故在执行表2获取承兑余额与总账金额一致的基础上，我们按以下选样标准对单张票据执行发函或检查： a.在执行表1的总账与明细账核对中，涉及差异的单张票据； b.异常的供应商（收票人），如与实体名称相近却并未被识别为关联方的供应商，或不属于该实体行业的供应商； c.除上述情况外，票面金额超过测试阈值的未逾期单张票据； d.已逾期单张票据（如有）。 _x000D_ | F2: No
A3: 2 | B3: M.01 银承BKD | C3: $G$48 | D3: Dana D Li:_x000D_ 差异原因是什么？补充_x000D_ | E3: Jayla Zhang:_x000D_ 已补充_x000D_ | F3: No
A4: 3 | B4: M.01 银承BKD | C4: $B$55 | D4: Dana D Li:_x000D_ 这里要和2.2表格的选样策略保持一致，应该也是没有符合条件的样本，下方的内容删掉吧_x000D_ | F4: No

Sheet 汇总
A1: V6 SWP
C3: 客户名称 | D3: DPCA | F3: 重要性水平(PM) | G3: 449080000
C5: 期末 | D5: 46022 | F5: 可容忍误差(TE) | G5: 337000000
C7: 记账本位币 | D7: CNY | F7: 名义金额(SAD) | G7: 16750000
C9: 适用会计准则 | D9: PRC
E13: Threshold(s)
C14: 认定 | D14: CRA | E14: 各项认定1 | F14: 所有相关认定 2
C15: 完整性 (C) | D15: N/A | E15: =IF(D15="Minimal",$G$5*50%,IF(D15="Low",$G$5*25%,IF(D15="Moderate",$G$5*15%,IF(D15="High",$G$5*10%,IF(D15="N/A","-",))))) -> - | F15: =G5*100% -> 337000000 | G15: 有限风险
C16: 存在性 (E) | D16: N/A | E16: =IF(D16="Minimal",$G$5*100%,IF(D16="Low",$G$5*75%,IF(D16="Moderate",$G$5*50%,IF(D16="High",$G$5*25%,IF(D16="N/A","-",))))) -> -
C17: 计价(V) | D17: N/A | E17: =IF(D17="Minimal",$G$5*100%,IF(D17="Low",$G$5*75%,IF(D17="Moderate",$G$5*50%,IF(D17="High",$G$5*25%,IF(D17="N/A","-",))))) -> -
C18: 权利和义务 (R&O) | D18: N/A | E18: =IF(D18="Minimal",$G$5*100%,IF(D18="Low",$G$5*75%,IF(D18="Moderate",$G$5*50%,IF(D18="High",$G$5*25%,IF(D18="N/A","-",))))) -> -
C19: 列报和披露 (P&D) | D19: N/A | E19: =IF(D19="Minimal",$G$5*100%,IF(D19="Low",$G$5*75%,IF(D19="Moderate",$G$5*50%,IF(D19="High",$G$5*25%,IF(D19="N/A","-",))))) -> -
C20: 1 各项认定的测试阈值，是根据EY GAM SUBSTANTIVE DESIGN 2.2.1
C21: 中的示例测试阈值（用占TE的百分比表示）在相应风险等级（CRA）区间的上限计算得出的。
C22: 除负债/费用类别账户的完整性认定应当使用负债/费用账户表之外，其他类别账户和认定均可使用资产/收入账户表。
C23: 2 所有相关认定的测试阈值，是所有有效认定对应之测试阈值的最小值。我们在 Lead中使用该测试阈值：（a）作为选取总账账户进行测试的起点；（b）作为（需要进一步调查的）金额波动范围的起点。
A25: P1 | C25: 序号 | D25: 报表科目 | E25: 执行实质性程序 | F25: 实质性程序类型 | G25: 认定 | H25: 程序描述 | I25: 执行 | J25: 索引 | K25: 如不执行PSP，原因需记录文字多于5个文字
C26: 1 | D26: 应付票据 | E26: M-01-GL: 将明细账与总账核对一致 | F26: PSP | G26: BS: E, C | H26: 通过执行分析和调查两期的应付票据科目重大变动来确定应付票据余额是否合理。 | I26: Yes | J26: M.00 Lead
I27: Yes | J27: M.01.01&02.01明细账 | K27: 详见<DPCC-银承>、<DPCA-银承>
C28: 2 | D28: 应付票据_银行承兑汇票 | E28: M-01-GL: 将应付票据明细账与总账核对一致，检查合同及其条款的合规性。 | F28: PSP | G28: BS: E, C | H28: 获取应付票据_银行承兑汇票明细账，将余额与相应的总分类账核对一致。检查应付票据_银行承兑汇票开票条件及存续状态等情况，对银行承兑汇票进行函证；检查银行承兑汇票保证合理性。 | I28: Yes | J28: M.01 银承BKD
A29: /P1 | C29: 3 | D29: 应付票据_商业承兑汇票 | E29: M-01-GL: 将应付票据明细账与总账核对一致，检查合同及其条款的合规性。 | F29: PSP | G29: BS: E, C | H29: 获取应付票据_商业承兑汇票明细账，将余额与相应的总分类账核对一致。检查应付票据_商业承兑汇票开票条件及存续状态等情况；必要时，对商业承兑汇票进行函证。 | I29: NO | J29: M.02 商承BKD | K29: 截止期末，被审单位商业承兑汇票期末余额为0，不适用此程序。
C32: 应付票据账户总结陈述
C33: 通过执行审计程序：
C34: √ | D34: 我们没有发现任何超过SAD的错报
D35: 我们已经完成了于该些科目相关的细节测试，并发现了一个或多个超过SAD的错报，我们已经将这些错报记录于审计差异汇总（SAD template)中, 并将该审计差异汇总表放入Canvas。
C38: 安永标记
C39: TB | D39: 已与科目余额表核对无误
C40: PY | D40: 与上年最终审定数核对一致
C41: A3 | D41: 与未审数、审定数核对一致
C42: A5 | D42: 与审计调整核对一致
C43: FS | D43: 与FS.0x与财务报表核对无误
C44: w | D44: 低于SAD的金额——放弃进一步调查
C45: Rx | D45: 重新计算，无异常
C46: m | D46: 余额/活动不符合测试范围–无需进一步调查
C47: SL | D47: 已与明细账核对无误

Sheet M.00 Lead
A1: 03878ede-ea5b-4f95-861a-b27c211af73e
J2: 返回汇总页
C4: 目标
C5: 通过执行分析和调查两期的应付票据科目重大变动来确定应付票据余额是否合理。
C8: 序号 | D8: 执行的程序 | G8: 程序表 | H8: 预审完成 | I8: 年审完成 | J8: 执行注意事项
C9: 1 | D9: 我们获取应付票据科目余额表本期金额以及上年审定数。 | G9: 表2 | H9: 是 | I9: 是
C10: 2 | D10: 我们将两期审定金额进行比对，对那些变动大于范围的事项，获得管理层解释并对解释是否合理进行调查。 | G10: 表2 | H10: 是 | I10: 是
C13: 在下文中描述我们当期对应付余额和相关波动的预期，以及这些预期的依据和理由。
C14: 预期减少，相关单体银承到期结清。
C19: 波动范围
C20: ="波动幅度 ("&汇总!D11&"):" -> 波动幅度 (): | D20: =汇总!$F$15 -> 337000000
C21: 波动幅度 (%): | D21: 0.1
F22: |------- TB -------| | K22: |------- PY -------|
B23: 表2 | C23: 账套名称/账套编码 | D23: 科目名称 | E23: 索引号 | H23: =汇总!D5 -> 46022 | K23: =DATE(YEAR($H$23)-1,12,31) -> 45657 | L23: 变动 | O23: 基于波动幅度判断，是否进一步调查？ | P23: 基于定性考虑判断，是否进一步调查？
F24: 期末账面数 | G24: 账表调整数 | H24: 期末未审数 | I24: 审计调整数 | J24: 期末审定数 | K24: 上期末审定数 | L24: 金额 | M24: % | N24: Notes
C25: DPCA | D25: 银行承兑汇票 | E25: M.01/ | F25: 50570211 | H25: =F25+G25 -> 50570211 | J25: =H25+I25 -> 50570211 | K25: 78462838 | L25: =J25-K25 -> -27892627 | M25: =IFERROR(L25/K25,1) -> -0.35548838 | O25: =IF(AND(L25<>0,ABS(L25)>=$D$20,OR(M25="N/A",ABS(IFERROR(L25/K25,0))>=$D$21)),"是","否") -> 否 | P25: 否
C26: DPCC | D26: 银行承兑汇票 | F26: 11616668 | H26: =F26+G26 -> 11616668 | J26: =H26+I26 -> 11616668 | K26: 56425688 | L26: =J26-K26 -> -44809020 | M26: =IFERROR(L26/K26,1) -> -0.79412447 | O26: =IF(AND(L26<>0,ABS(L26)>=$D$20,OR(M26="N/A",ABS(IFERROR(L26/K26,0))>=$D$21)),"是","否") -> 否 | P26: 否
C27: DPCA | D27: 商业承兑汇票 | E27: M.02/ | F27: 0 | H27: =F27+G27 -> 0 | J27: =H27+I27 -> 0 | K27: 3.2057007e+08 | L27: =J27-K27 -> -3.2057007e+08 | M27: =IFERROR(L27/K27,1) -> -1 | O27: =IF(AND(L27<>0,ABS(L27)>=$D$20,OR(M27="N/A",ABS(IFERROR(L27/K27,0))>=$D$21)),"是","否") -> 否 | P27: 否
C28: DPCC | D28: 商业承兑汇票 | E28: M.02/ | F28: 0 | H28: =F28+G28 -> 0 | J28: =H28+I28 -> 0 | K28: 2.2779698e+08 | L28: =J28-K28 -> -2.2779698e+08 | M28: =IFERROR(L28/K28,1) -> -1 | O28: =IF(AND(L28<>0,ABS(L28)>=$D$20,OR(M28="N/A",ABS(IFERROR(L28/K28,0))>=$D$21)),"是","否") -> 否 | P28: 否
E29: 合计 | F29: =SUM(F25:F28) -> 62186880 | G29: =SUM(G25:G28) -> 0 | H29: =F29+G29 -> 62186880 | I29: =SUM(I25:I28) -> 0 | J29: =H29+I29 -> 62186880 | K29: =SUM(K25:K28) -> 6.8325558e+08 | L29: =J29-K29 -> -6.210687e+08 | M29: =IFERROR(L29/K29,1) -> -0.90898445 | N29: [A] | O29: =IF(AND(L29<>0,ABS(L29)>=$D$20,OR(M29="N/A",ABS(IFERROR(L29/K29,0))>=$D$21)),"是","否") -> 是 | P29: 否
F30: RX | G30: RX | I30: RX | K30: RX
G31: A3 | H31: =[1]A3_单体报表审定数!$F$78 -> 62186880 | J31: =[1]A3_单体报表审定数!$DL$78 -> 62186880 | K31: =[1]A3_单体报表审定数!$DN$78 -> 6.8325558e+08
G32: Diff | H32: =H29-H31 -> 0 | J32: =J29-J31 -> 0 | K32: =K29-K31 -> 0
C34: 波动说明
C35: [A]本期应付票据减少621,068k，本期应付票据下降主要受商业承兑汇票减少影响。经了解，主要原因为部分供应商已不再接受商票结算，导致公司本期未新增商票，原有票据已兑付结清。
C41: 调整汇总表（如不适用请删除）
C42: 调整类型

Sheet M.01 银承BKD
A1: 777ea5b4-12a4-4b4f-bd5a-60b7ed0d4f78
I2: 返回汇总页
B4: 目标
B5: 复核应付票据_银行承兑汇票金额、期限、担保品等支持性文件，并执行函证程序。
B7: 序号 | C7: 执行的程序 | F7: 程序表 | G7: 预审完成 | H7: 年审完成 | I7: 执行注意事项
B8: 1 | C8: 获取银行承兑汇票（含财务公司承兑汇票）明细表，将明细表期末总金额与银行承兑汇票总账核对一致。复核利息费用和应付利息计算的合理性（如适用）。 | F8: M.01&02.01明细账及表1 | G8: 是 | H8: 是
B9: 2 | C9: 检查银行承兑汇票协议或其他短期借款安排的文件，以确认银行承兑汇票的条款、限制、循环信用额和其他相关规定，选择需要进行函证的银行承兑汇票进行函证，并核对银行回函金额与账面金额一致。 | F9: 表2.1、表2.2及表2.3 | G9: 是 | H9: 是
B10: 3 | C10: 根据银行承兑汇票明细表，获取逾期银行承兑汇票的信息，对逾期银行承兑汇票未支付事项选取样本进行调查，查看逾期未支付的银行承兑汇票是否应当转入短期借款。（如适用） | F10: 表2.1及表2.2 | G10: 是 | H10: 是
B11: 4 | C11: 将银行承兑汇票金额与授信额度或担保金额、银承保证金、结构性存款、理财产品等开票担保品账面价值进行核对，选取样本验证银行承兑汇票期末余额合理性（如适用）。 | F11: 表2.1及表2.4 | G11: 是 | H11: 是
B14: 表1 将明细账与总账核对一致
B15: 账套名称/账套编码 | C15: 科目名称 | D15: Lead页余额 | E15: 索引号 | F15: 明细账余额 | G15: 明细账索引 | H15: 差异重新计算 （Note1）
B16: DPCA | C16: 应付票据－银行承兑汇票-不带息 | D16: ='M.00 Lead'!F25 -> 50570211 | E16: /M.00 | F16: ='DPCA-银承'!G54 -> 50570211 | G16: /M.01&02.01明细账 | H16: =D16-F16 -> 0
B17: DPCC | C17: 银行承兑汇票 | D17: ='M.00 Lead'!F26 -> 11616668 | F17: ='DPCC-银承'!I31 -> 11616668 | H17: =D17-F17 -> 0
C19: 合计 | D19: =SUM(D16:D17) -> 62186880 | F19: =SUM(F16:F17) -> 62186880 | H19: =SUM(H16:H17) -> 0
D20: RX | F20: RX | H20: RX
B23: EY 测试属性解释: | DW23: 使用授信额度
B24: 对于应付票据_银行承兑汇票，我们执行以下程序，以确保： | DW24: 保证金质押开票
B25: 1) 向承兑银行发函确认应付票据_银行承兑汇票的余额，核对账面金额与回函金额相符。 | DW25: 结构性存款质押开票
B26: 2) 根据应付票据_银行承兑汇票明细表，获取了逾期银行承兑汇票的信息；对逾期银行承兑汇票未支付事项进行了调查，逾期未支付的银行承兑汇票已转入短期借款。
B27: 3) 使用授信额度或其他担保方式开立银行承兑汇票的，已检查银行承兑汇票的协议或银行授信审批文件，未发现异常情况。 | DW27: 理财产品质押开票
B28: 4) 将相关质押品账面价值与应付票据_银行承兑汇票余额进行核对，计算质押品账面价值与相关债务的比例，质押水平符合合同或协议约定要求。 | DW28: 应收票据质押开票
DW29: 第三方担保方式开票
B30: 表2.1 项目组在下面记录选样策略与理由
B31: 公司的银行承兑汇票主要用于货款结算，公司已统一使用了集团公司的资金管理系统，对包括银行承兑汇票在内资金业务统一核算管理；根据连续审计，未发现公司存在应付票据的错报，故在执行表2.3获取承兑余额与总账金额一致的基础上，我们按以下选样标准对单张票据执行发函或检查： a.在执行表1的总账与明细账核对中，涉及差异的单张票据； b.异常的供应商（收票人），如与实体名称相近却并未被识别为关联方的供应商，或不属于该实体行业的供应商； c.除上述情况外，票面金额超过测试阈值的未逾期单张票据； d.已逾期单张票据（如有）。
B35: 表2.2 根据表2.1的选样策略，选取测试项目执行EY测试属性1和2，并记录测试结论于下表
N36: EY Works | P36: 函证索引号 | Q36: 逾期原因（如适用） | R36: 针对未回函的应付票据执行的替代程序及结论
B37: EY测试属性类别 | C37: 账套名称/账套编码 | D37: 供应商名称 | E37: 出票人 | F37: 收票人 | G37: 签发日期 | H37: 到期日 | I37: 票据票面金额 | J37: 票据号码 | K37: 承兑人名称 | L37: 开票保证方式 | M37: 约定利率 | N37: 1 | O37: 2
B38: 我们对被审单位所有银行承兑汇票执行发函程序，未发现账面金额与回函金额不符以及逾期的情况，也无大于TT的票据，故不适用此表。
B41: 表2.3 核对银行回函金额（包括格式一与格式二）与账面金额是否一致
B42: 账套名称/账套编码 | C42: 承兑银行/回函银行 | D42: 回函金额 | E42: 账面金额 | F42: 索引号 | G42: 差异 | H42: 差异原因及解释
B43: DPCC | C43: 交通银行股份有限公司武汉经济技术开发区支行 | D43: =SUMIF('回函7.尚未支付的银行承兑汇票'!A:A,'M.01 银承BKD'!B43,'回函7.尚未支付的银行承兑汇票'!H:H) -> 11640668 | E43: =D17 -> 11616668 | F43: /M.01&02.01明细账&回函7.尚未支付的银行承兑汇票 | G43: =D43-E43 -> 24000 | H43: 差异金额系银行系统更新导致的回函错误，经询问客户并检查支付的银行回单417886852494，该票据2024/6/26已支付，未见其他异常。
B44: DPCA | C44: 中国建设银行股份有限公司武汉经济技术开发区支行 | D44: =SUMIF('回函7.尚未支付的银行承兑汇票'!A:A,'M.01 银承BKD'!B44,'回函7.尚未支付的银行承兑汇票'!H:H) -> 50570211 | E44: =D16 -> 50570211 | F44: /M.01&02.01明细账&回函8.尚未支付的银行承兑汇票 | G44: =D44-E44 -> 0 | H44: NA
B45: DPCA | C45: 交通银行股份有限公司武汉经济技术开发区支行 | F45: /M.01&02.01明细账&回函9.尚未支付的银行承兑汇票 | H45: NA
G46: =D46-E46 -> 0
G47: =D47-E47 -> 0
B49: 表2.4 对表2.2中测试项目涉及的承兑银行，执行EY测试属性3和4，并记录测试结论于下表
B50: EY测试属性类别 | C50: 账套名称/账套编码 | D50: 承兑银行/出具实体 | E50: 票据金额 | F50: 索引号 | G50: 开票方式 | H50: 授信额度或担保金额 | I50: 开票协议或抵质押协议约定的比例 | J50: 用于质押的资产账面价值 | P50: 质押水平是否符合约定 | Q50: EY Works | S50: 质押水平不符合约定的原因
J51: 用于质押开票的保证金账面价值 | K51: 用于质押开票的结构性存款账面价值 | L51: 用于质押开票的理财产品账面价值 | M51: 用于质押开票的应收票据账面价值 | N51: 其他 | O51: 小计 | Q51: 3 | R51: 4
J52: C 货币资金 | K52: 【/D200_结构性存款】 | L52: 【/D200_银行理财产品】 | M52: E2E3 | N52: 根据实际情况填列
B53: 同表2.2的测试条件，无符合要求的测试样本，不适用此程序。
...

Sheet DPCC-银承
A1: 账套名称/账套编码 | B1: 票据性质 | C1: 票据号码 | D1: 子票区间 | E1: 票据类型 | F1: 出票人户名 | G1: 出票行名称 | H1: 收款人户名 | I1: 金额 | J1: 出票日期 | K1: 到期日期 | L1: 承兑人名称 | M1: 能否转让 | N1: 是否分包流转 | O1: 操作日期 | P1: 收款人签收时间 | Q1: 备注 | R1: 票面备注 | S1: 票据状态 | T1: 流通状态
A2: DPCC | B2: 银承 | C2: 530152100701520251030001574475 | D2: 000000000001-000028431567 | E2: 银承 | F2: 神龙汽车有限公司成都分公司 | G2: 交通银行股份有限公司武汉经济技术开发区支行 | H2: 十堰银轮汽车零部件有限公司 | I2: 284315.67 | J2: 2025-10-30 | K2: 2026-04-27 | L2: 交通银行股份有限公司武汉经济技术开发区支行 | M2: 可再转让 | N2: 是 | O2: 2025-10-30 | P2: 2025-11-04 11:15:40 | Q2: 1100002821 | R2: 1100002821 | S2: 已收票 | T2: 可流通
A3: DPCC | B3: 银承 | C3: 530152100701520251030101570915 | D3: 000000000001-000162300000 | E3: 银承 | F3: 神龙汽车有限公司成都分公司 | G3: 交通银行股份有限公司武汉经济技术开发区支行 | H3: 宁波建新底盘系统有限公司 | I3: 1623000 | J3: 2025-10-30 | K3: 2026-04-27 | L3: 交通银行股份有限公司武汉经济技术开发区支行 | M3: 可再转让 | N3: 是 | O3: 2025-10-30 | P3: 2025-11-02 14:12:21 | Q3: 1100002814 | R3: 1100002814 | S3: 已收票 | T3: 可流通
A4: DPCC | B4: 银承 | C4: 530152100701520251030101314037 | D4: 000000000001-000026900000 | E4: 银承 | F4: 神龙汽车有限公司成都分公司 | G4: 交通银行股份有限公司武汉经济技术开发区支行 | H4: 泰州苏中天线集团有限公司 | I4: 269000 | J4: 2025-10-30 | K4: 2026-04-27 | L4: 交通银行股份有限公司武汉经济技术开发区支行 | M4: 可再转让 | N4: 是 | O4: 2025-10-30 | P4: 2025-10-31 18:34:20 | Q4: 1100002831 | R4: 1100002831 | S4: 已收票 | T4: 可流通
A5: DPCC | B5: 银承 | C5: 530152100701520251030001316401 | D5: 000000000001-000011800000 | E5: 银承 | F5: 神龙汽车有限公司成都分公司 | G5: 交通银行股份有限公司武汉经济技术开发区支行 | H5: 东来涂料技术（上海）股份有限公司 | I5: 118000 | J5: 2025-10-30 | K5: 2026-04-27 | L5: 交通银行股份有限公司武汉经济技术开发区支行 | M5: 可再转让 | N5: 是 | O5: 2025-10-30 | P5: 2025-10-31 17:44:17 | Q5: 1100002837 | R5: 1100002837 | S5: 已收票 | T5: 可流通
A6: DPCC | B6: 银承 | C6: 530152100701520251030001316410 | D6: 000000000001-000011747998 | E6: 银承 | F6: 神龙汽车有限公司成都分公司 | G6: 交通银行股份有限公司武汉经济技术开发区支行 | H6: 东来涂料技术（上海）股份有限公司 | I6: 117479.98 | J6: 2025-10-30 | K6: 2026-04-27 | L6: 交通银行股份有限公司武汉经济技术开发区支行 | M6: 可再转让 | N6: 是 | O6: 2025-10-30 | P6: 2025-10-31 17:44:17 | Q6: 1100002836 | R6: 1100002836 | S6: 已收票 | T6: 可流通
A7: DPCC | B7: 银承 | C7: 530152100701520251030001316590 | D7: 000000000001-000387852146 | E7: 银承 | F7: 神龙汽车有限公司成都分公司 | G7: 交通银行股份有限公司武汉经济技术开发区支行 | H7: 库博汽车标准配件（昆山）有限公司 | I7: 3878521.5 | J7: 2025-10-30 | K7: 2026-04-27 | L7: 交通银行股份有限公司武汉经济技术开发区支行 | M7: 可再转让 | N7: 是 | O7: 2025-10-30 | P7: 2025-10-31 18:27:11 | Q7: 1100002818 | R7: 1100002818 | S7: 已收票 | T7: 可流通
A8: DPCC | B8: 银承 | C8: 530152100701520251030101314053 | D8: 000000000001-000016885922 | E8: 银承 | F8: 神龙汽车有限公司成都分公司 | G8: 交通银行股份有限公司武汉经济技术开发区支行 | H8: 上海凯密特尔化学品有限公司 | I8: 168859.22 | J8: 2025-10-30 | K8: 2026-04-27 | L8: 交通银行股份有限公司武汉经济技术开发区支行 | M8: 可再转让 | N8: 是 | O8: 2025-10-30 | P8: 2025-11-03 12:28:09 | Q8: 1100002822 | R8: 1100002822 | S8: 已收票 | T8: 可流通
A9: DPCC | B9: 银承 | C9: 530152100701520251030001316604 | D9: 000000000001-000052364533 | E9: 银承 | F9: 神龙汽车有限公司成都分公司 | G9: 交通银行股份有限公司武汉经济技术开发区支行 | H9: 广西盛百汇电子股份有限公司 | I9: 523645.33 | J9: 2025-10-30 | K9: 2026-04-27 | L9: 交通银行股份有限公司武汉经济技术开发区支行 | M9: 可再转让 | N9: 是 | O9: 2025-10-30 | P9: 2025-10-31 19:59:15 | Q9: 1100002813 | R9: 1100002813 | S9: 已收票 | T9: 可流通
A10: DPCC | B10: 银承 | C10: 530152100701520251030001316372 | D10: 000000000001-000043743137 | E10: 银承 | F10: 神龙汽车有限公司成都分公司 | G10: 交通银行股份有限公司武汉经济技术开发区支行 | H10: 迈瑞特长春汽车电子有限公司 | I10: 437431.37 | J10: 2025-10-30 | K10: 2026-04-27 | L10: 交通银行股份有限公司武汉经济技术开发区支行 | M10: 可再转让 | N10: 是 | O10: 2025-10-30 | P10: 2025-11-07 09:04:12 | Q10: 1100002834 | R10: 1100002834 | S10: 已收票 | T10: 可流通
A11: DPCC | B11: 银承 | C11: 530152100701520251030101314061 | D11: 000000000001-000004400000 | E11: 银承 | F11: 神龙汽车有限公司成都分公司 | G11: 交通银行股份有限公司武汉经济技术开发区支行 | H11: 武汉新环球汽车内饰件有限公司 | I11: 44000 | J11: 2025-10-30 | K11: 2026-04-27 | L11: 交通银行股份有限公司武汉经济技术开发区支行 | M11: 可再转让 | N11: 是 | O11: 2025-10-30 | P11: 2025-11-17 10:44:24 | Q11: 1100002824 | R11: 1100002824 | S11: 已收票 | T11: 可流通
A12: DPCC | B12: 银承 | C12: 530152100701520251030001316532 | D12: 000000000001-000005327453 | E12: 银承 | F12: 神龙汽车有限公司成都分公司 | G12: 交通银行股份有限公司武汉经济技术开发区支行 | H12: 湖州安达汽车配件股份有限公司 | I12: 53274.53 | J12: 2025-10-30 | K12: 2026-04-27 | L12: 交通银行股份有限公司武汉经济技术开发区支行 | M12: 可再转让 | N12: 是 | O12: 2025-10-30 | P12: 2025-11-03 10:39:44 | Q12: 1100002829 | R12: 1100002829 | S12: 已收票 | T12: 可流通
A13: DPCC | B13: 银承 | C13: 530152100701520251030001316397 | D13: 000000000001-000008131117 | E13: 银承 | F13: 神龙汽车有限公司成都分公司 | G13: 交通银行股份有限公司武汉经济技术开发区支行 | H13: 上海寅申实业有限公司 | I13: 81311.17 | J13: 2025-10-30 | K13: 2026-04-27 | L13: 交通银行股份有限公司武汉经济技术开发区支行 | M13: 可再转让 | N13: 是 | O13: 2025-10-30 | P13: 2025-11-06 15:51:03 | Q13: 1100002827 | R13: 1100002827 | S13: 已收票 | T13: 可流通
... A29: DPCC | B29: 银承 | C29: 530152100701520251030101313964 | D29: 000000000001-000006800000 | E29: 银承 | F29: 神龙汽车有限公司成都分公司 | G29: 交通银行股份有限公司武汉经济技术开发区支行 | H29: 骆驼集团蓄电池销售有限公司 | I29: 68000 | J29: 2025-10-30 | K29: 2026-04-27 | L29: 交通银行股份有限公司武汉经济技术开发区支行 | M29: 可再转让 | N29: 是 | O29: 2025-10-30 | P29: 2025-10-31 18:22:29 | Q29: 1100002833 | R29: 1100002833 | S29: 已收票 | T29: 可流通
I31: =SUM(I2:I30) -> 11616668

Sheet DPCA-银承
A1: 账套名称/账套编码 | B1: 票据性质 | C1: 出票人 | D1: 收票人 | E1: 签发日期 | F1: 到期日 | G1: 票据票面金额 | H1: 票据号码 | I1: 起始子票区间 | J1: 结束子票区间 | K1: 承兑人名称 | L1: 票据状态
A2: DPCA | B2: 银承 | C2: 神龙汽车有限公司 | D2: 东风彼欧(成都)汽车外饰系统有限公司 | E2: 2025-10-30 | F2: 2026-04-27 | G2: 1000000 | H2: 530152100701520251030001255025 | I2: 000000000001-000100000000 | K2: 交通银行股份有限公司武汉经济技术开发区支行 | L2: 已收票-可流通
A3: DPCA | B3: 银承 | C3: 神龙汽车有限公司 | D3: 重庆中盟科技股份有限公司 | E3: 2025-10-30 | F3: 2026-04-27 | G3: 327000 | H3: 530152100701520251030001254854 | I3: 000000000001-000032700000 | K3: 交通银行股份有限公司武汉经济技术开发区支行 | L3: 已收票-可流通
A4: DPCA | B4: 银承 | C4: 神龙汽车有限公司 | D4: 深圳市理士新能源发展有限公司 | E4: 2025-10-30 | F4: 2026-04-27 | G4: 2000000 | H4: 530152100701520251030101251283 | I4: 000000000001-000200000000 | K4: 交通银行股份有限公司武汉经济技术开发区支行 | L4: 已收票-可流通
A5: DPCA | B5: 银承 | C5: 神龙汽车有限公司 | D5: 东来涂料技术（上海）股份有限公司 | E5: 2025-10-30 | F5: 2026-04-27 | G5: 223583.03 | H5: 530152100701520251030001254846 | I5: 000000000001-000022358303 | K5: 交通银行股份有限公司武汉经济技术开发区支行 | L5: 已收票-可流通
A6: DPCA | B6: 银承 | C6: 神龙汽车有限公司 | D6: 湖南湘江关西涂料（长沙）有限公司 | E6: 2025-10-30 | F6: 2026-04-27 | G6: 500000 | H6: 530152100701520251030101251435 | I6: 000000000001-000050000000 | K6: 交通银行股份有限公司武汉经济技术开发区支行 | L6: 已收票-可流通
A7: DPCA | B7: 银承 | C7: 神龙汽车有限公司 | D7: 上海凯密特尔化学品有限公司 | E7: 2025-10-30 | F7: 2026-04-27 | G7: 259635.59 | H7: 530152100701520251030101251291 | I7: 000000000001-000025963559 | K7: 交通银行股份有限公司武汉经济技术开发区支行 | L7: 已收票-可流通
A8: DPCA | B8: 银承 | C8: 神龙汽车有限公司 | D8: 广西盛百汇电子股份有限公司 | E8: 2025-10-30 | F8: 2026-04-27 | G8: 256000 | H8: 530152100701520251030001254879 | I8: 000000000001-000025600000 | K8: 交通银行股份有限公司武汉经济技术开发区支行 | L8: 已收票-可流通
A9: DPCA | B9: 银承 | C9: 神龙汽车有限公司 | D9: 宁波建新底盘系统有限公司 | E9: 2025-10-30 | F9: 2026-04-27 | G9: 1663509.7 | H9: 530152100701520251030001255017 | I9: 000000000001-000166350971 | K9: 交通银行股份有限公司武汉经济技术开发区支行 | L9: 已收票-可流通
A10: DPCA | B10: 银承 | C10: 神龙汽车有限公司 | D10: 武汉燎原模塑有限公司 | E10: 2025-10-30 | F10: 2026-04-27 | G10: 850000 | H10: 530152100701520251030101251525 | I10: 000000000001-000085000000 | K10: 交通银行股份有限公司武汉经济技术开发区支行 | L10: 已承兑-已锁定
A11: DPCA | B11: 银承 | C11: 神龙汽车有限公司 | D11: 骆驼集团蓄电池销售有限公司 | E11: 2025-10-30 | F11: 2026-04-27 | G11: 75000 | H11: 530152100701520251030101251398 | I11: 000000000001-000007500000 | K11: 交通银行股份有限公司武汉经济技术开发区支行 | L11: 已收票-可流通
A12: DPCA | B12: 银承 | C12: 神龙汽车有限公司 | D12: 湖北敏实汽车零部件有限公司 | E12: 2025-10-30 | F12: 2026-04-27 | G12: 2378.2 | H12: 530152100701520251030101251478 | I12: 000000000001-000000237820 | K12: 交通银行股份有限公司武汉经济技术开发区支行 | L12: 已收票-可流通
A13: DPCA | B13: 银承 | C13: 神龙汽车有限公司 | D13: 培奇爱汽车配件（太仓）有限公司 | E13: 2025-10-30 | F13: 2026-04-27 | G13: 119161.88 | H13: 530152100701520251030001255121 | I13: 000000000001-000011916188 | K13: 交通银行股份有限公司武汉经济技术开发区支行 | L13: 已承兑-已锁定
... A38: DPCA | B38: 银承 | C38: 神龙汽车有限公司 | D38: 重庆三爱海陵实业有限责任公司 | E38: 2025-10-30 | F38: 2026-04-27 | G38: 360418.51 | H38: 530152100701520251030101730902 | I38: 000000000001-000036041851 | K38: 交通银行股份有限公司武汉经济技术开发区支行 | L38: 已收票-可流通
A39: DPCA | B39: 银承 | C39: 神龙汽车有限公司 | D39: 重庆胜维德赫华翔汽车零部件有限公司 | E39: 46021 | F39: 20260630 | G39: 1861235.6 | H39: 510552100105820251230001500050 | I39: 000000000001-000186123562 | K39: 中国建设银行股份有限公司武汉经济技术开发区支行 | L39: 已出票-待收票
A40: DPCA | B40: 银承 | C40: 神龙汽车有限公司 | D40: 湖北敏实汽车零部件有限公司 | E40: 46020 | F40: 20260629 | G40: 3750000 | H40: 510552100105820251229102578757 | I40: 000000000001-000375000000 | K40: 中国建设银行股份有限公司武汉经济技术开发区支行 | L40: 已出票-待收票
A41: DPCA | B41: 银承 | C41: 神龙汽车有限公司 | D41: 安波福连接器系统(武汉)有限公司 | E41: 46020 | F41: 20260629 | G41: 1137793.6 | H41: 510552100105820251229102578724 | I41: 000000000001-000113779357 | K41: 中国建设银行股份有限公司武汉经济技术开发区支行 | L41: 已出票-待收票
A42: DPCA | B42: 银承 | C42: 神龙汽车有限公司 | D42: 深圳市英威腾电动汽车驱动技术有限公司 | E42: 46020 | F42: 20260629 | G42: 3104749.3 | H42: 510552100105820251229102578749 | I42: 000000000001-000310474933 | K42: 中国建设银行股份有限公司武汉经济技术开发区支行 | L42: 已出票-待收票
A43: DPCA | B43: 银承 | C43: 神龙汽车有限公司 | D43: 武汉惠恒实业有限公司 | E43: 46020 | F43: 20260629 | G43: 1500000 | H43: 510552100105820251229002581677 | I43: 000000000001-000150000000 | K43: 中国建设银行股份有限公司武汉经济技术开发区支行 | L43: 已出票-待收票
A44: DPCA | B44: 银承 | C44: 神龙汽车有限公司 | D44: 武汉聚鹏精密制造有限责任公司 | E44: 46020 | F44: 20260629 | G44: 1200000 | H44: 510552100105820251229002581685 | I44: 000000000001-000120000000 | K44: 中国建设银行股份有限公司武汉经济技术开发区支行 | L44: 已出票-待收票
A45: DPCA | B45: 银承 | C45: 神龙汽车有限公司 | D45: 武汉武耀安全玻璃股份有限公司 | E45: 46020 | F45: 20260629 | G45: 1000000 | H45: 510552100105820251229002581888 | I45: 000000000001-000100000000 | K45: 中国建设银行股份有限公司武汉经济技术开发区支行 | L45: 已出票-待收票
A46: DPCA | B46: 银承 | C46: 神龙汽车有限公司 | D46: 深圳市航盛电子股份有限公司 | E46: 46020 | F46: 20260629 | G46: 4009709.7 | H46: 510552100105820251229002581693 | I46: 000000000001-000400970972 | K46: 中国建设银行股份有限公司武汉经济技术开发区支行 | L46: 已出票-待收票
A47: DPCA | B47: 银承 | C47: 神龙汽车有限公司 | D47: 建新赵氏科技股份有限公司 | E47: 46020 | F47: 20260629 | G47: 2030957.1 | H47: 510552100105820251229102578732 | I47: 000000000001-000203095711 | K47: 中国建设银行股份有限公司武汉经济技术开发区支行 | L47: 已出票-待收票
A48: DPCA | B48: 银承 | C48: 神龙汽车有限公司 | D48: 南京奥特佳新能源科技有限公司 | E48: 46020 | F48: 20260629 | G48: 4177520.3 | H48: 510552100105820251229002581915 | I48: 000000000001-000417752032 | K48: 中国建设银行股份有限公司武汉经济技术开发区支行 | L48: 已出票-待收票
A49: DPCA | B49: 银承 | C49: 神龙汽车有限公司 | D49: 深圳市理士新能源发展有限公司 | E49: 46020 | F49: 20260629 | G49: 1602555.8 | H49: 510552100105820251229102578853 | I49: 000000000001-000160255575 | K49: 中国建设银行股份有限公司武汉经济技术开发区支行 | L49: 已出票-待收票
A50: DPCA | B50: 银承 | C50: 神龙汽车有限公司 | D50: 安庆雅德帝伯活塞有限公司 | E50: 46020 | F50: 20260629 | G50: 2409000 | H50: 510552100105820251229002581837 | I50: 000000000001-000240900000 | K50: 中国建设银行股份有限公司武汉经济技术开发区支行 | L50: 已出票-待收票
... A52: DPCA | B52: 银承 | C52: 神龙汽车有限公司 | D52: 湖北诺克合成橡塑密封科技有限公司 | E52: 46020 | F52: 20260629 | G52: 2000000 | H52: 510552100105820251229002581861 | I52: 000000000001-000200000000 | K52: 中国建设银行股份有限公司武汉经济技术开发区支行 | L52: 已出票-待收票
G54: =SUM(G2:G53) -> 50570211

Sheet 回函7.尚未支付的银行承兑汇票
B1: 函证信息 | C1: 函证信息 | D1: 函证信息 | E1: 回函信息 | F1: 回函信息 | G1: 回函信息 | H1: 回函信息 | I1: 回函信息 | J1: 回函信息 | K1: 回函信息 | L1: 跟进措施
A2: 公司 | B2: 函证编号 | C2: 公司名称 | D2: 银行名称 | E2: 银行承兑汇票号码 | F2: 结算账户账号 | G2: 币种 | H2: 票面金额 | I2: 出票日 | J2: 到期日 | K2: 抵（质）押品 | L2: 回函信息跟进工作 底稿索引
A3: DPCA | B3: 11424548-147068/CC5 | C3: 神龙汽车有限公司 | D3: 中国建设银行股份有限公司 | E3: 510552100105820251229002581915 | F3: 42001258136050000680 | G3: 人民币元 | H3: 4177520.3 | I3: 20251229 | J3: 20260629
A4: DPCA | B4: 11424548-147068/CC5 | C4: 神龙汽车有限公司 | D4: 中国建设银行股份有限公司 | E4: 510552100105820251229102578724 | F4: 42001258136050000680 | G4: 人民币元 | H4: 1137793.6 | I4: 20251229 | J4: 20260629
A5: DPCA | B5: 11424548-147068/CC5 | C5: 神龙汽车有限公司 | D5: 中国建设银行股份有限公司 | E5: 510552100105820251229002578732 | F5: 42001258136050000680 | G5: 人民币元 | H5: 2030957.1 | I5: 20251229 | J5: 20260629
A6: DPCA | B6: 11424548-147068/CC5 | C6: 神龙汽车有限公司 | D6: 中国建设银行股份有限公司 | E6: 510552100105820251229002581837 | F6: 42001258136050000680 | G6: 人民币元 | H6: 2409000 | I6: 20251229 | J6: 20260629
A7: DPCA | B7: 11424548-147068/CC5 | C7: 神龙汽车有限公司 | D7: 中国建设银行股份有限公司 | E7: 510552100105820251229102578845 | F7: 42001258136050000680 | G7: 人民币元 | H7: 3000000 | I7: 20251229 | J7: 20260629
A8: DPCA | B8: 11424548-147068/CC5 | C8: 神龙汽车有限公司 | D8: 中国建设银行股份有限公司 | E8: 510552100105820251229102578749 | F8: 42001258136050000680 | G8: 人民币元 | H8: 3104749.3 | I8: 20251229 | J8: 20260629
A9: DPCA | B9: 11424548-147068/CC5 | C9: 神龙汽车有限公司 | D9: 中国建设银行股份有限公司 | E9: 510552100105820251230001500050 | F9: 42001258136050000680 | G9: 人民币元 | H9: 1861235.6 | I9: 20251230 | J9: 20260630
A10: DPCA | B10: 11424548-147068/CC5 | C10: 神龙汽车有限公司 | D10: 中国建设银行股份有限公司 | E10: 510552100105820251229102578853 | F10: 42001258136050000680 | G10: 人民币元 | H10: 1602555.8 | I10: 20251229 | J10: 20260629
A11: DPCA | B11: 11424548-147068/CC5 | C11: 神龙汽车有限公司 | D11: 中国建设银行股份有限公司 | E11: 510552100105820251229102578757 | F11: 42001258136050000680 | G11: 人民币元 | H11: 3750000 | I11: 20251229 | J11: 20260629
A12: DPCA | B12: 11424548-147068/CC5 | C12: 神龙汽车有限公司 | D12: 中国建设银行股份有限公司 | E12: 510552100105820251229002581861 | F12: 42001258136050000680 | G12: 人民币元 | H12: 2000000 | I12: 20251229 | J12: 20260629
A13: DPCA | B13: 11424548-147068/CC5 | C13: 神龙汽车有限公司 | D13: 中国建设银行股份有限公司 | E13: 510552100105820251229002581677 | F13: 42001258136050000680 | G13: 人民币元 | H13: 1500000 | I13: 20251229 | J13: 20260629
A14: DPCA | B14: 11424548-147068/CC5 | C14: 神龙汽车有限公司 | D14: 中国建设银行股份有限公司 | E14: 510552100105820251229002581685 | F14: 42001258136050000680 | G14: 人民币元 | H14: 1200000 | I14: 20251229 | J14: 20260629
... A16: DPCA | B16: 11424548-147068/CC5 | C16: 神龙汽车有限公司 | D16: 中国建设银行股份有限公司 | E16: 510552100105820251229002581693 | F16: 42001258136050000680 | G16: 人民币元 | H16: 4009709.7 | I16: 20251229 | J16: 20260629
A17: DPCA | B17: 11424548-147068/CC8 | C17: 神龙汽车有限公司 | D17: 交通银行湖北省分行 | E17: 530152100701520251030001254696 | F17: 421865258010123005508 | G17: 人民币 | H17: 97834.89 | I17: 20251030 | J17: 20260427 | K17: 无
A18: DPCA | B18: 11424548-147068/CC8 | C18: 神龙汽车有限公司 | D18: 交通银行湖北省分行 | E18: 530152100701520251030001254846 | F18: 421865258010123005508 | G18: 人民币 | H18: 223583.03 | I18: 20251030 | J18: 20260427 | K18: 无
A19: DPCA | B19: 11424548-147068/CC8 | C19: 神龙汽车有限公司 | D19: 交通银行湖北省分行 | E19: 530152100701520251030001254854 | F19: 421865258010123005508 | G19: 人民币 | H19: 327000 | I19: 20251030 | J19: 20260427 | K19: 无
A20: DPCA | B20: 11424548-147068/CC8 | C20: 神龙汽车有限公司 | D20: 交通银行湖北省分行 | E20: 530152100701520251030001254879 | F20: 421865258010123005508 | G20: 人民币 | H20: 256000 | I20: 20251030 | J20: 20260427 | K20: 无
A21: DPCA | B21: 11424548-147068/CC8 | C21: 神龙汽车有限公司 | D21: 交通银行湖北省分行 | E21: 530152100701520251030001254862 | F21: 421865258010123005508 | G21: 人民币 | H21: 388053.76 | I21: 20251030 | J21: 20260427 | K21: 无
A22: DPCA | B22: 11424548-147068/CC8 | C22: 神龙汽车有限公司 | D22: 交通银行湖北省分行 | E22: 530152100701520251030001254926 | F22: 421865258010123005508 | G22: 人民币 | H22: 87867.62 | I22: 20251030 | J22: 20260427 | K22: 无
A23: DPCA | B23: 11424548-147068/CC8 | C23: 神龙汽车有限公司 | D23: 交通银行湖北省分行 | E23: 530152100701520251030001255009 | F23: 421865258010123005508 | G23: 人民币 | H23: 318462.96 | I23: 20251030 | J23: 20260427 | K23: 无
A24: DPCA | B24: 11424548-147068/CC8 | C24: 神龙汽车有限公司 | D24: 交通银行湖北省分行 | E24: 530152100701520251030001255017 | F24: 421865258010123005508 | G24: 人民币 | H24: 1663509.7 | I24: 20251030 | J24: 20260427 | K24: 无
A25: DPCA | B25: 11424548-147068/CC8 | C25: 神龙汽车有限公司 | D25: 交通银行湖北省分行 | E25: 530152100701520251030001255025 | F25: 421865258010123005508 | G25: 人民币 | H25: 1000000 | I25: 20251030 | J25: 20260427 | K25: 无
A26: DPCA | B26: 11424548-147068/CC8 | C26: 神龙汽车有限公司 | D26: 交通银行湖北省分行 | E26: 530152100701520251030001254887 | F26: 421865258010123005508 | G26: 人民币 | H26: 1205435.7 | I26: 20251030 | J26: 20260427 | K26: 无
A27: DPCA | B27: 11424548-147068/CC8 | C27: 神龙汽车有限公司 | D27: 交通银行湖北省分行 | E27: 530152100701520251030001255121 | F27: 421865258010123005508 | G27: 人民币 | H27: 119161.88 | I27: 20251030 | J27: 20260427 | K27: 无
A28: DPCA | B28: 11424548-147068/CC8 | C28: 神龙汽车有限公司 | D28: 交通银行湖北省分行 | E28: 530152100701520251030001255033 | F28: 421865258010123005508 | G28: 人民币 | H28: 316758.42 | I28: 20251030 | J28: 20260427 | K28: 无
... A82: DPCC | B82: 11424548-147068/CC16 | C82: 神龙汽车有限公司成都分公司 | D82: 交通银行湖北省分行 | E82: 530152100701520251030101314123 | F82: 421421052012002912395 | G82: 人民币 | H82: 611413.67 | I82: 20251030 | J82: 20260427 | K82: 无

Sheet SkywindSettingSheet
A1: 39019de7-7877-4430-a150-03b245f0def3
