Workbook

Sheet 汇总
A1: b1f3f80b-0552-4a3d-a30b-8b045766af91
C3: 客户名称 | D3: 河南豫能控股股份有限公司 | F3: 重要性水平(PM) | G3: =G5*2 -> 21000000
C5: 期末 | D5: 45657 | F5: 可容忍误差(TE) | G5: 10500000
C7: 记账本位币 | D7: CNY | F7: 名义金额(SAD) | G7: 1050000
C9: 适用会计准则 | D9: 中国会计准则
C12: CRA | D12: %*
C13: High | D13: 0.1
C14: Moderate | D14: 0.15
C15: Low | D15: 0.25
C16: Minimal | D16: 0.5
C17: N/A
C18: *我们期望执行的基准实质性审计程序性质、时间和范围对应的CRA风险比例，此比例为上限，项目组应按照实际情况进行调整。
C20: 认定 | D20: CRA | E20: Threshold | F20: 所有相关认定*
B21: High | C21: 完整性（C） | D21: Minimal | E21: =IFERROR(VLOOKUP(D21,$C$13:$D$16,2,FALSE)*$G$5,"-") -> 5250000 | F21: =MIN($E$21:$E$24) -> 5250000
B22: Moderate | C22: 发生（O） | D22: Minimal | E22: =IFERROR(VLOOKUP(D22,$C$13:$D$16,2,FALSE)*$G$5,"-") -> 5250000
B23: Low | C23: 计量（M） | D23: Minimal | E23: =IFERROR(VLOOKUP(D23,$C$13:$D$16,2,FALSE)*$G$5,"-") -> 5250000
B24: Minimal | C24: 列报与披露（P&D） | D24: Minimal | E24: =IFERROR(VLOOKUP(D24,$C$13:$D$16,2,FALSE)*$G$5,"-") -> 5250000
B25: N/A | C25: *使用所有相关认定中的最低阈值来计算该阈值。
C27: 该科目涉及OSP底稿可参考此链接 | E27: OSP SWP 研发费用 202YMMDD XYZ公司.xlsx
A29: P1 | C29: 序号 | D29: 报表科目 | E29: 执行实质性程序 | F29: 实质性程序类型 | G29: 认定 | H29: 程序描述 | I29: 执行 | J29: 索引 | K29: 如不执行PSP，原因需记录文字多于5个文字
C30: 1 | D30: 所有利润表科目（除收入和成本） | E30: VD-01.1-GL: 实质性程序{取得对账单并进行对比} | F30: PSP | G30: IS: O, M, C, P&D | H30: 取得所有利润表科目（除收入和成本外）金额。对比之前期间并调查异常或非预期变动或未发生预期变动的情况。调查任何异常交易，并基于综合风险评估和已确定的测试临界值测试交易。 | I30: Yes | J30: Uexp_Lead
C31: 2 | D31: 财务费用 | E31: VD-01.1-GL: 实质性程序{取得对账单并进行对比} | F31: PSP | G31: IS: O, M, C, P&D | H31: 1.从管理层处取得各利润表类账户的明细账。 2.将明细账金额与总账及我们的导引表核对一致。对比当期金额和上期金额，调查异常或非预期变动或者预期变动不足的情况。 3.分析费用明细的变动，并就异常事项检查记账凭证、合同等支持性证据，评估其发生的合理性。 4调查任何异常交易，并基于综合风险评估和已确定的测试临界值测试交易。 | I31: Yes | J31: Uexp财务费用BKD
C32: 3 | D32: 财务费用/投资收益 | E32: UC-01-GL: 利息和股息收入 | F32: PSP | G32: IS: O, M, C, P&D | H32: 测试重大投资的利息和股息收益，或通过与相关投资余额相比较来检查投资收益的合理性。 | I32: Yes | J32: Uexp利息测试
C33: 16 | D33: 费用科目（包括制造费用） | E33: VD-01.8-GL:执行截止程序 | F33: PSP | G33: IS: O, C | H33: 记录在账面的费用交易是否记录于正确期间 | I33: Yes | J33: Uexp_Cutoff
C35: IPE 考虑
A36: /P1 | C36: 18 | D36: IPE | H36: 执行IPE程序以评估客户提供的数据的准确性和完整性。可点击此处获取265 Form，获取后需更新链接至执行程序265GL 。 | I36: Yes | J36: <A6_400_IPE_FIL_20241231>
C38: 费用类账户总结陈述
C39: 费用类程序的执行结果详见CanvasForm
C41: 安永标记
C42: PY | D42: 与上年审计底稿核对一致（需项目组自行核对或者由GDS 提供服务核对）
C43: A3 | D43: 与未审数、审定数核对一致
C44: A5 | D44: 与审计调整核对一致
C45: TB | D45: 已与科目余额表核对无误
C46: SL | D46: 已与明细账核对无误
C47: m | D47: 余额/活动不符合测试范围–无需进一步调查
C48: FS | D48: 与FS.0x与财务报表核对无误
C49: w | D49: 低于SAD的金额——放弃进一步调查
C50: Rx | D50: 重新计算，无异常

Sheet Uexp_Lead
A1: c320deef-b651-4890-83c8-fa4b53e6fbdf
J2: 返回汇总页
C4: 目标
C5: 通过执行分析和调查两期的费用科目重大变动来确定费用科目是否合理。
C7: 序号 | D7: 执行的程序 | G7: 程序表 | H7: 预审完成 | I7: 年审完成 | J7: 执行注意事项
C8: 1 | D8: 我们获取费用科目余额表本期金额以及上年审定数。 | G8: 表1 | H8: 是 | I8: 是
C9: 2 | D9: 我们将两期审定金额进行比对，对那些变动大于范围的事项，获得管理层解释并对解释是否合理进行调查。 | G9: 表1 | H9: 是 | I9: 是
C12: 在下文中描述我们当期对账户波动的预期，以及这些预期的依据和理由。
C13: 被审计单位财务费用主要由利息收入和利息支出两部分组成，其中利息收入主要由网银贷款利息收入和借款担保费收入构成，利息支出主要由借款利息和应付债券利息构成。利息收入预期较上年降低，主要因为长期借款稳定性高，近年来根据集团要求预期本期筹资活动中会增加了长期借款的比例，新增统借统还借款预期减少，相应产生的担保费利息收入预期减少。利息支出较上年预期增加，主要系豫能控股为拓宽融资渠道、降低融资成本，计划2024年发行超短期融资券规模增加，相应的应付债券利息费用预期增加。
C20: ="波动幅度 ("&汇总!D7&"):" -> 波动幅度 (CNY): | D20: =汇总!$F$21 -> 5250000
C21: 波动幅度（%）： | D21: 0.1
E22: AA | F22: BB | G22: CC=AA+BB | H22: DD | I22: EE=CC+DD | J22: FF | K22: GG=EE-FF | L22: HH=GG/FF
K23: 本期审定数与上期审定数比较
B24: 表1 | C24: 科目名称 | D24: 索引号 | E24: 本期账面数 | F24: 本期账表调整数 | G24: 本期账面未审数 | H24: 本期审计调整金数 | I24: 本期账面审定数 | J24: 上期末审定数 | K24: 变动额 | L24: 变动率
C25: 财务费用 | D25: Uexp财务费用BKD | E25: =IFERROR(Uexp财务费用BKD!F45,"") -> 19461258 | G25: =E25+F25 -> 19461258 | H25: =IFERROR(Uexp财务费用BKD!L45,"") -> -19158.48 | I25: =G25+H25 -> 19442099 | J25: =IFERROR(Uexp财务费用BKD!N45,"") -> -1189100.5 | K25: =I25-J25 -> 20631200 | L25: =IF(J25<>0,K25/J25,1) -> -17.350258
B27: Notes | C27: 具体分析详见<Uexp财务费用BKD>
C32: 调整汇总表
C33: 原始租赁底稿测算租金信息有误，现按新的测算版本差额调整租赁房屋初始确认的使用权资产租赁负债
C34: AA#04 | D34: 财务费用 | F34: -19158.48
C35: AA#04 | D35: 租赁负债 | F35: 19158.48 | G35: <LR.04 租赁费 >

Sheet Uexp财务费用BKD
A1: ef949b77-f54f-447e-9d50-7c9f48bd6215
J2: 返回汇总页
C4: 目标
C5: 1.通过执行分析和调查两期的财务费用重大变动来确定其变动是否合理。
C6: 2.明细账金额、总账及报表金额是否一致，对重大不一致调查其调节项的性质及原因。
C8: 序号 | D8: 执行的程序 | G8: 程序表 | H8: 预审完成 | I8: 年审完成 | J8: 执行注意事项
C9: 1 | D9: 从管理层处取得本期财务费用账户的明细。 | G9: 表1 | H9: 是 | I9: 是
C10: 2 | D10: 对比当期金额和上期金额，调查变动大于范围或与预期不符的变动情况。并就异常事项检查记账凭证、合同等支持性证据，评估其发生的合理性。 | G10: 表1 | H10: 是 | I10: 是
C11: 3 | D11: 将明细账与管理层报表进行核对，并对差异大于SAD的项目进行调查。 | G11: 表1 | H11: 是 | I11: 是
C12: 4 | D12: 对于单项金额重大的财务费用，需要获取该单项费用的组成明细，需要获取支持性文件如合同等，在必要时进行费用测试。 | G12: TOD SWP U_Exp_Uexp.01 TOD年审 | H12: 是 | I12: 是
C13: 5 | D13: 我们对金额大于测试阈值或性质特殊的利息收入进行测试。 | G13: <Uexp利息测试> | H13: 否 | I13: 是
C14: 6 | D14: 将费用科目中存在着勾稽关系的费用类型，同相应的其他科目金额进行核对X-ref | G14: 表1 | H14: 是 | I14: 是
C18: 在下文中描述我们当期对账户波动的预期，以及这些预期的依据和理由。
C19: 被审计单位财务费用主要由利息收入和利息支出两部分组成，其中利息收入主要由网银贷款利息收入和借款担保费收入构成，利息支出主要由借款利息和应付债券利息构成。利息收入预期较上年降低，主要因为长期借款稳定性高，近年来根据集团要求预期本期筹资活动中会增加了长期借款的比例，新增统借统还借款预期减少，相应产生的担保费利息收入预期减少。利息支出较上年预期增加，主要系豫能控股为拓宽融资渠道、降低融资成本，计划2024年发行超短期融资券规模增加，相应的应付债券利息费用预期增加。
C26: ="波动范围 ("&D11&"):" -> 波动范围 (将明细账与管理层报表进行核对，并对差异大于SAD的项目进行调查。): | D26: =汇总!$F$21 -> 5250000
C27: 波动范围 (%): | D27: 0.1
F29: AA | H29: BB | I29: CC=AA+BB | L29: DD | M29: EE=CC+DD | N29: FF | O29: GG=EE-FF | P29: HH=GG/FF
A30: T1 | C30: TB | D30: TB | E30: TB | F30: TB
I31: =F31+H31 -> 0 | J31: =IF($I$45<>0,I31/$I$45,"") -> 0 | M31: =I31+L31 -> 0 | O31: =M31-N31 -> 0 | P31: =IF(N31<>0,O31/N31,1) -> 1
B32: 表1 | I32: 本期数 | N32: =DATE(YEAR(汇总!$D$5)-1,12,31) -> 45291 | O32: 本期审定数与上期审定数比较
C33: 账套名称/账套编码 | D33: 科目编码 | E33: 科目名称 | F33: 本期账面数 | G33: 本期账表调整编号 | H33: 本期账表调整数 | I33: 本期账面未审数 | J33: 结构比 | K33: 本期审计调整编号 | L33: 本期审计调整金数 | M33: 本期账面审定数 | N33: 上期末审定数 (PY) | O33: 变动额 | P33: 变动率% | Q33: For X-ref | R33: Notes
C34: 河南豫能控股股份有限公司 | D34: 66030201 | E34: 归集资金利息收入 | F34: -1848787 | I34: =F34+H34 -> -1848787 | J34: =IF($I$45<>0,I34/$I$45,"") -> -0.094998328 | M34: =I34+L34 -> -1848787 | N34: -3235152.5 | O34: =M34-N34 -> 1386365.5 | P34: =IF(N34<>0,O34/N34,1) -> -0.42853174 | Q34: Uexp利息测试 | R34: NB1
C35: 河南豫能控股股份有限公司 | D35: 66030202 | E35: 非归集资金利息收入 | F35: -415932.67 | I35: =F35+H35 -> -415932.67 | J35: =IF($I$45<>0,I35/$I$45,"") -> -0.021372343 | M35: =I35+L35 -> -415932.67 | N35: -1482021.1 | O35: =M35-N35 -> 1066088.4 | P35: =IF(N35<>0,O35/N35,1) -> -0.71934766 | Q35: Uexp利息测试 | R35: NB1
C36: 河南豫能控股股份有限公司 | D36: 66030203 | E36: 网银贷款利息收入 | F36: -40017319 | I36: =F36+H36 -> -40017319 | J36: =IF($I$45<>0,I36/$I$45,"") -> -2.0562555 | M36: =I36+L36 -> -40017319 | N36: -35780625 | O36: =M36-N36 -> -4236693.9 | P36: =IF(N36<>0,O36/N36,1) -> 0.11840749 | R36: NB1
C37: 河南豫能控股股份有限公司 | D37: 66030101 | E37: 长期借款利息支出 | F37: 54699886 | I37: =F37+H37 -> 54699886 | J37: =IF($I$45<>0,I37/$I$45,"") -> 2.8107066 | M37: =I37+L37 -> 54699886 | N37: 52778367 | O37: =M37-N37 -> 1921519.6 | P37: =IF(N37<>0,O37/N37,1) -> 0.036407333 | Q37: Q.05利息费用 | R37: NB2
C38: 河南豫能控股股份有限公司 | D38: 66030102 | E38: 短期借款利息支出 | F38: 2445128.6 | I38: =F38+H38 -> 2445128.6 | J38: =IF($I$45<>0,I38/$I$45,"") -> 0.12564083 | M38: =I38+L38 -> 2445128.6 | N38: 4745311.1 | O38: =M38-N38 -> -2300182.5 | P38: =IF(N38<>0,O38/N38,1) -> -0.48472745 | Q38: Q.05利息费用 | R38: NB2
C39: 河南豫能控股股份有限公司 | D39: 66030104 | E39: 应付债券 | F39: 20704524 | I39: =F39+H39 -> 20704524 | J39: =IF($I$45<>0,I39/$I$45,"") -> 1.0638842 | M39: =I39+L39 -> 20704524 | N39: 9520602.5 | O39: =M39-N39 -> 11183921 | P39: =IF(N39<>0,O39/N39,1) -> 1.1747073 | Q39: Q.05利息费用 | R39: NB3
C40: 河南豫能控股股份有限公司 | D40: 66030105 | E40: 其他 | F40: 267355.98 | I40: =F40+H40 -> 267355.98 | J40: =IF($I$45<>0,I40/$I$45,"") -> 0.013737857 | K40: AA#04 | L40: =Uexp_Lead!F34 -> -19158.48 | M40: =I40+L40 -> 248197.5 | N40: 0 | O40: =M40-N40 -> 248197.5 | P40: =IF(N40<>0,O40/N40,1) -> 1 | Q40: LR.04 租赁费
C41: 河南豫能控股股份有限公司 | D41: 660304 | E41: 银行手续费 | F41: 26911.79 | I41: =F41+H41 -> 26911.79 | J41: =IF($I$45<>0,I41/$I$45,"") -> 0.0013828392 | M41: =I41+L41 -> 26911.79 | N41: 92655.18 | O41: =M41-N41 -> -65743.39 | P41: =IF(N41<>0,O41/N41,1) -> -0.709549
C42: 河南豫能控股股份有限公司 | D42: 660306 | E42: 借款担保费收入 | F42: -16400510 | I42: =F42+H42 -> -16400510 | J42: =IF($I$45<>0,I42/$I$45,"") -> -0.8427261 | M42: =I42+L42 -> -16400510 | N42: -27828237 | O42: =M42-N42 -> 11427727 | P42: =IF(N42<>0,O42/N42,1) -> -0.41065222 | R42: NB4
A43: /T1 | I43: =F43+H43 -> 0 | J43: =IF($I$45<>0,I43/$I$45,"") -> 0 | M43: =I43+L43 -> 0 | O43: =M43-N43 -> 0 | P43: =IF(N43<>0,O43/N43,1) -> 1
E45: 合计 | F45: =SUM(F33:F44) -> 19461258 | H45: =SUM(H33:H44) -> 0 | I45: =SUM(I33:I44) -> 19461258 | J45: =SUM(J33:J44) -> 1 | L45: =SUM(L33:L44) -> -19158.48 | M45: =SUM(M33:M44) -> 19442099 | N45: =SUM(N33:N44) -> -1189100.5 | O45: =M45-N45 -> 20631200 | P45: =IF(N45<>0,O45/N45,1) -> -17.350258
F46: Rx | H46: Rx | I46: Rx | J46: Rx | L46: Rx | M46: Rx | N46: Rx
F47: 19461258 | H47: A3 | I47: 19461258 | M47: 19442099 | N47: -1189100.5
F48: =F45-F47 -> 0 | H48: Diff | I48: =I45-I47 -> 0 | M48: =M45-M47 -> 0 | N48: =N45-N47 -> -8.3819032e-09
B50: Notes | C50: 对变动不在范围内的项目进行调查，评估其合理性，并记录在“说明”中。对异常项目进行调查，并记录在“说明”中。
D52: 我们对变动金额超过50%TE(RMB5250,000.00 )且变动比例大于10%的明细项进行分析，同时，我们也对与预期变动不符，或可能存在的其他异常项进行分析，具体如下：
C54: NB1 | D54: 本期归集资金利息收入、非归集资金利息收入和网银贷款利息收入合计金额，较上期增加1,784k元，增幅4.41%，与上期基本持平；归集资金和非归集资金利息收入整体减少，网银贷款利息收入增加，主要系为补充子公司营运资金，豫能本部通过网银贷款给子公司的整体规模增加，进而列收子公司网银贷款利息增加。我们对利息收入在<Uexp利息测试>中进行测算，差异小于SAD，未见异常。关于网银贷款利息收入，我们在关联方底稿中与各家子公司网银贷款利息支出金额进行核对，未发现异常，核对情况详见<I_关联方核对_20241231_豫能本部>。且我们已在各家子公司借款底稿中进行测算，差异均小于SAD，未发现重大异常。
C58: NB2 | D58: 我们在<01豫能本部Q SWP 借款 20241231>底稿对借款利息支出进行了测算，差异小于SAD，未见明显差异；利息支出合并整体变动不大，其中长期借款利息支出增加1,922k元，短期借款利息减少2,300k元，主要是由于长期借款稳定性高，根据集团指引本期筹资活动中增加了长期借款的比例。
C61: NB3 | D61: 应付债券利息支出较去年增加人民币11,184千元，增幅117.47%，主要系本年发行超短期融资券规模增加所致，2023年起，为拓宽融资渠道、降低融资成本，豫能控股向中国银行间市场交易商协会申请注册发行不超过人民币15亿元的超短期融资券。2023年度仅3月份发行一期，金额5亿元，期限150天，票面利率3.05%；2024年1月、4月和8月分别发行3期金额5亿元的超短融，期限分别为210天、270天和270天，故本期债券利息相应增加。我们已在<01豫能本部Q SWP应付债券 20241231>中进行测算，差异小于SAD，未见明显异常。
...

Sheet Uexp利息测试
A1: 284a92ec-2ca6-4386-9d4e-e60c226247db
J2: 返回汇总页
C4: 必读！利息收入合理性测试适用范围：
C6: 目标
C7: 测试货币资金的利息收入并通过与相关余额进行比较来检查合理性。
C9: 序号 | D9: 执行的测试 | G9: 程序表 | H9: 预审完成 | I9: 年审完成 | J9: 执行注意事项
C10: 1 | D10: 活期存款 | G10: C_货币资金 | H10: 否 | I10: 是
C11: 1.1 | D11: 核对期末活期存款金额至公司期末银行存款明细清单。 | H11: 否 | I11: 是
C12: 1.2 | D12: 针对活期存款/协定存款/通知存款，使用期初、期末平均余额乘以适用的利率，测算本期利息收入。 | G12: 表1 | H12: 否 | I12: 是
C13: 1.3 | D13: 与财务费用底稿里的公司活期存款/协定存款/通知存款进行差异比较，若差异金额大于TT则调查原因及是否需要调整。必要时，采取月平均余额进行测算 | G13: 表1 | H13: 否 | I13: 是
C14: 2 | D14: 定期存款
C15: 2.1 | D15: 获取公司【20__年1月1日至20__年12月31日】的定期存款明细清单（包含期末已到期的定期存款）。 | G15: 表2 | H15: 否 | I15: 不适用 | J15: 本期无定期存款，不适用该程序
C16: 2.2 | D16: 核对期末尚未到期的定期存款金额至公司期末银行存款明细清单。 | G16: 表2 | H16: 否 | I16: 不适用 | J16: 本期无定期存款，不适用该程序
C17: 2.3 | D17: 针对定期存款，使用本金、利率、存款期限测算本期利息收入。 | G17: 表2 | H17: 否 | I17: 不适用 | J17: 本期无定期存款，不适用该程序
C18: 2.4 | D18: 与财务费用底稿里的公司定期存款利息收入进行差异比较，若差异金额大于TT则调查原因及是否需要调整。 | G18: 表2 | H18: 否 | I18: 不适用 | J18: 本期无定期存款，不适用该程序
C19: 3 | D19: 其他利息类型 | G19: 表3 | H19: 否 | I19: 不适用 | J19: 本期无其他利息类型，不适用该程序
B23: 表1 | C23: 对货币资金的利息收入进行测算——活期存款： | M23: NB2 | AA23: NB1
C24: |----------------------------------------C100 -----------------------------------------------------| | H24: AA | I24: BB | J24: CC=(AA+BB)/2 | M24: DD | N24: EE | O24: FF=CC*DD*EE | P24: 2024年1-12月利息收入余额变动情况
C25: 账套名称/账套编码 | D25: 末级科目 | E25: 账号 | F25: 账户名称 | G25: 原币币种 | H25: 期末原币 | I25: 期初原币金额 | J25: 本期原币平均余额 | K25: 2023年利率 | L25: 适用活期利率2024 | M25: 平均利率 | N25: 汇率（如适用） | O25: 安永测算本期利息收入 | P25: 1 | Q25: 1月末 | R25: 2 | S25: 2月末 | T25: 3 | U25: 3月末 | V25: 4 | W25: 4月末 | X25: 5 | Y25: 5月末 | Z25: 6 | AA25: 6月末 | AB25: 7 | AC25: 7月末 | AD25: 8 | AE25: 8月末 | AF25: 9 | AG25: 9月末 | AH25: 10 | AI25: 10月末 | AJ25: 11 | AK25: 11月末 | AL25: 12 | AM25: 12月末
C26: 河南豫能控股股份有限公司 | D26: 银行存款 | E26: 411060400010020021365 | F26: 河南豫能控股股份有限公司 | G26: RMB | H26: 3.7429711e+08 | I26: 1.6927892e+08 | J26: =AVERAGE(I26,Q26,S26,U26,W26,Y26,AA26,AC26,AE26,AG26,AI26,AK26,H26) -> 3.7858726e+08 | K26: 0.002 | L26: 0.001 | M26: =AVERAGE(K26:L26) -> 0.0015 | N26: 1 | O26: =J26*M26*N26 -> 567880.9 | P26: =SUMIFS($F$83:$F$272,$D$83:$D$272,E26,$E$83:$E$272,$P$25) -> 75178167 | Q26: =I26+P26 -> 2.4445709e+08 | R26: =SUMIFS($F$83:$F$272,$D$83:$D$272,E26,$E$83:$E$272,$R$25) -> -1.427954e+08 | S26: =Q26+R26 -> 1.0166169e+08 | T26: =SUMIFS($F$83:$F$272,$D$83:$D$272,E26,$E$83:$E$272,$T$25) -> 4.1609909e+08 | U26: =S26+T26 -> 5.1776078e+08 | V26: =SUMIFS($F$83:$F$272,$D$83:$D$272,E26,$E$83:$E$272,$V$25) -> 1.7284085e+08 | W26: =U26+V26 -> 6.9060163e+08 | X26: =SUMIFS($F$83:$F$272,$D$83:$D$272,E26,$E$83:$E$272,$X$25) -> -2.8977898e+08 | Y26: =W26+X26 -> 4.0082264e+08 | Z26: =SUMIFS($F$83:$F$272,$D$83:$D$272,E26,$E$83:$E$272,$Z$25) -> -1.1067609e+08 | AA26: =Y26+Z26 -> 2.9014656e+08 | AB26: =SUMIFS($F$83:$F$272,$D$83:$D$272,E26,$E$83:$E$272,$AB$25) -> 3.2503911e+08 | AC26: =AA26+AB26 -> 6.1518567e+08 | AD26: =SUMIFS($F$83:$F$272,$D$83:$D$272,E26,$E$83:$E$272,$AD$25) -> -1.4455343e+08 | AE26: =AC26+AD26 -> 4.7063224e+08 | AF26: =SUMIFS($F$83:$F$272,$D$83:$D$272,E26,$E$83:$E$272,$AF$25) -> -1.5839223e+08 | AG26: =AE26+AF26 -> 3.1224001e+08 | AH26: =SUMIFS($F$83:$F$272,$D$83:$D$272,E26,$E$83:$E$272,$AH$25) -> 1.300224e+08 | AI26: =AG26+AH26 -> 4.4226241e+08 | AJ26: =SUMIFS($F$83:$F$272,$D$83:$D$272,E26,$E$83:$E$272,$AJ$25) -> -1.4997471e+08 | AK26: =AI26+AJ26 -> 2.922877e+08 | AL26: =SUMIFS($F$83:$F$272,$D$83:$D$272,E26,$E$83:$E$272,$AL$25) -> 82009414 | AM26: =AK26+AL26 -> 3.7429711e+08 | AN26: =AM26-H26 -> 0
C27: 河南豫能控股股份有限公司 | D27: 银行存款 | E27: 602180267110001 | F27: 河南豫能控股股份有限公司 | G27: RMB | H27: 1.3326239e+08 | I27: 47433379 | J27: =AVERAGE(I27,Q27,S27,U27,W27,Y27,AA27,AC27,AE27,AG27,AI27,AK27,H27) -> 1.2276593e+08 | K27: 0.0135 | L27: 0.001 | M27: =AVERAGE(K27:L27) -> 0.00725 | N27: 1 | O27: =J27*M27*N27 -> 890052.97 | P27: =SUMIFS($F$83:$F$272,$D$83:$D$272,E27,$E$83:$E$272,$P$25) -> -40140577 | Q27: =I27+P27 -> 7292802 | R27: =SUMIFS($F$83:$F$272,$D$83:$D$272,E27,$E$83:$E$272,$R$25) -> 7610473.3 | S27: =Q27+R27 -> 14903275 | T27: =SUMIFS($F$83:$F$272,$D$83:$D$272,E27,$E$83:$E$272,$T$25) -> 2.3195256e+08 | U27: =S27+T27 -> 2.4685584e+08 | V27: =SUMIFS($F$83:$F$272,$D$83:$D$272,E27,$E$83:$E$272,$V$25) -> -1.6531191e+08 | W27: =U27+V27 -> 81543923 | X27: =SUMIFS($F$83:$F$272,$D$83:$D$272,E27,$E$83:$E$272,$X$25) -> 2397697.7 | Y27: =W27+X27 -> 83941621 | Z27: =SUMIFS($F$83:$F$272,$D$83:$D$272,E27,$E$83:$E$272,$Z$25) -> -51579690 | AA27: =Y27+Z27 -> 32361931 | AB27: =SUMIFS($F$83:$F$272,$D$83:$D$272,E27,$E$83:$E$272,$AB$25) -> 16710715 | AC27: =AA27+AB27 -> 49072646 | AD27: =SUMIFS($F$83:$F$272,$D$83:$D$272,E27,$E$83:$E$272,$AD$25) -> 3.8788421e+08 | AE27: =AC27+AD27 -> 4.3695685e+08 | AF27: =SUMIFS($F$83:$F$272,$D$83:$D$272,E27,$E$83:$E$272,$AF$25) -> -1.5372371e+08 | AG27: =AE27+AF27 -> 2.8323314e+08 | AH27: =SUMIFS($F$83:$F$272,$D$83:$D$272,E27,$E$83:$E$272,$AH$25) -> -1.8190711e+08 | AI27: =AG27+AH27 -> 1.0132603e+08 | AJ27: =SUMIFS($F$83:$F$272,$D$83:$D$272,E27,$E$83:$E$272,$AJ$25) -> -23552811 | AK27: =AI27+AJ27 -> 77773222 | AL27: =SUMIFS($F$83:$F$272,$D$83:$D$272,E27,$E$83:$E$272,$AL$25) -> 55489163 | AM27: =AK27+AL27 -> 1.3326239e+08 | AN27: =AM27-H27 -> 0
C28: 河南豫能控股股份有限公司 | D28: 银行存款 | E28: 41001533020052504904 | F28: 河南豫能控股股份有限公司 | G28: RMB | H28: 28597271 | I28: 82988568 | J28: =AVERAGE(I28,Q28,S28,U28,W28,Y28,AA28,AC28,AE28,AG28,AI28,AK28,H28) -> 59818046 | K28: 0.002 | L28: 0.001 | M28: =AVERAGE(K28:L28) -> 0.0015 | N28: 1 | O28: =J28*M28*N28 -> 89727.068 | P28: =SUMIFS($F$83:$F$272,$D$83:$D$272,E28,$E$83:$E$272,$P$25) -> 2.4381036e+08 | Q28: =I28+P28 -> 3.2679892e+08 | R28: =SUMIFS($F$83:$F$272,$D$83:$D$272,E28,$E$83:$E$272,$R$25) -> -2.9702569e+08 | S28: =Q28+R28 -> 29773231 | T28: =SUMIFS($F$83:$F$272,$D$83:$D$272,E28,$E$83:$E$272,$T$25) -> 10199981 | U28: =S28+T28 -> 39973212 | V28: =SUMIFS($F$83:$F$272,$D$83:$D$272,E28,$E$83:$E$272,$V$25) -> 8201550.3 | W28: =U28+V28 -> 48174762 | X28: =SUMIFS($F$83:$F$272,$D$83:$D$272,E28,$E$83:$E$272,$X$25) -> 15877210 | Y28: =W28+X28 -> 64051972 | Z28: =SUMIFS($F$83:$F$272,$D$83:$D$272,E28,$E$83:$E$272,$Z$25) -> -52906830 | AA28: =Y28+Z28 -> 11145143 | AB28: =SUMIFS($F$83:$F$272,$D$83:$D$272,E28,$E$83:$E$272,$AB$25) -> 10566112 | AC28: =AA28+AB28 -> 21711255 | AD28: =SUMIFS($F$83:$F$272,$D$83:$D$272,E28,$E$83:$E$272,$AD$25) -> -3068464.1 | AE28: =AC28+AD28 -> 18642791 | AF28: =SUMIFS($F$83:$F$272,$D$83:$D$272,E28,$E$83:$E$272,$AF$25) -> 10494853 | AG28: =AE28+AF28 -> 29137643 | AH28: =SUMIFS($F$83:$F$272,$D$83:$D$272,E28,$E$83:$E$272,$AH$25) -> 30956869 | AI28: =AG28+AH28 -> 60094512 | AJ28: =SUMIFS($F$83:$F$272,$D$83:$D$272,E28,$E$83:$E$272,$AJ$25) -> -43549205 | AK28: =AI28+AJ28 -> 16545307 | AL28: =SUMIFS($F$83:$F$272,$D$83:$D$272,E28,$E$83:$E$272,$AL$25) -> 12051964 | AM28: =AK28+AL28 -> 28597271 | AN28: =AM28-H28 -> 0
C29: 河南豫能控股股份有限公司 | D29: 其他货币资金 | E29: 254604223819 | F29: 河南豫能控股股份有限公司 | G29: RMB | H29: 0 | I29: 0 | J29: =AVERAGE(I29,Q29,S29,U29,W29,Y29,AA29,AC29,AE29,AG29,AI29,AK29,H29) -> 0 | K29: 0.002 | L29: 0.001 | M29: =AVERAGE(K29:L29) -> 0.0015 | N29: 1 | O29: =J29*M29*N29 -> 0 | P29: =SUMIFS($F$83:$F$272,$D$83:$D$272,E29,$E$83:$E$272,$P$25) -> 0 | Q29: =I29+P29 -> 0 | R29: =SUMIFS($F$83:$F$272,$D$83:$D$272,E29,$E$83:$E$272,$R$25) -> 0 | S29: =Q29+R29 -> 0 | T29: =SUMIFS($F$83:$F$272,$D$83:$D$272,E29,$E$83:$E$272,$T$25) -> 0 | U29: =S29+T29 -> 0 | V29: =SUMIFS($F$83:$F$272,$D$83:$D$272,E29,$E$83:$E$272,$V$25) -> 0 | W29: =U29+V29 -> 0 | X29: =SUMIFS($F$83:$F$272,$D$83:$D$272,E29,$E$83:$E$272,$X$25) -> 0 | Y29: =W29+X29 -> 0 | Z29: =SUMIFS($F$83:$F$272,$D$83:$D$272,E29,$E$83:$E$272,$Z$25) -> 0 | AA29: =Y29+Z29 -> 0 | AB29: =SUMIFS($F$83:$F$272,$D$83:$D$272,E29,$E$83:$E$272,$AB$25) -> 0 | AC29: =AA29+AB29 -> 0 | AD29: =SUMIFS($F$83:$F$272,$D$83:$D$272,E29,$E$83:$E$272,$AD$25) -> 0 | AE29: =AC29+AD29 -> 0 | AF29: =SUMIFS($F$83:$F$272,$D$83:$D$272,E29,$E$83:$E$272,$AF$25) -> 0 | AG29: =AE29+AF29 -> 0 | AH29: =SUMIFS($F$83:$F$272,$D$83:$D$272,E29,$E$83:$E$272,$AH$25) -> 0 | AI29: =AG29+AH29 -> 0 | AJ29: =SUMIFS($F$83:$F$272,$D$83:$D$272,E29,$E$83:$E$272,$AJ$25) -> 0 | AK29: =AI29+AJ29 -> 0 | AL29: =SUMIFS($F$83:$F$272,$D$83:$D$272,E29,$E$83:$E$272,$AL$25) -> 0 | AM29: =AK29+AL29 -> 0 | AN29: =AM29-H29 -> 0
C30: 河南豫能控股股份有限公司 | D30: 银行存款 | E30: 248141070518 | F30: 河南豫能控股股份有限公司 | G30: RMB | H30: 73948190 | I30: 31492099 | J30: =AVERAGE(I30,Q30,S30,U30,W30,Y30,AA30,AC30,AE30,AG30,AI30,AK30,H30) -> 81035588 | K30: 0.002 | L30: 0.001 | M30: =AVERAGE(K30:L30) -> 0.0015 | N30: 1 | O30: =J30*M30*N30 -> 121553.38 | P30: =SUMIFS($F$83:$F$272,$D$83:$D$272,E30,$E$83:$E$272,$P$25) -> 22069407 | Q30: =I30+P30 -> 53561507 | R30: =SUMIFS($F$83:$F$272,$D$83:$D$272,E30,$E$83:$E$272,$R$25) -> 6646450 | S30: =Q30+R30 -> 60207957 | T30: =SUMIFS($F$83:$F$272,$D$83:$D$272,E30,$E$83:$E$272,$T$25) -> 4597295.2 | U30: =S30+T30 -> 64805252 | V30: =SUMIFS($F$83:$F$272,$D$83:$D$272,E30,$E$83:$E$272,$V$25) -> 15337872 | W30: =U30+V30 -> 80143124 | X30: =SUMIFS($F$83:$F$272,$D$83:$D$272,E30,$E$83:$E$272,$X$25) -> 28270532 | Y30: =W30+X30 -> 1.0841366e+08 | Z30: =SUMIFS($F$83:$F$272,$D$83:$D$272,E30,$E$83:$E$272,$Z$25) -> -23665920 | AA30: =Y30+Z30 -> 84747735 | AB30: =SUMIFS($F$83:$F$272,$D$83:$D$272,E30,$E$83:$E$272,$AB$25) -> 96840437 | AC30: =AA30+AB30 -> 1.8158817e+08 | AD30: =SUMIFS($F$83:$F$272,$D$83:$D$272,E30,$E$83:$E$272,$AD$25) -> -71203693 | AE30: =AC30+AD30 -> 1.1038448e+08 | AF30: =SUMIFS($F$83:$F$272,$D$83:$D$272,E30,$E$83:$E$272,$AF$25) -> -50742202 | AG30: =AE30+AF30 -> 59642277 | AH30: =SUMIFS($F$83:$F$272,$D$83:$D$272,E30,$E$83:$E$272,$AH$25) -> -26114504 | AI30: =AG30+AH30 -> 33527773 | AJ30: =SUMIFS($F$83:$F$272,$D$83:$D$272,E30,$E$83:$E$272,$AJ$25) -> 77472654 | AK30: =AI30+AJ30 -> 1.1100043e+08 | AL30: =SUMIFS($F$83:$F$272,$D$83:$D$272,E30,$E$83:$E$272,$AL$25) -> -37052237 | AM30: =AK30+AL30 -> 73948190 | AN30: =AM30-H30 -> 0
C31: 河南豫能控股股份有限公司 | D31: 银行存款 | E31: 9550881310490119016 | F31: 河南豫能控股股份有限公司 | G31: RMB | H31: 151769.91 | I31: 1030603.9 | J31: =AVERAGE(I31,Q31,S31,U31,W31,Y31,AA31,AC31,AE31,AG31,AI31,AK31,H31) -> 9517008.2 | K31: 0.002 | L31: 0.001 | M31: =AVERAGE(K31:L31) -> 0.0015 | N31: 1 | O31: =J31*M31*N31 -> 14275.512 | P31: =SUMIFS($F$83:$F$272,$D$83:$D$272,E31,$E$83:$E$272,$P$25) -> -400 | Q31: =I31+P31 -> 1030203.9 | R31: =SUMIFS($F$83:$F$272,$D$83:$D$272,E31,$E$83:$E$272,$R$25) -> 0 | S31: =Q31+R31 -> 1030203.9 | T31: =SUMIFS($F$83:$F$272,$D$83:$D$272,E31,$E$83:$E$272,$T$25) -> 315.87 | U31: =S31+T31 -> 1030519.7 | V31: =SUMIFS($F$83:$F$272,$D$83:$D$272,E31,$E$83:$E$272,$V$25) -> 67360064 | W31: =U31+V31 -> 68390584 | X31: =SUMIFS($F$83:$F$272,$D$83:$D$272,E31,$E$83:$E$272,$X$25) -> -68240078 | Y31: =W31+X31 -> 150505.74 | Z31: =SUMIFS($F$83:$F$272,$D$83:$D$272,E31,$E$83:$E$272,$Z$25) -> 501.71 | AA31: =Y31+Z31 -> 151007.45 | AB31: =SUMIFS($F$83:$F$272,$D$83:$D$272,E31,$E$83:$E$272,$AB$25) -> -140 | AC31: =AA31+AB31 -> 150867.45 | AD31: =SUMIFS($F$83:$F$272,$D$83:$D$272,E31,$E$83:$E$272,$AD$25) -> 100 | AE31: =AC31+AD31 -> 150967.45 | AF31: =SUMIFS($F$83:$F$272,$D$83:$D$272,E31,$E$83:$E$272,$AF$25) -> 323.65 | AG31: =AE31+AF31 -> 151291.1 | AH31: =SUMIFS($F$83:$F$272,$D$83:$D$272,E31,$E$83:$E$272,$AH$25) -> 0 | AI31: =AG31+AH31 -> 151291.1 | AJ31: =SUMIFS($F$83:$F$272,$D$83:$D$272,E31,$E$83:$E$272,$AJ$25) -> 50000000 | AK31: =AI31+AJ31 -> 50151291 | AL31: =SUMIFS($F$83:$F$272,$D$83:$D$272,E31,$E$83:$E$272,$AL$25) -> -49999521 | AM31: =AK31+AL31 -> 151769.91 | AN31: =AM31-H31 -> -3.5797711e-09
C32: 河南豫能控股股份有限公司 | D32: 银行存款 | E32: 76210154500000244 | F32: 河南豫能控股股份有限公司 | G32: RMB | H32: 243422.76 | I32: 77938.2 | J32: =AVERAGE(I32,Q32,S32,U32,W32,Y32,AA32,AC32,AE32,AG32,AI32,AK32,H32) -> 130879.64 | K32: 0.002 | L32: 0.001 | M32: =AVERAGE(K32:L32) -> 0.0015 | N32: 1 | O32: =J32*M32*N32 -> 196.31946 | P32: =SUMIFS($F$83:$F$272,$D$83:$D$272,E32,$E$83:$E$272,$P$25) -> -300 | Q32: =I32+P32 -> 77638.2 | R32: =SUMIFS($F$83:$F$272,$D$83:$D$272,E32,$E$83:$E$272,$R$25) -> 0 | S32: =Q32+R32 -> 77638.2 | T32: =SUMIFS($F$83:$F$272,$D$83:$D$272,E32,$E$83:$E$272,$T$25) -> 52088.18 | U32: =S32+T32 -> 129726.38 | V32: =SUMIFS($F$83:$F$272,$D$83:$D$272,E32,$E$83:$E$272,$V$25) -> -300 | W32: =U32+V32 -> 129426.38 | X32: =SUMIFS($F$83:$F$272,$D$83:$D$272,E32,$E$83:$E$272,$X$25) -> 0 | Y32: =W32+X32 -> 129426.38 | Z32: =SUMIFS($F$83:$F$272,$D$83:$D$272,E32,$E$83:$E$272,$Z$25) -> 8569.49 | AA32: =Y32+Z32 -> 137995.87 | AB32: =SUMIFS($F$83:$F$272,$D$83:$D$272,E32,$E$83:$E$272,$AB$25) -> -26 | AC32: =AA32+AB32 -> 137969.87 | AD32: =SUMIFS($F$83:$F$272,$D$83:$D$272,E32,$E$83:$E$272,$AD$25) -> 0 | AE32: =AC32+AD32 -> 137969.87 | AF32: =SUMIFS($F$83:$F$272,$D$83:$D$272,E32,$E$83:$E$272,$AF$25) -> 2891.2 | AG32: =AE32+AF32 -> 140861.07 | AH32: =SUMIFS($F$83:$F$272,$D$83:$D$272,E32,$E$83:$E$272,$AH$25) -> -100 | AI32: =AG32+AH32 -> 140761.07 | AJ32: =SUMIFS($F$83:$F$272,$D$83:$D$272,E32,$E$83:$E$272,$AJ$25) -> -100 | AK32: =AI32+AJ32 -> 140661.07 | AL32: =SUMIFS($F$83:$F$272,$D$83:$D$272,E32,$E$83:$E$272,$AL$25) -> 102761.69 | AM32: =AK32+AL32 -> 243422.76 | AN32: =AM32-H32 -> -4.9476512e-10
C33: 河南豫能控股股份有限公司 | D33: 银行存款 | E33: 76210167330000043 | F33: 河南豫能控股股份有限公司 | G33: RMB | H33: 0 | I33: 0 | J33: =AVERAGE(I33,Q33,S33,U33,W33,Y33,AA33,AC33,AE33,AG33,AI33,AK33,H33) -> 0 | K33: 0.008 | L33: 0.001 | M33: =AVERAGE(K33:L33) -> 0.0045 | N33: 1 | O33: =J33*M33*N33 -> 0 | P33: =SUMIFS($F$83:$F$272,$D$83:$D$272,E33,$E$83:$E$272,$P$25) -> 0 | Q33: =I33+P33 -> 0 | R33: =SUMIFS($F$83:$F$272,$D$83:$D$272,E33,$E$83:$E$272,$R$25) -> 0 | S33: =Q33+R33 -> 0 | T33: =SUMIFS($F$83:$F$272,$D$83:$D$272,E33,$E$83:$E$272,$T$25) -> 0 | U33: =S33+T33 -> 0 | V33: =SUMIFS($F$83:$F$272,$D$83:$D$272,E33,$E$83:$E$272,$V$25) -> 0 | W33: =U33+V33 -> 0 | X33: =SUMIFS($F$83:$F$272,$D$83:$D$272,E33,$E$83:$E$272,$X$25) -> 0 | Y33: =W33+X33 -> 0 | Z33: =SUMIFS($F$83:$F$272,$D$83:$D$272,E33,$E$83:$E$272,$Z$25) -> 0 | AA33: =Y33+Z33 -> 0 | AB33: =SUMIFS($F$83:$F$272,$D$83:$D$272,E33,$E$83:$E$272,$AB$25) -> 0 | AC33: =AA33+AB33 -> 0 | AD33: =SUMIFS($F$83:$F$272,$D$83:$D$272,E33,$E$83:$E$272,$AD$25) -> 0 | AE33: =AC33+AD33 -> 0 | AF33: =SUMIFS($F$83:$F$272,$D$83:$D$272,E33,$E$83:$E$272,$AF$25) -> 0 | AG33: =AE33+AF33 -> 0 | AH33: =SUMIFS($F$83:$F$272,$D$83:$D$272,E33,$E$83:$E$272,$AH$25) -> 0 | AI33: =AG33+AH33 -> 0 | AJ33: =SUMIFS($F$83:$F$272,$D$83:$D$272,E33,$E$83:$E$272,$AJ$25) -> 0 | AK33: =AI33+AJ33 -> 0 | AL33: =SUMIFS($F$83:$F$272,$D$83:$D$272,E33,$E$83:$E$272,$AL$25) -> 0 | AM33: =AK33+AL33 -> 0 | AN33: =AM33-H33 -> 0
C34: 河南豫能控股股份有限公司 | D34: 银行存款 | E34: 410102010190073901 | F34: 河南豫能控股股份有限公司 | G34: RMB | H34: 6698375.7 | I34: 7979603.9 | J34: =AVERAGE(I34,Q34,S34,U34,W34,Y34,AA34,AC34,AE34,AG34,AI34,AK34,H34) -> 8025062.3 | K34: 0.0161 | L34: 0.001 | M34: =AVERAGE(K34:L34) -> 0.00855 | N34: 1 | O34: =J34*M34*N34 -> 68614.283 | P34: =SUMIFS($F$83:$F$272,$D$83:$D$272,E34,$E$83:$E$272,$P$25) -> 1934594.8 | Q34: =I34+P34 -> 9914198.7 | R34: =SUMIFS($F$83:$F$272,$D$83:$D$272,E34,$E$83:$E$272,$R$25) -> -5179431.7 | S34: =Q34+R34 -> 4734767 | T34: =SUMIFS($F$83:$F$272,$D$83:$D$272,E34,$E$83:$E$272,$T$25) -> -881444.77 | U34: =S34+T34 -> 3853322.2 | V34: =SUMIFS($F$83:$F$272,$D$83:$D$272,E34,$E$83:$E$272,$V$25) -> 6590994.4 | W34: =U34+V34 -> 10444317 | X34: =SUMIFS($F$83:$F$272,$D$83:$D$272,E34,$E$83:$E$272,$X$25) -> 523247.03 | Y34: =W34+X34 -> 10967564 | Z34: =SUMIFS($F$83:$F$272,$D$83:$D$272,E34,$E$83:$E$272,$Z$25) -> -2616712.5 | AA34: =Y34+Z34 -> 8350851.1 | AB34: =SUMIFS($F$83:$F$272,$D$83:$D$272,E34,$E$83:$E$272,$AB$25) -> -1200062.5 | AC34: =AA34+AB34 -> 7150788.6 | AD34: =SUMIFS($F$83:$F$272,$D$83:$D$272,E34,$E$83:$E$272,$AD$25) -> 2924013 | AE34: =AC34+AD34 -> 10074802 | AF34: =SUMIFS($F$83:$F$272,$D$83:$D$272,E34,$E$83:$E$272,$AF$25) -> -1751536.6 | AG34: =AE34+AF34 -> 8323265.1 | AH34: =SUMIFS($F$83:$F$272,$D$83:$D$272,E34,$E$83:$E$272,$AH$25) -> -160871.37 | AI34: =AG34+AH34 -> 8162393.7 | AJ34: =SUMIFS($F$83:$F$272,$D$83:$D$272,E34,$E$83:$E$272,$AJ$25) -> -490831.45 | AK34: =AI34+AJ34 -> 7671562.2 | AL34: =SUMIFS($F$83:$F$272,$D$83:$D$272,E34,$E$83:$E$272,$AL$25) -> -973186.55 | AM34: =AK34+AL34 -> 6698375.7 | AN34: =AM34-H34 -> 0
C35: 河南豫能控股股份有限公司 | D35: 银行存款 | E35: 8111101012201326045 | F35: 河南豫能控股股份有限公司 | G35: RMB | H35: 12816316 | I35: 35959352 | J35: =AVERAGE(I35,Q35,S35,U35,W35,Y35,AA35,AC35,AE35,AG35,AI35,AK35,H35) -> 53822186 | K35: 0.0155 | L35: 0.001 | M35: =AVERAGE(K35:L35) -> 0.00825 | N35: 1 | O35: =J35*M35*N35 -> 444033.04 | P35: =SUMIFS($F$83:$F$272,$D$83:$D$272,E35,$E$83:$E$272,$P$25) -> -9941459.4 | Q35: =I35+P35 -> 26017893 | R35: =SUMIFS($F$83:$F$272,$D$83:$D$272,E35,$E$83:$E$272,$R$25) -> 72301430 | S35: =Q35+R35 -> 98319323 | T35: =SUMIFS($F$83:$F$272,$D$83:$D$272,E35,$E$83:$E$272,$T$25) -> -52190871 | U35: =S35+T35 -> 46128452 | V35: =SUMIFS($F$83:$F$272,$D$83:$D$272,E35,$E$83:$E$272,$V$25) -> 78555636 | W35: =U35+V35 -> 1.2468409e+08 | X35: =SUMIFS($F$83:$F$272,$D$83:$D$272,E35,$E$83:$E$272,$X$25) -> -81013791 | Y35: =W35+X35 -> 43670297 | Z35: =SUMIFS($F$83:$F$272,$D$83:$D$272,E35,$E$83:$E$272,$Z$25) -> 9954607.3 | AA35: =Y35+Z35 -> 53624904 | AB35: =SUMIFS($F$83:$F$272,$D$83:$D$272,E35,$E$83:$E$272,$AB$25) -> -13599888 | AC35: =AA35+AB35 -> 40025017 | AD35: =SUMIFS($F$83:$F$272,$D$83:$D$272,E35,$E$83:$E$272,$AD$25) -> -1860686.7 | AE35: =AC35+AD35 -> 38164330 | AF35: =SUMIFS($F$83:$F$272,$D$83:$D$272,E35,$E$83:$E$272,$AF$25) -> 1.0465876e+08 | AG35: =AE35+AF35 -> 1.4282309e+08 | AH35: =SUMIFS($F$83:$F$272,$D$83:$D$272,E35,$E$83:$E$272,$AH$25) -> -1.1228076e+08 | AI35: =AG35+AH35 -> 30542334 | AJ35: =SUMIFS($F$83:$F$272,$D$83:$D$272,E35,$E$83:$E$272,$AJ$25) -> -23629310 | AK35: =AI35+AJ35 -> 6913023.6 | AL35: =SUMIFS($F$83:$F$272,$D$83:$D$272,E35,$E$83:$E$272,$AL$25) -> 5903292.5 | AM35: =AK35+AL35 -> 12816316 | AN35: =AM35-H35 -> 7.6368451e-08
C36: 河南豫能控股股份有限公司 | D36: 银行存款 | E36: 941003010078976675 | F36: 河南豫能控股股份有限公司 | G36: RMB | H36: 3423538.1 | I36: 5925742.3 | J36: =AVERAGE(I36,Q36,S36,U36,W36,Y36,AA36,AC36,AE36,AG36,AI36,AK36,H36) -> 6032220.2 | K36: 0.002 | L36: 0.001 | M36: =AVERAGE(K36:L36) -> 0.0015 | N36: 1 | O36: =J36*M36*N36 -> 9048.3304 | P36: =SUMIFS($F$83:$F$272,$D$83:$D$272,E36,$E$83:$E$272,$P$25) -> 2064942.9 | Q36: =I36+P36 -> 7990685.2 | R36: =SUMIFS($F$83:$F$272,$D$83:$D$272,E36,$E$83:$E$272,$R$25) -> -1042640.6 | S36: =Q36+R36 -> 6948044.6 | T36: =SUMIFS($F$83:$F$272,$D$83:$D$272,E36,$E$83:$E$272,$T$25) -> -1074219 | U36: =S36+T36 -> 5873825.6 | V36: =SUMIFS($F$83:$F$272,$D$83:$D$272,E36,$E$83:$E$272,$V$25) -> -1552914.4 | W36: =U36+V36 -> 4320911.2 | X36: =SUMIFS($F$83:$F$272,$D$83:$D$272,E36,$E$83:$E$272,$X$25) -> 1050075 | Y36: =W36+X36 -> 5370986.2 | Z36: =SUMIFS($F$83:$F$272,$D$83:$D$272,E36,$E$83:$E$272,$Z$25) -> 5329290.5 | AA36: =Y36+Z36 -> 10700277 | AB36: =SUMIFS($F$83:$F$272,$D$83:$D$272,E36,$E$83:$E$272,$AB$25) -> -4095170 | AC36: =AA36+AB36 -> 6605106.7 | AD36: =SUMIFS($F$83:$F$272,$D$83:$D$272,E36,$E$83:$E$272,$AD$25) -> -1655693 | AE36: =AC36+AD36 -> 4949413.7 | AF36: =SUMIFS($F$83:$F$272,$D$83:$D$272,E36,$E$83:$E$272,$AF$25) -> -1095311.3 | AG36: =AE36+AF36 -> 3854102.4 | AH36: =SUMIFS($F$83:$F$272,$D$83:$D$272,E36,$E$83:$E$272,$AH$25) -> 521856.14 | AI36: =AG36+AH36 -> 4375958.5 | AJ36: =SUMIFS($F$83:$F$272,$D$83:$D$272,E36,$E$83:$E$272,$AJ$25) -> 3704313.5 | AK36: =AI36+AJ36 -> 8080272 | AL36: =SUMIFS($F$83:$F$272,$D$83:$D$272,E36,$E$83:$E$272,$AL$25) -> -4656733.8 | AM36: =AK36+AL36 -> 3423538.2 | AN36: =AM36-H36 -> 0
C37: 河南豫能控股股份有限公司 | D37: 银行存款 | E37: 1702028119200104256 | F37: 河南豫能控股股份有限公司 | G37: RMB | H37: 23739333 | I37: 43469554 | J37: =AVERAGE(I37,Q37,S37,U37,W37,Y37,AA37,AC37,AE37,AG37,AI37,AK37,H37) -> 66347685 | K37: 0.002 | L37: 0.001 | M37: =AVERAGE(K37:L37) -> 0.0015 | N37: 1 | O37: =J37*M37*N37 -> 99521.528 | P37: =SUMIFS($F$83:$F$272,$D$83:$D$272,E37,$E$83:$E$272,$P$25) -> -17912569 | Q37: =I37+P37 -> 25556985 | R37: =SUMIFS($F$83:$F$272,$D$83:$D$272,E37,$E$83:$E$272,$R$25) -> -1675308.9 | S37: =Q37+R37 -> 23881676 | T37: =SUMIFS($F$83:$F$272,$D$83:$D$272,E37,$E$83:$E$272,$T$25) -> 699002.11 | U37: =S37+T37 -> 24580678 | V37: =SUMIFS($F$83:$F$272,$D$83:$D$272,E37,$E$83:$E$272,$V$25) -> 18272125 | W37: =U37+V37 -> 42852803 | X37: =SUMIFS($F$83:$F$272,$D$83:$D$272,E37,$E$83:$E$272,$X$25) -> 20877437 | Y37: =W37+X37 -> 63730240 | Z37: =SUMIFS($F$83:$F$272,$D$83:$D$272,E37,$E$83:$E$272,$Z$25) -> -6100772.8 | AA37: =Y37+Z37 -> 57629467 | AB37: =SUMIFS($F$83:$F$272,$D$83:$D$272,E37,$E$83:$E$272,$AB$25) -> -27442194 | AC37: =AA37+AB37 -> 30187273 | AD37: =SUMIFS($F$83:$F$272,$D$83:$D$272,E37,$E$83:$E$272,$AD$25) -> 22219653 | AE37: =AC37+AD37 -> 52406926 | AF37: =SUMIFS($F$83:$F$272,$D$83:$D$272,E37,$E$83:$E$272,$AF$25) -> 627871.49 | AG37: =AE37+AF37 -> 53034798 | AH37: =SUMIFS($F$83:$F$272,$D$83:$D$272,E37,$E$83:$E$272,$AH$25) -> 2.0067347e+08 | AI37: =AG37+AH37 -> 2.5370827e+08 | AJ37: =SUMIFS($F$83:$F$272,$D$83:$D$272,E37,$E$83:$E$272,$AJ$25) -> -85966365 | AK37: =AI37+AJ37 -> 1.677419e+08 | AL37: =SUMIFS($F$83:$F$272,$D$83:$D$272,E37,$E$83:$E$272,$AL$25) -> -1.4400257e+08 | AM37: =AK37+AL37 -> 23739333 | AN37: =AM37-H37 -> -2.9802322e-08
... C47: 河南豫能控股股份有限公司 | D47: 银行存款 | E47: 15550000004931230 | F47: 河南豫能控股股份有限公司 | G47: RMB | H47: 50925.53 | I47: 154171.67 | J47: =AVERAGE(I47,Q47,S47,U47,W47,Y47,AA47,AC47,AE47,AG47,AI47,AK47,H47) -> 2427487.8 | K47: 0.002 | L47: 0.001 | M47: =AVERAGE(K47:L47) -> 0.0015 | N47: 1 | O47: =J47*M47*N47 -> 3641.2318 | P47: =SUMIFS($F$83:$F$272,$D$83:$D$272,E47,$E$83:$E$272,$P$25) -> -200 | Q47: =I47+P47 -> 153971.67 | R47: =SUMIFS($F$83:$F$272,$D$83:$D$272,E47,$E$83:$E$272,$R$25) -> 30018056 | S47: =Q47+R47 -> 30172027 | T47: =SUMIFS($F$83:$F$272,$D$83:$D$272,E47,$E$83:$E$272,$T$25) -> -29992593 | U47: =S47+T47 -> 179434.68 | V47: =SUMIFS($F$83:$F$272,$D$83:$D$272,E47,$E$83:$E$272,$V$25) -> -602.75 | W47: =U47+V47 -> 178831.93 | X47: =SUMIFS($F$83:$F$272,$D$83:$D$272,E47,$E$83:$E$272,$X$25) -> 6250 | Y47: =W47+X47 -> 185081.93 | Z47: =SUMIFS($F$83:$F$272,$D$83:$D$272,E47,$E$83:$E$272,$Z$25) -> 1083.7 | AA47: =Y47+Z47 -> 186165.63 | AB47: =SUMIFS($F$83:$F$272,$D$83:$D$272,E47,$E$83:$E$272,$AB$25) -> 0 | AC47: =AA47+AB47 -> 186165.63 | AD47: =SUMIFS($F$83:$F$272,$D$83:$D$272,E47,$E$83:$E$272,$AD$25) -> -162765.2 | AE47: =AC47+AD47 -> 23400.43 | AF47: =SUMIFS($F$83:$F$272,$D$83:$D$272,E47,$E$83:$E$272,$AF$25) -> 76.08 | AG47: =AE47+AF47 -> 23476.51 | AH47: =SUMIFS($F$83:$F$272,$D$83:$D$272,E47,$E$83:$E$272,$AH$25) -> 0 | AI47: =AG47+AH47 -> 23476.51 | AJ47: =SUMIFS($F$83:$F$272,$D$83:$D$272,E47,$E$83:$E$272,$AJ$25) -> 16736.11 | AK47: =AI47+AJ47 -> 40212.62 | AL47: =SUMIFS($F$83:$F$272,$D$83:$D$272,E47,$E$83:$E$272,$AL$25) -> 10712.91 | AM47: =AK47+AL47 -> 50925.53 | AN47: =AM47-H47 -> -8.8766683e-10
C48: 河南豫能控股股份有限公司 | D48: 银行存款 | E48: 15550000005026331 | F48: 河南豫能控股股份有限公司 | G48: RMB | H48: 0 | I48: 0 | J48: =(H48+I48)/2 -> 0 | O48: =J48*M48*N48 -> 0 | P48: =SUMIFS($F$83:$F$272,$D$83:$D$272,E48,$E$83:$E$272,$P$25) -> 0 | Q48: =I48+P48 -> 0 | R48: =SUMIFS($F$83:$F$272,$D$83:$D$272,E48,$E$83:$E$272,$R$25) -> 0 | S48: =Q48+R48 -> 0 | T48: =SUMIFS($F$83:$F$272,$D$83:$D$272,E48,$E$83:$E$272,$T$25) -> 0 | U48: =S48+T48 -> 0 | V48: =SUMIFS($F$83:$F$272,$D$83:$D$272,E48,$E$83:$E$272,$V$25) -> 0 | W48: =U48+V48 -> 0 | X48: =SUMIFS($F$83:$F$272,$D$83:$D$272,E48,$E$83:$E$272,$X$25) -> 0 | Y48: =W48+X48 -> 0 | Z48: =SUMIFS($F$83:$F$272,$D$83:$D$272,E48,$E$83:$E$272,$Z$25) -> 11104.44 | AA48: =Y48+Z48 -> 11104.44 | AB48: =SUMIFS($F$83:$F$272,$D$83:$D$272,E48,$E$83:$E$272,$AB$25) -> 0 | AC48: =AA48+AB48 -> 11104.44 | AD48: =SUMIFS($F$83:$F$272,$D$83:$D$272,E48,$E$83:$E$272,$AD$25) -> -11104.44 | AE48: =AC48+AD48 -> 2.401066e-09 | AF48: =SUMIFS($F$83:$F$272,$D$83:$D$272,E48,$E$83:$E$272,$AF$25) -> 10415.36 | AG48: =AE48+AF48 -> 10415.36 | AH48: =SUMIFS($F$83:$F$272,$D$83:$D$272,E48,$E$83:$E$272,$AH$25) -> 0 | AI48: =AG48+AH48 -> 10415.36 | AJ48: =SUMIFS($F$83:$F$272,$D$83:$D$272,E48,$E$83:$E$272,$AJ$25) -> 0 | AK48: =AI48+AJ48 -> 10415.36 | AL48: =SUMIFS($F$83:$F$272,$D$83:$D$272,E48,$E$83:$E$272,$AL$25) -> -10415.36 | AM48: =AK48+AL48 -> 2.401066e-09 | AN48: =AM48-H48 -> 2.401066e-09
J49: =(H49+I49)/2 -> 0 | O49: =J49*M49*N49 -> 0
J50: =(H50+I50)/2 -> 0 | O50: =J50*M50*N50 -> 0
J51: =(H51+I51)/2 -> 0 | O51: =J51*M51*N51 -> 0
F53: 合计 | H53: =SUM(H26:H51) -> 6.5927515e+08 | O53: =SUM(O26:O51) -> 2440992.7
G54: 活期存款 | H54: 6.5927515e+08 | I54: refer to <C.01.1 BKD&Confirmation> | O54: Rx
G55: Diff | H55: =H53-H54 -> 0 | N55: Total Diff | O55: =IFERROR(P65+O53-P70,0) -> 176273.08 | P55: w
B58: 表2 | C58: 对货币资金的利息收入进行测算——定期存款： | H58: AA | I58: BB | N58: CC | O58: DD | P58: EE=(AA*BB*CC/360)*DD
...

Sheet Uexp_Cutoff
A1: 27072530-60da-4b5d-87b1-4357f8557a1f
J2: 返回汇总页
C5: 目标
C6: 测试记录在账面的费用交易是否记录于正确期间
C8: 序号 | D8: 执行的程序 | G8: 程序表 | H8: 预审完成 | I8: 年审完成 | J8: 执行注意事项
C9: 1 | D9: 结合我们对于被审计单位费用确认时点的理解，考虑截止性测试的涵盖期间。 | G9: 表1 | H9: 否 | I9: 是 | J9: 考虑我们从其他审计程序中获取的审计证据（例如，已测试过的折旧、摊销、职工薪酬、租赁费、保险费等），确认我们是否已经对全部期间费用的截止性执行了充分、适当的审计程序。
C10: 2 | D10: 获取截止测试涵盖期间内的期间费用明细账，并考虑IPE测试的结果。 | G10: 【请项目组更新底稿索引】 | H10: 否 | I10: 是
C11: 3 | D11: 获得测试期间内所选交易的支持文件，并确定它们是否记录在适当的期间。项目组可以检查发生额大于TE的交易，或项目组发现符合其他特定标准的交易作为关键项（key item）。如果关键项（key item）的检查不足以应对CRA的风险水平，项目组应当采取安永审计抽样工具抽取代表性样本。 | G11: 表2及表3 | H11: 否 | I11: 是
B15: 表1 | C15: 确定截止性测试的涵盖期间
C16: 测试期间（输入前后天数） | D16: 测试期间确定依据/原因 | E16: 测试开始日期 | F16: 测试结束日期
C17: 30 | D17: 根据公司费用报销管理制度规定各项费用需在发生日起30天内完成报销审批，且月底结账期间正常情况下不再进行频繁的费用报销及计提；综上所述，我们选取资产负债表日前后各30天作为截止性测试期间。 | E17: =汇总!D5-C17 -> 45627 | F17: 45688
B19: 表2 | C19: 记录确定截止性测试样本的策略
C20: 我们选取金额大于测试阈值（50%TE:5,250,000.00元）的作为测试样本。测试期间剔除利息支出、租赁负债利息支出等已在其他底稿测试的费用明细后，12月1日-12月31日的全部费用金额仅为人民币386千元，2025年1月1日-1月31日全部费用金额为273千元，无金额大于测试阈值的样本，且样本池金额合计小于SAD，我们不再执行进一步审计程序。
B25: 表3 | C25: 测试期间费用的截止性
C26: 记账日期 | D26: 交易事项描述 | E26: 发票日期 | F26: 交易金额 | G26: 发票号码 | H26: 业务发生日期 | I26: 交易是否被记录在正确的期间 | J26: 说明我们所执行的工作以及检查的外部审计证据。
C27: 本期资产负债表日前记录的交易
C28: 本期公司无金额大于测试阈值的样本，且金额合计小于SAD，不执行进一步程序。
C30: 本期资产负债表日后记录的交易
C31: 本期公司无金额大于测试阈值的样本，且金额合计小于SAD，不执行进一步程序。
B37: Notes | C37: 本期公司无金额大于测试阈值的样本，且金额合计小于SAD，不执行进一步程序。

Sheet SkywindSettingSheet
A1: 4dc9ee5d-f2ce-45d3-9ab7-e53d6fd7e35c
A3: {"Id":"2120093264","IsProject":false,"ProjectId":"2006600230","TempProjectName":"测试上数","TempType":2}
A4: TRUE
A5: 管理费用
