Workbook

Sheet 汇总 
A1: V6 SWP
B2: 该科目涉及OSP底稿可参考此链接 | F2: OSP K1 SWP 固定资产及在建工程盘点 202YMMDD XYZ公司.xlsx
F3: OSP K1 SWP 固定资产权属检查 202YMMDD XYZ公司.xlsx
B5: K.00 | C5: K.00 Lead Sheet | F5: 程序页 | G5: 执行 | H5: 不执行的原因 | I5: 注意事项
B6: 1 | C6: 获取和编制固定资产两期变动的引导表，并与试算平衡表和上年底稿核对一致。对固定资产变动建立预期并说明理由，对不符合预期的变动以及异常变动进行调查和分析。 | F6: K.00 Lead Sheet | G6: 是
B7: K.01 | C7: K.01 Agree SL to GL（认定：IS：E、V、C、M） | F7: 程序页 | G7: 执行 | H7: 不执行的原因 | I7: 注意事项
B8: 1 | C8: 获取固定资产后推明细表，并将其与试算平衡表和固定资产清单核对一致。 | F8: K.01 Agree SL to GL | G8: 是
B9: K.02 | C9: K.02.1 新增测试（认定：E、V、C、P&D） | F9: 程序页 | G9: 执行 | H9: 不执行的原因 | I9: 注意事项
B10: 1 | C10: 获取当期按类别划分的所有固定资产新增清单，并将该清单与固定资产后推核对一致，调查超过SAD名义金额的差额。 | F10: 新增清单 | G10: 是 | I10: 若在建工程为不重大账户未开底稿，则项目组需要在K1 SWP中核对在建工程转入与转出金额是否一致，并按照<J.02.2 CIP transfer (ToD)>的测试属性执行该程序。
B11: 2 | C11: 对本年新增资产执行关键性样本测试和代表性样本测试（如需要）。 | F11: K.02.1 新增测试 | G11: 否 | H11: 本年无购置新增，不再执行程序，在建工程转入已在在建工程底稿<J.02.2 CIP transfer (ToD)>执行测试
F12: K.02.1a 新增选样输出
B13: K.02 | C13: K.02.2 处置测试（认定：E、V、R&O） | F13: 程序页 | G13: 执行 | H13: 不执行的原因 | I13: 注意事项
B14: 1 | C14: 获取当期按类别划分的所有固定资产处置清单，包括记录的处置的损益，并将该清单与固定资产后推核对一致，我们调查超过SAD名义金额的差额。 | F14: 处置清单 | G14: 否 | H14: 本期无处置
B15: 2 | C15: 对本年处置资产执行关键性样本测试和代表性样本测试（如需要）。 | F15: K.02.2 处置测试 | G15: 否 | H15: 本期无处置
F16: K.02.2a 处置选样输出
B17: K.03 | C17: K.03 折旧测试（认定：IS:V、O、M、P&D） | F17: 程序页 | G17: 执行 | H17: 不执行的原因 | I17: 注意事项
B18: 1 | C18: 执行实质性分析程序(SAP)测试折旧费用，可参考264 GL 或K.03.1 SAP模板执行。如不执行，可直接执行K.03.2 折旧测试TOD。 | F18: K.03.1 SAP | G18: 否 | H18: 有限风险账户，直接执行by item折旧测试
B19: 2 | C19: 如选择执行详细测试，可使用该底稿记录。 | F19: K.03.2 折旧测试TOD | G19: 是 | H19: 本年折旧在FA List中by item进行测试
B20: 3 | C20: 检查固定资产各项目的折旧政策是否符合有关规定，是否与上期一致，评价其合理性。若改变折旧政策，检查其依据是否充分。 | F20: K.03.3 折旧政策复核 | G20: 是
B21: K.04 | C21: K.04 固定资产的减值（认定：BS：V IS：M） | F21: 程序页 | G21: 执行 | H21: 不执行的原因 | I21: 注意事项
B22: 1 | C22: 1.使用在审计过程中所获得的信息来确定管理层是否已识别适当的减值迹象；可使用PSP Canvas form K.04：识别减值迹象，也可使用 <SWP减值迹象识别> 对减值迹象进行评估，并根据指引要求获取相关支持性文件。 2.如有减值迹象的，评价管理层假设、未来现金流等减值评估的合理性，核实并测算减值金额。 3.检查是否存在转回固定资产减值准备的情况，确定减值准备在以后会计期间没有转回。 | F22: 减值测试 | G22: 否 | H22: 已在<减值测试 20251231_电驱动>中执行了相关减值测试

Sheet K.00 Lead Sheet
B1: 标准工作底稿: K1 SWP 不动产、厂房和设备及相关账户（PPE）
B2: 客户名称 | C2: 六六六有限公司 | D2: 此工作底稿需要与以下 Canvas PSP guided workflow forms一起使用： •K.00 PPE引导表 •K.01 将明细账与总账核对一致 •K.02 增加和处置 •K.03 折旧、损耗和摊销 •K.04 固定资产减值 •账户结论
B3: 期末 | C3: 46022
B4: 分析日期 | C4: 45670
B5: 可容忍误差（TE） | C5: 2408000
B6: 名义金额（SAD） | C6: 161000
B7: 适用会计准则（GAAP） | C7: PRC
B8: 记账本位币 | C8: CNY
B9: K.00 编制引导表并比较余额
B11: 返回汇总页
D13: Threshold(s) | J13: 安永标记
B14: 认定 | C14: CRA | D14: 各项认定1 | E14: 所有相关认定 2 | H14: TB | I14: 已与科目余额表核对无误
B15: 完整性（C） | C15: N/A | D15: =IF(C15="Minimal",$C$5*100%,IF(C15="Low",$C$5*75%,IF(C15="Moderate",$C$5*50%,IF(C15="High",$C$5*25%,IF(C15="N/A","-",))))) -> - | E15: =MIN($D$15:$D$19) -> 1204000 | H15: PY | I15: 与上年最终审定数核对一致
B16: 存在性/发生 (E/O) | C16: Moderate | D16: =IF(C16="Minimal",$C$5*100%,IF(C16="Low",$C$5*75%,IF(C16="Moderate",$C$5*50%,IF(C16="High",$C$5*25%,IF(C16="N/A","-",))))) -> 1204000 | H16: A3 | I16: 与未审数、审定数核对一致
B17: 计价/计量（V/M） | C17: Moderate | D17: =IF(C17="Minimal",$C$5*100%,IF(C17="Low",$C$5*75%,IF(C17="Moderate",$C$5*50%,IF(C17="High",$C$5*25%,IF(C17="N/A","-",))))) -> 1204000 | H17: A5 | I17: 与审计调整核对一致
B18: 权利和义务（R&O） | C18: N/A | D18: =IF(C18="Minimal",$C$5*100%,IF(C18="Low",$C$5*75%,IF(C18="Moderate",$C$5*50%,IF(C18="High",$C$5*25%,IF(C18="N/A","-",))))) -> - | H18: FS | I18: 与FS.0x与财务报表核对无误
B19: 列报和披露（P&D） | C19: N/A | D19: =IF(C19="Minimal",$C$5*100%,IF(C19="Low",$C$5*75%,IF(C19="Moderate",$C$5*50%,IF(C19="High",$C$5*25%,IF(C19="N/A","-",))))) -> - | H19: w | I19: 低于SAD的金额——放弃进一步调查
B20: 1 各项认定的测试阈值，是根据EY GAM SUBSTANTIVE DESIGN 2.2.1 | H20: Rx | I20: 重新计算，无异常
B21: 中的示例测试阈值（用占TE的百分比表示）在相应风险等级（CRA）区间的上限计算得出的。 | H21: m | I21: 余额/活动不符合测试范围–无需进一步调查
B22: 除负债/费用类别账户的完整性认定应当使用负债/费用账户表之外，其他类别账户和认定均可使用资产/收入账户表。 | H22: SL | I22: 已与明细账核对无误
B23: 2 所有相关认定的测试阈值，是所有有效认定对应之测试阈值的最小值。我们在
B24: Lead中使用该测试阈值：（a）作为选取总账账户进行测试的起点；（b）作为（需要进一步调查的）金额波动范围的起点。
B26: 在下文中描述我们对固定资产在此期间的相关账户余额和相关波动的预期，以及我们对这些预期的依据和理由。
B27: 账户变更 | C27: 预期及额外考虑
B28: 新增 | C28: 被审计单位上期在建的部分设备，预计本期可达到预计可使用状态进行转固，因此，我们预计本期固定资产的原值将存在在建转入的新增变动。
B29: 减少 | C29: 被审计单位本期业务无重大变化，因此，我们预计本期固定资产的原值将不存在重大处置的变动。
B30: 在建工程转入（如适用） | C30: 被审计单位上年有需要安装的固定资产，预计本期有转固计划。
B31: 转让、外汇和其他调整 | C31: 被审计单位接收东风（武汉）电驱动系统有限公司资产，部分设备经评估可变现净值低于账面价值，以进行减值处理。
B32: 折旧方法 | C32: 直线法，我们预计本年较上年无变化。
B33: 折旧费用 | C33: 因为被审计单位折旧方法和使用寿命没有变化，将与往年一样正常计提折旧。因此，我们预计本年度累计折旧较上年增加系东风（武汉）电驱动系统有限公司转入新增。
B34: 使用寿命变化 | C34: 由于本年度被审计单位的折旧政策未发生变化，我们预计被审计单位固定资产的使用寿命也不会发生变化。
B37: 波动范围
B38: ="波动幅度 ("&C8&"):" -> 波动幅度 (CNY): | C38: =$E$15 -> 1204000
B39: 波动幅度 (%): | C39: 0.1
B41: 我们获取或编制了与上期对比的重大账户（固定资产）引导表。我们将本期余额与试算平衡表核对一致，并将上期余额与上期审定数核对一致（如适用）。
B42: 我们将期末余额与上期余额进行对比。调查超出测试阈值（金额和百分比）的波动，以及代表异常或预期外变动或未发生预期中变动的波动，并确定其对我们计划实质性程序的影响 (如有)。
E45: |------- TB -------| | J45: |------- PY -------|
E46: ="货币/单位: "&C8 -> 货币/单位: CNY
E47: =$C$3 -> 46022 | J47: =DATE(YEAR($C$3)-1,12,31) -> 45657 | K47: 本期和上期期末余额 | N47: 基于波动幅度判断，是否进一步调查？ | O47: 基于定性考虑判断，是否进一步调查？
B48: 总账科目编码 | C48: 科目名称 | D48: 索引号 | E48: 期末账面数 | F48: 账表调整数 | G48: 期末未审数 | H48: 审计调整数 | I48: 期末审定数 | J48: 上期末审定数 | K48: 变动金额 | L48: 变动% | M48: Notes
...

Sheet K.01 Agree SL to GL
B1: 标准工作底稿: K1 SWP 不动产、厂房和设备及相关账户（PPE）
B2: K.01 将明细账与总账核对一致
B4: 返回汇总页
B6: 获取上期末至本期末（或中期，如适用）固定资产及相关新增、处置、转让和折旧的后推明细表。（原值、累计折旧、减值均为正数填列，本期减少以负数填列，账表调整、审计调整数据均直接链接至K.00 Lead。）
B7: 我们将期初固定资产余额与上期审定数核对一致，将期末固定资产余额与固定资产明细账和试算表核对一致。我们调查了大于SAD的差异。我们将利润表金额（如，折旧费用）与试算表核对一致（如适用）。
B8: 我们选择了超过测试阈值的后推活动（如，新增、处置、固定资产转入、转移和折旧费用），以执行K.02和K.03的实质性程序。对于未包含在本程序表范围内的程序，我们交叉索引至完成该程序的单独程序表。我们评估了固定资产的转移和其他调整，以了解调整的性质，并确定是否需要执行额外程序。
B9: 表1
D10: 固定资产类别 | F10: 房屋建筑物 | I10: 机器设备 | L10: 运输设备 | O10: 电子产品及通讯设备 | R10: 合计
E11: 账面数 | F11: 账表调整/审计调整 | G11: 审定数 | H11: 账面数 | I11: 账表调整/审计调整 | J11: 审定数 | K11: 账面数 | L11: 账表调整/审计调整 | M11: 审定数 | N11: 账面数 | O11: 账表调整/审计调整 | P11: 审定数 | Q11: 账面数 | R11: 账表调整/审计调整 | S11: 审定数 | T11: CHECK
C12: 年初余额 | D12: PY | E12: 322612.2 | G12: =SUM(E12:F12) -> 322612.2 | H12: 1.760351e+08 | J12: =SUM(H12:I12) -> 1.760351e+08 | K12: 844044.29 | M12: =SUM(K12:L12) -> 844044.29 | N12: 290507.47 | P12: =SUM(N12:O12) -> 290507.47 | Q12: =SUM(E12,H12,K12,N12) -> 1.7749227e+08 | R12: =SUM(F12,I12,L12,O12) -> 0 | S12: =SUM(G12,J12,M12,P12) -> 1.7749227e+08 | T12: =S12-'K.00 Lead Sheet'!J49 -> 0
C13: 购置 | D13: K.02.1 | E13: 0 | G13: =SUM(E13:F13) -> 0 | H13: 0 | J13: =SUM(H13:I13) -> 0 | K13: 0 | M13: =SUM(K13:L13) -> 0 | N13: 0 | P13: =SUM(N13:O13) -> 0 | Q13: =SUM(E13,H13,K13,N13) -> 0 | R13: =SUM(F13,I13,L13,O13) -> 0 | S13: =SUM(G13,J13,M13,P13) -> 0
C14: 其他转入-内部划转 | D14: J1.02 | E14: 0 | G14: =SUM(E14:F14) -> 0 | H14: 0 | J14: =SUM(H14:I14) -> 0 | K14: 0 | M14: =SUM(K14:L14) -> 0 | N14: 0 | P14: =SUM(N14:O14) -> 0 | Q14: =SUM(E14,H14,K14,N14) -> 0 | R14: =SUM(F14,I14,L14,O14) -> 0 | S14: =SUM(G14,J14,M14,P14) -> 0
C15: 在建工程转入 | E15: 0 | G15: =SUM(E15:F15) -> 0 | H15: 10508233 | J15: =SUM(H15:I15) -> 10508233 | K15: 0 | M15: =SUM(K15:L15) -> 0 | N15: 28926 | P15: =SUM(N15:O15) -> 28926 | Q15: =SUM(E15,H15,K15,N15) -> 10537159 | R15: =SUM(F15,I15,L15,O15) -> 0 | S15: =SUM(G15,J15,M15,P15) -> 10537159
B16: 原值 | C16: 处置或报废 | D16: K.02.2 | E16: 0 | G16: =SUM(E16:F16) -> 0 | H16: 0 | J16: =SUM(H16:I16) -> 0 | K16: 0 | M16: =SUM(K16:L16) -> 0 | N16: 0 | P16: =SUM(N16:O16) -> 0 | Q16: =SUM(E16,H16,K16,N16) -> 0 | R16: =SUM(F16,I16,L16,O16) -> 0 | S16: =SUM(G16,J16,M16,P16) -> 0
C17: 其他减少-内部划转 | E17: 0 | G17: =SUM(E17:F17) -> 0 | H17: 0 | J17: =SUM(H17:I17) -> 0 | K17: -34688.33 | M17: =SUM(K17:L17) -> -34688.33 | N17: 0 | P17: =SUM(N17:O17) -> 0 | Q17: =SUM(E17,H17,K17,N17) -> -34688.33 | R17: =SUM(F17,I17,L17,O17) -> 0 | S17: =SUM(G17,J17,M17,P17) -> -34688.33
C18: […] | E18: 0 | G18: =SUM(E18:F18) -> 0 | H18: 0 | J18: =SUM(H18:I18) -> 0 | K18: 0 | M18: =SUM(K18:L18) -> 0 | N18: 0 | P18: =SUM(N18:O18) -> 0 | Q18: =SUM(E18,H18,K18,N18) -> 0 | R18: =SUM(F18,I18,L18,O18) -> 0 | S18: =SUM(G18,J18,M18,P18) -> 0
C19: 年末余额 | D19: Rx | E19: =E12+E13+E14+E15+E16+E17+E18 -> 322612.2 | F19: =F12+F13+F14+F15+F16+F17+F18 -> 0 | G19: =G12+G13+G14+G15+G16+G17+G18 -> 322612.2 | H19: =H12+H13+H14+H15+H16+H17+H18 -> 1.8654334e+08 | I19: =I12+I13+I14+I15+I16+I17+I18 -> 0 | J19: =J12+J13+J14+J15+J16+J17+J18 -> 1.8654334e+08 | K19: =K12+K13+K14+K15+K16+K17+K18 -> 809355.96 | L19: =L12+L13+L14+L15+L16+L17+L18 -> 0 | ... S19: =S12+S13+S14+S15+S16+S17+S18 -> 1.8799474e+08 | T19: =S19-'K.00 Lead Sheet'!I49 -> 0
C20: 年初余额 | D20: PY | E20: 25718.05 | G20: =SUM(E20:F20) -> 25718.05 | H20: 67548902 | J20: =SUM(H20:I20) -> 67548902 | K20: 214550.28 | M20: =SUM(K20:L20) -> 214550.28 | N20: 94642.63 | P20: =SUM(N20:O20) -> 94642.63 | Q20: =SUM(E20,H20,K20,N20) -> 67883813 | R20: =SUM(F20,I20,L20,O20) -> 0 | S20: =SUM(G20,J20,M20,P20) -> 67883813 | T20: =S20-'K.00 Lead Sheet'!J50 -> 0
C21: 计提 | D21: K.03.2 | E21: 9048.27 | G21: =SUM(E21:F21) -> 9048.27 | H21: 18482397 | J21: =SUM(H21:I21) -> 18482397 | K21: 96563.03 | M21: =SUM(K21:L21) -> 96563.03 | N21: 41841.33 | P21: =SUM(N21:O21) -> 41841.33 | Q21: =SUM(E21,H21,K21,N21) -> 18629849 | R21: =SUM(F21,I21,L21,O21) -> 0 | S21: =SUM(G21,J21,M21,P21) -> 18629849 | T21: <K.03 折旧测试>
B22: 累计折旧 | C22: 处置或报废 | D22: K.02.2 | E22: 0 | G22: =SUM(E22:F22) -> 0 | H22: 0 | J22: =SUM(H22:I22) -> 0 | K22: 0 | M22: =SUM(K22:L22) -> 0 | N22: 0 | P22: =SUM(N22:O22) -> 0 | Q22: =SUM(E22,H22,K22,N22) -> 0 | R22: =SUM(F22,I22,L22,O22) -> 0 | S22: =SUM(G22,J22,M22,P22) -> 0
C23: 内部划转增加 | E23: 0 | G23: =SUM(E23:F23) -> 0 | H23: 0 | J23: =SUM(H23:I23) -> 0 | K23: 0 | M23: =SUM(K23:L23) -> 0 | N23: 0 | P23: =SUM(N23:O23) -> 0 | Q23: =SUM(E23,H23,K23,N23) -> 0 | R23: =SUM(F23,I23,L23,O23) -> 0 | S23: =SUM(G23,J23,M23,P23) -> 0
C24: 内部划转减少 | E24: 0 | G24: =SUM(E24:F24) -> 0 | H24: 0 | J24: =SUM(H24:I24) -> 0 | K24: -34688.33 | M24: =SUM(K24:L24) -> -34688.33 | N24: 0 | P24: =SUM(N24:O24) -> 0 | Q24: =SUM(E24,H24,K24,N24) -> -34688.33 | R24: =SUM(F24,I24,L24,O24) -> 0 | S24: =SUM(G24,J24,M24,P24) -> -34688.33
C25: 年末余额 | D25: Rx | E25: =E20+E21+E22+E23+E24 -> 34766.32 | F25: =F20+F21+F22+F23+F24 -> 0 | G25: =G20+G21+G22+G23+G24 -> 34766.32 | H25: =H20+H21+H22+H23+H24 -> 86031298 | I25: =I20+I21+I22+I23+I24 -> 0 | J25: =J20+J21+J22+J23+J24 -> 86031298 | K25: =K20+K21+K22+K23+K24 -> 276424.98 | L25: =L20+L21+L22+L23+L24 -> 0 | ... P25: =P20+P21+P22+P23+P24 -> 136483.96 | Q25: =SUM(E25,H25,K25,N25) -> 86478974 | R25: =R20+R21+R22+R23+R24 -> 0 | S25: =S20+S21+S22+S23+S24 -> 86478974 | T25: =S25-'K.00 Lead Sheet'!I50 -> 0
C26: 年初余额 | D26: PY | E26: 0 | G26: =SUM(E26:F26) -> 0 | H26: 0 | J26: =SUM(H26:I26) -> 0 | K26: 0 | M26: =SUM(K26:L26) -> 0 | N26: 0 | P26: =SUM(N26:O26) -> 0 | Q26: =SUM(E26,H26,K26,N26) -> 0 | R26: =SUM(F26,I26,L26,O26) -> 0 | S26: =SUM(G26,J26,M26,P26) -> 0 | T26: =S26-'K.00 Lead Sheet'!J51 -> 0
C27: 计提 | D27: SWP 减值 | E27: 0 | G27: =SUM(E27:F27) -> 0 | H27: 73838868 | J27: =SUM(H27:I27) -> 73838868 | K27: 196566.1 | M27: =SUM(K27:L27) -> 196566.1 | N27: 0 | P27: =SUM(N27:O27) -> 0 | Q27: =SUM(E27,H27,K27,N27) -> 74035435 | R27: =SUM(F27,I27,L27,O27) -> 0 | S27: =SUM(G27,J27,M27,P27) -> 74035435
B28: 减值准备 | C28: 处置或报废 | D28: K.02.2 | E28: 0 | G28: =SUM(E28:F28) -> 0 | H28: 0 | J28: =SUM(H28:I28) -> 0 | K28: 0 | M28: =SUM(K28:L28) -> 0 | N28: 0 | P28: =SUM(N28:O28) -> 0 | Q28: =SUM(E28,H28,K28,N28) -> 0 | R28: =SUM(F28,I28,L28,O28) -> 0 | S28: =SUM(G28,J28,M28,P28) -> 0
C29: 内部重分类 | E29: 0 | G29: =SUM(E29:F29) -> 0 | H29: 0 | J29: =SUM(H29:I29) -> 0 | K29: 0 | M29: =SUM(K29:L29) -> 0 | N29: 0 | P29: =SUM(N29:O29) -> 0 | Q29: =SUM(E29,H29,K29,N29) -> 0 | R29: =SUM(F29,I29,L29,O29) -> 0 | S29: =SUM(G29,J29,M29,P29) -> 0
C30: […] | E30: 0 | G30: =SUM(E30:F30) -> 0 | H30: 0 | J30: =SUM(H30:I30) -> 0 | K30: 0 | M30: =SUM(K30:L30) -> 0 | N30: 0 | P30: =SUM(N30:O30) -> 0 | Q30: =SUM(E30,H30,K30,N30) -> 0 | R30: =SUM(F30,I30,L30,O30) -> 0 | S30: =SUM(G30,J30,M30,P30) -> 0
C31: 年末余额 | D31: Rx | E31: =E26+E27+E28+E29+E30 -> 0 | F31: =F26+F27+F28+F29+F30 -> 0 | G31: =G26+G27+G28+G29+G30 -> 0 | H31: =H26+H27+H28+H29+H30 -> 73838868 | I31: =I26+I27+I28+I29+I30 -> 0 | J31: =J26+J27+J28+J29+J30 -> 73838868 | K31: =K26+K27+K28+K29+K30 -> 196566.1 | L31: =L26+L27+L28+L29+L30 -> 0 | ... S31: =S26+S27+S28+S29+S30 -> 74035435 | T31: =S31-'K.00 Lead Sheet'!I51 -> 0
B32: 净值 (NBV) | C32: 年初余额 | D32: Rx | E32: =E12-E20-E26 -> 296894.15 | F32: =F12-F20-F26 -> 0 | G32: =G12-G20-G26 -> 296894.15 | H32: =H12-H20-H26 -> 1.084862e+08 | I32: =I12-I20-I26 -> 0 | J32: =J12-J20-J26 -> 1.084862e+08 | K32: =K12-K20-K26 -> 629494.01 | L32: =L12-L20-L26 -> 0 | ... S32: =S12-S20-S26 -> 1.0960845e+08 | T32: =S32-'K.00 Lead Sheet'!J55 -> 0
C33: 年末余额 | D33: Rx | E33: =E19-E25-E31 -> 287845.88 | F33: =F19-F25-F31 -> 0 | G33: =G19-G25-G31 -> 287845.88 | H33: =H19-H25-H31 -> 26673169 | I33: =I19-I25-I31 -> 0 | J33: =J19-J25-J31 -> 26673169 | K33: =K19-K25-K31 -> 336364.88 | L33: =L19-L25-L31 -> 0 | ... S33: =S19-S25-S31 -> 27480329 | T33: =S33-'K.00 Lead Sheet'!I55 -> 0
B34: 变动 | C34: 原值变动金额 | D34: 本年VS上年 | E34: =E19-E12 -> 0 | G34: =G19-G12 -> 0 | H34: =H19-H12 -> 10508233 | J34: =J19-J12 -> 10508233 | K34: =K19-K12 -> -34688.33 | M34: =M19-M12 -> -34688.33 | N34: =N19-N12 -> 28926 | P34: =P19-P12 -> 28926 | Q34: =Q19-Q12 -> 10502471 | R34: =R19-R12 -> 0 | S34: =S19-S12 -> 10502471
C35: 原值变动比例 | D35: % | E35: =IFERROR(E34/E12,1) -> 0 | G35: =IFERROR(G34/G12,1) -> 0 | H35: =IFERROR(H34/H12,1) -> 0.059693964 | J35: =IFERROR(J34/J12,1) -> 0.059693964 | K35: =IFERROR(K34/K12,1) -> -0.04109776 | M35: =IFERROR(M34/M12,1) -> -0.04109776 | N35: =IFERROR(N34/N12,1) -> 0.099570589 | P35: =IFERROR(P34/P12,1) -> 0.099570589 | Q35: =IFERROR(Q34/Q12,1) -> 0.059171428 | R35: =IFERROR(R34/R12,1) -> 1 | S35: =IFERROR(S34/S12,1) -> 0.059171428
C36: 累计折旧变动金额 | D36: 本年VS上年 | E36: =E25-E20 -> 9048.27 | G36: =G25-G20 -> 9048.27 | H36: =H25-H20 -> 18482397 | J36: =J25-J20 -> 18482397 | K36: =K25-K20 -> 61874.7 | M36: =M25-M20 -> 61874.7 | N36: =N25-N20 -> 41841.33 | P36: =P25-P20 -> 41841.33 | Q36: =Q25-Q20 -> 18595161 | R36: =R25-R20 -> 0 | S36: =S25-S20 -> 18595161
C37: 累计折旧变动比例 | D37: % | E37: =IFERROR(E36/E20,1) -> 0.35182566 | G37: =IFERROR(G36/G20,1) -> 0.35182566 | H37: =IFERROR(H36/H20,1) -> 0.27361506 | J37: =IFERROR(J36/J20,1) -> 0.27361506 | K37: =IFERROR(K36/K20,1) -> 0.28839254 | M37: =IFERROR(M36/M20,1) -> 0.28839254 | N37: =IFERROR(N36/N20,1) -> 0.44209813 | P37: =IFERROR(P36/P20,1) -> 0.44209813 | Q37: =IFERROR(Q36/Q20,1) -> 0.27392629 | R37: =IFERROR(R36/R20,1) -> 1 | S37: =IFERROR(S36/S20,1) -> 0.27392629
C38: 减值准备变动金额 | D38: 本年VS上年 | E38: =E31-E26 -> 0 | G38: =G31-G26 -> 0 | H38: =H31-H26 -> 73838868 | J38: =J31-J26 -> 73838868 | K38: =K31-K26 -> 196566.1 | M38: =M31-M26 -> 196566.1 | N38: =N31-N26 -> 0 | P38: =P31-P26 -> 0 | Q38: =Q31-Q26 -> 74035435 | R38: =R31-R26 -> 0 | S38: =S31-S26 -> 74035435
C39: 减值准备变动比例 | D39: % | E39: =IFERROR(E38/E26,1) -> 1 | G39: =IFERROR(G38/G26,1) -> 1 | H39: =IFERROR(H38/H26,1) -> 1 | J39: =IFERROR(J38/J26,1) -> 1 | K39: =IFERROR(K38/K26,1) -> 1 | M39: =IFERROR(M38/M26,1) -> 1 | N39: =IFERROR(N38/N26,1) -> 1 | P39: =IFERROR(P38/P26,1) -> 1 | Q39: =IFERROR(Q38/Q26,1) -> 1 | R39: =IFERROR(R38/R26,1) -> 1 | S39: =IFERROR(S38/S26,1) -> 1
C40: 净值变动金额 | D40: 本年VS上年 | E40: =E33-E32 -> -9048.27 | G40: =G33-G32 -> -9048.27 | H40: =H33-H32 -> -81813032 | J40: =J33-J32 -> -81813032 | K40: =K33-K32 -> -293129.13 | M40: =M33-M32 -> -293129.13 | N40: =N33-N32 -> -12915.33 | P40: =P33-P32 -> -12915.33 | Q40: =Q33-Q32 -> -82128125 | R40: =R33-R32 -> 0 | S40: =S33-S32 -> -82128125
C41: 净值变动比例 | D41: % | E41: =IFERROR(E40/E32,1) -> -0.030476417 | G41: =IFERROR(G40/G32,1) -> -0.030476417 | H41: =IFERROR(H40/H32,1) -> -0.75413307 | J41: =IFERROR(J40/J32,1) -> -0.75413307 | K41: =IFERROR(K40/K32,1) -> -0.46565833 | M41: =IFERROR(M40/M32,1) -> -0.46565833 | N41: =IFERROR(N40/N32,1) -> -0.065940013 | P41: =IFERROR(P40/P32,1) -> -0.065940013 | Q41: =IFERROR(Q40/Q32,1) -> -0.74928641 | R41: =IFERROR(R40/R32,1) -> 1 | S41: =IFERROR(S40/S32,1) -> -0.74928641
B43: TB-原值 | E43: 322612.2 | H43: 1.8654334e+08 | K43: 809355.96 | N43: 319433.47 | Q43: =SUM(E43,H43,K43,N43) -> 1.8799474e+08
...

Sheet FA list
A1: 7054f053-bac2-4036-a572-53d350c3c8de
B2: 1.项目组可以自定义固定资产清单表格，也可直接使用系统导出的固定资产清单，但必须确保必需字段（固定资产类别、编号、名称、开始入账日期、使用寿命、残值率、原值、累计折旧、净值）完整。可参考链接： | W2: 返回汇总页
B3: 2.获取期末的固定资产明细清单，将固定资产明细清单的金额与K.01 Agree SL to GL 表1的金额进行核对，核对结果详见K.01 Agree SL to GL 表2，并调查大于SAD的差异。
B4: 3.固定资产的类别：请使用被审计单位的台账，无需对资产的类别添加自己的重分类修改。
B5: 4.如果折旧测试较难执行实质性分析程序或从实质性分析程序中获得的证据水平不足以得出审计结论，我们可在<FA List>中执行全量折旧测试，底稿形式可参考：
C9: 固定资产明细清单 | M9: 46022 | O9: EY 测算 | Y9: 45901 | Z9: 减值时间
B10: AFS类别 | C10: 固定资产类别 | D10: 固定资产编号 | E10: 固定资产名称 | F10: 入账开始日期 | G10: 使用寿命(年) | H10: 使用寿命(月) | I10: 残值率 | J10: 原值 | K10: 累计折旧 | L10: 减值准备 | M10: 净值 | N10: 已提足折旧 | O10: 提足折旧时间 | P10: 提足折旧时间 | Q10: 本期计提折旧 | R10: 处置日期 | S10: 本期应折旧月数 | T10: 本期应折旧金额 | U10: 差异 | V10: 减值前折旧月数 | W10: 减值后折旧月数
B11: 机器设备 | C11: 固定资产-机械设备 | D11: 000010000000 | E11: 定子铁芯上料设备 | F11: 44561 | G11: 12 | H11: =G11*12 -> 144 | I11: 0 | J11: 155238.93 | K11: 43466.9 | L11: 0 | M11: =J11-K11-L11 -> 111772.03 | N11: =IF(ROUND(J11*(1-I11),0)=ROUND(K11,0),"是","否") -> 否 | O11: =IFERROR(YEAR(EOMONTH(F11,H11)),"") -> 2033 | P11: =IFERROR(EOMONTH(F11,H11),"") -> 48944 | Q11: 13971.5 | S11: =IFERROR(IF(OR(AND(R11<>"",YEAR(R11)<YEAR($M$9)),AND(P11<>"",YEAR(P11)<YEAR($M$9))),0,IF(YEAR(F11)>YEAR($M$9),0,IF(OR((IF(YEAR(F11)<YEAR($M$9),1,IF(MONTH(F11)=12,99,MONTH(F11)+1))>12),(IF(YEAR(F11)<YEAR($M$9),1,IF(MONTH(F11)=12,99,MONTH(F11)+1))>MIN(MONTH($M$9),IF(AND(R11<>"",YEAR(R11)=YEAR($M$9)),MONTH(R11),99),IF(AND(P11<>"",YEAR(P11)=YEAR($M$9)),MONTH(P11),99)))),0,MIN(MONTH($M$9),IF(AND(R11<>"",YEAR(R11)=YEAR($M$9)),MONTH(R11),99),IF(AND(P11<>"",YEAR(P11)=YEAR($M$9)),MONTH(P11),99))-IF(YEAR(F11)<YEAR($M$9),1,IF(MONTH(F11)=12,99,MONTH(F11)+1))+1))),0) -> 12 | T11: =(J11*(1-I11))/H11*S11 -> 12936.577 | U11: =T11-Q11 -> -1034.9225
B12: 机器设备 | C12: 固定资产-机械设备 | D12: 000010000001 | E12: 打标刻印机 | F12: 44561 | G12: 12 | H12: =G12*12 -> 144 | I12: 0 | J12: 245938.05 | K12: 63355.88 | L12: 181723.6 | M12: =J12-K12-L12 -> 858.57 | N12: =IF(ROUND(J12*(1-I12),0)=ROUND(K12,0),"是","否") -> 否 | O12: =IFERROR(YEAR(EOMONTH(F12,H12)),"") -> 2033 | P12: =IFERROR(EOMONTH(F12,H12),"") -> 48944 | Q12: 16627.65 | S12: =IFERROR(IF(OR(AND(R12<>"",YEAR(R12)<YEAR($M$9)),AND(P12<>"",YEAR(P12)<YEAR($M$9))),0,IF(YEAR(F12)>YEAR($M$9),0,IF(OR((IF(YEAR(F12)<YEAR($M$9),1,IF(MONTH(F12)=12,99,MONTH(F12)+1))>12),(IF(YEAR(F12)<YEAR($M$9),1,IF(MONTH(F12)=12,99,MONTH(F12)+1))>MIN(MONTH($M$9),IF(AND(R12<>"",YEAR(R12)=YEAR($M$9)),MONTH(R12),99),IF(AND(P12<>"",YEAR(P12)=YEAR($M$9)),MONTH(P12),99)))),0,MIN(MONTH($M$9),IF(AND(R12<>"",YEAR(R12)=YEAR($M$9)),MONTH(R12),99),IF(AND(P12<>"",YEAR(P12)=YEAR($M$9)),MONTH(P12),99))-IF(YEAR(F12)<YEAR($M$9),1,IF(MONTH(F12)=12,99,MONTH(F12)+1))+1))),0) -> 12 | T12: =J12*(1-I12)/H12*9+(J12-(J12*(1-I12)/H12)*V12-L12)/W12*3 -> 15043.129 | U12: =T12-Q12 -> -1584.5205 | V12: =DATEDIF(F12,$Y$9,"M") -> 44 | W12: =H12-V12 -> 100
B13: 机器设备 | C13: 固定资产-机械设备 | D13: 000010000002 | E13: 电机下线装置 | F13: 44561 | G13: 12 | H13: =G13*12 -> 144 | I13: 0 | J13: 183646.02 | K13: 47308.88 | L13: 135696.02 | M13: =J13-K13-L13 -> 641.12 | N13: =IF(ROUND(J13*(1-I13),0)=ROUND(K13,0),"是","否") -> 否 | O13: =IFERROR(YEAR(EOMONTH(F13,H13)),"") -> 2033 | P13: =IFERROR(EOMONTH(F13,H13),"") -> 48944 | Q13: 12416.14 | S13: =IFERROR(IF(OR(AND(R13<>"",YEAR(R13)<YEAR($M$9)),AND(P13<>"",YEAR(P13)<YEAR($M$9))),0,IF(YEAR(F13)>YEAR($M$9),0,IF(OR((IF(YEAR(F13)<YEAR($M$9),1,IF(MONTH(F13)=12,99,MONTH(F13)+1))>12),(IF(YEAR(F13)<YEAR($M$9),1,IF(MONTH(F13)=12,99,MONTH(F13)+1))>MIN(MONTH($M$9),IF(AND(R13<>"",YEAR(R13)=YEAR($M$9)),MONTH(R13),99),IF(AND(P13<>"",YEAR(P13)=YEAR($M$9)),MONTH(P13),99)))),0,MIN(MONTH($M$9),IF(AND(R13<>"",YEAR(R13)=YEAR($M$9)),MONTH(R13),99),IF(AND(P13<>"",YEAR(P13)=YEAR($M$9)),MONTH(P13),99))-IF(YEAR(F13)<YEAR($M$9),1,IF(MONTH(F13)=12,99,MONTH(F13)+1))+1))),0) -> 12 | T13: =J13*(1-I13)/H13*9+(J13-(J13*(1-I13)/H13)*V13-L13)/W13*3 -> 11063.334 | U13: =T13-Q13 -> -1352.8056 | V13: =DATEDIF(F13,$M$9,"M") -> 48 | W13: =H13-V13 -> 96
B14: 机器设备 | C14: 固定资产-机械设备 | D14: 000010000003 | E14: 精密切割机 | F14: 44561 | G14: 12 | H14: =G14*12 -> 144 | I14: 0 | J14: 4247.79 | K14: 1415.92 | L14: 0 | M14: =J14-K14-L14 -> 2831.87 | N14: =IF(ROUND(J14*(1-I14),0)=ROUND(K14,0),"是","否") -> 否 | O14: =IFERROR(YEAR(EOMONTH(F14,H14)),"") -> 2033 | P14: =IFERROR(EOMONTH(F14,H14),"") -> 48944 | Q14: 353.98 | S14: =IFERROR(IF(OR(AND(R14<>"",YEAR(R14)<YEAR($M$9)),AND(P14<>"",YEAR(P14)<YEAR($M$9))),0,IF(YEAR(F14)>YEAR($M$9),0,IF(OR((IF(YEAR(F14)<YEAR($M$9),1,IF(MONTH(F14)=12,99,MONTH(F14)+1))>12),(IF(YEAR(F14)<YEAR($M$9),1,IF(MONTH(F14)=12,99,MONTH(F14)+1))>MIN(MONTH($M$9),IF(AND(R14<>"",YEAR(R14)=YEAR($M$9)),MONTH(R14),99),IF(AND(P14<>"",YEAR(P14)=YEAR($M$9)),MONTH(P14),99)))),0,MIN(MONTH($M$9),IF(AND(R14<>"",YEAR(R14)=YEAR($M$9)),MONTH(R14),99),IF(AND(P14<>"",YEAR(P14)=YEAR($M$9)),MONTH(P14),99))-IF(YEAR(F14)<YEAR($M$9),1,IF(MONTH(F14)=12,99,MONTH(F14)+1))+1))),0) -> 12 | T14: =(J14*(1-I14))/H14*S14 -> 353.9825 | U14: =T14-Q14 -> 0.0025
B15: 机器设备 | C15: 固定资产-机械设备 | D15: 000010000004 | E15: 定转子切割机 | F15: 44561 | G15: 12 | H15: =G15*12 -> 144 | I15: 0 | J15: 33628.32 | K15: 11209.44 | L15: 0 | M15: =J15-K15-L15 -> 22418.88 | N15: =IF(ROUND(J15*(1-I15),0)=ROUND(K15,0),"是","否") -> 否 | O15: =IFERROR(YEAR(EOMONTH(F15,H15)),"") -> 2033 | P15: =IFERROR(EOMONTH(F15,H15),"") -> 48944 | Q15: 2802.36 | S15: =IFERROR(IF(OR(AND(R15<>"",YEAR(R15)<YEAR($M$9)),AND(P15<>"",YEAR(P15)<YEAR($M$9))),0,IF(YEAR(F15)>YEAR($M$9),0,IF(OR((IF(YEAR(F15)<YEAR($M$9),1,IF(MONTH(F15)=12,99,MONTH(F15)+1))>12),(IF(YEAR(F15)<YEAR($M$9),1,IF(MONTH(F15)=12,99,MONTH(F15)+1))>MIN(MONTH($M$9),IF(AND(R15<>"",YEAR(R15)=YEAR($M$9)),MONTH(R15),99),IF(AND(P15<>"",YEAR(P15)=YEAR($M$9)),MONTH(P15),99)))),0,MIN(MONTH($M$9),IF(AND(R15<>"",YEAR(R15)=YEAR($M$9)),MONTH(R15),99),IF(AND(P15<>"",YEAR(P15)=YEAR($M$9)),MONTH(P15),99))-IF(YEAR(F15)<YEAR($M$9),1,IF(MONTH(F15)=12,99,MONTH(F15)+1))+1))),0) -> 12 | T15: =(J15*(1-I15))/H15*S15 -> 2802.36 | U15: =T15-Q15 -> 0
B16: 机器设备 | C16: 固定资产-机械设备 | D16: 000010000005 | E16: 定子上料机器人 | F16: 45272 | G16: 12 | H16: =G16*12 -> 144 | I16: 0 | J16: 171681.41 | K16: 28613.56 | L16: 0 | M16: =J16-K16-L16 -> 143067.85 | N16: =IF(ROUND(J16*(1-I16),0)=ROUND(K16,0),"是","否") -> 否 | O16: =IFERROR(YEAR(EOMONTH(F16,H16)),"") -> 2035 | P16: =IFERROR(EOMONTH(F16,H16),"") -> 49674 | Q16: 14306.78 | S16: =IFERROR(IF(OR(AND(R16<>"",YEAR(R16)<YEAR($M$9)),AND(P16<>"",YEAR(P16)<YEAR($M$9))),0,IF(YEAR(F16)>YEAR($M$9),0,IF(OR((IF(YEAR(F16)<YEAR($M$9),1,IF(MONTH(F16)=12,99,MONTH(F16)+1))>12),(IF(YEAR(F16)<YEAR($M$9),1,IF(MONTH(F16)=12,99,MONTH(F16)+1))>MIN(MONTH($M$9),IF(AND(R16<>"",YEAR(R16)=YEAR($M$9)),MONTH(R16),99),IF(AND(P16<>"",YEAR(P16)=YEAR($M$9)),MONTH(P16),99)))),0,MIN(MONTH($M$9),IF(AND(R16<>"",YEAR(R16)=YEAR($M$9)),MONTH(R16),99),IF(AND(P16<>"",YEAR(P16)=YEAR($M$9)),MONTH(P16),99))-IF(YEAR(F16)<YEAR($M$9),1,IF(MONTH(F16)=12,99,MONTH(F16)+1))+1))),0) -> 12 | T16: =(J16*(1-I16))/H16*S16 -> 14306.784 | U16: =T16-Q16 -> 0.0041666667
B17: 机器设备 | C17: 固定资产-机械设备 | D17: 000010000006 | E17: 定子缓存设备 | F17: 45272 | G17: 12 | H17: =G17*12 -> 144 | I17: 0 | J17: 137168.14 | K17: 20017.63 | L17: 116592.95 | M17: =J17-K17-L17 -> 557.56 | N17: =IF(ROUND(J17*(1-I17),0)=ROUND(K17,0),"是","否") -> 否 | O17: =IFERROR(YEAR(EOMONTH(F17,H17)),"") -> 2035 | P17: =IFERROR(EOMONTH(F17,H17),"") -> 49674 | Q17: 8586.95 | S17: =IFERROR(IF(OR(AND(R17<>"",YEAR(R17)<YEAR($M$9)),AND(P17<>"",YEAR(P17)<YEAR($M$9))),0,IF(YEAR(F17)>YEAR($M$9),0,IF(OR((IF(YEAR(F17)<YEAR($M$9),1,IF(MONTH(F17)=12,99,MONTH(F17)+1))>12),(IF(YEAR(F17)<YEAR($M$9),1,IF(MONTH(F17)=12,99,MONTH(F17)+1))>MIN(MONTH($M$9),IF(AND(R17<>"",YEAR(R17)=YEAR($M$9)),MONTH(R17),99),IF(AND(P17<>"",YEAR(P17)=YEAR($M$9)),MONTH(P17),99)))),0,MIN(MONTH($M$9),IF(AND(R17<>"",YEAR(R17)=YEAR($M$9)),MONTH(R17),99),IF(AND(P17<>"",YEAR(P17)=YEAR($M$9)),MONTH(P17),99))-IF(YEAR(F17)<YEAR($M$9),1,IF(MONTH(F17)=12,99,MONTH(F17)+1))+1))),0) -> 12 | T17: =J17*(1-I17)/H17*9+(J17-(J17*(1-I17)/H17)*V17-L17)/W17*3 -> 8515.8546 | U17: =T17-Q17 -> -71.095417 | V17: =DATEDIF(F17,$M$9,"M") -> 24 | W17: =H17-V17 -> 120
B18: 机器设备 | C18: 固定资产-机械设备 | D18: 000010000007 | E18: 充电桩老化房I/7927L23034/03 | F18: 45643 | G18: 12 | H18: =G18*12 -> 144 | I18: 0 | J18: 252293.58 | K18: 21024.47 | L18: 0 | M18: =J18-K18-L18 -> 231269.11 | N18: =IF(ROUND(J18*(1-I18),0)=ROUND(K18,0),"是","否") -> 否 | O18: =IFERROR(YEAR(EOMONTH(F18,H18)),"") -> 2036 | P18: =IFERROR(EOMONTH(F18,H18),"") -> 50040 | Q18: 21024.47 | S18: =IFERROR(IF(OR(AND(R18<>"",YEAR(R18)<YEAR($M$9)),AND(P18<>"",YEAR(P18)<YEAR($M$9))),0,IF(YEAR(F18)>YEAR($M$9),0,IF(OR((IF(YEAR(F18)<YEAR($M$9),1,IF(MONTH(F18)=12,99,MONTH(F18)+1))>12),(IF(YEAR(F18)<YEAR($M$9),1,IF(MONTH(F18)=12,99,MONTH(F18)+1))>MIN(MONTH($M$9),IF(AND(R18<>"",YEAR(R18)=YEAR($M$9)),MONTH(R18),99),IF(AND(P18<>"",YEAR(P18)=YEAR($M$9)),MONTH(P18),99)))),0,MIN(MONTH($M$9),IF(AND(R18<>"",YEAR(R18)=YEAR($M$9)),MONTH(R18),99),IF(AND(P18<>"",YEAR(P18)=YEAR($M$9)),MONTH(P18),99))-IF(YEAR(F18)<YEAR($M$9),1,IF(MONTH(F18)=12,99,MONTH(F18)+1))+1))),0) -> 12 | T18: =(J18*(1-I18))/H18*S18 -> 21024.465 | U18: =T18-Q18 -> -0.005
B19: 机器设备 | C19: 固定资产-机械设备 | D19: 000010000008 | E19: 控制器总成装配检测生产线(P33A 混线改造)工站 | F19: 45644 | G19: 12 | H19: =G19*12 -> 144 | I19: 0 | J19: 157522.12 | K19: 9861.17 | L19: 146954.98 | M19: =J19-K19-L19 -> 705.97 | N19: =IF(ROUND(J19*(1-I19),0)=ROUND(K19,0),"是","否") -> 否 | O19: =IFERROR(YEAR(EOMONTH(F19,H19)),"") -> 2036 | P19: =IFERROR(EOMONTH(F19,H19),"") -> 50040 | Q19: 9861.17 | S19: =IFERROR(IF(OR(AND(R19<>"",YEAR(R19)<YEAR($M$9)),AND(P19<>"",YEAR(P19)<YEAR($M$9))),0,IF(YEAR(F19)>YEAR($M$9),0,IF(OR((IF(YEAR(F19)<YEAR($M$9),1,IF(MONTH(F19)=12,99,MONTH(F19)+1))>12),(IF(YEAR(F19)<YEAR($M$9),1,IF(MONTH(F19)=12,99,MONTH(F19)+1))>MIN(MONTH($M$9),IF(AND(R19<>"",YEAR(R19)=YEAR($M$9)),MONTH(R19),99),IF(AND(P19<>"",YEAR(P19)=YEAR($M$9)),MONTH(P19),99)))),0,MIN(MONTH($M$9),IF(AND(R19<>"",YEAR(R19)=YEAR($M$9)),MONTH(R19),99),IF(AND(P19<>"",YEAR(P19)=YEAR($M$9)),MONTH(P19),99))-IF(YEAR(F19)<YEAR($M$9),1,IF(MONTH(F19)=12,99,MONTH(F19)+1))+1))),0) -> 12 | T19: =J19*(1-I19)/H19*9+(J19-(J19*(1-I19)/H19)*V19-L19)/W19*3 -> 9786.9574 | U19: =T19-Q19 -> -74.212576 | V19: =DATEDIF(F19,$M$9,"M") -> 12 | W19: =H19-V19 -> 132
B20: 机器设备 | C20: 固定资产-机械设备 | D20: 000010000009 | E20: 充电桩装配工位-装配工位1 | F20: 45645 | G20: 12 | H20: =G20*12 -> 144 | I20: 0 | J20: 53976.9 | K20: 4498.08 | L20: 0 | M20: =J20-K20-L20 -> 49478.82 | N20: =IF(ROUND(J20*(1-I20),0)=ROUND(K20,0),"是","否") -> 否 | O20: =IFERROR(YEAR(EOMONTH(F20,H20)),"") -> 2036 | P20: =IFERROR(EOMONTH(F20,H20),"") -> 50040 | Q20: 4498.08 | S20: =IFERROR(IF(OR(AND(R20<>"",YEAR(R20)<YEAR($M$9)),AND(P20<>"",YEAR(P20)<YEAR($M$9))),0,IF(YEAR(F20)>YEAR($M$9),0,IF(OR((IF(YEAR(F20)<YEAR($M$9),1,IF(MONTH(F20)=12,99,MONTH(F20)+1))>12),(IF(YEAR(F20)<YEAR($M$9),1,IF(MONTH(F20)=12,99,MONTH(F20)+1))>MIN(MONTH($M$9),IF(AND(R20<>"",YEAR(R20)=YEAR($M$9)),MONTH(R20),99),IF(AND(P20<>"",YEAR(P20)=YEAR($M$9)),MONTH(P20),99)))),0,MIN(MONTH($M$9),IF(AND(R20<>"",YEAR(R20)=YEAR($M$9)),MONTH(R20),99),IF(AND(P20<>"",YEAR(P20)=YEAR($M$9)),MONTH(P20),99))-IF(YEAR(F20)<YEAR($M$9),1,IF(MONTH(F20)=12,99,MONTH(F20)+1))+1))),0) -> 12 | T20: =(J20*(1-I20))/H20*S20 -> 4498.075 | U20: =T20-Q20 -> -0.005
B21: 机器设备 | C21: 固定资产-机械设备 | D21: 000010000010 | E21: 充电桩装配工位-装配工位2 | F21: 45645 | G21: 12 | H21: =G21*12 -> 144 | I21: 0 | J21: 53976.9 | K21: 4498.08 | L21: 0 | M21: =J21-K21-L21 -> 49478.82 | N21: =IF(ROUND(J21*(1-I21),0)=ROUND(K21,0),"是","否") -> 否 | O21: =IFERROR(YEAR(EOMONTH(F21,H21)),"") -> 2036 | P21: =IFERROR(EOMONTH(F21,H21),"") -> 50040 | Q21: 4498.08 | S21: =IFERROR(IF(OR(AND(R21<>"",YEAR(R21)<YEAR($M$9)),AND(P21<>"",YEAR(P21)<YEAR($M$9))),0,IF(YEAR(F21)>YEAR($M$9),0,IF(OR((IF(YEAR(F21)<YEAR($M$9),1,IF(MONTH(F21)=12,99,MONTH(F21)+1))>12),(IF(YEAR(F21)<YEAR($M$9),1,IF(MONTH(F21)=12,99,MONTH(F21)+1))>MIN(MONTH($M$9),IF(AND(R21<>"",YEAR(R21)=YEAR($M$9)),MONTH(R21),99),IF(AND(P21<>"",YEAR(P21)=YEAR($M$9)),MONTH(P21),99)))),0,MIN(MONTH($M$9),IF(AND(R21<>"",YEAR(R21)=YEAR($M$9)),MONTH(R21),99),IF(AND(P21<>"",YEAR(P21)=YEAR($M$9)),MONTH(P21),99))-IF(YEAR(F21)<YEAR($M$9),1,IF(MONTH(F21)=12,99,MONTH(F21)+1))+1))),0) -> 12 | T21: =(J21*(1-I21))/H21*S21 -> 4498.075 | U21: =T21-Q21 -> -0.005
B22: 机器设备 | C22: 固定资产-机械设备 | D22: 000010000011 | E22: 充电桩装配工位-下线检查工位 | F22: 45645 | G22: 12 | H22: =G22*12 -> 144 | I22: 0 | J22: 53993.1 | K22: 4499.43 | L22: 0 | M22: =J22-K22-L22 -> 49493.67 | N22: =IF(ROUND(J22*(1-I22),0)=ROUND(K22,0),"是","否") -> 否 | O22: =IFERROR(YEAR(EOMONTH(F22,H22)),"") -> 2036 | P22: =IFERROR(EOMONTH(F22,H22),"") -> 50040 | Q22: 4499.43 | S22: =IFERROR(IF(OR(AND(R22<>"",YEAR(R22)<YEAR($M$9)),AND(P22<>"",YEAR(P22)<YEAR($M$9))),0,IF(YEAR(F22)>YEAR($M$9),0,IF(OR((IF(YEAR(F22)<YEAR($M$9),1,IF(MONTH(F22)=12,99,MONTH(F22)+1))>12),(IF(YEAR(F22)<YEAR($M$9),1,IF(MONTH(F22)=12,99,MONTH(F22)+1))>MIN(MONTH($M$9),IF(AND(R22<>"",YEAR(R22)=YEAR($M$9)),MONTH(R22),99),IF(AND(P22<>"",YEAR(P22)=YEAR($M$9)),MONTH(P22),99)))),0,MIN(MONTH($M$9),IF(AND(R22<>"",YEAR(R22)=YEAR($M$9)),MONTH(R22),99),IF(AND(P22<>"",YEAR(P22)=YEAR($M$9)),MONTH(P22),99))-IF(YEAR(F22)<YEAR($M$9),1,IF(MONTH(F22)=12,99,MONTH(F22)+1))+1))),0) -> 12 | T22: =(J22*(1-I22))/H22*S22 -> 4499.425 | U22: =T22-Q22 -> -0.005
B23: 机器设备 | C23: 固定资产-工业炉窑 | D23: 000060000000 | E23: 干燥机 | F23: 44561 | G23: 10 | H23: =G23*12 -> 120 | I23: 0 | J23: 3852019.2 | K23: 1445107.2 | L23: 2392512 | M23: =J23-K23-L23 -> 14400 | N23: =IF(ROUND(J23*(1-I23),0)=ROUND(K23,0),"是","否") -> 否 | O23: =IFERROR(YEAR(EOMONTH(F23,H23)),"") -> 2031 | P23: =IFERROR(EOMONTH(F23,H23),"") -> 48213 | Q23: 289501.44 | S23: =IFERROR(IF(OR(AND(R23<>"",YEAR(R23)<YEAR($M$9)),AND(P23<>"",YEAR(P23)<YEAR($M$9))),0,IF(YEAR(F23)>YEAR($M$9),0,IF(OR((IF(YEAR(F23)<YEAR($M$9),1,IF(MONTH(F23)=12,99,MONTH(F23)+1))>12),(IF(YEAR(F23)<YEAR($M$9),1,IF(MONTH(F23)=12,99,MONTH(F23)+1))>MIN(MONTH($M$9),IF(AND(R23<>"",YEAR(R23)=YEAR($M$9)),MONTH(R23),99),IF(AND(P23<>"",YEAR(P23)=YEAR($M$9)),MONTH(P23),99)))),0,MIN(MONTH($M$9),IF(AND(R23<>"",YEAR(R23)=YEAR($M$9)),MONTH(R23),99),IF(AND(P23<>"",YEAR(P23)=YEAR($M$9)),MONTH(P23),99))-IF(YEAR(F23)<YEAR($M$9),1,IF(MONTH(F23)=12,99,MONTH(F23)+1))+1))),0) -> 12 | T23: =J23*(1-I23)/H23*9+(J23-(J23*(1-I23)/H23)*V23-L23)/W23*3 -> 285513.92 | U23: =T23-Q23 -> -3987.5194 | V23: =DATEDIF(F23,$M$9,"M") -> 48 | W23: =H23-V23 -> 72
B24: 机器设备 | C24: 固定资产-工业炉窑 | D24: 000060000001 | E24: 滴漆机 | F24: 44561 | G24: 10 | H24: =G24*12 -> 120 | I24: 0 | J24: 15345836 | K24: 6138334.5 | L24: 0 | M24: =J24-K24-L24 -> 9207501.8 | N24: =IF(ROUND(J24*(1-I24),0)=ROUND(K24,0),"是","否") -> 否 | O24: =IFERROR(YEAR(EOMONTH(F24,H24)),"") -> 2031 | P24: =IFERROR(EOMONTH(F24,H24),"") -> 48213 | Q24: 1534583.6 | S24: =IFERROR(IF(OR(AND(R24<>"",YEAR(R24)<YEAR($M$9)),AND(P24<>"",YEAR(P24)<YEAR($M$9))),0,IF(YEAR(F24)>YEAR($M$9),0,IF(OR((IF(YEAR(F24)<YEAR($M$9),1,IF(MONTH(F24)=12,99,MONTH(F24)+1))>12),(IF(YEAR(F24)<YEAR($M$9),1,IF(MONTH(F24)=12,99,MONTH(F24)+1))>MIN(MONTH($M$9),IF(AND(R24<>"",YEAR(R24)=YEAR($M$9)),MONTH(R24),99),IF(AND(P24<>"",YEAR(P24)=YEAR($M$9)),MONTH(P24),99)))),0,MIN(MONTH($M$9),IF(AND(R24<>"",YEAR(R24)=YEAR($M$9)),MONTH(R24),99),IF(AND(P24<>"",YEAR(P24)=YEAR($M$9)),MONTH(P24),99))-IF(YEAR(F24)<YEAR($M$9),1,IF(MONTH(F24)=12,99,MONTH(F24)+1))+1))),0) -> 12 | T24: =(J24*(1-I24))/H24*S24 -> 1534583.6 | U24: =T24-Q24 -> -0.00099999993
B25: 机器设备 | C25: 固定资产-工业炉窑 | D25: 000060000002 | E25: 热套机 | F25: 44561 | G25: 10 | H25: =G25*12 -> 120 | I25: 0 | J25: 6609254 | K25: 2479263.4 | L25: 4110956 | M25: =J25-K25-L25 -> 19034.62 | N25: =IF(ROUND(J25*(1-I25),0)=ROUND(K25,0),"是","否") -> 否 | O25: =IFERROR(YEAR(EOMONTH(F25,H25)),"") -> 2031 | P25: =IFERROR(EOMONTH(F25,H25),"") -> 48213 | Q25: 496487.16 | S25: =IFERROR(IF(OR(AND(R25<>"",YEAR(R25)<YEAR($M$9)),AND(P25<>"",YEAR(P25)<YEAR($M$9))),0,IF(YEAR(F25)>YEAR($M$9),0,IF(OR((IF(YEAR(F25)<YEAR($M$9),1,IF(MONTH(F25)=12,99,MONTH(F25)+1))>12),(IF(YEAR(F25)<YEAR($M$9),1,IF(MONTH(F25)=12,99,MONTH(F25)+1))>MIN(MONTH($M$9),IF(AND(R25<>"",YEAR(R25)=YEAR($M$9)),MONTH(R25),99),IF(AND(P25<>"",YEAR(P25)=YEAR($M$9)),MONTH(P25),99)))),0,MIN(MONTH($M$9),IF(AND(R25<>"",YEAR(R25)=YEAR($M$9)),MONTH(R25),99),IF(AND(P25<>"",YEAR(P25)=YEAR($M$9)),MONTH(P25),99))-IF(YEAR(F25)<YEAR($M$9),1,IF(MONTH(F25)=12,99,MONTH(F25)+1))+1))),0) -> 12 | T25: =J25*(1-I25)/H25*9+(J25-(J25*(1-I25)/H25)*V25-L25)/W25*3 -> 489635.56 | U25: =T25-Q25 -> -6851.5959 | V25: =DATEDIF(F25,$M$9,"M") -> 48 | W25: =H25-V25 -> 72
B26: 机器设备 | C26: 固定资产-自动化控制及汽车生产专用设备 | D26: 000070000000 | E26: 水温传感器/AC连接器装配工站 | F26: 44561 | G26: 8 | H26: =G26*12 -> 96 | I26: 0 | J26: 450566.28 | K26: 211269.21 | L26: 238236.91 | M26: =J26-K26-L26 -> 1060.16 | N26: =IF(ROUND(J26*(1-I26),0)=ROUND(K26,0),"是","否") -> 否 | O26: =IFERROR(YEAR(EOMONTH(F26,H26)),"") -> 2029 | P26: =IFERROR(EOMONTH(F26,H26),"") -> 47483 | Q26: 42306.85 | S26: =IFERROR(IF(OR(AND(R26<>"",YEAR(R26)<YEAR($M$9)),AND(P26<>"",YEAR(P26)<YEAR($M$9))),0,IF(YEAR(F26)>YEAR($M$9),0,IF(OR((IF(YEAR(F26)<YEAR($M$9),1,IF(MONTH(F26)=12,99,MONTH(F26)+1))>12),(IF(YEAR(F26)<YEAR($M$9),1,IF(MONTH(F26)=12,99,MONTH(F26)+1))>MIN(MONTH($M$9),IF(AND(R26<>"",YEAR(R26)=YEAR($M$9)),MONTH(R26),99),IF(AND(P26<>"",YEAR(P26)=YEAR($M$9)),MONTH(P26),99)))),0,MIN(MONTH($M$9),IF(AND(R26<>"",YEAR(R26)=YEAR($M$9)),MONTH(R26),99),IF(AND(P26<>"",YEAR(P26)=YEAR($M$9)),MONTH(P26),99))-IF(YEAR(F26)<YEAR($M$9),1,IF(MONTH(F26)=12,99,MONTH(F26)+1))+1))),0) -> 12 | T26: =J26*(1-I26)/H26*9+(J26-(J26*(1-I26)/H26)*V26-L26)/W26*3 -> 41430.978 | U26: =T26-Q26 -> -875.87187 | V26: =DATEDIF(F26,$M$9,"M") -> 48 | W26: =H26-V26 -> 48
B27: 机器设备 | C27: 固定资产-自动化控制及汽车生产专用设备 | D27: 000070000001 | E27: PM模块搭载工站 | F27: 44561 | G27: 8 | H27: =G27*12 -> 96 | I27: 0 | J27: 335844.18 | K27: 157476.34 | L27: 177577.6 | M27: =J27-K27-L27 -> 790.24 | N27: =IF(ROUND(J27*(1-I27),0)=ROUND(K27,0),"是","否") -> 否 | O27: =IFERROR(YEAR(EOMONTH(F27,H27)),"") -> 2029 | P27: =IFERROR(EOMONTH(F27,H27),"") -> 47483 | Q27: 31534.78 | S27: =IFERROR(IF(OR(AND(R27<>"",YEAR(R27)<YEAR($M$9)),AND(P27<>"",YEAR(P27)<YEAR($M$9))),0,IF(YEAR(F27)>YEAR($M$9),0,IF(OR((IF(YEAR(F27)<YEAR($M$9),1,IF(MONTH(F27)=12,99,MONTH(F27)+1))>12),(IF(YEAR(F27)<YEAR($M$9),1,IF(MONTH(F27)=12,99,MONTH(F27)+1))>MIN(MONTH($M$9),IF(AND(R27<>"",YEAR(R27)=YEAR($M$9)),MONTH(R27),99),IF(AND(P27<>"",YEAR(P27)=YEAR($M$9)),MONTH(P27),99)))),0,MIN(MONTH($M$9),IF(AND(R27<>"",YEAR(R27)=YEAR($M$9)),MONTH(R27),99),IF(AND(P27<>"",YEAR(P27)=YEAR($M$9)),MONTH(P27),99))-IF(YEAR(F27)<YEAR($M$9),1,IF(MONTH(F27)=12,99,MONTH(F27)+1))+1))),0) -> 12 | T27: =J27*(1-I27)/H27*9+(J27-(J27*(1-I27)/H27)*V27-L27)/W27*3 -> 30881.923 | U27: =T27-Q27 -> -652.8575 | V27: =DATEDIF(F27,$M$9,"M") -> 48 | W27: =H27-V27 -> 48
B28: 机器设备 | C28: 固定资产-自动化控制及汽车生产专用设备 | D28: 000070000002 | E28: PM模块拧紧（自动）工站 | F28: 44561 | G28: 8 | H28: =G28*12 -> 96 | I28: 0 | J28: 787491.08 | K28: 369252.26 | L28: 416385.91 | M28: =J28-K28-L28 -> 1852.91 | N28: =IF(ROUND(J28*(1-I28),0)=ROUND(K28,0),"是","否") -> 否 | O28: =IFERROR(YEAR(EOMONTH(F28,H28)),"") -> 2029 | P28: =IFERROR(EOMONTH(F28,H28),"") -> 47483 | Q28: 73943.1 | S28: =IFERROR(IF(OR(AND(R28<>"",YEAR(R28)<YEAR($M$9)),AND(P28<>"",YEAR(P28)<YEAR($M$9))),0,IF(YEAR(F28)>YEAR($M$9),0,IF(OR((IF(YEAR(F28)<YEAR($M$9),1,IF(MONTH(F28)=12,99,MONTH(F28)+1))>12),(IF(YEAR(F28)<YEAR($M$9),1,IF(MONTH(F28)=12,99,MONTH(F28)+1))>MIN(MONTH($M$9),IF(AND(R28<>"",YEAR(R28)=YEAR($M$9)),MONTH(R28),99),IF(AND(P28<>"",YEAR(P28)=YEAR($M$9)),MONTH(P28),99)))),0,MIN(MONTH($M$9),IF(AND(R28<>"",YEAR(R28)=YEAR($M$9)),MONTH(R28),99),IF(AND(P28<>"",YEAR(P28)=YEAR($M$9)),MONTH(P28),99))-IF(YEAR(F28)<YEAR($M$9),1,IF(MONTH(F28)=12,99,MONTH(F28)+1))+1))),0) -> 12 | T28: =J28*(1-I28)/H28*9+(J28-(J28*(1-I28)/H28)*V28-L28)/W28*3 -> 72412.266 | U28: =T28-Q28 -> -1530.8344 | V28: =DATEDIF(F28,$M$9,"M") -> 48 | W28: =H28-V28 -> 48
B29: 机器设备 | C29: 固定资产-自动化控制及汽车生产专用设备 | D29: 000070000003 | E29: 水道气密性氦检（自动）工站 | F29: 44561 | G29: 8 | H29: =G29*12 -> 96 | I29: 0 | J29: 802846.83 | K29: 376452.52 | L29: 424505.25 | M29: =J29-K29-L29 -> 1889.06 | N29: =IF(ROUND(J29*(1-I29),0)=ROUND(K29,0),"是","否") -> 否 | O29: =IFERROR(YEAR(EOMONTH(F29,H29)),"") -> 2029 | P29: =IFERROR(EOMONTH(F29,H29),"") -> 47483 | Q29: 75384.96 | S29: =IFERROR(IF(OR(AND(R29<>"",YEAR(R29)<YEAR($M$9)),AND(P29<>"",YEAR(P29)<YEAR($M$9))),0,IF(YEAR(F29)>YEAR($M$9),0,IF(OR((IF(YEAR(F29)<YEAR($M$9),1,IF(MONTH(F29)=12,99,MONTH(F29)+1))>12),(IF(YEAR(F29)<YEAR($M$9),1,IF(MONTH(F29)=12,99,MONTH(F29)+1))>MIN(MONTH($M$9),IF(AND(R29<>"",YEAR(R29)=YEAR($M$9)),MONTH(R29),99),IF(AND(P29<>"",YEAR(P29)=YEAR($M$9)),MONTH(P29),99)))),0,MIN(MONTH($M$9),IF(AND(R29<>"",YEAR(R29)=YEAR($M$9)),MONTH(R29),99),IF(AND(P29<>"",YEAR(P29)=YEAR($M$9)),MONTH(P29),99))-IF(YEAR(F29)<YEAR($M$9),1,IF(MONTH(F29)=12,99,MONTH(F29)+1))+1))),0) -> 12 | T29: =J29*(1-I29)/H29*9+(J29-(J29*(1-I29)/H29)*V29-L29)/W29*3 -> 73824.276 | U29: =T29-Q29 -> -1560.6844 | V29: =DATEDIF(F29,$M$9,"M") -> 48 | W29: =H29-V29 -> 48
B30: 机器设备 | C30: 固定资产-自动化控制及汽车生产专用设备 | D30: 000070000004 | E30: UVW分总成装配工站 | F30: 44561 | G30: 8 | H30: =G30*12 -> 96 | I30: 0 | J30: 464169.84 | K30: 217647.87 | L30: 245429.82 | M30: =J30-K30-L30 -> 1092.15 | N30: =IF(ROUND(J30*(1-I30),0)=ROUND(K30,0),"是","否") -> 否 | O30: =IFERROR(YEAR(EOMONTH(F30,H30)),"") -> 2029 | P30: =IFERROR(EOMONTH(F30,H30),"") -> 47483 | Q30: 43584.18 | S30: =IFERROR(IF(OR(AND(R30<>"",YEAR(R30)<YEAR($M$9)),AND(P30<>"",YEAR(P30)<YEAR($M$9))),0,IF(YEAR(F30)>YEAR($M$9),0,IF(OR((IF(YEAR(F30)<YEAR($M$9),1,IF(MONTH(F30)=12,99,MONTH(F30)+1))>12),(IF(YEAR(F30)<YEAR($M$9),1,IF(MONTH(F30)=12,99,MONTH(F30)+1))>MIN(MONTH($M$9),IF(AND(R30<>"",YEAR(R30)=YEAR($M$9)),MONTH(R30),99),IF(AND(P30<>"",YEAR(P30)=YEAR($M$9)),MONTH(P30),99)))),0,MIN(MONTH($M$9),IF(AND(R30<>"",YEAR(R30)=YEAR($M$9)),MONTH(R30),99),IF(AND(P30<>"",YEAR(P30)=YEAR($M$9)),MONTH(P30),99))-IF(YEAR(F30)<YEAR($M$9),1,IF(MONTH(F30)=12,99,MONTH(F30)+1))+1))),0) -> 12 | T30: =J30*(1-I30)/H30*9+(J30-(J30*(1-I30)/H30)*V30-L30)/W30*3 -> 42681.866 | U30: =T30-Q30 -> -902.31375 | V30: =DATEDIF(F30,$M$9,"M") -> 48 | W30: =H30-V30 -> 48
B31: 机器设备 | C31: 固定资产-自动化控制及汽车生产专用设备 | D31: 000070000005 | E31: UVW装配工站 | F31: 44561 | G31: 8 | H31: =G31*12 -> 96 | I31: 0 | J31: 349089.31 | K31: 163686.95 | L31: 184580.96 | M31: =J31-K31-L31 -> 821.4 | N31: =IF(ROUND(J31*(1-I31),0)=ROUND(K31,0),"是","否") -> 否 | O31: =IFERROR(YEAR(EOMONTH(F31,H31)),"") -> 2029 | P31: =IFERROR(EOMONTH(F31,H31),"") -> 47483 | Q31: 32778.46 | S31: =IFERROR(IF(OR(AND(R31<>"",YEAR(R31)<YEAR($M$9)),AND(P31<>"",YEAR(P31)<YEAR($M$9))),0,IF(YEAR(F31)>YEAR($M$9),0,IF(OR((IF(YEAR(F31)<YEAR($M$9),1,IF(MONTH(F31)=12,99,MONTH(F31)+1))>12),(IF(YEAR(F31)<YEAR($M$9),1,IF(MONTH(F31)=12,99,MONTH(F31)+1))>MIN(MONTH($M$9),IF(AND(R31<>"",YEAR(R31)=YEAR($M$9)),MONTH(R31),99),IF(AND(P31<>"",YEAR(P31)=YEAR($M$9)),MONTH(P31),99)))),0,MIN(MONTH($M$9),IF(AND(R31<>"",YEAR(R31)=YEAR($M$9)),MONTH(R31),99),IF(AND(P31<>"",YEAR(P31)=YEAR($M$9)),MONTH(P31),99))-IF(YEAR(F31)<YEAR($M$9),1,IF(MONTH(F31)=12,99,MONTH(F31)+1))+1))),0) -> 12 | T31: =J31*(1-I31)/H31*9+(J31-(J31*(1-I31)/H31)*V31-L31)/W31*3 -> 32099.854 | U31: =T31-Q31 -> -678.60625 | V31: =DATEDIF(F31,$M$9,"M") -> 48 | W31: =H31-V31 -> 48
B32: 机器设备 | C32: 固定资产-自动化控制及汽车生产专用设备 | D32: 000070000006 | E32: 电流传感器&线束装配工站 | F32: 44561 | G32: 8 | H32: =G32*12 -> 96 | I32: 0 | J32: 411165.42 | K32: 192794.27 | L32: 217403.68 | M32: =J32-K32-L32 -> 967.47 | N32: =IF(ROUND(J32*(1-I32),0)=ROUND(K32,0),"是","否") -> 否 | O32: =IFERROR(YEAR(EOMONTH(F32,H32)),"") -> 2029 | P32: =IFERROR(EOMONTH(F32,H32),"") -> 47483 | Q32: 38607.23 | S32: =IFERROR(IF(OR(AND(R32<>"",YEAR(R32)<YEAR($M$9)),AND(P32<>"",YEAR(P32)<YEAR($M$9))),0,IF(YEAR(F32)>YEAR($M$9),0,IF(OR((IF(YEAR(F32)<YEAR($M$9),1,IF(MONTH(F32)=12,99,MONTH(F32)+1))>12),(IF(YEAR(F32)<YEAR($M$9),1,IF(MONTH(F32)=12,99,MONTH(F32)+1))>MIN(MONTH($M$9),IF(AND(R32<>"",YEAR(R32)=YEAR($M$9)),MONTH(R32),99),IF(AND(P32<>"",YEAR(P32)=YEAR($M$9)),MONTH(P32),99)))),0,MIN(MONTH($M$9),IF(AND(R32<>"",YEAR(R32)=YEAR($M$9)),MONTH(R32),99),IF(AND(P32<>"",YEAR(P32)=YEAR($M$9)),MONTH(P32),99))-IF(YEAR(F32)<YEAR($M$9),1,IF(MONTH(F32)=12,99,MONTH(F32)+1))+1))),0) -> 12 | T32: =J32*(1-I32)/H32*9+(J32-(J32*(1-I32)/H32)*V32-L32)/W32*3 -> 37807.947 | U32: =T32-Q32 -> -799.2825 | V32: =DATEDIF(F32,$M$9,"M") -> 48 | W32: =H32-V32 -> 48
B33: 机器设备 | C33: 固定资产-自动化控制及汽车生产专用设备 | D33: 000070000007 | E33: 电容装配工站 | F33: 44561 | G33: 8 | H33: =G33*12 -> 96 | I33: 0 | J33: 446106.12 | K33: 209177.85 | L33: 235878.6 | M33: =J33-K33-L33 -> 1049.67 | N33: =IF(ROUND(J33*(1-I33),0)=ROUND(K33,0),"是","否") -> 否 | O33: =IFERROR(YEAR(EOMONTH(F33,H33)),"") -> 2029 | P33: =IFERROR(EOMONTH(F33,H33),"") -> 47483 | Q33: 41888.05 | S33: =IFERROR(IF(OR(AND(R33<>"",YEAR(R33)<YEAR($M$9)),AND(P33<>"",YEAR(P33)<YEAR($M$9))),0,IF(YEAR(F33)>YEAR($M$9),0,IF(OR((IF(YEAR(F33)<YEAR($M$9),1,IF(MONTH(F33)=12,99,MONTH(F33)+1))>12),(IF(YEAR(F33)<YEAR($M$9),1,IF(MONTH(F33)=12,99,MONTH(F33)+1))>MIN(MONTH($M$9),IF(AND(R33<>"",YEAR(R33)=YEAR($M$9)),MONTH(R33),99),IF(AND(P33<>"",YEAR(P33)=YEAR($M$9)),MONTH(P33),99)))),0,MIN(MONTH($M$9),IF(AND(R33<>"",YEAR(R33)=YEAR($M$9)),MONTH(R33),99),IF(AND(P33<>"",YEAR(P33)=YEAR($M$9)),MONTH(P33),99))-IF(YEAR(F33)<YEAR($M$9),1,IF(MONTH(F33)=12,99,MONTH(F33)+1))+1))),0) -> 12 | T33: =J33*(1-I33)/H33*9+(J33-(J33*(1-I33)/H33)*V33-L33)/W33*3 -> 41020.853 | U33: =T33-Q33 -> -867.1975 | V33: =DATEDIF(F33,$M$9,"M") -> 48 | W33: =H33-V33 -> 48
B34: 机器设备 | C34: 固定资产-自动化控制及汽车生产专用设备 | D34: 000070000008 | E34: 放电电阻装配/线束装配工站 | F34: 44561 | G34: 8 | H34: =G34*12 -> 96 | I34: 0 | J34: 399067.19 | K34: 187121.44 | L34: 211006.77 | M34: =J34-K34-L34 -> 938.98 | N34: =IF(ROUND(J34*(1-I34),0)=ROUND(K34,0),"是","否") -> 否 | O34: =IFERROR(YEAR(EOMONTH(F34,H34)),"") -> 2029 | P34: =IFERROR(EOMONTH(F34,H34),"") -> 47483 | Q34: 37471.24 | S34: =IFERROR(IF(OR(AND(R34<>"",YEAR(R34)<YEAR($M$9)),AND(P34<>"",YEAR(P34)<YEAR($M$9))),0,IF(YEAR(F34)>YEAR($M$9),0,IF(OR((IF(YEAR(F34)<YEAR($M$9),1,IF(MONTH(F34)=12,99,MONTH(F34)+1))>12),(IF(YEAR(F34)<YEAR($M$9),1,IF(MONTH(F34)=12,99,MONTH(F34)+1))>MIN(MONTH($M$9),IF(AND(R34<>"",YEAR(R34)=YEAR($M$9)),MONTH(R34),99),IF(AND(P34<>"",YEAR(P34)=YEAR($M$9)),MONTH(P34),99)))),0,MIN(MONTH($M$9),IF(AND(R34<>"",YEAR(R34)=YEAR($M$9)),MONTH(R34),99),IF(AND(P34<>"",YEAR(P34)=YEAR($M$9)),MONTH(P34),99))-IF(YEAR(F34)<YEAR($M$9),1,IF(MONTH(F34)=12,99,MONTH(F34)+1))+1))),0) -> 12 | T34: =J34*(1-I34)/H34*9+(J34-(J34*(1-I34)/H34)*V34-L34)/W34*3 -> 36695.476 | U34: =T34-Q34 -> -775.76437 | V34: =DATEDIF(F34,$M$9,"M") -> 48 | W34: =H34-V34 -> 48
B35: 机器设备 | C35: 固定资产-自动化控制及汽车生产专用设备 | D35: 000070000009 | E35: 线束装配+AOI检查工站 | F35: 44561 | G35: 8 | H35: =G35*12 -> 96 | I35: 0 | J35: 309233.56 | K35: 144998.71 | L35: 163507.26 | M35: =J35-K35-L35 -> 727.59 | N35: =IF(ROUND(J35*(1-I35),0)=ROUND(K35,0),"是","否") -> 否 | O35: =IFERROR(YEAR(EOMONTH(F35,H35)),"") -> 2029 | P35: =IFERROR(EOMONTH(F35,H35),"") -> 47483 | Q35: 29036.12 | S35: =IFERROR(IF(OR(AND(R35<>"",YEAR(R35)<YEAR($M$9)),AND(P35<>"",YEAR(P35)<YEAR($M$9))),0,IF(YEAR(F35)>YEAR($M$9),0,IF(OR((IF(YEAR(F35)<YEAR($M$9),1,IF(MONTH(F35)=12,99,MONTH(F35)+1))>12),(IF(YEAR(F35)<YEAR($M$9),1,IF(MONTH(F35)=12,99,MONTH(F35)+1))>MIN(MONTH($M$9),IF(AND(R35<>"",YEAR(R35)=YEAR($M$9)),MONTH(R35),99),IF(AND(P35<>"",YEAR(P35)=YEAR($M$9)),MONTH(P35),99)))),0,MIN(MONTH($M$9),IF(AND(R35<>"",YEAR(R35)=YEAR($M$9)),MONTH(R35),99),IF(AND(P35<>"",YEAR(P35)=YEAR($M$9)),MONTH(P35),99))-IF(YEAR(F35)<YEAR($M$9),1,IF(MONTH(F35)=12,99,MONTH(F35)+1))+1))),0) -> 12 | T35: =J35*(1-I35)/H35*9+(J35-(J35*(1-I35)/H35)*V35-L35)/W35*3 -> 28434.991 | U35: =T35-Q35 -> -601.12875 | V35: =DATEDIF(F35,$M$9,"M") -> 48 | W35: =H35-V35 -> 48
B36: 机器设备 | C36: 固定资产-自动化控制及汽车生产专用设备 | D36: 000070000010 | E36: FIPG涂胶及检测（自动）工站 | F36: 44561 | G36: 8 | H36: =G36*12 -> 96 | I36: 0 | J36: 1215741.5 | K36: 570057.62 | L36: 642823.35 | M36: =J36-K36-L36 -> 2860.55 | N36: =IF(ROUND(J36*(1-I36),0)=ROUND(K36,0),"是","否") -> 否 | O36: =IFERROR(YEAR(EOMONTH(F36,H36)),"") -> 2029 | P36: =IFERROR(EOMONTH(F36,H36),"") -> 47483 | Q36: 114154.55 | S36: =IFERROR(IF(OR(AND(R36<>"",YEAR(R36)<YEAR($M$9)),AND(P36<>"",YEAR(P36)<YEAR($M$9))),0,IF(YEAR(F36)>YEAR($M$9),0,IF(OR((IF(YEAR(F36)<YEAR($M$9),1,IF(MONTH(F36)=12,99,MONTH(F36)+1))>12),(IF(YEAR(F36)<YEAR($M$9),1,IF(MONTH(F36)=12,99,MONTH(F36)+1))>MIN(MONTH($M$9),IF(AND(R36<>"",YEAR(R36)=YEAR($M$9)),MONTH(R36),99),IF(AND(P36<>"",YEAR(P36)=YEAR($M$9)),MONTH(P36),99)))),0,MIN(MONTH($M$9),IF(AND(R36<>"",YEAR(R36)=YEAR($M$9)),MONTH(R36),99),IF(AND(P36<>"",YEAR(P36)=YEAR($M$9)),MONTH(P36),99))-IF(YEAR(F36)<YEAR($M$9),1,IF(MONTH(F36)=12,99,MONTH(F36)+1))+1))),0) -> 12 | T36: =J36*(1-I36)/H36*9+(J36-(J36*(1-I36)/H36)*V36-L36)/W36*3 -> 111791.23 | U36: =T36-Q36 -> -2363.3194 | V36: =DATEDIF(F36,$M$9,"M") -> 48 | W36: =H36-V36 -> 48
... B53: 机器设备 | C53: 固定资产-自动化控制及汽车生产专用设备 | D53: 000070000027 | E53: 预插绝缘机 | F53: 44561 | G53: 8 | H53: =G53*12 -> 96 | I53: 0 | J53: 1892220 | K53: 888372.23 | L53: 981541.87 | M53: =J53-K53-L53 -> 22305.86 | N53: =IF(ROUND(J53*(1-I53),0)=ROUND(K53,0),"是","否") -> 否 | O53: =IFERROR(YEAR(EOMONTH(F53,H53)),"") -> 2029 | P53: =IFERROR(EOMONTH(F53,H53),"") -> 47483 | Q53: 178789.74 | S53: =IFERROR(IF(OR(AND(R53<>"",YEAR(R53)<YEAR($M$9)),AND(P53<>"",YEAR(P53)<YEAR($M$9))),0,IF(YEAR(F53)>YEAR($M$9),0,IF(OR((IF(YEAR(F53)<YEAR($M$9),1,IF(MONTH(F53)=12,99,MONTH(F53)+1))>12),(IF(YEAR(F53)<YEAR($M$9),1,IF(MONTH(F53)=12,99,MONTH(F53)+1))>MIN(MONTH($M$9),IF(AND(R53<>"",YEAR(R53)=YEAR($M$9)),MONTH(R53),99),IF(AND(P53<>"",YEAR(P53)=YEAR($M$9)),MONTH(P53),99)))),0,MIN(MONTH($M$9),IF(AND(R53<>"",YEAR(R53)=YEAR($M$9)),MONTH(R53),99),IF(AND(P53<>"",YEAR(P53)=YEAR($M$9)),MONTH(P53),99))-IF(YEAR(F53)<YEAR($M$9),1,IF(MONTH(F53)=12,99,MONTH(F53)+1))+1))),0) -> 12 | T53: =J53*(1-I53)/H53*9+(J53-(J53*(1-I53)/H53)*V53-L53)/W53*3 -> 175181.13 | U53: =T53-Q53 -> -3608.6119 | V53: =DATEDIF(F53,$M$9,"M") -> 48 | W53: =H53-V53 -> 48
B54: 机器设备 | C54: 固定资产-自动化控制及汽车生产专用设备 | D54: 000070000028 | E54: 恒温箱 | F54: 44561 | G54: 8 | H54: =G54*12 -> 96 | I54: 0 | J54: 88000 | K54: 44000 | L54: 0 | M54: =J54-K54-L54 -> 44000 | N54: =IF(ROUND(J54*(1-I54),0)=ROUND(K54,0),"是","否") -> 否 | O54: =IFERROR(YEAR(EOMONTH(F54,H54)),"") -> 2029 | P54: =IFERROR(EOMONTH(F54,H54),"") -> 47483 | Q54: 11000 | S54: =IFERROR(IF(OR(AND(R54<>"",YEAR(R54)<YEAR($M$9)),AND(P54<>"",YEAR(P54)<YEAR($M$9))),0,IF(YEAR(F54)>YEAR($M$9),0,IF(OR((IF(YEAR(F54)<YEAR($M$9),1,IF(MONTH(F54)=12,99,MONTH(F54)+1))>12),(IF(YEAR(F54)<YEAR($M$9),1,IF(MONTH(F54)=12,99,MONTH(F54)+1))>MIN(MONTH($M$9),IF(AND(R54<>"",YEAR(R54)=YEAR($M$9)),MONTH(R54),99),IF(AND(P54<>"",YEAR(P54)=YEAR($M$9)),MONTH(P54),99)))),0,MIN(MONTH($M$9),IF(AND(R54<>"",YEAR(R54)=YEAR($M$9)),MONTH(R54),99),IF(AND(P54<>"",YEAR(P54)=YEAR($M$9)),MONTH(P54),99))-IF(YEAR(F54)<YEAR($M$9),1,IF(MONTH(F54)=12,99,MONTH(F54)+1))+1))),0) -> 12 | T54: =(J54*(1-I54))/H54*S54 -> 11000 | U54: =T54-Q54 -> 0
B55: 机器设备 | C55: 固定资产-自动化控制及汽车生产专用设备 | D55: 000070000029 | E55: ROM写入设备 | F55: 44579 | G55: 8 | H55: =G55*12 -> 96 | I55: 0 | J55: 499643.74 | K55: 229076.95 | L55: 269365.23 | M55: =J55-K55-L55 -> 1201.56 | N55: =IF(ROUND(J55*(1-I55),0)=ROUND(K55,0),"是","否") -> 否 | O55: =IFERROR(YEAR(EOMONTH(F55,H55)),"") -> 2030 | P55: =IFERROR(EOMONTH(F55,H55),"") -> 47514 | Q55: 46915.16 | S55: =IFERROR(IF(OR(AND(R55<>"",YEAR(R55)<YEAR($M$9)),AND(P55<>"",YEAR(P55)<YEAR($M$9))),0,IF(YEAR(F55)>YEAR($M$9),0,IF(OR((IF(YEAR(F55)<YEAR($M$9),1,IF(MONTH(F55)=12,99,MONTH(F55)+1))>12),(IF(YEAR(F55)<YEAR($M$9),1,IF(MONTH(F55)=12,99,MONTH(F55)+1))>MIN(MONTH($M$9),IF(AND(R55<>"",YEAR(R55)=YEAR($M$9)),MONTH(R55),99),IF(AND(P55<>"",YEAR(P55)=YEAR($M$9)),MONTH(P55),99)))),0,MIN(MONTH($M$9),IF(AND(R55<>"",YEAR(R55)=YEAR($M$9)),MONTH(R55),99),IF(AND(P55<>"",YEAR(P55)=YEAR($M$9)),MONTH(P55),99))-IF(YEAR(F55)<YEAR($M$9),1,IF(MONTH(F55)=12,99,MONTH(F55)+1))+1))),0) -> 12 | T55: =J55*(1-I55)/H55*9+(J55-(J55*(1-I55)/H55)*V55-L55)/W55*3 -> 45963.719 | U55: =T55-Q55 -> -951.44128 | V55: =DATEDIF(F55,$M$9,"M") -> 47 | W55: =H55-V55 -> 49
B56: 机器设备 | C56: 固定资产-自动化控制及汽车生产专用设备 | D56: 000070000030 | E56: 控制器总成特性检测设备 | F56: 44579 | G56: 8 | H56: =G56*12 -> 96 | I56: 0 | J56: 8048608.9 | K56: 3690130.8 | L56: 4339122.4 | M56: =J56-K56-L56 -> 19355.69 | N56: =IF(ROUND(J56*(1-I56),0)=ROUND(K56,0),"是","否") -> 否 | O56: =IFERROR(YEAR(EOMONTH(F56,H56)),"") -> 2030 | P56: =IFERROR(EOMONTH(F56,H56),"") -> 47514 | Q56: 755742.13 | S56: =IFERROR(IF(OR(AND(R56<>"",YEAR(R56)<YEAR($M$9)),AND(P56<>"",YEAR(P56)<YEAR($M$9))),0,IF(YEAR(F56)>YEAR($M$9),0,IF(OR((IF(YEAR(F56)<YEAR($M$9),1,IF(MONTH(F56)=12,99,MONTH(F56)+1))>12),(IF(YEAR(F56)<YEAR($M$9),1,IF(MONTH(F56)=12,99,MONTH(F56)+1))>MIN(MONTH($M$9),IF(AND(R56<>"",YEAR(R56)=YEAR($M$9)),MONTH(R56),99),IF(AND(P56<>"",YEAR(P56)=YEAR($M$9)),MONTH(P56),99)))),0,MIN(MONTH($M$9),IF(AND(R56<>"",YEAR(R56)=YEAR($M$9)),MONTH(R56),99),IF(AND(P56<>"",YEAR(P56)=YEAR($M$9)),MONTH(P56),99))-IF(YEAR(F56)<YEAR($M$9),1,IF(MONTH(F56)=12,99,MONTH(F56)+1))+1))),0) -> 12 | T56: =J56*(1-I56)/H56*9+(J56-(J56*(1-I56)/H56)*V56-L56)/W56*3 -> 740415.56 | U56: =T56-Q56 -> -15326.571 | V56: =DATEDIF(F56,$M$9,"M") -> 47 | W56: =H56-V56 -> 49
B57: 机器设备 | C57: 固定资产-自动化控制及汽车生产专用设备 | D57: 000070000031 | E57: 控制器总成特性检测设备 | F57: 44579 | G57: 8 | H57: =G57*12 -> 96 | I57: 0 | J57: 8048608.9 | K57: 3690130.8 | L57: 4339122.4 | M57: =J57-K57-L57 -> 19355.69 | N57: =IF(ROUND(J57*(1-I57),0)=ROUND(K57,0),"是","否") -> 否 | O57: =IFERROR(YEAR(EOMONTH(F57,H57)),"") -> 2030 | P57: =IFERROR(EOMONTH(F57,H57),"") -> 47514 | Q57: 755742.13 | S57: =IFERROR(IF(OR(AND(R57<>"",YEAR(R57)<YEAR($M$9)),AND(P57<>"",YEAR(P57)<YEAR($M$9))),0,IF(YEAR(F57)>YEAR($M$9),0,IF(OR((IF(YEAR(F57)<YEAR($M$9),1,IF(MONTH(F57)=12,99,MONTH(F57)+1))>12),(IF(YEAR(F57)<YEAR($M$9),1,IF(MONTH(F57)=12,99,MONTH(F57)+1))>MIN(MONTH($M$9),IF(AND(R57<>"",YEAR(R57)=YEAR($M$9)),MONTH(R57),99),IF(AND(P57<>"",YEAR(P57)=YEAR($M$9)),MONTH(P57),99)))),0,MIN(MONTH($M$9),IF(AND(R57<>"",YEAR(R57)=YEAR($M$9)),MONTH(R57),99),IF(AND(P57<>"",YEAR(P57)=YEAR($M$9)),MONTH(P57),99))-IF(YEAR(F57)<YEAR($M$9),1,IF(MONTH(F57)=12,99,MONTH(F57)+1))+1))),0) -> 12 | T57: =J57*(1-I57)/H57*9+(J57-(J57*(1-I57)/H57)*V57-L57)/W57*3 -> 740415.56 | U57: =T57-Q57 -> -15326.571 | V57: =DATEDIF(F57,$M$9,"M") -> 47 | W57: =H57-V57 -> 49
B58: 机器设备 | C58: 固定资产-自动化控制及汽车生产专用设备 | D58: 000070000032 | E58: DTC确认设备 | F58: 44579 | G58: 8 | H58: =G58*12 -> 96 | I58: 0 | J58: 499643.74 | K58: 229076.95 | L58: 269365.23 | M58: =J58-K58-L58 -> 1201.56 | N58: =IF(ROUND(J58*(1-I58),0)=ROUND(K58,0),"是","否") -> 否 | O58: =IFERROR(YEAR(EOMONTH(F58,H58)),"") -> 2030 | P58: =IFERROR(EOMONTH(F58,H58),"") -> 47514 | Q58: 46915.16 | S58: =IFERROR(IF(OR(AND(R58<>"",YEAR(R58)<YEAR($M$9)),AND(P58<>"",YEAR(P58)<YEAR($M$9))),0,IF(YEAR(F58)>YEAR($M$9),0,IF(OR((IF(YEAR(F58)<YEAR($M$9),1,IF(MONTH(F58)=12,99,MONTH(F58)+1))>12),(IF(YEAR(F58)<YEAR($M$9),1,IF(MONTH(F58)=12,99,MONTH(F58)+1))>MIN(MONTH($M$9),IF(AND(R58<>"",YEAR(R58)=YEAR($M$9)),MONTH(R58),99),IF(AND(P58<>"",YEAR(P58)=YEAR($M$9)),MONTH(P58),99)))),0,MIN(MONTH($M$9),IF(AND(R58<>"",YEAR(R58)=YEAR($M$9)),MONTH(R58),99),IF(AND(P58<>"",YEAR(P58)=YEAR($M$9)),MONTH(P58),99))-IF(YEAR(F58)<YEAR($M$9),1,IF(MONTH(F58)=12,99,MONTH(F58)+1))+1))),0) -> 12 | T58: =J58*(1-I58)/H58*9+(J58-(J58*(1-I58)/H58)*V58-L58)/W58*3 -> 45963.719 | U58: =T58-Q58 -> -951.44128 | V58: =DATEDIF(F58,$M$9,"M") -> 47 | W58: =H58-V58 -> 49
B59: 机器设备 | C59: 固定资产-自动化控制及汽车生产专用设备 | D59: 000070000033 | E59: 助力臂 | F59: 44579 | G59: 8 | H59: =G59*12 -> 96 | I59: 0 | J59: 43274.34 | K59: 21186.39 | L59: 0 | M59: =J59-K59-L59 -> 22087.95 | N59: =IF(ROUND(J59*(1-I59),0)=ROUND(K59,0),"是","否") -> 否 | O59: =IFERROR(YEAR(EOMONTH(F59,H59)),"") -> 2030 | P59: =IFERROR(EOMONTH(F59,H59),"") -> 47514 | Q59: 5409.29 | S59: =IFERROR(IF(OR(AND(R59<>"",YEAR(R59)<YEAR($M$9)),AND(P59<>"",YEAR(P59)<YEAR($M$9))),0,IF(YEAR(F59)>YEAR($M$9),0,IF(OR((IF(YEAR(F59)<YEAR($M$9),1,IF(MONTH(F59)=12,99,MONTH(F59)+1))>12),(IF(YEAR(F59)<YEAR($M$9),1,IF(MONTH(F59)=12,99,MONTH(F59)+1))>MIN(MONTH($M$9),IF(AND(R59<>"",YEAR(R59)=YEAR($M$9)),MONTH(R59),99),IF(AND(P59<>"",YEAR(P59)=YEAR($M$9)),MONTH(P59),99)))),0,MIN(MONTH($M$9),IF(AND(R59<>"",YEAR(R59)=YEAR($M$9)),MONTH(R59),99),IF(AND(P59<>"",YEAR(P59)=YEAR($M$9)),MONTH(P59),99))-IF(YEAR(F59)<YEAR($M$9),1,IF(MONTH(F59)=12,99,MONTH(F59)+1))+1))),0) -> 12 | T59: =(J59*(1-I59))/H59*S59 -> 5409.2925 | U59: =T59-Q59 -> 0.0025
...

Sheet 新增清单
B2: 获取当期按类别划分的所有固定资产新增清单，并将该清单与固定资产后推核对一致。调查超过SAD名义金额的差额（例如，新增清单和后推明细表之间未被解释的差额）。 | U2: 返回汇总页
B4: 注：项目组可以自定义固定资产新增清单表格，也可直接使用系统导出的固定资产新增清单，但必须确保必需字段（固定资产类别、编号、名称、入账开始日期、原值、新增方式）完整。
B7: 固定资产类别 | C7: 固定资产编号 | D7: 固定资产名称 | E7: 入账开始日期 | F7: 使用寿命(年) | G7: 使用寿命(月) | H7: 残值率 | I7: 原值 | J7: 累计折旧 | K7: 减值准备 | L7: 净值 | M7: 新增方式
B8: 固定资产-机械设备 | C8: 000010000012 | D8: 插纸机 | E8: 46013 | F8: 12 | G8: =F8*12 -> 144 | H8: 0 | I8: 355386.52 | J8: 0 | K8: 0 | L8: =I8-J8-K8 -> 355386.52 | M8: 在建工程转入
B9: 固定资产-机械设备 | C9: 000010000013 | D9: 线成型机 | E9: 46013 | F9: 12 | G9: =F9*12 -> 144 | H9: 0 | I9: 1074800 | J9: 0 | K9: 0 | L9: =I9-J9-K9 -> 1074800 | M9: 在建工程转入
B10: 固定资产-机械设备 | C10: 000010000014 | D10: 绕组压入机 | E10: 46013 | F10: 12 | G10: =F10*12 -> 144 | H10: 0 | I10: 243900 | J10: 0 | K10: 0 | L10: =I10-J10-K10 -> 243900 | M10: 在建工程转入
B11: 固定资产-机械设备 | C11: 000010000015 | D11: 扩口机 | E11: 46013 | F11: 12 | G11: =F11*12 -> 144 | H11: 0 | I11: 355000 | J11: 0 | K11: 0 | L11: =I11-J11-K11 -> 355000 | M11: 在建工程转入
B12: 固定资产-机械设备 | C12: 000010000016 | D12: 扩扭一体机 | E12: 46013 | F12: 12 | G12: =F12*12 -> 144 | H12: 0 | I12: 701900 | J12: 0 | K12: 0 | L12: =I12-J12-K12 -> 701900 | M12: 在建工程转入
B13: 固定资产-机械设备 | C13: 000010000017 | D13: 翻转机 | E13: 46013 | F13: 12 | G13: =F13*12 -> 144 | H13: 0 | I13: 155000 | J13: 0 | K13: 0 | L13: =I13-J13-K13 -> 155000 | M13: 在建工程转入
B14: 固定资产-机械设备 | C14: 000010000018 | D14: 端部切平机 | E14: 46013 | F14: 12 | G14: =F14*12 -> 144 | H14: 0 | I14: 340200 | J14: 0 | K14: 0 | L14: =I14-J14-K14 -> 340200 | M14: 在建工程转入
B15: 固定资产-机械设备 | C15: 000010000019 | D15: 端部焊接机 | E15: 46013 | F15: 12 | G15: =F15*12 -> 144 | H15: 0 | I15: 446250 | J15: 0 | K15: 0 | L15: =I15-J15-K15 -> 446250 | M15: 在建工程转入
B16: 固定资产-机械设备 | C16: 000010000020 | D16: 补焊机 | E16: 46013 | F16: 12 | G16: =F16*12 -> 144 | H16: 0 | I16: 305000 | J16: 0 | K16: 0 | L16: =I16-J16-K16 -> 305000 | M16: 在建工程转入
B17: 固定资产-机械设备 | C17: 000010000021 | D17: BUSBAR焊接机 | E17: 46013 | F17: 12 | G17: =F17*12 -> 144 | H17: 0 | I17: 377000 | J17: 0 | K17: 0 | L17: =I17-J17-K17 -> 377000 | M17: 在建工程转入
B18: 固定资产-机械设备 | C18: 000010000022 | D18: 滴漆机(扁线设备) | E18: 46013 | F18: 12 | G18: =F18*12 -> 144 | H18: 0 | I18: 2007067 | J18: 0 | K18: 0 | L18: =I18-J18-K18 -> 2007067 | M18: 在建工程转入
B19: 固定资产-机械设备 | C19: 000010000023 | D19: 涂敷机 | E19: 46013 | F19: 12 | G19: =F19*12 -> 144 | H19: 0 | I19: 987600 | J19: 0 | K19: 0 | L19: =I19-J19-K19 -> 987600 | M19: 在建工程转入
... B30: 固定资产-检测设备 | C30: 000090000017 | D30: 测试设备 | E30: 46013 | F30: 6 | G30: =F30*12 -> 72 | H30: 0 | I30: 101769.91 | J30: 0 | K30: 0 | L30: =I30-J30-K30 -> 101769.91 | M30: 在建工程转入
B31: 固定资产-电子产品及通讯设备 | C31: 000110000061 | D31: 笔记本 | E31: 45672 | F31: 8 | G31: =F31*12 -> 96 | H31: 0 | I31: 5163 | J31: 624.1 | K31: 0 | L31: =I31-J31-K31 -> 4538.9 | M31: 在建工程转入
B32: 固定资产-电子产品及通讯设备 | C32: 000110000062 | D32: 笔记本 | E32: 45672 | F32: 8 | G32: =F32*12 -> 96 | H32: 0 | I32: 5163 | J32: 591.59 | K32: 0 | L32: =I32-J32-K32 -> 4571.41 | M32: 在建工程转入
B33: 固定资产-电子产品及通讯设备 | C33: 000110000063 | D33: 笔记本 | E33: 45672 | F33: 8 | G33: =F33*12 -> 96 | H33: 0 | I33: 6200 | J33: 710.42 | K33: 0 | L33: =I33-J33-K33 -> 5489.58 | M33: 在建工程转入
B34: 固定资产-电子产品及通讯设备 | C34: 000110000064 | D34: 笔记本 | E34: 45672 | F34: 8 | G34: =F34*12 -> 96 | H34: 0 | I34: 6200 | J34: 710.42 | K34: 0 | L34: =I34-J34-K34 -> 5489.58 | M34: 在建工程转入
B35: 固定资产-电子产品及通讯设备 | C35: 000110000065 | D35: 笔记本 | E35: 45672 | F35: 8 | G35: =F35*12 -> 96 | H35: 0 | I35: 6200 | J35: 710.42 | K35: 0 | L35: =I35-J35-K35 -> 5489.58 | M35: 在建工程转入
H36: 合计 | I36: =SUM(I8:I35) -> 10537159
I37: =I36-'K.01 Agree SL to GL'!Q15 -> 0

Sheet SkywindSettingSheet
A1: db9ce45c-b5c9-4e6d-be28-967b500f20b6
A3: {"Id":"2120100351","IsProject":false,"ProjectId":"2006602268","TempProjectName":"云端天风测试","TempType":2,"Upload":"上传","Download":"下载"}
A4: TRUE
