Workbook

Sheet 汇总 
A1: V6 SWP
B2: 该科目涉及OSP底稿可参考此链接 | F2: OSP K1 SWP 固定资产及在建工程盘点 202YMMDD XYZ公司.xlsx
F3: OSP K1 SWP 固定资产权属检查 202YMMDD XYZ公司.xlsx
B5: K.00 | C5: K.00 Lead Sheet | F5: 程序页 | G5: 执行 | H5: 不执行的原因 | I5: 注意事项
B6: 1 | C6: 获取和编制固定资产两期变动的引导表，并与试算平衡表和上年底稿核对一致。对固定资产变动建立预期并说明理由，对不符合预期的变动以及异常变动进行调查和分析。 | F6: K.00 Lead Sheet
B7: K.01 | C7: K.01 Agree SL to GL（认定：IS：E、V、C、M） | F7: 程序页 | G7: 执行 | H7: 不执行的原因 | I7: 注意事项
B8: 1 | C8: 获取固定资产后推明细表，并将其与试算平衡表和固定资产清单核对一致。 | F8: K.01 Agree SL to GL
B9: K.02 | C9: K.02.1 新增测试（认定：E、V、C、P&D） | F9: 程序页 | G9: 执行 | H9: 不执行的原因 | I9: 注意事项
B10: 1 | C10: 获取当期按类别划分的所有固定资产新增清单，并将该清单与固定资产后推核对一致，调查超过SAD名义金额的差额。 | F10: 新增清单 | I10: 若在建工程为不重大账户未开底稿，则项目组需要在K1 SWP中核对在建工程转入与转出金额是否一致，并按照<J.02.2 CIP transfer (ToD)>的测试属性执行该程序。
B11: 2 | C11: 对本年新增资产执行关键性样本测试和代表性样本测试（如需要）。 | F11: K.02.1 新增测试
F12: K.02.1a 新增选样输出
B13: K.02 | C13: K.02.2 处置测试（认定：E、V、R&O） | F13: 程序页 | G13: 执行 | H13: 不执行的原因 | I13: 注意事项
B14: 1 | C14: 获取当期按类别划分的所有固定资产处置清单，包括记录的处置的损益，并将该清单与固定资产后推核对一致，我们调查超过SAD名义金额的差额。 | F14: 处置清单
B15: 2 | C15: 对本年处置资产执行关键性样本测试和代表性样本测试（如需要）。 | F15: K.02.2 处置测试
F16: K.02.2a 处置选样输出
B17: K.03 | C17: K.03 折旧测试（认定：IS:V、O、M、P&D） | F17: 程序页 | G17: 执行 | H17: 不执行的原因 | I17: 注意事项
B18: 1 | C18: 执行实质性分析程序(SAP)测试折旧费用，可参考264 GL 或K.03.1 SAP模板执行。如不执行，可直接执行K.03.2 折旧测试TOD。 | F18: K.03.1 SAP
B19: 2 | C19: 如选择执行详细测试，可使用该底稿记录。 | F19: K.03.2 折旧测试TOD
B20: 3 | C20: 检查固定资产各项目的折旧政策是否符合有关规定，是否与上期一致，评价其合理性。若改变折旧政策，检查其依据是否充分。 | F20: K.03.3 折旧政策复核
B21: K.04 | C21: K.04 固定资产的减值（认定：BS：V IS：M） | F21: 程序页 | G21: 执行 | H21: 不执行的原因 | I21: 注意事项
B22: 1 | C22: 1.使用在审计过程中所获得的信息来确定管理层是否已识别适当的减值迹象；可使用PSP Canvas form K.04：识别减值迹象，也可使用 <SWP减值迹象识别> 对减值迹象进行评估，并根据指引要求获取相关支持性文件。 2.如有减值迹象的，评价管理层假设、未来现金流等减值评估的合理性，核实并测算减值金额。 3.检查是否存在转回固定资产减值准备的情况，确定减值准备在以后会计期间没有转回。 | F22: 项目组自行填写底稿索引

Sheet K.00 Lead Sheet
B1: 标准工作底稿: K1 SWP 不动产、厂房和设备及相关账户（PPE）
B2: 客户名称 | C2: 东风鸿远工程咨询有限公司 | D2: 此工作底稿需要与以下 Canvas PSP guided workflow forms一起使用： •K.00 PPE引导表 •K.01 将明细账与总账核对一致 •K.02 增加和处置 •K.03 折旧、损耗和摊销 •K.04 固定资产减值 •账户结论
B3: 期末 | C3: 46387
B4: 分析日期 | C4: 46168.736
B5: 可容忍误差（TE）
B6: 名义金额（SAD）
B7: 适用会计准则（GAAP） | C7: PRC
B8: 记账本位币 | C8: CNY
B9: K.00 编制引导表并比较余额
B11: 返回汇总页
D13: Threshold(s) | J13: 安永标记
B14: 认定 | C14: CRA | D14: 各项认定1 | E14: 所有相关认定 2 | H14: TB | I14: 已与科目余额表核对无误
B15: 完整性（C） | D15: =IF(C15="Minimal",$C$5*100%,IF(C15="Low",$C$5*75%,IF(C15="Moderate",$C$5*50%,IF(C15="High",$C$5*25%,IF(C15="N/A","-",))))) | E15: =MIN($D$15:$D$19) | H15: PY | I15: 与上年最终审定数核对一致
B16: 存在性/发生 (E/O) | D16: =IF(C16="Minimal",$C$5*100%,IF(C16="Low",$C$5*75%,IF(C16="Moderate",$C$5*50%,IF(C16="High",$C$5*25%,IF(C16="N/A","-",))))) | H16: A3 | I16: 与未审数、审定数核对一致
B17: 计价/计量（V/M） | D17: =IF(C17="Minimal",$C$5*100%,IF(C17="Low",$C$5*75%,IF(C17="Moderate",$C$5*50%,IF(C17="High",$C$5*25%,IF(C17="N/A","-",))))) | H17: A5 | I17: 与审计调整核对一致
B18: 权利和义务（R&O） | D18: =IF(C18="Minimal",$C$5*100%,IF(C18="Low",$C$5*75%,IF(C18="Moderate",$C$5*50%,IF(C18="High",$C$5*25%,IF(C18="N/A","-",))))) | H18: FS | I18: 与FS.0x与财务报表核对无误
B19: 列报和披露（P&D） | D19: =IF(C19="Minimal",$C$5*100%,IF(C19="Low",$C$5*75%,IF(C19="Moderate",$C$5*50%,IF(C19="High",$C$5*25%,IF(C19="N/A","-",))))) | H19: w | I19: 低于SAD的金额——放弃进一步调查
B20: 1 各项认定的测试阈值，是根据EY GAM SUBSTANTIVE DESIGN 2.2.1 | H20: Rx | I20: 重新计算，无异常
B21: 中的示例测试阈值（用占TE的百分比表示）在相应风险等级（CRA）区间的上限计算得出的。 | H21: m | I21: 余额/活动不符合测试范围–无需进一步调查
B22: 除负债/费用类别账户的完整性认定应当使用负债/费用账户表之外，其他类别账户和认定均可使用资产/收入账户表。 | H22: SL | I22: 已与明细账核对无误
B23: 2 所有相关认定的测试阈值，是所有有效认定对应之测试阈值的最小值。我们在
B24: Lead中使用该测试阈值：（a）作为选取总账账户进行测试的起点；（b）作为（需要进一步调查的）金额波动范围的起点。
B26: 在下文中描述我们对固定资产在此期间的相关账户余额和相关波动的预期，以及我们对这些预期的依据和理由。
B27: 账户变更 | C27: 预期及额外考虑
B28: 新增
B29: 减少
B30: 在建工程转入（如适用）
B31: 转让、外汇和其他调整
B32: 折旧方法
B33: 折旧费用
B34: 使用寿命变化
B37: 波动范围
B38: ="波动幅度 ("&C8& "):" | C38: =$E$15
B39: 波动幅度 (%): | C39: 0.1
B41: 我们获取或编制了与上期对比的重大账户（固定资产）引导表。我们将本期余额与试算平衡表核对一致，并将上期余额与上期审定数核对一致（如适用）。
B42: 我们将期末余额与上期余额进行对比。调查超出测试阈值（金额和百分比）的波动，以及代表异常或预期外变动或未发生预期中变动的波动，并确定其对我们计划实质性程序的影响 (如有)。
E45: |------- TB -------| | J45: |------- PY -------|
E46: ="货币/单位: "&C8
E47: =$C$3 | J47: =DATE(YEAR($C$3)-1,12,31) | K47: 本期和上期期末余额 | N47: 基于波动幅度判断，是否进一步调查？ | O47: 基于定性考虑判断，是否进一步调查？
B48: 总账科目编码 | C48: 科目名称 | D48: 索引号 | E48: 期末账面数 | F48: 账表调整数 | G48: 期末未审数 | H48: 审计调整数 | I48: 期末审定数 | J48: 上期末审定数 | K48: 变动金额 | L48: 变动% | M48: Notes
...

Sheet K.01 Agree SL to GL
B1: 标准工作底稿: K1 SWP 不动产、厂房和设备及相关账户（PPE）
B2: K.01 将明细账与总账核对一致
B4: 返回汇总页
B6: 获取上期末至本期末（或中期，如适用）固定资产及相关新增、处置、转让和折旧的后推明细表。（原值、累计折旧、减值均为正数填列，本期减少以负数填列，账表调整、审计调整数据均直接链接至K.00 Lead。）
B7: 我们将期初固定资产余额与上期审定数核对一致，将期末固定资产余额与固定资产明细账和试算表核对一致。我们调查了大于SAD的差异。我们将利润表金额（如，折旧费用）与试算表核对一致（如适用）。
B8: 我们选择了超过测试阈值的后推活动（如，新增、处置、固定资产转入、转移和折旧费用），以执行K.02和K.03的实质性程序。对于未包含在本程序表范围内的程序，我们交叉索引至完成该程序的单独程序表。我们评估了固定资产的转移和其他调整，以了解调整的性质，并确定是否需要执行额外程序。
B9: 表1 | Z9: |--------------------------- Rx ------------------------------|
D10: 固定资产类别 | F10: 房屋建筑物 | I10: 机器设备 | L10: 运输设备 | O10: 电子产品及通讯设备 | R10: 合计 | U10: 【…】 | X10: 【…】 | AA10: 合计
E11: 账面数 | F11: 账表调整/审计调整 | G11: 审定数 | H11: 账面数 | I11: 账表调整/审计调整 | J11: 审定数 | K11: 账面数 | L11: 账表调整/审计调整 | M11: 审定数 | N11: 账面数 | O11: 账表调整/审计调整 | P11: 审定数 | Q11: 账面数 | R11: 账表调整/审计调整 | S11: 审定数 | T11: 账面数 | U11: 账表调整/审计调整 | V11: 审定数 | W11: 账面数 | X11: 账表调整/审计调整 | Y11: 审定数 | Z11: 账面数 | AA11: 账表调整/审计调整 | AB11: 审定数 | AC11: CHECK
C12: 年初余额 | D12: PY | E12: 322612.2 | G12: 322612.2 | H12: 1.760351e+08 | J12: 1.760351e+08 | K12: 844044.29 | M12: 844044.29 | N12: 290507.47 | P12: 290507.47 | Q12: 1.7749227e+08 | R12: 0 | S12: 1.7749227e+08 | T12: 0 | V12: =SUM(T12:U12) | Y12: =SUM(W12:X12) | Z12: =SUM(E12,H12,K12,N12,Q12,T12,W12) | AA12: =SUM(F12,I12,L12,O12,R12,U12,X12) | AB12: =SUM(G12,J12,M12,P12,S12,V12,Y12) | AC12: =AB12-'K.00 Lead Sheet'!J49
C13: 购置 | D13: K.02.1 | G13: =SUM(E13:F13) | J13: =SUM(H13:I13) | M13: =SUM(K13:L13) | P13: =SUM(N13:O13) | S13: =SUM(Q13:R13) | V13: =SUM(T13:U13) | Y13: =SUM(W13:X13) | Z13: =SUM(E13,H13,K13,N13,Q13,T13,W13) | AA13: =SUM(F13,I13,L13,O13,R13,U13,X13) | AB13: =SUM(G13,J13,M13,P13,S13,V13,Y13)
C14: 在建工程转入 | D14: J1.02 | G14: =SUM(E14:F14) | J14: =SUM(H14:I14) | M14: =SUM(K14:L14) | P14: =SUM(N14:O14) | S14: =SUM(Q14:R14) | V14: =SUM(T14:U14) | Y14: =SUM(W14:X14) | Z14: =SUM(E14,H14,K14,N14,Q14,T14,W14) | AA14: =SUM(F14,I14,L14,O14,R14,U14,X14) | AB14: =SUM(G14,J14,M14,P14,S14,V14,Y14)
B15: 原值 | C15: 处置或报废 | D15: K.02.2 | G15: =SUM(E15:F15) | J15: =SUM(H15:I15) | M15: =SUM(K15:L15) | P15: =SUM(N15:O15) | S15: =SUM(Q15:R15) | V15: =SUM(T15:U15) | Y15: =SUM(W15:X15) | Z15: =SUM(E15,H15,K15,N15,Q15,T15,W15) | AA15: =SUM(F15,I15,L15,O15,R15,U15,X15) | AB15: =SUM(G15,J15,M15,P15,S15,V15,Y15)
C16: 内部重分类 | G16: =SUM(E16:F16) | J16: =SUM(H16:I16) | M16: =SUM(K16:L16) | P16: =SUM(N16:O16) | S16: =SUM(Q16:R16) | V16: =SUM(T16:U16) | Y16: =SUM(W16:X16) | Z16: =SUM(E16,H16,K16,N16,Q16,T16,W16) | AA16: =SUM(F16,I16,L16,O16,R16,U16,X16) | AB16: =SUM(G16,J16,M16,P16,S16,V16,Y16)
C17: […] | G17: =SUM(E17:F17) | J17: =SUM(H17:I17) | M17: =SUM(K17:L17) | P17: =SUM(N17:O17) | S17: =SUM(Q17:R17) | V17: =SUM(T17:U17) | Y17: =SUM(W17:X17) | Z17: =SUM(E17,H17,K17,N17,Q17,T17,W17) | AA17: =SUM(F17,I17,L17,O17,R17,U17,X17) | AB17: =SUM(G17,J17,M17,P17,S17,V17,Y17)
C18: 年末余额 | D18: Rx | E18: =E12+E13+E14+E15+E16+E17 | F18: =F12+F13+F14+F15+F16+F17 | G18: =G12+G13+G14+G15+G16+G17 | H18: =H12+H13+H14+H15+H16+H17 | I18: =I12+I13+I14+I15+I16+I17 | J18: =J12+J13+J14+J15+J16+J17 | K18: =K12+K13+K14+K15+K16+K17 | L18: =L12+L13+L14+L15+L16+L17 | ... AB18: =AB12+AB13+AB14+AB15+AB16+AB17 | AC18: =AB18-'K.00 Lead Sheet'!I49
C19: 年初余额 | D19: PY | G19: =SUM(E19:F19) | J19: =SUM(H19:I19) | M19: =SUM(K19:L19) | P19: =SUM(N19:O19) | S19: =SUM(Q19:R19) | V19: =SUM(T19:U19) | Y19: =SUM(W19:X19) | Z19: =SUM(E19,H19,K19,N19,Q19,T19,W19) | AA19: =SUM(F19,I19,L19,O19,R19,U19,X19) | AB19: =SUM(G19,J19,M19,P19,S19,V19,Y19) | AC19: =AB19-'K.00 Lead Sheet'!J50
C20: 计提 | D20: K.03.2 | G20: =SUM(E20:F20) | J20: =SUM(H20:I20) | M20: =SUM(K20:L20) | P20: =SUM(N20:O20) | S20: =SUM(Q20:R20) | V20: =SUM(T20:U20) | Y20: =SUM(W20:X20) | Z20: =SUM(E20,H20,K20,N20,Q20,T20,W20) | AA20: =SUM(F20,I20,L20,O20,R20,U20,X20) | AB20: =SUM(G20,J20,M20,P20,S20,V20,Y20) | AC20: <K.03 折旧测试>
B21: 累计折旧 | C21: 处置或报废 | D21: K.02.2 | G21: =SUM(E21:F21) | J21: =SUM(H21:I21) | M21: =SUM(K21:L21) | P21: =SUM(N21:O21) | S21: =SUM(Q21:R21) | V21: =SUM(T21:U21) | Y21: =SUM(W21:X21) | Z21: =SUM(E21,H21,K21,N21,Q21,T21,W21) | AA21: =SUM(F21,I21,L21,O21,R21,U21,X21) | AB21: =SUM(G21,J21,M21,P21,S21,V21,Y21)
C22: 内部重分类 | G22: =SUM(E22:F22) | J22: =SUM(H22:I22) | M22: =SUM(K22:L22) | P22: =SUM(N22:O22) | S22: =SUM(Q22:R22) | V22: =SUM(T22:U22) | Y22: =SUM(W22:X22) | Z22: =SUM(E22,H22,K22,N22,Q22,T22,W22) | AA22: =SUM(F22,I22,L22,O22,R22,U22,X22) | AB22: =SUM(G22,J22,M22,P22,S22,V22,Y22)
C23: […] | G23: =SUM(E23:F23) | J23: =SUM(H23:I23) | M23: =SUM(K23:L23) | P23: =SUM(N23:O23) | S23: =SUM(Q23:R23) | V23: =SUM(T23:U23) | Y23: =SUM(W23:X23) | Z23: =SUM(E23,H23,K23,N23,Q23,T23,W23) | AA23: =SUM(F23,I23,L23,O23,R23,U23,X23) | AB23: =SUM(G23,J23,M23,P23,S23,V23,Y23)
C24: 年末余额 | D24: Rx | E24: =E19+E20+E21+E22+E23 | F24: =F19+F20+F21+F22+F23 | G24: =G19+G20+G21+G22+G23 | H24: =H19+H20+H21+H22+H23 | I24: =I19+I20+I21+I22+I23 | J24: =J19+J20+J21+J22+J23 | K24: =K19+K20+K21+K22+K23 | L24: =L19+L20+L21+L22+L23 | ... AB24: =AB19+AB20+AB21+AB22+AB23 | AC24: =AB24-'K.00 Lead Sheet'!I50
C25: 年初余额 | D25: PY | G25: =SUM(E25:F25) | J25: =SUM(H25:I25) | M25: =SUM(K25:L25) | P25: =SUM(N25:O25) | S25: =SUM(Q25:R25) | V25: =SUM(T25:U25) | Y25: =SUM(W25:X25) | Z25: =SUM(E25,H25,K25,N25,Q25,T25,W25) | AA25: =SUM(F25,I25,L25,O25,R25,U25,X25) | AB25: =SUM(G25,J25,M25,P25,S25,V25,Y25) | AC25: =AB25-'K.00 Lead Sheet'!J51
C26: 计提 | D26: SWP 减值 | G26: =SUM(E26:F26) | J26: =SUM(H26:I26) | M26: =SUM(K26:L26) | P26: =SUM(N26:O26) | S26: =SUM(Q26:R26) | V26: =SUM(T26:U26) | Y26: =SUM(W26:X26) | Z26: =SUM(E26,H26,K26,N26,Q26,T26,W26) | AA26: =SUM(F26,I26,L26,O26,R26,U26,X26) | AB26: =SUM(G26,J26,M26,P26,S26,V26,Y26)
B27: 减值准备 | C27: 处置或报废 | D27: K.02.2 | G27: =SUM(E27:F27) | J27: =SUM(H27:I27) | M27: =SUM(K27:L27) | P27: =SUM(N27:O27) | S27: =SUM(Q27:R27) | V27: =SUM(T27:U27) | Y27: =SUM(W27:X27) | Z27: =SUM(E27,H27,K27,N27,Q27,T27,W27) | AA27: =SUM(F27,I27,L27,O27,R27,U27,X27) | AB27: =SUM(G27,J27,M27,P27,S27,V27,Y27)
C28: 内部重分类 | G28: =SUM(E28:F28) | J28: =SUM(H28:I28) | M28: =SUM(K28:L28) | P28: =SUM(N28:O28) | S28: =SUM(Q28:R28) | V28: =SUM(T28:U28) | Y28: =SUM(W28:X28) | Z28: =SUM(E28,H28,K28,N28,Q28,T28,W28) | AA28: =SUM(F28,I28,L28,O28,R28,U28,X28) | AB28: =SUM(G28,J28,M28,P28,S28,V28,Y28)
C29: […] | G29: =SUM(E29:F29) | J29: =SUM(H29:I29) | M29: =SUM(K29:L29) | P29: =SUM(N29:O29) | S29: =SUM(Q29:R29) | V29: =SUM(T29:U29) | Y29: =SUM(W29:X29) | Z29: =SUM(E29,H29,K29,N29,Q29,T29,W29) | AA29: =SUM(F29,I29,L29,O29,R29,U29,X29) | AB29: =SUM(G29,J29,M29,P29,S29,V29,Y29)
C30: 年末余额 | D30: Rx | E30: =E25+E26+E27+E28+E29 | F30: =F25+F26+F27+F28+F29 | G30: =G25+G26+G27+G28+G29 | H30: =H25+H26+H27+H28+H29 | I30: =I25+I26+I27+I28+I29 | J30: =J25+J26+J27+J28+J29 | K30: =K25+K26+K27+K28+K29 | L30: =L25+L26+L27+L28+L29 | ... AB30: =AB25+AB26+AB27+AB28+AB29 | AC30: =AB30-'K.00 Lead Sheet'!I51
B31: 净值 (NBV) | C31: 年初余额 | D31: Rx | E31: =E12-E19-E25 | F31: =F12-F19-F25 | G31: =G12-G19-G25 | H31: =H12-H19-H25 | I31: =I12-I19-I25 | J31: =J12-J19-J25 | K31: =K12-K19-K25 | L31: =L12-L19-L25 | ... AB31: =AB12-AB19-AB25 | AC31: =AB31-'K.00 Lead Sheet'!J55
C32: 年末余额 | D32: Rx | E32: =E18-E24-E30 | F32: =F18-F24-F30 | G32: =G18-G24-G30 | H32: =H18-H24-H30 | I32: =I18-I24-I30 | J32: =J18-J24-J30 | K32: =K18-K24-K30 | L32: =L18-L24-L30 | ... AB32: =AB18-AB24-AB30 | AC32: =AB32-'K.00 Lead Sheet'!I55
B33: 变动 | C33: 原值变动金额 | D33: 本年VS上年 | E33: =E18-E12 | G33: =G18-G12 | H33: =H18-H12 | J33: =J18-J12 | K33: =K18-K12 | M33: =M18-M12 | N33: =N18-N12 | P33: =P18-P12 | Q33: =Q18-Q12 | S33: =S18-S12 | T33: =T18-T12 | V33: =V18-V12 | W33: =W18-W12 | Y33: =Y18-Y12 | Z33: =Z18-Z12 | AA33: =AA18-AA12 | AB33: =AB18-AB12
C34: 原值变动比例 | D34: % | E34: =IFERROR(E33/E12,1) | G34: =IFERROR(G33/G12,1) | H34: =IFERROR(H33/H12,1) | J34: =IFERROR(J33/J12,1) | K34: =IFERROR(K33/K12,1) | M34: =IFERROR(M33/M12,1) | N34: =IFERROR(N33/N12,1) | P34: =IFERROR(P33/P12,1) | Q34: =IFERROR(Q33/Q12,1) | S34: =IFERROR(S33/S12,1) | T34: =IFERROR(T33/T12,1) | V34: =IFERROR(V33/V12,1) | W34: =IFERROR(W33/W12,1) | Y34: =IFERROR(Y33/Y12,1) | Z34: =IFERROR(Z33/Z12,1) | AA34: =IFERROR(AA33/AA12,1) | AB34: =IFERROR(AB33/AB12,1)
C35: 累计折旧变动金额 | D35: 本年VS上年 | E35: =E24-E19 | G35: =G24-G19 | H35: =H24-H19 | J35: =J24-J19 | K35: =K24-K19 | M35: =M24-M19 | N35: =N24-N19 | P35: =P24-P19 | Q35: =Q24-Q19 | S35: =S24-S19 | T35: =T24-T19 | V35: =V24-V19 | W35: =W24-W19 | Y35: =Y24-Y19 | Z35: =Z24-Z19 | AA35: =AA24-AA19 | AB35: =AB24-AB19
C36: 累计折旧变动比例 | D36: % | E36: =IFERROR(E35/E19,1) | G36: =IFERROR(G35/G19,1) | H36: =IFERROR(H35/H19,1) | J36: =IFERROR(J35/J19,1) | K36: =IFERROR(K35/K19,1) | M36: =IFERROR(M35/M19,1) | N36: =IFERROR(N35/N19,1) | P36: =IFERROR(P35/P19,1) | Q36: =IFERROR(Q35/Q19,1) | S36: =IFERROR(S35/S19,1) | T36: =IFERROR(T35/T19,1) | V36: =IFERROR(V35/V19,1) | W36: =IFERROR(W35/W19,1) | Y36: =IFERROR(Y35/Y19,1) | Z36: =IFERROR(Z35/Z19,1) | AA36: =IFERROR(AA35/AA19,1) | AB36: =IFERROR(AB35/AB19,1)
C37: 减值准备变动金额 | D37: 本年VS上年 | E37: =E30-E25 | G37: =G30-G25 | H37: =H30-H25 | J37: =J30-J25 | K37: =K30-K25 | M37: =M30-M25 | N37: =N30-N25 | P37: =P30-P25 | Q37: =Q30-Q25 | S37: =S30-S25 | T37: =T30-T25 | V37: =V30-V25 | W37: =W30-W25 | Y37: =Y30-Y25 | Z37: =Z30-Z25 | AA37: =AA30-AA25 | AB37: =AB30-AB25
C38: 减值准备变动比例 | D38: % | E38: =IFERROR(E37/E25,1) | G38: =IFERROR(G37/G25,1) | H38: =IFERROR(H37/H25,1) | J38: =IFERROR(J37/J25,1) | K38: =IFERROR(K37/K25,1) | M38: =IFERROR(M37/M25,1) | N38: =IFERROR(N37/N25,1) | P38: =IFERROR(P37/P25,1) | Q38: =IFERROR(Q37/Q25,1) | S38: =IFERROR(S37/S25,1) | T38: =IFERROR(T37/T25,1) | V38: =IFERROR(V37/V25,1) | W38: =IFERROR(W37/W25,1) | Y38: =IFERROR(Y37/Y25,1) | Z38: =IFERROR(Z37/Z25,1) | AA38: =IFERROR(AA37/AA25,1) | AB38: =IFERROR(AB37/AB25,1)
C39: 净值变动金额 | D39: 本年VS上年 | E39: =E32-E31 | G39: =G32-G31 | H39: =H32-H31 | J39: =J32-J31 | K39: =K32-K31 | M39: =M32-M31 | N39: =N32-N31 | P39: =P32-P31 | Q39: =Q32-Q31 | S39: =S32-S31 | T39: =T32-T31 | V39: =V32-V31 | W39: =W32-W31 | Y39: =Y32-Y31 | Z39: =Z32-Z31 | AA39: =AA32-AA31 | AB39: =AB32-AB31
C40: 净值变动比例 | D40: % | E40: =IFERROR(E39/E31,1) | G40: =IFERROR(G39/G31,1) | H40: =IFERROR(H39/H31,1) | J40: =IFERROR(J39/J31,1) | K40: =IFERROR(K39/K31,1) | M40: =IFERROR(M39/M31,1) | N40: =IFERROR(N39/N31,1) | P40: =IFERROR(P39/P31,1) | Q40: =IFERROR(Q39/Q31,1) | S40: =IFERROR(S39/S31,1) | T40: =IFERROR(T39/T31,1) | V40: =IFERROR(V39/V31,1) | W40: =IFERROR(W39/W31,1) | Y40: =IFERROR(Y39/Y31,1) | Z40: =IFERROR(Z39/Z31,1) | AA40: =IFERROR(AA39/AA31,1) | AB40: =IFERROR(AB39/AB31,1)
B42: TB-原值 | Z42: =SUM(E42,H42,K42,N42,Q42,T42,W42)
B43: 差异 | E43: =E18-E42 | H43: =H18-H42 | K43: =K18-K42 | N43: =N18-N42 | Q43: =Q18-Q42 | T43: =T18-T42 | W43: =W18-W42 | Z43: =Z18-Z42
...

Sheet FA list
A1: 7054f053-bac2-4036-a572-53d350c3c8de
B2: 1.项目组可以自定义固定资产清单表格，也可直接使用系统导出的固定资产清单，但必须确保必需字段（固定资产类别、编号、名称、开始入账日期、使用寿命、残值率、原值、累计折旧、净值）完整。可参考链接： | W2: 返回汇总页
B3: 2.获取期末的固定资产明细清单，将固定资产明细清单的金额与K.01 Agree SL to GL 表1的金额进行核对，核对结果详见K.01 Agree SL to GL 表2，并调查大于SAD的差异。
B4: 3.固定资产的类别：请使用被审计单位的台账，无需对资产的类别添加自己的重分类修改。
B5: 4.如果折旧测试较难执行实质性分析程序或从实质性分析程序中获得的证据水平不足以得出审计结论，我们可在<FA List>中执行全量折旧测试，底稿形式可参考：

Sheet K.02.1 新增测试 
B1: 标准工作底稿: K1 SWP 不动产、厂房和设备及相关账户（PPE）
B2: K.02.1：详细测试 (新增)
B4: 返回汇总页
B6: 记录我们的详细测试所涵盖的总体（指引：纳入充分的描述，以使经验丰富且之前与该项审计无关的审计师能够理解样本是如何选择的，例如，总体的分类或筛选。）
B12: 购置总金额
B13: Breakdown中购置金额 | F13: ='K.01 Agree SL to GL'!Z13 | G13: K.01
B14: 差异 | F14: =F12-F13 | G14: Rx | H14: 差异是否需要进一步调查？ | J14: =IF(ABS(F14)>'K.00 Lead Sheet'!$C$6, "是", "否")
B16: 减：测试的关键项目
B17: 进行代表性抽样的剩余总体 | F17: =F12-F16
B19: 在下方描述选择关键项目的理由（请参阅Canvas指导工作流程的“关键项目”部分，包括信息图标）
B25: EY 测试属性解释:
B26: 对于每个被选中进行测试的项目，我们检查了相关的第三方证据以及相关的会计分录，并确定：
B27: 1) 测试样本于恰当的日期被正确资本化为固定资产（即，不应该费用化）。
B28: 2) 历史成本已根据适用的财务报告框架进行记录。
B29: 3) 管理层对测试项目采用的使用寿命和折旧方法是适当的（符合实体的会计政策和适用的财务报告框架）。
B30: 4) 该资产已被归入适当的固定资产类别。
N32: |------- Rx -------| | O32: EY Works
B33: 样本类型 | C33: 固定资产类别 | D33: 总账账户代码 | E33: 固定资产编号 | F33: 固定资产名称 | G33: 资产原价 | H33: 资本化日期 | I33: 使用寿命(月) | J33: 残值率 | K33: 折旧方法 | L33: 资产原价（通过审计证据/支持性文件取得） | M33: 获得的证据/支持的描述（例如，我们检查的控制权转移时点的单据/销售发票/合同/订单等） | N33: 资产原价差异 | O33: 1 | P33: 2 | Q33: 3 | R33: 4
N34: =G34-L34
N35: =G35-L35
N36: =G36-L36
B38: 标记图例: 记录已识别的异常情况以及如何解决这些异常情况的详细信息，包括执行的其他实质性程序（指南：包括足够的描述，以使之前与审计无关的经验丰富的审计师能够理解执行的程序）。

Sheet K.02.1a 新增选样输出
B2: 将此选项页替换为安永智能选样工作文件中的“选样项目详细信息” | N2: 返回汇总页

Sheet 新增清单
B2: 获取当期按类别划分的所有固定资产新增清单，并将该清单与固定资产后推核对一致。调查超过SAD名义金额的差额（例如，新增清单和后推明细表之间未被解释的差额）。 | U2: 返回汇总页
B4: 注：项目组可以自定义固定资产新增清单表格，也可直接使用系统导出的固定资产新增清单，但必须确保必需字段（固定资产类别、编号、名称、入账开始日期、原值、新增方式）完整。

Sheet K.02.2 处置测试
B1: 标准工作底稿: K1 SWP 不动产、厂房和设备及相关账户（PPE）
B2: K.02.2：详细测试 (处置/报废)
B4: 返回汇总页
B6: 记录我们的详细测试所涵盖的总体（指引：纳入充分的描述，以使经验丰富且之前与该项审计无关的审计师能够理解样本是如何选择的，例如，总体的分类或筛选。）
E12: |------- Rx -------|
E13: 账面净值 | G13: 原值 | I13: 累计折旧 | K13: 减值准备
B14: 处置/报废总金额 | E14: =G14-I14-K14
B15: Breakdown中处置/报废金额 | E15: =G15-I15-K15 | F15: K.01 | G15: =-'K.01 Agree SL to GL'!Z15 | H15: K.01 | I15: =-'K.01 Agree SL to GL'!Z21 | J15: K.01 | K15: =-'K.01 Agree SL to GL'!Z27 | L15: K.01
B16: 差异 | E16: =E14-E15 | F16: Rx | G16: =G14-G15 | H16: Rx | I16: =I14-I15 | J16: Rx | K16: =K14-K15 | L16: Rx
B17: 差异是否需要进一步调查？ | E17: =IF(ABS(E16)>'K.00 Lead Sheet'!$C$6, "是", "否") | G17: =IF(ABS(G16)>'K.00 Lead Sheet'!$C$6, "是", "否") | I17: =IF(ABS(I16)>'K.00 Lead Sheet'!$C$6, "是", "否") | K17: =IF(ABS(K16)>'K.00 Lead Sheet'!$C$6, "是", "否")
B19: 减：测试的关键项目
B20: 进行代表性抽样的剩余总体 | E20: =E14-E19
B22: 在下方描述选择关键项目的理由（请参阅Canvas指导工作流程的“关键项目”部分，包括信息图标）
B28: EY 测试属性解释:
B29: 对于每个被选中进行测试的项目，我们检查了相关的第三方证据以及相关的会计分录，并确定：
B30: 1) 测试样本（原值和累计折旧余额）已从固定资产明细账和总账中正确移除。
B31: 2) 重新计算资产处置时点的账面净值，并计算处置损益。确认处置损益已按照适用的财务报告框架正确记录和分类。
B32: 3) 如果适用，正确记录处置收入金额。如果资产被出售（即收到收益），则获得发票或付款证明等，并确认与日记账分录中记录的收益金额一致。
B34: 固定资产处置/报废测试 | L34: |------- Rx -------| | O34: |------- Rx -------| | Q34: |------- Rx -------| | S34: EY Works
B35: 样本序号 | C35: 样本类型 | D35: 固定资产类别 | E35: 总账账户 | F35: 固定资产编号 | G35: 固定资产名称 | H35: 处置/报废日 | I35: 原值 | J35: 累计折旧 | K35: 减值准备 | L35: 净值 | M35: 出售价格 | N35: 处置交易凭证号 | O35: 处置损益 | P35: 出售价格（通过审计证据/支持性文件取得） | Q35: 出售价格差异 | R35: 获得的证据/支持的描述（例如，我们检查的具体销售发票/合同/订单/审批文件等） | S35: 1 | T35: 2 | U35: 3
B36: 1 | L36: =I36-J36-K36 | O36: =M36-L36 | Q36: =P36-M36
B37: 2 | L37: =I37-J37-K37 | O37: =M37-L37 | Q37: =P37-M37
B38: 3 | L38: =I38-J38-K38 | O38: =M38-L38 | Q38: =P38-M38
B40: 标记图例: 记录已识别的异常情况以及如何解决这些异常情况的详细信息，包括执行的其他实质性程序（指南：包括足够的描述，以使之前与审计无关的经验丰富的审计师能够理解执行的程序）。

Sheet K.02.2a 处置选样输出
B2: 将此选项页替换为安永智能选样工作文件中的“选样项目详细信息” | N2: 返回汇总页

Sheet SkywindSettingSheet
A1: db9ce45c-b5c9-4e6d-be28-967b500f20b6
A3: {"Id":"2120100351","IsProject":false,"ProjectId":"2006602268","TempProjectName":"云端天风测试","TempType":2,"Upload":"上传","Download":"下载"}
A4: TRUE
