Workbook

Sheet 汇总
A1: V6 SWP
B2: 该科目涉及OSP底稿及函证底稿可参考此链接 | F2: OSP N SWP 应付账款账龄复核 202YMMDD XYZ公司.xlsx
F3: 函证 SWP 负债类科目 202YMMDD XYZ公司.xlsx
B5: N.00 | C5: N.00 应付账款引导表（认定：E、C） | F5: 程序页 | G5: 执行 | H5: 不执行的原因 | I5: 注意事项
B6: 1 | C6: 我们将两期金额进行比对，对那些变动大于范围或异常的事项，获得管理层解释并对解释是否合理进行调查并获取相关的支持性文件。 | F6: N.00 Lead sheet
B7: 2 | C7: 如果项目仅对部分总账科目执行程序，需评估未执行程序的总账科目加总金额是否大于TE，如大于TE，请项目组执行额外的测试程序。
B8: N.01 | C8: N.01 将明细账与总账核对一致（认定：E、C、V） | F8: 程序页 | G8: 执行 | H8: 不执行的原因 | I8: 注意事项
B9: 1 | C9: 获取应付账款明细账（列示至各供应商的余额）N.01.01明细账BKD，与总账核对，如差异大于SAD，获取差异差异调节表并对调节项金额大于测试阈值及性质异常的项目执行进一步测试。 | F9: N.01 明细账与总账核对
B10: 2 | C10: 对应付账款外币余额，我们使用第三方汇率(独立于被审计单位获得汇率)重新计算，并将重新计算的余额与被审计单位的余额进行比较。
B11: N.02 | C11: N.02 异常项复核（认定：E、C、V、R&O、P&D） | F11: 程序页 | G11: 执行 | H11: 不执行的原因 | I11: 注意事项
B12: 1 | C12: 对（单独或合计）大于测试阈值的借方余额，获取记账分录并检查对应支持性文件，确定对方科目账务处理是否正确，应付账款借方余额是否有必要根据名义金额进行重分类调整。 | F12: N.02 异常项复核
B13: 2 | C13: 根据应付账款明细账，我们识别金额、供应商或其他被认为异常或预期外的项目（例如，关联方、员工、客户、严重逾期余额），选择项目并记录做出此决定的依据；我们获取这些项目的支持性证据并记录检查结果。
B14: N.03 | C14: N.03 应付账款截止测试（认定：E、C、R&O） | F14: 程序页 | G14: 执行 | H14: 不执行的原因 | I14: 注意事项
B15: 1 | C15: 若我们从其他程序中获得一部分审计证据（交叉索引至相关底稿）或未获取审计证据时，需结合我们对于被审计单位业务的了解，考虑截止性测试的范围与涵盖期间，基于风险评估确定样本策略，并记录我们认为影响我们确定截止时间、样本策略的因素。 IPE 考虑： | F15: N.03 截止测试 | I15: 若我们已从其他程序中获得了充分适当的审计证据，以应对应付账款截止风险时，无需执行本程序，并交叉索引至相关底稿；
B16: N.04 | C16: N.04寻找未入账负债（认定：C、V） | F16: 程序页 | G16: 执行 | H16: 不执行的原因 | I16: 注意事项
B17: 1 | C17: 通过寻找未入账的应付账款，验证资产负债表日应付账款的计价和完整性。 | F17: N.04 寻找未入账负债

Sheet N.00 Lead sheet
B1: 标准工作底稿: N SWP 应付账款
B2: 客户名称 | C2: 东风鸿远工程咨询有限公司 | D2: 此工作底稿需要与以下 Canvas PSP guided workflow forms一起使用： •N.00应付账款引导表 •N.01将明细账与总账核对一致 •N.02异常项复核 •N.03应付账款截止测试 •N.04寻找未入账负债 •账户结论
B3: 期末 | C3: 46387
B4: 分析日期 | C4: 46169.596
B5: 可容忍误差（TE）
B6: 名义金额（SAD）
B7: 适用会计准则 | C7: PRC
B8: 记账本位币 | C8: CNY
B9: N.00 编制引导表并比较余额
B11: 返回汇总页
D13: Threshold(s) | H13: 安永标记
B14: 认定 | C14: CRA | D14: 各项认定1 | E14: 所有相关认定 2 | H14: TB | I14: 已与科目余额表核对无误
B15: 完整性 (C) | D15: =IF(C15="Minimal",$C$5*50%,IF(C15="Low",$C$5*25%,IF(C15="Moderate",$C$5*15%,IF(C15="High",$C$5*10%,IF(C15="N/A","-",))))) | E15: =MIN($D$15:$D$19) | H15: PY | I15: 与上年最终审定数核对一致
B16: 存在性 (E) | D16: =IF(C16="Minimal",$C$5*100%,IF(C16="Low",$C$5*75%,IF(C16="Moderate",$C$5*50%,IF(C16="High",$C$5*25%,IF(C16="N/A","-",))))) | H16: A3 | I16: 与未审数、审定数核对一致
B17: 计价（V） | D17: =IF(C17="Minimal",$C$5*100%,IF(C17="Low",$C$5*75%,IF(C17="Moderate",$C$5*50%,IF(C17="High",$C$5*25%,IF(C17="N/A","-",))))) | H17: A5 | I17: 与审计调整核对一致
B18: 权利和义务（R&O） | D18: =IF(C18="Minimal",$C$5*100%,IF(C18="Low",$C$5*75%,IF(C18="Moderate",$C$5*50%,IF(C18="High",$C$5*25%,IF(C18="N/A","-",))))) | H18: FS | I18: 与FS.0x与财务报表核对无误
B19: 列报和披露（P&D） | D19: =IF(C19="Minimal",$C$5*100%,IF(C19="Low",$C$5*75%,IF(C19="Moderate",$C$5*50%,IF(C19="High",$C$5*25%,IF(C19="N/A","-",))))) | H19: w | I19: 低于SAD的金额——放弃进一步调查
B20: 1 各项认定的测试阈值，是根据EY GAM SUBSTANTIVE DESIGN 2.2.1 | H20: Rx | I20: 重新计算，无异常
B21: 中的示例测试阈值（用占TE的百分比表示）在相应风险等级（CRA）区间的上限计算得出的。 | H21: m | I21: 余额/活动不符合测试范围–无需进一步调查
B22: 除负债/费用类别账户的完整性认定应当使用负债/费用账户表之外，其他类别账户和认定均可使用资产/收入账户表。 | H22: SL | I22: 已与明细账核对无误
B23: 2 所有相关认定的测试阈值，是所有有效认定对应之测试阈值的最小值。我们在 Lead中使用该测试阈值：（a）作为选取总账账户进行测试的起点；（b）作为（需要进一步调查的）金额波动范围的起点。
B25: 在下文中描述我们对应付账款在此期间的相关账户余额和相关波动的预期，以及我们对这些预期的依据和理由。
B30: 波动范围
B31: ="波动幅度 ("&C8& "):" | C31: =$E$15
B32: 波动幅度 (%): | C32: 0.1
F35: |------- TB -------| | K35: |------- PY -------|
B36: 表1 | F36: ="货币/单位: "&C8
B37: 账套名称/账套编码 | C37: 总账科目编码 | D37: 科目名称 | E37: 索引号 | F37: =C3 | K37: =DATE(YEAR($C$3)-1,12,31) | L37: 本期和上期期末余额 | N37: Notes | O37: 基于波动幅度判断，是否进一步调查？ | P37: 基于定性考虑判断，是否进一步调查？
F38: 期末账面数 | G38: 账表调整数 | H38: 期末未审数 | I38: 审计调整数 | J38: 期末审定数 | K38: 上期末审定数 | L38: 变动金额 | M38: 变动%
B39: 东风鸿远工程咨询有限公司 | C39: 2121 | D39: 应付账款 | E39: N.01/ | H39: =F39+G39 | J39: =H39+I39 | K39: -57526376 | L39: =J39-K39 | M39: =IFERROR(L39/K39,1) | N39: [A] | O39: =IF(AND(ABS(L39)>=$C$31,ABS(M39)>=$C$32),"是","否")
H40: =F40+G40 | J40: =H40+I40 | K40: 0 | L40: =J40-K40 | M40: =IFERROR(L40/K40,1) | O40: =IF(AND(ABS(L40)>=$C$31,ABS(M40)>=$C$32),"是","否")
H41: =F41+G41 | J41: =H41+I41 | L41: =J41-K41 | M41: =IFERROR(L41/K41,1) | O41: =IF(AND(ABS(L41)>=$C$31,ABS(M41)>=$C$32),"是","否")
H42: =F42+G42 | J42: =H42+I42 | L42: =J42-K42 | M42: =IFERROR(L42/K42,1) | O42: =IF(AND(ABS(L42)>=$C$31,ABS(M42)>=$C$32),"是","否")
H43: =F43+G43 | J43: =H43+I43 | L43: =J43-K43 | M43: =IFERROR(L43/K43,1) | O43: =IF(AND(ABS(L43)>=$C$31,ABS(M43)>=$C$32),"是","否")
D46: 合计 | F46: =SUM(F39:F43) | G46: =SUM(G39:G43) | H46: =SUM(H39:H43) | I46: =SUM(I39:I43) | J46: =SUM(J39:J43) | K46: =SUM(K39:K43) | L46: =J46-K46 | M46: =IFERROR(L46/K46,1) | O46: =IF(AND(ABS(L46)>=$C$31,ABS(M46)>=$C$32),"是","否")
F47: RX | G47: RX | H47: RX | I47: RX | J47: RX | K47: RX
G48: A3
G49: Diff | H49: =H46-H48 | J49: =J46-J48 | K49: =K46-K48
E50: 未执行程序的总账科目加总金额是否大于TE | F50: =IF(ABS(F45-'N.01 明细账与总账核对'!E18)>'N.00 Lead sheet'!$C$5,"是","否") | G50: Note2
B52: 波动说明
...

Sheet N.01 明细账与总账核对
B1: 标准工作底稿: N SWP 应付账款
B2: N.01: 明细账与总账核对并执行细节测试
B4: 返回汇总页
B6: =MIN('N.00 Lead sheet'!$D$15,'N.00 Lead sheet'!$D$16) | C6: 用于识别总账和明细账之间差异的测试阈值
B9: 表1 将明细账与总账核对一致。 | I9: |------- Rx -------|
B10: 账套名称/账套编码 | C10: 总账科目编码 | D10: 科目名称 | E10: Lead页余额 | F10: 索引号 | G10: 明细账余额 | H10: 明细账索引 | I10: 差异重新计算 （Note1） | J10: 外币余额
J11: 是否适当重新计量? (使用下拉列表) | K11: 工作底稿参考
E12: =-IFERROR(_xlfn.XLOOKUP(C12,'N.00 Lead sheet'!$C$39:$C$43,'N.00 Lead sheet'!$F$39:$F$43),0) | F12: /N.00 | H12: /N.01.01明细账 | I12: =E12-G12 | K12: =IF(J12="","",IF(J12="是","Note2",IF(J12="否","Note2","不适用")))
E13: =-IFERROR(_xlfn.XLOOKUP(C13,'N.00 Lead sheet'!$C$39:$C$43,'N.00 Lead sheet'!$F$39:$F$43),0) | I13: =E13-G13 | K13: =IF(J13="","",IF(J13="是","Note2",IF(J13="否","Note2","不适用")))
E14: =-IFERROR(_xlfn.XLOOKUP(C14,'N.00 Lead sheet'!$C$39:$C$43,'N.00 Lead sheet'!$F$39:$F$43),0) | I14: =E14-G14 | K14: =IF(J14="","",IF(J14="是","Note2",IF(J14="否","Note2","不适用")))
E15: =-IFERROR(_xlfn.XLOOKUP(C15,'N.00 Lead sheet'!$C$39:$C$43,'N.00 Lead sheet'!$F$39:$F$43),0) | I15: =E15-G15 | K15: =IF(J15="","",IF(J15="是","Note2",IF(J15="否","Note2","不适用")))
E16: =-IFERROR(_xlfn.XLOOKUP(C16,'N.00 Lead sheet'!$C$39:$C$43,'N.00 Lead sheet'!$F$39:$F$43),0) | I16: =E16-G16 | K16: =IF(J16="","",IF(J16="是","Note2",IF(J16="否","Note2","不适用")))
D18: 合计 | E18: =SUM(E12:E16) | G18: =SUM(G12:G16) | I18: =SUM(I12:I16)
E19: RX | G19: RX | I19: RX
B21: Note1：如果总账和明细账差异金额大于SAD请在以下解释差异并执行相应的程序：针对金额大于测试阈值及性质异常的项目我们需进一步进行测试。(如不适用请删除）
B26: Note2：对外币余额，我们使用第三方汇率（独立于客户获得汇率）重新计算，并将重新计算的余额与客户的余额进行比较。(如不适用请删除）
C27: |------- N.01.01明细账 -------| | D27: EY Works | F27: |------- N.01.01明细账 -------|
B28: 原币币种 | C28: 原币金额 | D28: 折算汇率 | E28: 折合本位币 | F28: 账面本位币金额 | G28: 差异
B29: USD | E29: =C29*D29 | G29: =E29-F29
B30: CNY | E30: =C30*D30 | G30: =E30-F30
E31: =C31*D31 | G31: =E31-F31

Sheet N.01.01明细账
B1: 标准底稿: N SWP 应付账款
B2: N.01.01 获取应付账款明细账
B5: 账套名称/账套编码 | C5: 科目编码 | D5: 供应商代码 | E5: 供应商名称 | F5: 款项性质 | G5: 供应商性质 | H5: 46387 | N5: 46022 | O5: 变动 | Q5: Notes | R5: 应付账款分账龄
H6: 原币币种 | I6: 原币金额 | J6: 期末账面数 | K6: 本期审计调整编号 | L6: 重分类调整 | M6: 期末审定数 | N6: 上期末审定数 | O6: 金额 | P6: % | R6: 0-90天 | S6: 91-365天 | T6: 1年至2年 | U6: 2年至3年 | V6: 3年以上 | W6: check
B7: 东风鸿远工程咨询有限公司 | C7: 2121 | D7: I_9202 | E7: 东风鸿远工程咨询有限公司监理分公司 | F7: 采购款 | G7: 关联方 | H7: CNY | I7: 0 | M7: =J7+L7 | N7: 0 | O7: =M7-N7 | P7: =IF(N7<>0,O7/N7,"") | R7: 0 | S7: 0 | T7: 0 | U7: 0 | V7: 0 | W7: =SUM(R7:V7)-M7 | X7: =T7+U7+V7
B8: 东风鸿远工程咨询有限公司 | C8: 2121 | D8: I_9149 | E8: 东风咨询有限公司 | F8: 采购款 | G8: 关联方 | H8: CNY | I8: -3874030.1 | M8: =J8+L8 | N8: -3874030.1 | O8: =M8-N8 | P8: =IF(N8<>0,O8/N8,"") | Q8: NB1 | R8: 17923.36 | S8: -115904.15 | T8: -3223581.1 | U8: -552468.23 | V8: 0 | W8: =SUM(R8:V8)-M8 | X8: =T8+U8+V8
B9: 东风鸿远工程咨询有限公司 | C9: 2121 | D9: I_9151 | E9: 东风国际招标有限公司 | F9: 采购款 | G9: 关联方 | H9: CNY | I9: -24168.87 | M9: =J9+L9 | N9: -24168.87 | O9: =M9-N9 | P9: =IF(N9<>0,O9/N9,"") | R9: 0 | S9: 0 | T9: 0 | U9: -24168.87 | V9: 0 | W9: =SUM(R9:V9)-M9 | X9: =T9+U9+V9
B10: 东风鸿远工程咨询有限公司 | C10: 2121 | D10: I_9201 | E10: 东风鸿远工程咨询有限公司武汉分公司 | F10: 采购款 | G10: 关联方 | H10: CNY | I10: 0 | M10: =J10+L10 | N10: 0 | O10: =M10-N10 | P10: =IF(N10<>0,O10/N10,"") | R10: 0 | S10: 0 | T10: 0 | U10: 0 | V10: 0 | W10: =SUM(R10:V10)-M10 | X10: =T10+U10+V10
B11: 东风鸿远工程咨询有限公司 | C11: 2121 | D11: I_9205 | E11: 上海东南联合工程设计有限公司武汉分公司 | F11: 采购款 | G11: 关联方 | H11: CNY | I11: -321415.1 | M11: =J11+L11 | N11: -321415.1 | O11: =M11-N11 | P11: =IF(N11<>0,O11/N11,"") | R11: -145000 | S11: 0 | T11: -176415.1 | U11: 0 | V11: 0 | W11: =SUM(R11:V11)-M11 | X11: =T11+U11+V11
B12: 东风鸿远工程咨询有限公司 | C12: 2121 | D12: I_9204 | E12: 上海东南联合工程设计有限公司 | F12: 采购款 | G12: 关联方 | H12: CNY | I12: -188000 | M12: =J12+L12 | N12: -188000 | O12: =M12-N12 | P12: =IF(N12<>0,O12/N12,"") | R12: -188000 | S12: 0 | T12: 0 | U12: 0 | V12: 0 | W12: =SUM(R12:V12)-M12 | X12: =T12+U12+V12
B13: 东风鸿远工程咨询有限公司 | C13: 2121 | D13: I_2446 | E13: 联友智连科技有限公司 | F13: 采购款 | G13: 关联方 | H13: CNY | I13: -9744.98 | M13: =J13+L13 | N13: -9744.98 | O13: =M13-N13 | P13: =IF(N13<>0,O13/N13,"") | R13: -9744.98 | S13: 0 | T13: 0 | U13: 0 | V13: 0 | W13: =SUM(R13:V13)-M13 | X13: =T13+U13+V13
B14: 东风鸿远工程咨询有限公司 | C14: 2121 | D14: E_614092 | E14: 襄阳市市政工程设计院有限公司 | F14: 采购款 | G14: 供应商 | H14: CNY | I14: -1101157.4 | M14: =J14+L14 | N14: -1101157.4 | O14: =M14-N14 | P14: =IF(N14<>0,O14/N14,"") | R14: 0 | S14: 0 | T14: -183962.26 | U14: 0 | V14: -917195.1 | W14: =SUM(R14:V14)-M14 | X14: =T14+U14+V14
B15: 东风鸿远工程咨询有限公司 | C15: 2121 | D15: E_625077 | E15: 中城科泽工程设计集团有限责任公司襄阳分院 | F15: 采购款 | G15: 供应商 | H15: CNY | I15: -19417.48 | M15: =J15+L15 | N15: -19417.48 | O15: =M15-N15 | P15: =IF(N15<>0,O15/N15,"") | R15: 0 | S15: 0 | T15: 0 | U15: 0 | V15: -19417.48 | W15: =SUM(R15:V15)-M15 | X15: =T15+U15+V15
B16: 东风鸿远工程咨询有限公司 | C16: 2121 | D16: E_624605 | E16: 湖北王壹建筑装饰工程有限公司 | F16: 采购款 | G16: 供应商 | H16: CNY | I16: 0 | M16: =J16+L16 | N16: 0 | O16: =M16-N16 | P16: =IF(N16<>0,O16/N16,"") | R16: 0 | S16: 0 | T16: 0 | U16: 0 | V16: 0 | W16: =SUM(R16:V16)-M16 | X16: =T16+U16+V16
B17: 东风鸿远工程咨询有限公司 | C17: 2121 | D17: E_624955 | E17: 襄阳瑞喜钻探工程有限公司 | F17: 采购款 | G17: 供应商 | H17: CNY | I17: -937233.68 | M17: =J17+L17 | N17: -937233.68 | O17: =M17-N17 | P17: =IF(N17<>0,O17/N17,"") | R17: -383493.38 | S17: -257373.5 | T17: -296366.8 | U17: 0 | V17: 0 | W17: =SUM(R17:V17)-M17 | X17: =T17+U17+V17
B18: 东风鸿远工程咨询有限公司 | C18: 2121 | D18: E_175725 | E18: 中机三勘岩土工程有限公司 | F18: 采购款 | G18: 供应商 | H18: CNY | I18: -2565700 | M18: =J18+L18 | N18: -2565700 | O18: =M18-N18 | P18: =IF(N18<>0,O18/N18,"") | Q18: NB6 | R18: -50754.7 | S18: 0 | T18: 0 | U18: -2514945.3 | V18: 0 | W18: =SUM(R18:V18)-M18 | X18: =T18+U18+V18
B19: 东风鸿远工程咨询有限公司 | C19: 2121 | D19: E_622567 | E19: 湖北省地源洁能工程有限公司 | F19: 采购款 | G19: 供应商 | H19: CNY | I19: 0 | M19: =J19+L19 | N19: 0 | O19: =M19-N19 | P19: =IF(N19<>0,O19/N19,"") | R19: 0 | S19: 0 | T19: 0 | U19: 0 | V19: 0 | W19: =SUM(R19:V19)-M19 | X19: =T19+U19+V19
B20: 东风鸿远工程咨询有限公司 | C20: 2121 | D20: E_612717 | E20: 湖北建研立科低碳科技有限公司 | F20: 采购款 | G20: 供应商 | H20: CNY | I20: -230500 | M20: =J20+L20 | N20: -230500 | O20: =M20-N20 | P20: =IF(N20<>0,O20/N20,"") | R20: -230500 | S20: 0 | T20: 0 | U20: 0 | V20: 0 | W20: =SUM(R20:V20)-M20 | X20: =T20+U20+V20
B21: 东风鸿远工程咨询有限公司 | C21: 2121 | D21: E_679403 | E21: 襄阳汇达讯财务咨询有限公司 | F21: 采购款 | G21: 供应商 | H21: CNY | I21: -16693.76 | M21: =J21+L21 | N21: -16693.76 | O21: =M21-N21 | P21: =IF(N21<>0,O21/N21,"") | R21: -16693.76 | S21: 0 | T21: 0 | U21: 0 | V21: 0 | W21: =SUM(R21:V21)-M21 | X21: =T21+U21+V21
B22: 东风鸿远工程咨询有限公司 | C22: 2121 | D22: 66666 | E22: 虚拟客商 | F22: 采购款 | G22: 供应商 | H22: CNY | I22: 0 | M22: =J22+L22 | N22: 0 | O22: =M22-N22 | P22: =IF(N22<>0,O22/N22,"") | R22: 0 | S22: 0 | T22: 0 | U22: 0 | V22: 0 | W22: =SUM(R22:V22)-M22 | X22: =T22+U22+V22
B23: 东风鸿远工程咨询有限公司 | C23: 2121 | D23: E_622929 | E23: 武汉管陈岩土工程有限公司 | F23: 采购款 | G23: 供应商 | H23: CNY | I23: -15125.25 | M23: =J23+L23 | N23: -15125.25 | O23: =M23-N23 | P23: =IF(N23<>0,O23/N23,"") | R23: 0 | S23: -5736.9 | T23: -9388.35 | U23: 0 | V23: 0 | W23: =SUM(R23:V23)-M23 | X23: =T23+U23+V23
B24: 东风鸿远工程咨询有限公司 | C24: 2121 | D24: E_580949 | E24: 中建三局集团有限公司 | F24: 采购款 | G24: 供应商 | H24: CNY | I24: -1857538.5 | M24: =J24+L24 | N24: -1857538.5 | O24: =M24-N24 | P24: =IF(N24<>0,O24/N24,"") | R24: -789922.53 | S24: -14566.72 | T24: -265550.94 | U24: -289366.8 | V24: -498131.5 | W24: =SUM(R24:V24)-M24 | X24: =T24+U24+V24
B25: 东风鸿远工程咨询有限公司 | C25: 2121 | D25: E_622215 | E25: 山东庆辉联达地质勘察有限公司 | F25: 采购款 | G25: 供应商 | H25: CNY | I25: -100602 | M25: =J25+L25 | N25: -100602 | O25: =M25-N25 | P25: =IF(N25<>0,O25/N25,"") | R25: -79993.4 | S25: -20608.6 | T25: 0 | U25: 0 | V25: 0 | W25: =SUM(R25:V25)-M25 | X25: =T25+U25+V25
B26: 东风鸿远工程咨询有限公司 | C26: 2121 | D26: E_614445 | E26: 湖北襄拓建工程有限公司 | F26: 采购款 | G26: 供应商 | H26: CNY | I26: -380988.56 | M26: =J26+L26 | N26: -380988.56 | O26: =M26-N26 | P26: =IF(N26<>0,O26/N26,"") | R26: -149098.24 | S26: -72086 | T26: -53369.2 | U26: -106435.12 | V26: 0 | W26: =SUM(R26:V26)-M26 | X26: =T26+U26+V26
B27: 东风鸿远工程咨询有限公司 | C27: 2121 | D27: E_598238 | E27: 中信建筑设计研究总院有限公司 | F27: 采购款 | G27: 供应商 | H27: CNY | I27: -124711.5 | M27: =J27+L27 | N27: -124711.5 | O27: =M27-N27 | P27: =IF(N27<>0,O27/N27,"") | R27: -47169.81 | S27: 0 | T27: 0 | U27: -77541.69 | V27: 0 | W27: =SUM(R27:V27)-M27 | X27: =T27+U27+V27
B28: 东风鸿远工程咨询有限公司 | C28: 2121 | D28: E_601843 | E28: 中国建筑设计研究院有限公司 | F28: 采购款 | G28: 供应商 | H28: CNY | I28: 0 | M28: =J28+L28 | N28: 0 | O28: =M28-N28 | P28: =IF(N28<>0,O28/N28,"") | R28: 0 | S28: 0 | T28: 0 | U28: 0 | V28: 0 | W28: =SUM(R28:V28)-M28 | X28: =T28+U28+V28
B29: 东风鸿远工程咨询有限公司 | C29: 2121 | D29: E_612459 | E29: 武汉狮山风景园林规划设计有限公司 | F29: 采购款 | G29: 供应商 | H29: CNY | I29: -1073083.3 | M29: =J29+L29 | N29: -1073083.3 | O29: =M29-N29 | P29: =IF(N29<>0,O29/N29,"") | R29: 0 | S29: -12400 | T29: 0 | U29: -1060683.3 | V29: 0 | W29: =SUM(R29:V29)-M29 | X29: =T29+U29+V29
B30: 东风鸿远工程咨询有限公司 | C30: 2121 | D30: E_608358 | E30: 新泰市泉沟镇华中钻井队 | F30: 采购款 | G30: 供应商 | H30: CNY | I30: -43649.5 | M30: =J30+L30 | N30: -43649.5 | O30: =M30-N30 | P30: =IF(N30<>0,O30/N30,"") | R30: 0 | S30: -4005 | T30: -39644.5 | U30: 0 | V30: 0 | W30: =SUM(R30:V30)-M30 | X30: =T30+U30+V30
B31: 东风鸿远工程咨询有限公司 | C31: 2121 | D31: E_468464 | E31: 湖北建科国际工程有限公司 | F31: 采购款 | G31: 供应商 | H31: CNY | I31: -33909.5 | M31: =J31+L31 | N31: -33909.5 | O31: =M31-N31 | P31: =IF(N31<>0,O31/N31,"") | R31: 0 | S31: 0 | T31: -33909.5 | U31: 0 | V31: 0 | W31: =SUM(R31:V31)-M31 | X31: =T31+U31+V31
B32: 东风鸿远工程咨询有限公司 | C32: 2121 | D32: E_625163 | E32: 老河口市蕴航工程勘察有限公司 | F32: 采购款 | G32: 供应商 | H32: CNY | I32: -269573.72 | M32: =J32+L32 | N32: -269573.72 | O32: =M32-N32 | P32: =IF(N32<>0,O32/N32,"") | R32: -6000.9 | S32: 0 | T32: -11650.49 | U32: -251922.33 | V32: 0 | W32: =SUM(R32:V32)-M32 | X32: =T32+U32+V32
B33: 东风鸿远工程咨询有限公司 | C33: 2121 | D33: E_623952 | E33: 武汉蕃华施工图设计审查有限公司 | F33: 采购款 | G33: 供应商 | H33: CNY | I33: -3883.5 | M33: =J33+L33 | N33: -3883.5 | O33: =M33-N33 | P33: =IF(N33<>0,O33/N33,"") | R33: 0 | S33: 0 | T33: 0 | U33: -3883.5 | V33: 0 | W33: =SUM(R33:V33)-M33 | X33: =T33+U33+V33
B34: 东风鸿远工程咨询有限公司 | C34: 2121 | D34: E_683167 | E34: 武汉企创通企业服务有限公司 | F34: 采购款 | G34: 供应商 | H34: CNY | I34: -3564.36 | M34: =J34+L34 | N34: -3564.36 | O34: =M34-N34 | P34: =IF(N34<>0,O34/N34,"") | R34: 0 | S34: -3564.36 | T34: 0 | U34: 0 | V34: 0 | W34: =SUM(R34:V34)-M34 | X34: =T34+U34+V34
... B48: 东风鸿远工程咨询有限公司 | C48: 2121 | D48: E_624681 | E48: 湖北南诚工程咨询有限公司 | F48: 采购款 | G48: 供应商 | H48: CNY | I48: -70000 | M48: =J48+L48 | N48: -70000 | O48: =M48-N48 | P48: =IF(N48<>0,O48/N48,"") | R48: 0 | S48: 0 | T48: -67961.17 | U48: -2038.83 | V48: 0 | W48: =SUM(R48:V48)-M48 | X48: =T48+U48+V48
B49: 东风鸿远工程咨询有限公司 | C49: 2121 | D49: E_605958 | E49: 四川省建筑设计研究院有限公司 | F49: 采购款 | G49: 供应商 | H49: CNY | I49: -6146733.9 | M49: =J49+L49 | N49: -6146733.9 | O49: =M49-N49 | P49: =IF(N49<>0,O49/N49,"") | Q49: NB7 | R49: -500000 | S49: -13950 | T49: 0 | U49: 0 | V49: -5632783.9 | W49: =SUM(R49:V49)-M49 | X49: =T49+U49+V49
B50: 东风鸿远工程咨询有限公司 | C50: 2121 | D50: E_622843 | E50: 武汉游途网络科技有限公司 | F50: 采购款 | G50: 供应商 | H50: CNY | I50: 0 | M50: =J50+L50 | N50: 0 | O50: =M50-N50 | P50: =IF(N50<>0,O50/N50,"") | R50: 0 | S50: 0 | T50: 0 | U50: 0 | V50: 0 | W50: =SUM(R50:V50)-M50 | X50: =T50+U50+V50
B51: 东风鸿远工程咨询有限公司 | C51: 2121 | D51: E_618178 | E51: 北京盈建科软件股份有限公司 | F51: 采购款 | G51: 供应商 | H51: CNY | I51: -40000 | M51: =J51+L51 | N51: -40000 | O51: =M51-N51 | P51: =IF(N51<>0,O51/N51,"") | R51: 0 | S51: 0 | T51: -40000 | U51: 0 | V51: 0 | W51: =SUM(R51:V51)-M51 | X51: =T51+U51+V51
B52: 东风鸿远工程咨询有限公司 | C52: 2121 | D52: E_613804 | E52: 武汉意创格致建筑工程设计有限公司 | F52: 采购款 | G52: 供应商 | H52: CNY | I52: -15637.12 | M52: =J52+L52 | N52: -15637.12 | O52: =M52-N52 | P52: =IF(N52<>0,O52/N52,"") | R52: 0 | S52: 0 | T52: 0 | U52: 0 | V52: -15637.12 | W52: =SUM(R52:V52)-M52 | X52: =T52+U52+V52
B53: 东风鸿远工程咨询有限公司 | C53: 2121 | D53: E_614043 | E53: 汉江中保信保安服务集团有限公司 | F53: 采购款 | G53: 供应商 | H53: CNY | I53: -33300 | M53: =J53+L53 | N53: -33300 | O53: =M53-N53 | P53: =IF(N53<>0,O53/N53,"") | R53: -33300 | S53: 0 | T53: 0 | U53: 0 | V53: 0 | W53: =SUM(R53:V53)-M53 | X53: =T53+U53+V53
B54: 东风鸿远工程咨询有限公司 | C54: 2121 | D54: E_619093 | E54: 中兵北勘(河北)工程检测有限公司 | F54: 采购款 | G54: 供应商 | H54: CNY | I54: 0 | M54: =J54+L54 | N54: 0 | O54: =M54-N54 | P54: =IF(N54<>0,O54/N54,"") | R54: 0 | S54: 0 | T54: 0 | U54: 0 | V54: 0 | W54: =SUM(R54:V54)-M54 | X54: =T54+U54+V54
B55: 东风鸿远工程咨询有限公司 | C55: 2121 | D55: E_600087 | E55: 湖北省鄂西北工程勘察有限责任公司 | F55: 采购款 | G55: 供应商 | H55: CNY | I55: -2189774.6 | M55: =J55+L55 | N55: -2189774.6 | O55: =M55-N55 | P55: =IF(N55<>0,O55/N55,"") | Q55: NB8 | R55: 0 | S55: -70000 | T55: -910671.69 | U55: -40377.35 | V55: -1168725.5 | W55: =SUM(R55:V55)-M55 | X55: =T55+U55+V55
...

Sheet N.02 异常项复核
B1: 标准工作底稿: N SWP 应付账款
B2: N.02: 借方余额测试和异常项目复核
B4: 返回汇总页
B6: ='N.00 Lead sheet'!E15 | C6: 用于识别和测试项目的测试阈值
B8: 安永属性测试说明：
B9: 1）获取并检查支持异常项目/借方余额的文档（例如，供应商发票、合同、采购订单、付款水单等），以及与应付账款明细账的相关详细信息（例如，供应商名称、发票编号、发票金额和商品/服务的性质）核对一致。
B10: 2） 我们获取了与所选交易相关的记账分录。我们确认应付账款记账分录的对方科目账务处理正确‌。
B11: 3） 根据我们对支持性文件（包括记账分录）的审查，得出结论认为，所选交易在应付账款中的分类是适当的。
B13: 借方余额测试
B14: 表1 我们获取了N.01.01明细账BKD中期末余额为借方的供应商，对（单独或合计）大于测试阈值的借方余额，检查了对应的支持文件，确认是否需要进行重分类。
B16: 借项期末余额合计
B17: 是否执行借方余额测试 | C17: =IF(C16>'N.00 Lead sheet'!$E$15,"是","否")
B18: 是否调整 | C18: =IF(C16>'N.00 Lead sheet'!$C$6,"是","否")
B20: 分析所选项目，以进行了解和正确分类。
L22: EY Works
B23: 供应商名称 | C23: 借方余额 | D23: 形成应付账款借方余额入账凭证 | G23: 根据交易性质获取的支持性证据信息 | L23: 1 | M23: 2 | N23: 3 | O23: 备注
D24: 凭证编号 | E24: 日期 | F24: 金额 | G24: 交易性质 | H24: 交易凭据名称 | I24: 交易凭据编号 | J24: 交易凭据日期 | K24: 交易凭据金额
B34: 其他异常项测试
B36: 表2 在下面记录选择关键项目的理由
L41: EY Works
B42: 选择标准 | C42: 供应商名称 | D42: 应付账款入账凭证 | G42: 支持性证据信息 （确认控制权转移/接受服务的交易凭据，如提单、运输单据（GDN)、第三方交货证明等） | L42: 1 | M42: 2 | N42: 3 | O42: 备注
D43: 凭证编号 | E43: 日期 | F43: 金额 | G43: 交易性质 | H43: 交易凭据名称 | I43: 交易凭据编号 | J43: 交易凭据日期 | K43: 交易凭据金额
B50: Notes：记录识别的异常情况的详细信息以及如何解决这些异常情况，包括执行的额外实质性程序

Sheet N.03 截止测试
B1: 标准工作底稿: N SWP 应付账款
B2: N.03: 应付账款截止测试
B4: 返回汇总页
B6: 表1 记录确定测试期间和样本策略的理由。
B11: 表2 记录用于执行程序的总体
B13: 资料名称 | C13: 涵盖期间 | D13: 备注
B18: 测试：用于在正确期间正确评估交易记录的截止测试项目
B20: 安永属性测试说明：
B21: 根据支持性证据（例如，提单、运输单据（GDN)、第三方交货证明等）确定所选交易已记录在适当会计期间，包含所有关联的总账账户（如，资产负债表和利润表账户）中。
B23: 应付账款入账凭证 | F23: 支持性证据信息 （确认控制权转移/接受服务的交易凭据，如提单、运输单据（GDN)、第三方交货证明等） | I23: 金额涉及： （用“√”标记） | K23: EY Works | L23: 备注
B24: 凭证编号 | C24: 日期 | D24: 金额 | E24: 供应商名称 | F24: 交易凭据名称 | G24: 交易凭据编号 | H24: 交易发生日期 | I24: 本期 | J24: 资产负债表日后期间 | K24: 1
B25: 截止日前的交易测试
B36: 截止日后的交易测试
B48: Notes：记录识别的异常情况的详细信息以及如何解决这些异常情况，包括执行的额外实质性程序

Sheet N.04 寻找未入账负债
B1: 标准工作底稿: N SWP 应付账款
B2: N.04: 寻找未入账负债
B4: 返回汇总页
B6: 请项目组使用以下链接获取标准底稿执行Search For程序：
B7: N&P SURL SWP 寻找未入账负债 202YMMDD XYZ公司.xlsx

Sheet SkywindSettingSheet
A1: eca72055-06d3-4dd3-bf25-5248c0ca8d3d
