Workbook

Sheet 汇总
A1: V6 SWP
B2: C.00 | C2: C.00 Lead sheet（认定：E、 V 、C） | F2: 程序页 | G2: 执行 | H2: 不执行的原因 | I2: 注意事项
B3: 1 | C3: 我们通过波动分析，识别不符合我们预期的账户设置以及账户余额的变化，并确认这些变化对计划实施的实质性程序的影响。 | F3: C.00 Lead
F4: C.00 BKD
B5: C.01 | C5: C.01 Confirmations（认定：E、 V 、C、R&O、P&D） | F5: 程序页 | G5: 执行 | H5: 不执行的原因 | I5: 注意事项
B6: 1 | C6: 我们对所有性质或金额重大的账户发送询证函，将回函金额核对到银行余额调节表中的银行余额，对于无余额调节项的账户，我们将回函金额直接核对到账面余额。我们审阅回函中的其他信息，我们在<C.01>记录函证跟进工作； 当函证程序不适用时，或回函除金额外的其他信息（如资金归集）需要进一步测试，我们在<C.01b>中记录我们的工作。 | F6: C.01 Confirmations
F7: C.01b 特殊账户程序
B8: C.00b | C8: C.00b Other classification （认定：P&D） | F8: 程序页 | G8: 执行 | H8: 不执行的原因 | I8: 注意事项
B9: 1 | C9: 我们评估管理层对货币资金明细项的分类是否正确，包括其中的受限项目、现金及现金等价物类别的项目。 | F9: C.00b Other classification
B10: C.02 | C10: C.02 Bank reconciliations（认定：E、 V 、C） | F10: 程序页 | G10: 执行 | H10: 不执行的原因 | I10: 注意事项
B11: 1 | C11: 我们通过<C.01>及<C.01b>识别存在余额调节项的银行账户，并获取这些账户的余额调节表。 我们识别并选择了大于TT测试阈值的调节项以及其他被认为异常或预期外的调节项进行测试，我们识别并调查超SAD名义金额的未调节差异。 我们针对选中测试的有调节项的银行账户及识别出存在与调节项完整性相关的重大错报风险的银行账户，获取并复核了期后银行对账单。 | F11: C.02 Bank reconciliations
F12: C.02a外币测算
B13: C.03 | C13: C.03 Cutoff （认定：E、 C） | F13: 程序页 | G13: 执行 | H13: 不执行的原因 | I13: 注意事项
B14: 1 | C14: 此程序涉及被审计单位，在适用函证测试范围内的银行账户，与被审计单位的另一个银行账户（不局限于适用函证测试的银行账户）之间的转账。我们记录了确定截止期间的理由，包含我们在⻛险评估程序中的考虑事项，以及这些事项如何影响我们对截⽌期间和样本量的确定。 IPE 考虑： | F14: C.03 Cutoff | I14: 根据账户的性质和交易的金额，选取金额以及性质重大的账户进行截止性测试。 中国境内的银行转账业务基本能够实现T+1入账，因此我们往往选择资产负债表日前后1天作为测试期间；但如在期末，存在较多跨境交易和国际账户，则需适当延长测试期间。 | J14: 46387
B16: C.00 | C16: Supplementary | F16: 文件名称
B17: C.00a | C17: 我们评估管理层对现⾦和现⾦等价物负值余额分类的适当性。 | F17: C.00a Negative cash | J17: ../../../../emma_jh_he_cn_ey_com/Documents/Desktop/FY26/C%20PO/C.00d%20Negative%20cash.xlsx?web=1
B18: C.00c | C18: 我们对现金执行了盘点程序。 | F18: C.00c 现金盘点 | J18: ../../../../emma_jh_he_cn_ey_com/Documents/Desktop/FY26/C%20PO/C.00e%20%E7%8E%B0%E9%87%91%E7%9B%98%E7%82%B9.xlsx?web=1

Sheet C.00 Lead
A1: 022d804f-8de8-4987-b9ac-42632653fc60 | B1: 标准工作底稿: C SWP 货币资金
B2: 客户名称 | C2: 东风鸿远工程咨询有限公司 | D2: 此工作底稿需要与以下 Canvas PSP guided workflow forms一起使用： • C.00 Cash lead sheet • C.01 Bank confirmations • C.02 Bank reconciliations • C.03 Cash cutoff • Account conclusion
B3: 期末 | C3: 46387
B4: 分析日期 | C4: 46168.728
B5: 可容忍误差(TE)
B6: 名义金额(SAD)
B7: 适用会计准则 | C7: PRC
B8: 记账本位币 | C8: CNY
B9: C.00 编制引导表并比较余额
B11: 返回汇总页
D13: Threshold(s) | H13: 安永标记
B14: 认定 | C14: CRA | D14: 各项认定1 | E14: 所有相关认定 2 | H14: TB | I14: 已与科目余额表核对无误
B15: 完整性 (C) | D15: =IF(C15="Minimal",$C$5*100%,IF(C15="Low",$C$5*75%,IF(C15="Moderate",$C$5*50%,IF(C15="High",$C$5*25%,IF(C15="N/A","-",))))) | E15: =MIN($D$15:$D$19) | H15: PY | I15: 与上年最终审定数核对一致
B16: 存在性 (E) | D16: =IF(C16="Minimal",$C$5*100%,IF(C16="Low",$C$5*75%,IF(C16="Moderate",$C$5*50%,IF(C16="High",$C$5*25%,IF(C16="N/A","-",))))) | H16: A3 | I16: 与未审数、审定数核对一致
B17: 计价（V） | D17: =IF(C17="Minimal",$C$5*100%,IF(C17="Low",$C$5*75%,IF(C17="Moderate",$C$5*50%,IF(C17="High",$C$5*25%,IF(C17="N/A","-",))))) | H17: A5 | I17: 与审计调整核对一致
B18: 权利和义务（R&O） | D18: =IF(C18="Minimal",$C$5*100%,IF(C18="Low",$C$5*75%,IF(C18="Moderate",$C$5*50%,IF(C18="High",$C$5*25%,IF(C18="N/A","-",))))) | H18: FS | I18: 与FS.0x与财务报表核对无误
B19: 列报和披露（P&D） | D19: =IF(C19="Minimal",$C$5*100%,IF(C19="Low",$C$5*75%,IF(C19="Moderate",$C$5*50%,IF(C19="High",$C$5*25%,IF(C19="N/A","-",))))) | H19: w | I19: 低于SAD的金额——放弃进一步调查
B20: 1 各项认定的测试阈值，是根据EY GAM SUBSTANTIVE DESIGN 2.2.1 | H20: Rx | I20: 重新计算，无异常
B21: 中的示例测试阈值（用占TE的百分比表示）在相应风险等级（CRA）区间的上限计算得出的。 | H21: m | I21: 余额/活动不符合测试范围–无需进一步调查
B22: 除负债/费用类别账户的完整性认定应当使用负债/费用账户表之外，其他类别账户和认定均可使用资产/收入账户表。 | H22: SL | I22: 已与明细账核对无误
B23: 2 所有相关认定的测试阈值，是所有有效认定对应之测试阈值的最小值。我们在 Lead中使用该测试阈值：（a）作为选取总账账户进行测试的起点；（b）作为（需要进一步调查的）金额波动范围的起点。
B25: 在下文中描述我们当期对现金账户余额和相关波动的预期，以及这些预期的依据和理由。
B30: 波动范围
B31: ="波动幅度 ("&C8& "):" | C31: =E15
B32: 波动幅度（%）： | C32: 0.1
B34: 表1 | F34: |------- TB -------| | K34: |------- PY -------|
F35: ="货币/单位: "&C8
F36: =C3 | K36: =DATE(YEAR($C$3)-1,12,31) | L36: 本期和上期期末余额 | O36: 基于波动幅度判断，是否进一步调查？ | P36: 基于定性考虑判断，是否进一步调查？
B37: 账套名称/账套编码 | C37: 总账科目编码 | D37: 科目名称 | E37: 索引号 | F37: 期末账面数 | G37: 账表调整数 | H37: 期末未审数 | I37: 审计调整数 | J37: 期末审定数 | K37: 上期末审定数 | L37: 变动金额 | M37: 变动% | N37: Notes
B38: 东风鸿远工程咨询有限公司 | C38: 1002 | D38: 银行存款 | E38: C.00 BKD/ | H38: =F38+G38 | J38: =H38+I38 | K38: 5924414.1 | L38: =J38-K38 | M38: =IF(K38<>0,L38/K38,1) | N38: [A] | O38: =IF(AND(ABS(L38)>=$C$31,ABS(M38)>=$C$32),"是","否")
B39: 东风鸿远工程咨询有限公司福建分公司 | C39: 1002 | D39: 银行存款 | H39: =F39+G39 | J39: =H39+I39 | K39: 605.89 | L39: =J39-K39 | M39: =IF(K39<>0,L39/K39,1) | O39: =IF(AND(ABS(L39)>=$C$31,ABS(M39)>=$C$32),"是","否")
B40: 东风鸿远工程咨询有限公司武汉分公司 | C40: 1002 | D40: 银行存款 | H40: =F40+G40 | J40: =H40+I40 | K40: 8043.03 | L40: =J40-K40 | M40: =IF(K40<>0,L40/K40,1) | O40: =IF(AND(ABS(L40)>=$C$31,ABS(M40)>=$C$32),"是","否")
B41: 东风鸿远工程咨询有限公司监理分公司 | C41: 1002 | D41: 银行存款 | K41: 122094.03
E43: 合计 | F43: =SUM(F37:F40) | G43: =SUM(G37:G40) | H43: =SUM(H37:H40) | I43: =SUM(I37:I40) | J43: =SUM(J37:J40) | K43: =SUM(K37:K40) | L43: =J43-K43 | M43: =IF(K43<>0,L43/K43,1) | O43: =IF(AND(ABS(L43)>=$C$31,ABS(M43)>=$C$32),"是","否")
F44: Rx | G44: Rx | H44: Rx | I44: Rx | J44: Rx | K44: Rx
G46: A3
G47: Diff | H47: =H43-H46 | J47: =J43-J46 | K47: =K43-K46
B49: 波动说明
B50: [A]
B54: 调整汇总表（如不适用请删除）
...

Sheet C.00 BKD
A1: cd8846d7-01cb-4e39-99f2-dd3fb53a39f3 | B1: 标准工作底稿: C SWP 货币资金
B2: C.00 BKD
B4: 返回汇总页
B6: 全量货币资金明细表
B8: TB | C8: TB | D8: TB | E8: TB | F8: TB | G8: TB | H8: TB | I8: PBC&C.01 | J8: EY Works | K8: EY Works
B9: 公司名称 | C9: 科目名称 | D9: 银行/存款机构名称 | E9: 账号1 | F9: 币种 | G9: 期末账面金额 （原币） | H9: 期末账面金额 （本币） | I9: 货币资金账户的性质和用途 | J9: 是否对账户执行银行函证程序？ | K9: 记录我们判断账户在金额及性质上均不重大的理由和执行的工作，或，在<C.01b>记录我们执行的替代性程序。 | L9: Notes
K12: =IF(J12="是","N/a","")
K13: =IF(J13="是","N/a","")
K14: =IF(J14="是","N/a","")
K15: =IF(J15="是","N/a","")
B16: 1.本表格包括所有的货币资金信息，我们将本期账户及其余额与上期账户及其余额核对，确保本期内新增、销户的账户均包含在表格中。
H17: =SUM(H10:H15)
H18: RX
G19: C_Lead | H19: =H17-'C.00 Lead'!F42
B21: Notes

Sheet SkywindSettingSheet
A1: 0a1351bf-0789-4e2c-8675-482199dfc116
