Workbook

Sheet 汇总
A1: V6 SWP
B2: 该科目涉及OSP底稿可参考此链接 | E2: OSP L1 SWP 开发支出 202YMMDD XYZ公司.xlsx
E3: OSP L1 SWP 无形资产权属检查 202YMMDD XYZ公司.xlsx
E4: OSP L1 SWP 无形资产资本化支出 202YMMDD XYZ公司.xlsx
B6: L1.00 | C6: L1.00 Lead sheet（认定：E、V、C、R&O、P&D） | F6: 程序页 | G6: 执行 | H6: 不执行的原因
B7: 1 | C7: 获取和编制无形资产两期变动的引导表，并与试算平衡表和上年底稿核对一致。对无形资产变动建立预期并说明理由，对不符合预期的变动以及异常变动进行调查和分析。 | F7: L1.00 Lead sheet
B8: L1.01.1 | C8: L1.01.1 Agree SL to GL（认定：E、V、C、R&O、P&D） | F8: 程序页 | G8: 执行 | H8: 不执行的原因
B9: 1 | C9: 获取无形资产后推明细表，并将其与试算平衡表和无形资产清单核对一致。 | F9: L1.01.1 Agree SL to GL
B10: L1.02.1 | C10: L1.02.1 新增测试 &新增清单（认定：E、V、C、R&O、P&D） | F10: 程序页 | G10: 执行 | H10: 不执行的原因
B11: 1 | C11: 获取当期按类别划分的所有无形资产新增清单，并将该列表与无形资产后推核对一致，调查超过SAD名义金额的差额。 | F11: 新增清单
B12: 2 | C12: 对本年新增资产执行关键项目测试和代表性样本测试（如需要）。 | F12: L1.02.1 新增测试
B13: L1.02.2 | C13: L1.02.2 处置测试 & 处置清单（认定：E、V、C、R&O、P&D） | F13: 程序页 | G13: 执行 | H13: 不执行的原因
B14: 1 | C14: 获取当期按类别划分的所有无形资产处置清单，包括记录的处置的损益，并将该列表与无形资产后推核对一致，我们调查超过SAD名义金额的差额。 | F14: 处置清单
B15: 2 | C15: 对本年处置资产执行关键项目测试和代表性样本测试（如需要）。 | F15: L1.02.2 处置测试
B16: L1.03 | C16: L1.03 摊销测试（认定：E、V、C、R&O、P&D） | F16: 程序页 | G16: 执行 | H16: 不执行的原因
B17: 1 | C17: 按照公司摊销政策对本年应计提摊销执行重新计算（by item），并与账面进行核对，调查超过SAD名义金额的差额。 检查无形资产各项目的摊销政策是否符合有关规定，是否与上期一致，其是否具有商业合理性。若改变摊销政策，检查其依据是否充分。 | F17: L1.03 摊销测试
B18: L1.04 | C18: L1.04 无形资产的减值（认定：V） | F18: 程序页 | G18: 执行 | H18: 不执行的原因
B19: 1 | C19: 验证是否已按照公司的会计政策或适用财务报告框架进行了适当调整，以反映无形资产的账面价值的减值。 | F19: 项目组自行填写底稿索引

Sheet L1.00 Lead sheet
B1: 标准工作底稿: L1 SWP 无形资产
B2: 客户名称 | C2: 东风鸿远工程咨询有限公司
B3: 期末 | C3: 46387
B4: 分析日期 | C4: 46169.597
B5: 可容忍误差(TE）
B6: 名义金额（SAD）
B7: 公认会计准则（GAAP） | C7: PRC
B8: 记账本位币 | C8: CNY
B9: L1.00：编制引导表并比较余额
B11: 返回汇总页
D13: Threshold(s) | H13: 安永标记
B14: 认定 | C14: CRA | D14: 各项认定1 | E14: 所有相关认定 2 | H14: TB | I14: 已与科目余额表核对无误
B15: 完整性 (C) | D15: =IF(C15="Minimal",$C$5*100%,IF(C15="Low",$C$5*75%,IF(C15="Moderate",$C$5*50%,IF(C15="High",$C$5*25%,IF(C15="N/A","-",))))) | E15: =MIN($D$15:$D$19) | H15: PY | I15: 与上年最终审定数核对一致
B16: 存在性 (E) / 发生 (O) | D16: =IF(C16="Minimal",$C$5*100%,IF(C16="Low",$C$5*75%,IF(C16="Moderate",$C$5*50%,IF(C16="High",$C$5*25%,IF(C16="N/A","-",))))) | H16: A3 | I16: 与未审数、审定数核对一致
B17: 计价/计量 (V/M) | D17: =IF(C17="Minimal",$C$5*100%,IF(C17="Low",$C$5*75%,IF(C17="Moderate",$C$5*50%,IF(C17="High",$C$5*25%,IF(C17="N/A","-",))))) | H17: A5 | I17: 与审计调整核对一致
B18: 权利和义务 (R&O) | D18: =IF(C18="Minimal",$C$5*100%,IF(C18="Low",$C$5*75%,IF(C18="Moderate",$C$5*50%,IF(C18="High",$C$5*25%,IF(C18="N/A","-",))))) | H18: FS | I18: 与FS.0x与财务报表核对无误
B19: 列报和披露 (P&D) | D19: =IF(C19="Minimal",$C$5*100%,IF(C19="Low",$C$5*75%,IF(C19="Moderate",$C$5*50%,IF(C19="High",$C$5*25%,IF(C19="N/A","-",))))) | H19: w | I19: 低于SAD的金额——放弃进一步调查
B20: 1 各项认定的测试阈值，是根据EY GAM SUBSTANTIVE DESIGN 2.2.1 | H20: Rx | I20: 重新计算，无异常
B21: 中的示例测试阈值（用占TE的百分比表示）在相应风险等级（CRA）区间的上限计算得出的。 | H21: m | I21: 余额/活动不符合测试范围–无需进一步调查
B22: 除负债/费用类别账户的完整性认定应当使用负债/费用账户表之外，其他类别账户和认定均可使用资产/收入账户表。 | H22: SL | I22: 已与明细账核对无误
B23: 2 所有相关认定的测试阈值，是所有有效认定对应之测试阈值的最小值。我们在 Lead中使用该测试阈值：（a）作为选取总账账户进行测试的起点；（b）作为（需要进一步调查的）金额波动范围的起点。
B25: 以下描述我们对无形资产的预期，在此期间的相关账户余额和相关波动，以及我们这些预期的依据和理由。（请对无形资产L1.01.1 BKD中表1的变动项分别进行预期，如新增、处置、摊销方法、摊销年限、摊销费用、使用寿命变化等。）
B31: 波动范围
B32: ="波动幅度 ("&C8& "):" | C32: =$E$15
B33: 波动幅度(%): | C33: 0.1
B35: 我们获取或编制了与上期对比的重大账户（无形资产）引导表。我们将本期余额与试算平衡表核对一致，并将上期余额与上期审定数核对一致（如适用）。
B36: 我们将期末余额与上期余额进行对比。调查超出测试阈值（金额和百分比）的波动，以及代表异常或预期外变动或未发生预期中变动的波动，并确定其对我们计划实质性程序的影响（如有）。
E38: |------- TB -------| | J38: |------- PY -------|
E39: ="货币/单位: "&C8
E40: =C3 | J40: =DATE(YEAR($C$3)-1,12,31) | K40: 本期和上期期末余额 | N40: 基于波动幅度判断，是否进一步调查？ | O40: 基于定性考虑判断，是否进一步调查？
B41: 总账科目编码 | C41: 科目名称 | D41: 索引号 | E41: 期末账面数 | F41: 账表调整数 | G41: 期末未审数 | H41: 审计调整数 | I41: 期末审定数 | J41: 上期末审定数 | K41: 变动金额 | L41: 变动% | M41: Notes
B42: 1701 | C42: 无形资产 | D42: L.01.1 | E42: ='L1.01.1 Agree SL to GL'!T37 | G42: =E42+F42 | I42: =G42+H42 | J42: 1.4041923e+10 | K42: =I42-J42 | L42: =IF(J42<>0,K42/J42,1) | M42: [A] | N42: =IF(AND(ABS(K42)>=$C$32,ABS(L42)>=$C$33),"是","否")
B43: 1702 | C43: 累计摊销 | D43: L.01.1 | E43: ='L1.01.1 Agree SL to GL'!T39 | G43: =E43+F43 | I43: =G43+H43 | J43: 9.2632666e+09 | K43: =I43-J43 | L43: =IF(J43<>0,K43/J43,1) | N43: =IF(AND(ABS(K43)>=$C$32,ABS(L43)>=$C$33),"是","否")
B44: 1703 | C44: 减值准备 | D44: L.01.1 | E44: ='L1.01.1 Agree SL to GL'!T41 | G44: =E44+F44 | I44: =G44+H44 | J44: 2.8684149e+09 | K44: =I44-J44 | L44: =IF(J44<>0,K44/J44,1) | N44: =IF(AND(ABS(K44)>=$C$32,ABS(L44)>=$C$33),"是","否")
C46: 合计 | E46: =E42-E43-E44 | F46: =F42-F43-F44 | G46: =G42-G43-G44 | H46: =H42-H43-H44 | I46: =I42-I43-I44 | J46: =J42-J43-J44 | K46: =K42-K43-K44 | L46: =IF(J46<>0,K46/J46,1) | N46: =IF(AND(ABS(K46)>=$C$32,ABS(L46)>=$C$33),"是","否")
C48: check with A3
C49: Diff | G49: =G48-G46 | I49: =I48-I46 | J49: =J48-J46
B51: 波动说明
B52: [A]
B57: 调整汇总表（如不适用请删除）
...

Sheet L1.01.1 Agree SL to GL
B1: 标准工作底稿: L1 SWP 无形资产
B2: L1.01.1 明细账与总账核对一致
B4: 返回汇总页
B6: 获取上期末至本期末（或中期，如适用）无形资产及相关新增、处置、转让和摊销的后推明细表。（原值、累计摊销、减值均为正数填列，本期减少以负数填列，账表调整、审计调整数据均直接链接至L1.00 Lead sheet。）以下资产类别作为示例，审计团队需按照被审计单位实际情况修改。
B7: 将期初无形资产余额与上期审定数核对一致，将期末无形资产余额与无形资产明细账和试算表核对一致。调查大于SAD的差异。
B8: 我们选择了超过测试阈值的后推活动（如，新增、处置、转移和摊销费用），以执行L1.02和L1.03的实质性程序。对于未包含在本程序表范围内的程序，我们交叉索引至完成该程序的单独程序表。我们评估了无形资产的其他转出和其他调整，以了解调整的性质，并确定是否需要执行额外程序。
B9: 表1
F10: 土地使用权 | I10: 非专利技术 | L10: 专利权 | O10: 软件 | R10: 其他 | U10: 合计 | W10: Check
E11: 账面数 | F11: 账表调整/审计调整 | G11: 审定数 | H11: 账面数 | I11: 账表调整/审计调整 | J11: 审定数 | K11: 账面数 | L11: 账表调整/审计调整 | M11: 审定数 | N11: 账面数 | O11: 账表调整/审计调整 | P11: 审定数 | Q11: 账面数 | R11: 账表调整/审计调整 | S11: 审定数 | T11: 账面数 | U11: 账表调整/审计调整 | V11: 审定数
B12: 原值 | C12: 年初余额 | D12: PY | E12: 2.894701e+08 | F12: 211 | G12: =SUM(E12:F12) | H12: 3.0947623e+09 | I12: 0 | J12: =SUM(H12:I12) | K12: 5.8544226e+09 | L12: 0 | M12: =SUM(K12:L12) | N12: 6.7621062e+08 | O12: 0 | P12: =SUM(N12:O12) | Q12: 4.1270576e+09 | R12: 0 | S12: =SUM(Q12:R12) | T12: =SUM(Q12,N12,K12,H12,E12) | U12: =F12+I12+L12+O12+R12 | V12: =G12+J12+M12+P12+S12 | W12: =V12-'L1.00 Lead sheet'!J42
C13: 购置 | D13: L1.02.1 | G13: =SUM(E13:F13) | J13: =SUM(H13:I13) | M13: =SUM(K13:L13) | P13: =SUM(N13:O13) | S13: =SUM(Q13:R13) | T13: =SUM(Q13,N13,K13,H13,E13) | U13: =F13+I13+L13+O13+R13 | V13: =G13+J13+M13+P13+S13
C14: 本年其他新增 | G14: =SUM(E14:F14) | J14: =SUM(H14:I14) | M14: =SUM(K14:L14) | P14: =SUM(N14:O14) | S14: =SUM(Q14:R14) | T14: =SUM(Q14,N14,K14,H14,E14) | U14: =F14+I14+L14+O14+R14 | V14: =G14+J14+M14+P14+S14
C15: 处置或报废 | D15: L1.02.2 | G15: =SUM(E15:F15) | J15: =SUM(H15:I15) | M15: =SUM(K15:L15) | P15: =SUM(N15:O15) | S15: =SUM(Q15:R15) | T15: =SUM(Q15,N15,K15,H15,E15) | U15: =F15+I15+L15+O15+R15 | V15: =G15+J15+M15+P15+S15
C16: 本年其他转出 | G16: =SUM(E16:F16) | J16: =SUM(H16:I16) | M16: =SUM(K16:L16) | P16: =SUM(N16:O16) | S16: =SUM(Q16:R16) | T16: =SUM(Q16,N16,K16,H16,E16) | U16: =F16+I16+L16+O16+R16 | V16: =G16+J16+M16+P16+S16
C17: 年末余额 | D17: Rx | E17: =SUM(E12:E16) | F17: =SUM(F12:F16) | G17: =SUM(G12:G16) | H17: =SUM(H12:H16) | I17: =SUM(I12:I16) | J17: =SUM(J12:J16) | K17: =SUM(K12:K16) | L17: =SUM(L12:L16) | ... V17: =SUM(V12:V16) | W17: =V17-'L1.00 Lead sheet'!I42
C18: 年初余额 | D18: PY | E18: 60441788 | F18: 0 | G18: =SUM(E18:F18) | H18: 2.5573709e+09 | I18: 0 | J18: =SUM(H18:I18) | K18: 3.3245493e+09 | L18: 0 | M18: =SUM(K18:L18) | N18: 5.5397529e+08 | O18: 0 | P18: =SUM(N18:O18) | Q18: 2.7669293e+09 | R18: 0 | S18: =SUM(Q18:R18) | T18: =SUM(Q18,N18,K18,H18,E18) | U18: =F18+I18+L18+O18+R18 | V18: =G18+J18+M18+P18+S18 | W18: =V18-'L1.00 Lead sheet'!J43
C19: 计提 | D19: L1.01.1a | G19: =SUM(E19:F19) | J19: =SUM(H19:I19) | M19: =SUM(K19:L19) | P19: =SUM(N19:O19) | S19: =SUM(Q19:R19) | T19: =SUM(Q19,N19,K19,H19,E19) | U19: =F19+I19+L19+O19+R19 | V19: =G19+J19+M19+P19+S19 | W19: =V19+'L1.03 摊销测试'!H18
B20: 累计摊销 | C20: 处置或报废 | D20: L1.02.2 | G20: =SUM(E20:F20) | J20: =SUM(H20:I20) | M20: =SUM(K20:L20) | P20: =SUM(N20:O20) | S20: =SUM(Q20:R20) | T20: =SUM(Q20,N20,K20,H20,E20) | U20: =F20+I20+L20+O20+R20 | V20: =G20+J20+M20+P20+S20
C21: 本年其他转出 | G21: =SUM(E21:F21) | J21: =SUM(H21:I21) | M21: =SUM(K21:L21) | P21: =SUM(N21:O21) | S21: =SUM(Q21:R21) | T21: =SUM(Q21,N21,K21,H21,E21) | U21: =F21+I21+L21+O21+R21 | V21: =G21+J21+M21+P21+S21
C22: =C17 | D22: Rx | E22: =SUM(E18:E21) | F22: =SUM(F18:F21) | G22: =SUM(G18:G21) | H22: =SUM(H18:H21) | I22: =SUM(I18:I21) | J22: =SUM(J18:J21) | K22: =SUM(K18:K21) | L22: =SUM(L18:L21) | ... V22: =SUM(V18:V21) | W22: =V22-'L1.00 Lead sheet'!I43
C23: 年初余额 | D23: PY | E23: 0 | F23: 0 | G23: =SUM(E23:F23) | H23: 4.1652613e+08 | I23: 0 | J23: =SUM(H23:I23) | K23: 1.9889879e+09 | L23: 0 | M23: =SUM(K23:L23) | N23: 5406999.2 | O23: 0 | P23: =SUM(N23:O23) | Q23: 4.5749393e+08 | R23: 0 | S23: =SUM(Q23:R23) | T23: =SUM(Q23,N23,K23,H23,E23) | U23: =F23+I23+L23+O23+R23 | V23: =G23+J23+M23+P23+S23 | W23: =V23-'L1.00 Lead sheet'!J44
C24: 计提 | D24: SWP减值 | G24: =SUM(E24:F24) | J24: =SUM(H24:I24) | M24: =SUM(K24:L24) | P24: =SUM(N24:O24) | S24: =SUM(Q24:R24) | T24: =SUM(Q24,N24,K24,H24,E24) | U24: =F24+I24+L24+O24+R24 | V24: =G24+J24+M24+P24+S24
B25: 减值准备 | C25: 处置或报废 | D25: L1.02.2 | G25: =SUM(E25:F25) | J25: =SUM(H25:I25) | M25: =SUM(K25:L25) | P25: =SUM(N25:O25) | S25: =SUM(Q25:R25) | T25: =SUM(Q25,N25,K25,H25,E25) | U25: =F25+I25+L25+O25+R25 | V25: =G25+J25+M25+P25+S25
C26: 本年其他转出 | D26: SWP减值 | G26: =SUM(E26:F26) | J26: =SUM(H26:I26) | M26: =SUM(K26:L26) | P26: =SUM(N26:O26) | S26: =SUM(Q26:R26) | T26: =SUM(Q26,N26,K26,H26,E26) | U26: =F26+I26+L26+O26+R26 | V26: =G26+J26+M26+P26+S26
C27: =C17 | D27: Rx | E27: =SUM(E23:E26) | F27: =SUM(F23:F26) | G27: =SUM(G23:G26) | H27: =SUM(H23:H26) | I27: =SUM(I23:I26) | J27: =SUM(J23:J26) | K27: =SUM(K23:K26) | L27: =SUM(L23:L26) | ... V27: =SUM(V23:V26) | W27: =V27-'L1.00 Lead sheet'!I44
B28: 净值 (NBV) | C28: =C17 | D28: Rx | E28: =E17-E22-E27 | F28: =F17-F22-F27 | G28: =G17-G22-G27 | H28: =H17-H22-H27 | I28: =I17-I22-I27 | J28: =J17-J22-J27 | K28: =K17-K22-K27 | L28: =L17-L22-L27 | ... S28: =S17-S22-S27 | T28: =SUM(S28,N28,K28,H28,E28) | U28: =F28+I28+L28+O28+R28 | V28: =G28+J28+M28+P28+S28 | W28: =V28-'L1.00 Lead sheet'!I48
C29: =C12 | D29: Rx | E29: =E12-E18-E23 | F29: =F12-F18-F23 | G29: =G12-G18-G23 | H29: =H12-H18-H23 | I29: =I12-I18-I23 | J29: =J12-J18-J23 | K29: =K12-K18-K23 | L29: =L12-L18-L23 | ... S29: =S12-S18-S23 | T29: =SUM(S29,N29,K29,H29,E29) | U29: =F29+I29+L29+O29+R29 | V29: =G29+J29+M29+P29+S29 | W29: =V29-'L1.00 Lead sheet'!J48
B30: 变动 | C30: 原值变动金额 | D30: 本年VS上年 | E30: =E17-E12 | F30: =F17-F12 | G30: =G17-G12 | H30: =H17-H12 | I30: =I17-I12 | J30: =J17-J12 | K30: =K17-K12 | L30: =L17-L12 | ... V30: =V17-V12
C31: 原值变动比例 | D31: % | E31: =IFERROR(E30/E12,1) | G31: =IFERROR(G30/G12,1) | H31: =IFERROR(H30/H12,1) | J31: =IFERROR(J30/J12,1) | K31: =IFERROR(K30/K12,1) | M31: =IFERROR(M30/M12,1) | N31: =IFERROR(N30/N12,1) | P31: =IFERROR(P30/P12,1) | Q31: =IFERROR(Q30/Q12,1) | S31: =IFERROR(S30/S12,1) | T31: =IFERROR(T30/T12,1) | V31: =IFERROR(V30/V12,1)
C32: 累计摊销变动金额 | D32: 本年VS上年 | E32: =E22-E18 | G32: =G22-G18 | H32: =H22-H18 | J32: =J22-J18 | K32: =K22-K18 | M32: =M22-M18 | N32: =N22-N18 | P32: =P22-P18 | Q32: =Q22-Q18 | S32: =S22-S18 | T32: =T22-T18 | V32: =V22-V18
C33: 累计摊销变动比例 | D33: % | E33: =IFERROR(E32/E18,1) | G33: =IFERROR(G32/G18,1) | H33: =IFERROR(H32/H18,1) | J33: =IFERROR(J32/J18,1) | K33: =IFERROR(K32/K18,1) | M33: =IFERROR(M32/M18,1) | N33: =IFERROR(N32/N18,1) | P33: =IFERROR(P32/P18,1) | Q33: =IFERROR(Q32/Q18,1) | S33: =IFERROR(S32/S18,1) | T33: =IFERROR(T32/T18,1) | V33: =IFERROR(V32/V18,1)
C34: 减值准备变动金额 | D34: 本年VS上年 | E34: =E27-E23 | G34: =G27-G23 | H34: =H27-H23 | J34: =J27-J23 | K34: =K27-K23 | M34: =M27-M23 | N34: =N27-N23 | P34: =P27-P23 | Q34: =Q27-Q23 | S34: =S27-S23 | T34: =T27-T23 | V34: =V27-V23
C35: 减值准备变动比例 | D35: % | E35: =IFERROR(E34/E23,1) | G35: =IFERROR(G34/G23,1) | H35: =IFERROR(H34/H23,1) | J35: =IFERROR(J34/J23,1) | K35: =IFERROR(K34/K23,1) | M35: =IFERROR(M34/M23,1) | N35: =IFERROR(N34/N23,1) | P35: =IFERROR(P34/P23,1) | Q35: =IFERROR(Q34/Q23,1) | S35: =IFERROR(S34/S23,1) | T35: =IFERROR(T34/T23,1) | V35: =IFERROR(V34/V23,1)
B37: TB-原值 | T37: =E37+H37+K37+N37+Q37
B38: 差异 | E38: =E37-E17 | H38: =H37-H17 | K38: =K37-K17 | N38: =N37-N17 | Q38: =Q37-Q17 | T38: =T37-T17
B39: TB-累计摊销 | T39: =E39+H39+K39+N39+Q39
B40: 差异 | E40: =E39-E22 | H40: =H39-H22 | K40: =K39-K22 | N40: =N39-N22 | Q40: =Q39-Q22 | T40: =T39-T22
B41: TB-减值准备 | T41: =E41+H41+K41+N41+Q41
B42: 差异 | E42: =E41-E27 | H42: =H41-H27 | K42: =K41-K27 | N42: =N41-N27 | Q42: =Q41-Q27 | T42: =T41-T27
B43: TB-净值 | T43: =E43+H43+K43+N43+Q43
...

Sheet L1.02.1 新增测试
B1: 标准工作底稿: L1 SWP 无形资产
B2: L1.02.1：详细测试 (新增)
B4: 返回汇总页
B6: 记录我们的详细测试所涵盖的总体（指引：纳入充分的描述，以使经验丰富且之前与该项审计无关的审计师能够理解样本是如何选择的，例如，总体的分类或筛选。）
B12: 购置总金额
B13: Breakdown中购置金额 | E13: ='L1.01.1 Agree SL to GL'!T13 | F13: L1.01.1
B14: 差异 | E14: =E12-E13 | F14: Rx | G14: 差异是否需要进一步调查？ | J14: =IF(ABS(E14)>'L1.00 Lead sheet'!$C$6, "Yes", "No")
B16: 减：测试的关键项目
B17: 进行代表性抽样的剩余总体 | E17: =E12-E16
B19: 在下方描述选择关键项目的理由（请参阅Canvas指导工作流程的“关键项目”部分，包括信息图标）
B25: EY 测试属性解释:
B26: 对于每个被选中进行测试的项目，我们检查了相关的第三方证据以及相关的会计分录，并确定：
B27: 1) 测试样本于恰当的日期被正确资本化为无形资产（即，不应该费用化）。
B28: 2) 历史成本已根据适用的财务报告框架进行记录。
B29: 3) 管理层对测试项目采用的使用寿命和摊销方法是适当的（符合实体的会计政策和适用的财务报告框架）。
B30: 4) 该资产已被归入适当的无形资产类别。
O31: |------- Rx -------| | P31: EY Works
B32: 样本序号 | C32: 样本类型 | D32: 无形资产类别 | E32: 总账账户代码 | F32: 无形资产编号 | G32: 无形资产名称 | H32: 资产原价 | I32: 资本化日期 | J32: 使用寿命 (月) | K32: 残值率 | L32: 摊销政策 | M32: 资产原价（通过审计证据/支持性文件取得） | N32: 获得的证据/支持的描述（例如，我们检查的控制权转移时点的单据/销售发票/合同/订单等） | O32: 资产原价差异 | P32: 1 | Q32: 2 | R32: 3 | S32: 4
B33: 1 | O33: =M33-H33
B34: 2 | O34: =M34-H34
B35: 3 | O35: =M35-H35
B36: 4 | O36: =M36-H36
B37: 5 | O37: =M37-H37
B39: 标记图例: 记录已识别的异常情况以及如何解决这些异常情况的详细信息，包括执行的其他实质性程序（指南：包括足够的描述，以使之前与审计无关的经验丰富的审计师能够理解执行的程序）。

Sheet L1.02.1a 选样输出
B2: 注：样本新增测试请与L1.02.1 新增（本年购置）测试金额核对一致。 | N2: 返回汇总页

Sheet 新增清单
O2: 返回汇总页
B3: 获取当期按类别划分的所有无形资产新增清单，并将该列表与无形资产后推核对一致。调查超过SAD名义金额的差额（例如，新增清单和后推明细表之间没被解释的差额）。
B5: 注：项目组可以自定义无形资产新增清单表格，也可直接使用系统导出的无形资产新增清单，但必须确保必需字段（无形资产类别、编号、名称、入账开始日期、使用寿命、残值率、原值、新增方式）完整。

Sheet L1.02.2 处置测试
B1: 标准工作底稿: L1 SWP 无形资产
B2: L1.02.2：详细测试 (处置)
B4: 返回汇总页
B6: 记录我们的详细测试所涵盖的总体（指引：纳入充分的描述，以使经验丰富且之前与该项审计无关的审计师能够理解样本是如何选择的，例如，总体的分类或筛选。）
E12: |------- Rx -------|
E13: 账面价值 | G13: 原价 | I13: 累计摊销 | K13: 减值准备
B14: 减少总金额 | E14: =G14-I14-K14
B15: Breakdown中减少金额 | E15: =G15-I15-K15 | F15: L1.01.1 | G15: =-('L1.01.1 Agree SL to GL'!T15) | H15: L1.01.1 | I15: =-('L1.01.1 Agree SL to GL'!T20) | J15: L1.01.1 | K15: =-('L1.01.1 Agree SL to GL'!T25) | L15: L1.01.1
B16: 差异 | E16: =E14-E15 | F16: Rx | G16: =G14-G15 | H16: Rx | I16: =I14-I15 | J16: Rx | K16: =K14-K15 | L16: Rx
B17: 差异是否需要进一步调查？ | E17: =IF(ABS(E16)>'L1.00 Lead sheet'!$C$6, "Yes", "No") | G17: =IF(ABS(G16)>'L1.00 Lead sheet'!$C$6, "Yes", "No") | I17: =IF(ABS(I16)>'L1.00 Lead sheet'!$C$6, "Yes", "No") | K17: =IF(ABS(K16)>'L1.00 Lead sheet'!$C$6, "Yes", "No")
B19: 减：测试的关键项目
B20: 进行代表性抽样的剩余总体 | E20: =E14-E19
B22: 在下方描述选择关键项目的理由（请参阅Canvas指导工作流程的“关键项目”部分，包括信息图标）
B28: EY 测试属性解释:
B29: 对于每个被选中进行测试的项目，我们检查了相关的第三方证据以及相关的会计分录，并确定：
B30: 1) 测试样本（原值和累计摊销余额）已从无形资产明细账和总账中正确移除。
B31: 2) 重新计算资产处置时点的账面净值，并计算处置损益。确认处置损益已按照适用的财务报告框架正确记录和分类。
B32: 3)如果适用，正确记录处置收入金额。如果资产被出售（即收到收益），则获得发票或付款证明等，并确认与日记账分录中记录的收益金额一致。
L34: |------- Rx -------| | O34: |------- Rx -------| | Q34: |------- Rx -------| | S34: EY Works
B35: 样本序号 | C35: 样本类型 | D35: 无形资产类别 | E35: 总账账户代码 | F35: 无形资产编号 | G35: 无形资产名称 | H35: 处置/报废日 | I35: 原价 | J35: 累计摊销 | K35: 减值准备 | L35: 账面价值 | M35: 出售价格 | N35: 处置交易凭证号 | O35: 处置损益 | P35: 出售价格（通过审计证据/支持性文件取得） | Q35: 出售价格差异 | R35: 获得的证据/支持的描述（例如，我们检查的具体销售发票/合同/订单/审批文件等） | S35: 1 | T35: 2 | U35: 3
B36: 1 | L36: =SUM(I36:K36) | O36: =M36-L36 | Q36: =P36-M36
B37: 2 | L37: =SUM(I37:K37) | O37: =M37-L37 | Q37: =P37-M37
B38: 3 | L38: =SUM(I38:K38) | O38: =M38-L38 | Q38: =P38-M38
B39: 4 | L39: =SUM(I39:K39) | O39: =M39-L39 | Q39: =P39-M39
B40: 5 | L40: =SUM(I40:K40) | O40: =M40-L40 | Q40: =P40-M40
B42: 标记图例: 记录已识别的异常情况以及如何解决这些异常情况的详细信息，包括执行的其他实质性程序（指南：包括足够的描述，以使之前与审计无关的经验丰富的审计师能够理解执行的程序）。

Sheet L1.02.2a 选样输出
B2: 注：样本处置测试请与L1.02.2 处置（处置及报废）测试金额核对一致。 | N2: 返回汇总页

Sheet 处置清单
N2: 返回汇总页
B3: 获取当期按类别划分的所有无形资产处置清单，包括记录的处置的损益，并将该列表与无形资产后推核对一致。我们调查超过SAD名义金额的差额（例如，处置清单和后推明细表之间没被解释的差额）。我们考虑了实体经营的任何重大变化是否导致资产报废和/或处置，如果是，我们确保这些资产计入当期处置。
B6: 注：项目组可以自定义无形资产处置清单表格，也可直接使用系统导出的无形资产处置清单，但必须确保必需字段（无形资产类别、编号、名称、原值、累计折旧、减值、净值、处置日期、减少方式）完整。

Sheet L1.03 摊销测试
B1: 标准工作底稿: L1 SWP 无形资产
B2: L1.03：详细测试 (摊销)
B4: 注：1.如果下列表格不适用，项目组可以自定义下方无形资产清单表格，也可直接使用系统导出的无形资产清单，但必须确保必需字段完整。
B5: 2.无形资产的类别：请使用被审计单位的台账，无需对资产的类别添加自己的重分类修改，资产类别应当与L1.01.1中列示的类别匹配。
B7: 返回汇总页
B9: 按公司的摊销政策重新计算本年应计提的摊销费用并与账面本年摊销费用比对。重新计算摊销出现差异的，我们进行进一步核查以得出结论。
B10: |-------------------------------------------------------------------------------------------------------------------------------------------------必需字段*----------------------------------------------------------------------------------------------------------------------------------------------------------|
B11: 表1 无形资产明细清单 | N11: 若处置或报废，须填写 | P11: EY Works
B12: 无形资产编号 | C12: 无形资产名称 | D12: 无形资产类别 | E12: 入账开始日期 | F12: 残值率 | G12: 使用寿命(月) | H12: 本期摊销 | I12: 本期计提减值准备 | J12: 期末原值 | K12: 期末累计摊销 | L12: 期末减值准备 | M12: 期末净值 | N12: 处置日期 | O12: 原值减少金额 | P12: 提足折旧时间 | Q12: 本期应摊销月数 | R12: 本期应摊销金额 | S12: 本期差异 | T12: 标记
P13: =IFERROR(EOMONTH(E13,G13-MONTH(1)),"") | Q13: {=IFERROR(IF(N13="",_xlfn.IFS(YEAR(E13)<YEAR('L1.00 Lead sheet'!$C$3),_xlfn.IFS(YEAR(P13)>YEAR('L1.00 Lead sheet'!$C$3),MONTH('L1.00 Lead sheet'!$C$3),YEAR(P13)=YEAR('L1.00 Lead sheet'!$C$3),IF(MONTH(P13)>=MONTH('L1.00 Lead sheet'!$C$3),MONTH('L1.00 Lead sheet'!$C$3),MONTH(P13)),YEAR(P13)<YEAR('L1.00 Lead sheet'!$C$3),0),(YEAR(E13)=YEAR('L1.00 Lead sheet'!$C$3)),MONTH('L1.00 Lead sheet'!$C$3)+1-(MONTH(E13)),YEAR(E13)>YEAR('L1.00 Lead sheet'!$C$3),0),_xlfn.IFS(EOMONTH(E13,G13-1)<DATE(YEAR('L1.00 Lead sheet'!$C$3),1,1),0,AND(DATE(YEAR('L1.00 Lead sheet'!$C$3),1,1)<EOMONTH(E13,G13-1),EOMONTH(E13,G13-1)<DATE(YEAR('L1.00 Lead sheet'!$C$3),MONTH('L1.00 Lead sheet'!$C$3),DAY('L1.00 Lead sheet'!$C$3))),IF(DATE(YEAR(N13),MONTH(N13),DAY(N13))<EOMONTH(E13,G13-1),MONTH(N13)-1,MONTH(EOMONTH(E13,G13-1))),EOMONTH(E13,G13-1)=DATE(YEAR('L1.00 Lead sheet'!$C$3),MONTH('L1.00 Lead sheet'!$C$3),DAY('L1.00 Lead sheet'!$C$3)),IF(DATE(YEAR(N13),MONTH(N13),DAY(N13))>EOMONTH(E13,G13-1),MONTH(EOMONTH(E13,G13-1)),MONTH(N13)-1),EOMONTH(E13,G13-1)>DATE(YEAR('L1.00 Lead sheet'!$C$3),MONTH('L1.00 Lead sheet'!$C$3),DAY('L1.00 Lead sheet'!$C$3)),IF(YEAR(E13)>YEAR('L1.00 Lead sheet'!$C$3),0,IF(YEAR(E13)=YEAR('L1.00 Lead sheet'!$C$3),IF(YEAR(N13)>YEAR('L1.00 Lead sheet'!$C$3),MONTH('L1.00 Lead sheet'!$C$3)-MONTH(E13)+1,MONTH(N13)-MONTH(E13)+1),_xlfn.IFS(YEAR(N13)>YEAR('L1.00 Lead sheet'!$C$3),MONTH('L1.00 Lead sheet'!$C$3),YEAR(N13)=YEAR('L1.00 Lead sheet'!$C$3),MONTH(N13)-1,YEAR(N13)<YEAR('L1.00 Lead sheet'!$C$3),0))))),0)} | R13: =-(IFERROR(IF(J13=0,(O13*(1-F13))/G13*Q13,(J13*(1-F13))/G13*Q13),0)) | S13: =R13-H13 | T13: =IF(ABS(S13)>'L1.00 Lead sheet'!$C$6,"Note","w")
P14: =IFERROR(EOMONTH(E14,G14-MONTH(1)),"") | Q14: {=IFERROR(IF(N14="",_xlfn.IFS(YEAR(E14)<YEAR('L1.00 Lead sheet'!$C$3),_xlfn.IFS(YEAR(P14)>YEAR('L1.00 Lead sheet'!$C$3),MONTH('L1.00 Lead sheet'!$C$3),YEAR(P14)=YEAR('L1.00 Lead sheet'!$C$3),IF(MONTH(P14)>=MONTH('L1.00 Lead sheet'!$C$3),MONTH('L1.00 Lead sheet'!$C$3),MONTH(P14)),YEAR(P14)<YEAR('L1.00 Lead sheet'!$C$3),0),(YEAR(E14)=YEAR('L1.00 Lead sheet'!$C$3)),MONTH('L1.00 Lead sheet'!$C$3)+1-(MONTH(E14)),YEAR(E14)>YEAR('L1.00 Lead sheet'!$C$3),0),_xlfn.IFS(EOMONTH(E14,G14-1)<DATE(YEAR('L1.00 Lead sheet'!$C$3),1,1),0,AND(DATE(YEAR('L1.00 Lead sheet'!$C$3),1,1)<EOMONTH(E14,G14-1),EOMONTH(E14,G14-1)<DATE(YEAR('L1.00 Lead sheet'!$C$3),MONTH('L1.00 Lead sheet'!$C$3),DAY('L1.00 Lead sheet'!$C$3))),IF(DATE(YEAR(N14),MONTH(N14),DAY(N14))<EOMONTH(E14,G14-1),MONTH(N14)-1,MONTH(EOMONTH(E14,G14-1))),EOMONTH(E14,G14-1)=DATE(YEAR('L1.00 Lead sheet'!$C$3),MONTH('L1.00 Lead sheet'!$C$3),DAY('L1.00 Lead sheet'!$C$3)),IF(DATE(YEAR(N14),MONTH(N14),DAY(N14))>EOMONTH(E14,G14-1),MONTH(EOMONTH(E14,G14-1)),MONTH(N14)-1),EOMONTH(E14,G14-1)>DATE(YEAR('L1.00 Lead sheet'!$C$3),MONTH('L1.00 Lead sheet'!$C$3),DAY('L1.00 Lead sheet'!$C$3)),IF(YEAR(E14)>YEAR('L1.00 Lead sheet'!$C$3),0,IF(YEAR(E14)=YEAR('L1.00 Lead sheet'!$C$3),IF(YEAR(N14)>YEAR('L1.00 Lead sheet'!$C$3),MONTH('L1.00 Lead sheet'!$C$3)-MONTH(E14)+1,MONTH(N14)-MONTH(E14)+1),_xlfn.IFS(YEAR(N14)>YEAR('L1.00 Lead sheet'!$C$3),MONTH('L1.00 Lead sheet'!$C$3),YEAR(N14)=YEAR('L1.00 Lead sheet'!$C$3),MONTH(N14)-1,YEAR(N14)<YEAR('L1.00 Lead sheet'!$C$3),0))))),0)} | R14: =-(IFERROR(IF(J14=0,(O14*(1-F14))/G14*Q14,(J14*(1-F14))/G14*Q14),0)) | S14: =R14-H14 | T14: =IF(ABS(S14)>'L1.00 Lead sheet'!$C$6,"Note","w")
P15: =IFERROR(EOMONTH(E15,G15-MONTH(1)),"") | Q15: {=IFERROR(IF(N15="",_xlfn.IFS(YEAR(E15)<YEAR('L1.00 Lead sheet'!$C$3),_xlfn.IFS(YEAR(P15)>YEAR('L1.00 Lead sheet'!$C$3),MONTH('L1.00 Lead sheet'!$C$3),YEAR(P15)=YEAR('L1.00 Lead sheet'!$C$3),IF(MONTH(P15)>=MONTH('L1.00 Lead sheet'!$C$3),MONTH('L1.00 Lead sheet'!$C$3),MONTH(P15)),YEAR(P15)<YEAR('L1.00 Lead sheet'!$C$3),0),(YEAR(E15)=YEAR('L1.00 Lead sheet'!$C$3)),MONTH('L1.00 Lead sheet'!$C$3)+1-(MONTH(E15)),YEAR(E15)>YEAR('L1.00 Lead sheet'!$C$3),0),_xlfn.IFS(EOMONTH(E15,G15-1)<DATE(YEAR('L1.00 Lead sheet'!$C$3),1,1),0,AND(DATE(YEAR('L1.00 Lead sheet'!$C$3),1,1)<EOMONTH(E15,G15-1),EOMONTH(E15,G15-1)<DATE(YEAR('L1.00 Lead sheet'!$C$3),MONTH('L1.00 Lead sheet'!$C$3),DAY('L1.00 Lead sheet'!$C$3))),IF(DATE(YEAR(N15),MONTH(N15),DAY(N15))<EOMONTH(E15,G15-1),MONTH(N15)-1,MONTH(EOMONTH(E15,G15-1))),EOMONTH(E15,G15-1)=DATE(YEAR('L1.00 Lead sheet'!$C$3),MONTH('L1.00 Lead sheet'!$C$3),DAY('L1.00 Lead sheet'!$C$3)),IF(DATE(YEAR(N15),MONTH(N15),DAY(N15))>EOMONTH(E15,G15-1),MONTH(EOMONTH(E15,G15-1)),MONTH(N15)-1),EOMONTH(E15,G15-1)>DATE(YEAR('L1.00 Lead sheet'!$C$3),MONTH('L1.00 Lead sheet'!$C$3),DAY('L1.00 Lead sheet'!$C$3)),IF(YEAR(E15)>YEAR('L1.00 Lead sheet'!$C$3),0,IF(YEAR(E15)=YEAR('L1.00 Lead sheet'!$C$3),IF(YEAR(N15)>YEAR('L1.00 Lead sheet'!$C$3),MONTH('L1.00 Lead sheet'!$C$3)-MONTH(E15)+1,MONTH(N15)-MONTH(E15)+1),_xlfn.IFS(YEAR(N15)>YEAR('L1.00 Lead sheet'!$C$3),MONTH('L1.00 Lead sheet'!$C$3),YEAR(N15)=YEAR('L1.00 Lead sheet'!$C$3),MONTH(N15)-1,YEAR(N15)<YEAR('L1.00 Lead sheet'!$C$3),0))))),0)} | R15: =-(IFERROR(IF(J15=0,(O15*(1-F15))/G15*Q15,(J15*(1-F15))/G15*Q15),0)) | S15: =R15-H15 | T15: =IF(ABS(S15)>'L1.00 Lead sheet'!$C$6,"Note","w")
P16: =IFERROR(EOMONTH(E16,G16-MONTH(1)),"") | Q16: {=IFERROR(IF(N16="",_xlfn.IFS(YEAR(E16)<YEAR('L1.00 Lead sheet'!$C$3),_xlfn.IFS(YEAR(P16)>YEAR('L1.00 Lead sheet'!$C$3),MONTH('L1.00 Lead sheet'!$C$3),YEAR(P16)=YEAR('L1.00 Lead sheet'!$C$3),IF(MONTH(P16)>=MONTH('L1.00 Lead sheet'!$C$3),MONTH('L1.00 Lead sheet'!$C$3),MONTH(P16)),YEAR(P16)<YEAR('L1.00 Lead sheet'!$C$3),0),(YEAR(E16)=YEAR('L1.00 Lead sheet'!$C$3)),MONTH('L1.00 Lead sheet'!$C$3)+1-(MONTH(E16)),YEAR(E16)>YEAR('L1.00 Lead sheet'!$C$3),0),_xlfn.IFS(EOMONTH(E16,G16-1)<DATE(YEAR('L1.00 Lead sheet'!$C$3),1,1),0,AND(DATE(YEAR('L1.00 Lead sheet'!$C$3),1,1)<EOMONTH(E16,G16-1),EOMONTH(E16,G16-1)<DATE(YEAR('L1.00 Lead sheet'!$C$3),MONTH('L1.00 Lead sheet'!$C$3),DAY('L1.00 Lead sheet'!$C$3))),IF(DATE(YEAR(N16),MONTH(N16),DAY(N16))<EOMONTH(E16,G16-1),MONTH(N16)-1,MONTH(EOMONTH(E16,G16-1))),EOMONTH(E16,G16-1)=DATE(YEAR('L1.00 Lead sheet'!$C$3),MONTH('L1.00 Lead sheet'!$C$3),DAY('L1.00 Lead sheet'!$C$3)),IF(DATE(YEAR(N16),MONTH(N16),DAY(N16))>EOMONTH(E16,G16-1),MONTH(EOMONTH(E16,G16-1)),MONTH(N16)-1),EOMONTH(E16,G16-1)>DATE(YEAR('L1.00 Lead sheet'!$C$3),MONTH('L1.00 Lead sheet'!$C$3),DAY('L1.00 Lead sheet'!$C$3)),IF(YEAR(E16)>YEAR('L1.00 Lead sheet'!$C$3),0,IF(YEAR(E16)=YEAR('L1.00 Lead sheet'!$C$3),IF(YEAR(N16)>YEAR('L1.00 Lead sheet'!$C$3),MONTH('L1.00 Lead sheet'!$C$3)-MONTH(E16)+1,MONTH(N16)-MONTH(E16)+1),_xlfn.IFS(YEAR(N16)>YEAR('L1.00 Lead sheet'!$C$3),MONTH('L1.00 Lead sheet'!$C$3),YEAR(N16)=YEAR('L1.00 Lead sheet'!$C$3),MONTH(N16)-1,YEAR(N16)<YEAR('L1.00 Lead sheet'!$C$3),0))))),0)} | R16: =-(IFERROR(IF(J16=0,(O16*(1-F16))/G16*Q16,(J16*(1-F16))/G16*Q16),0)) | S16: =R16-H16 | T16: =IF(ABS(S16)>'L1.00 Lead sheet'!$C$6,"Note","w")
P17: =IFERROR(EOMONTH(E17,G17-MONTH(1)),"") | Q17: {=IFERROR(IF(N17="",_xlfn.IFS(YEAR(E17)<YEAR('L1.00 Lead sheet'!$C$3),_xlfn.IFS(YEAR(P17)>YEAR('L1.00 Lead sheet'!$C$3),MONTH('L1.00 Lead sheet'!$C$3),YEAR(P17)=YEAR('L1.00 Lead sheet'!$C$3),IF(MONTH(P17)>=MONTH('L1.00 Lead sheet'!$C$3),MONTH('L1.00 Lead sheet'!$C$3),MONTH(P17)),YEAR(P17)<YEAR('L1.00 Lead sheet'!$C$3),0),(YEAR(E17)=YEAR('L1.00 Lead sheet'!$C$3)),MONTH('L1.00 Lead sheet'!$C$3)+1-(MONTH(E17)),YEAR(E17)>YEAR('L1.00 Lead sheet'!$C$3),0),_xlfn.IFS(EOMONTH(E17,G17-1)<DATE(YEAR('L1.00 Lead sheet'!$C$3),1,1),0,AND(DATE(YEAR('L1.00 Lead sheet'!$C$3),1,1)<EOMONTH(E17,G17-1),EOMONTH(E17,G17-1)<DATE(YEAR('L1.00 Lead sheet'!$C$3),MONTH('L1.00 Lead sheet'!$C$3),DAY('L1.00 Lead sheet'!$C$3))),IF(DATE(YEAR(N17),MONTH(N17),DAY(N17))<EOMONTH(E17,G17-1),MONTH(N17)-1,MONTH(EOMONTH(E17,G17-1))),EOMONTH(E17,G17-1)=DATE(YEAR('L1.00 Lead sheet'!$C$3),MONTH('L1.00 Lead sheet'!$C$3),DAY('L1.00 Lead sheet'!$C$3)),IF(DATE(YEAR(N17),MONTH(N17),DAY(N17))>EOMONTH(E17,G17-1),MONTH(EOMONTH(E17,G17-1)),MONTH(N17)-1),EOMONTH(E17,G17-1)>DATE(YEAR('L1.00 Lead sheet'!$C$3),MONTH('L1.00 Lead sheet'!$C$3),DAY('L1.00 Lead sheet'!$C$3)),IF(YEAR(E17)>YEAR('L1.00 Lead sheet'!$C$3),0,IF(YEAR(E17)=YEAR('L1.00 Lead sheet'!$C$3),IF(YEAR(N17)>YEAR('L1.00 Lead sheet'!$C$3),MONTH('L1.00 Lead sheet'!$C$3)-MONTH(E17)+1,MONTH(N17)-MONTH(E17)+1),_xlfn.IFS(YEAR(N17)>YEAR('L1.00 Lead sheet'!$C$3),MONTH('L1.00 Lead sheet'!$C$3),YEAR(N17)=YEAR('L1.00 Lead sheet'!$C$3),MONTH(N17)-1,YEAR(N17)<YEAR('L1.00 Lead sheet'!$C$3),0))))),0)} | R17: =-(IFERROR(IF(J17=0,(O17*(1-F17))/G17*Q17,(J17*(1-F17))/G17*Q17),0)) | S17: =R17-H17 | T17: =IF(ABS(S17)>'L1.00 Lead sheet'!$C$6,"Note","w")
D18: 合计 | H18: =SUM(H12:H17) | I18: =SUM(I12:I17) | J18: =SUM(J12:J17) | K18: =SUM(K12:K17) | L18: =SUM(L12:L17) | M18: =SUM(M12:M17) | O18: =SUM(O12:O17) | R18: =SUM(R12:R17) | S18: =SUM(S12:S17) | T18: =IF(ABS(S18)>'L1.00 Lead sheet'!$C$6,"Note","w")
H19: Rx | I19: Rx | J19: Rx | K19: Rx | L19: Rx | M19: Rx | O19: Rx | R19: Rx
B21: 检查无形资产各项目的摊销政策是否符合有关规定，是否与上期一致，其是否具有商业合理性。若改变摊销政策，检查其依据是否充分。
B22: 表2 公司摊销政策复核表
B23: 资产类别 | C23: =YEAR('L1.00 Lead sheet'!C3)&"年度" | D23: =YEAR('L1.00 Lead sheet'!C3)-1&"年度" | E23: 差异 | F23: 差异说明 | G23: 使用寿命的
C24: 使用寿命 | D24: 使用寿命 | G24: 商业合理性分析
B25: ='L1.01.1 Agree SL to GL'!F10 | E25: =C25=D25
B26: ='L1.01.1 Agree SL to GL'!I10 | E26: =C26=D26
B27: ='L1.01.1 Agree SL to GL'!L10 | E27: =C27=D27
B28: ='L1.01.1 Agree SL to GL'!O10 | E28: =C28=D28
B29: ='L1.01.1 Agree SL to GL'!R10 | E29: =C29=D29

Sheet SkywindSettingSheet
A1: b8e777cf-a974-4dca-af89-7da1caee1666
