Workbook

Sheet 汇总
A1: V6 SWP
C3: 客户名称 | D3: 东风鸿远工程咨询有限公司 | F3: 重要性水平(PM)
C5: 期末 | D5: 46387 | F5: 可容忍误差(TE)
C7: 记账本位币 | D7: CNY | F7: 名义金额(SAD)
C9: 适用会计准则 | D9: PRC
E13: Threshold(s)
C14: 认定 | D14: CRA | E14: 各项认定1 | F14: 所有相关认定 2
C15: 完整性 (C) | E15: =IF(D15="Minimal",$G$5*50%,IF(D15="Low",$G$5*25%,IF(D15="Moderate",$G$5*15%,IF(D15="High",$G$5*10%,IF(D15="N/A","-",))))) | F15: =MIN($E$15:$E$19)
C16: 存在性 (E) | E16: =IF(D16="Minimal",$G$5*100%,IF(D16="Low",$G$5*75%,IF(D16="Moderate",$G$5*50%,IF(D16="High",$G$5*25%,IF(D16="N/A","-",)))))
C17: 计价(V) | E17: =IF(D17="Minimal",$G$5*100%,IF(D17="Low",$G$5*75%,IF(D17="Moderate",$G$5*50%,IF(D17="High",$G$5*25%,IF(D17="N/A","-",)))))
C18: 权利和义务 (R&O) | E18: =IF(D18="Minimal",$G$5*100%,IF(D18="Low",$G$5*75%,IF(D18="Moderate",$G$5*50%,IF(D18="High",$G$5*25%,IF(D18="N/A","-",)))))
C19: 列报和披露 (P&D) | E19: =IF(D19="Minimal",$G$5*100%,IF(D19="Low",$G$5*75%,IF(D19="Moderate",$G$5*50%,IF(D19="High",$G$5*25%,IF(D19="N/A","-",)))))
C20: 1 各项认定的测试阈值，是根据EY GAM SUBSTANTIVE DESIGN 2.2.1
C21: 中的示例测试阈值（用占TE的百分比表示）在相应风险等级（CRA）区间的上限计算得出的。
C22: 除负债/费用类别账户的完整性认定应当使用负债/费用账户表之外，其他类别账户和认定均可使用资产/收入账户表。
C23: 2 所有相关认定的测试阈值，是所有有效认定对应之测试阈值的最小值。我们在 Lead中使用该测试阈值：（a）作为选取总账账户进行测试的起点；（b）作为（需要进一步调查的）金额波动范围的起点。
A25: P1 | C25: 序号 | D25: 报表科目 | E25: 执行实质性程序 | F25: 实质性程序类型 | G25: 认定 | H25: 程序描述 | I25: 执行 | J25: 索引 | K25: 如不执行PSP，原因需记录文字多于5个文字
C26: 1 | D26: 应付票据 | E26: M-01-GL: 将明细账与总账核对一致 | F26: PSP | G26: BS: E, C | H26: 通过执行分析和调查两期的应付票据科目重大变动来确定应付票据余额是否合理。 | J26: M.00 Lead
J27: M.01.01&02.01明细账
C28: 2 | D28: 应付票据_银行承兑汇票 | E28: M-01-GL: 将应付票据明细账与总账核对一致，检查合同及其条款的合规性。 | F28: PSP | G28: BS: E, C | H28: 获取应付票据_银行承兑汇票明细账，将余额与相应的总分类账核对一致。检查应付票据_银行承兑汇票开票条件及存续状态等情况，对银行承兑汇票进行函证；检查银行承兑汇票保证合理性。 | J28: M.01 银承BKD
A29: /P1 | C29: 3 | D29: 应付票据_商业承兑汇票 | E29: M-01-GL: 将应付票据明细账与总账核对一致，检查合同及其条款的合规性。 | F29: PSP | G29: BS: E, C | H29: 获取应付票据_商业承兑汇票明细账，将余额与相应的总分类账核对一致。检查应付票据_商业承兑汇票开票条件及存续状态等情况；必要时，对商业承兑汇票进行函证。 | J29: M.02 商承BKD
C32: 应付票据账户总结陈述
C33: 通过执行审计程序：
D34: 我们没有发现任何超过SAD的错报
D35: 我们已经完成了于该些科目相关的细节测试，并发现了一个或多个超过SAD的错报，我们已经将这些错报记录于审计差异汇总（SAD template)中, 并将该审计差异汇总表放入Canvas。
C38: 安永标记
C39: TB | D39: 已与科目余额表核对无误
C40: PY | D40: 与上年最终审定数核对一致
C41: A3 | D41: 与未审数、审定数核对一致
C42: A5 | D42: 与审计调整核对一致
C43: FS | D43: 与FS.0x与财务报表核对无误
C44: w | D44: 低于SAD的金额——放弃进一步调查
C45: Rx | D45: 重新计算，无异常
C46: m | D46: 余额/活动不符合测试范围–无需进一步调查
C47: SL | D47: 已与明细账核对无误

Sheet M.00 Lead
A1: 03878ede-ea5b-4f95-861a-b27c211af73e
J2: 返回汇总页
C4: 目标
C5: 通过执行分析和调查两期的应付票据科目重大变动来确定应付票据余额是否合理。
C8: 序号 | D8: 执行的程序 | G8: 程序表 | H8: 预审完成 | I8: 年审完成 | J8: 执行注意事项
C9: 1 | D9: 我们获取应付票据科目余额表本期金额以及上年审定数。 | G9: 表2
C10: 2 | D10: 我们将两期审定金额进行比对，对那些变动大于范围的事项，获得管理层解释并对解释是否合理进行调查。 | G10: 表2
C13: 在下文中描述我们当期对应付余额和相关波动的预期，以及这些预期的依据和理由。
C19: 波动范围
C20: ="波动幅度 ("&汇总!D11& "):" | D20: =汇总!$F$15
C21: 波动幅度 (%): | D21: 0.1
F22: |------- TB -------| | K22: |------- PY -------|
B23: 表2 | C23: 账套名称/账套编码 | D23: 科目名称 | E23: 索引号 | H23: =汇总!D5 | K23: =DATE(YEAR($H$23)-1,12,31) | L23: 变动 | O23: 基于波动幅度判断，是否进一步调查？ | P23: 基于定性考虑判断，是否进一步调查？
F24: 期末账面数 | G24: 账表调整数 | H24: 期末未审数 | I24: 审计调整数 | J24: 期末审定数 | K24: 上期末审定数 | L24: 金额 | M24: % | N24: Notes
C25: DPCA | D25: 银行承兑汇票 | E25: M.01/ | H25: =F25+G25 | J25: =H25+I25 | K25: 50570211 | L25: =J25-K25 | M25: =IFERROR(L25/K25,1) | N25: [A] | O25: =IF(AND(L25<>0,ABS(L25)>=$D$20,OR(M25="N/A",ABS(IFERROR(L25/K25,0))>=$D$21)),"是","否")
C26: DPCC | D26: 银行承兑汇票 | H26: =F26+G26 | J26: =H26+I26 | K26: 11616668 | L26: =J26-K26 | M26: =IFERROR(L26/K26,1) | O26: =IF(AND(L26<>0,ABS(L26)>=$D$20,OR(M26="N/A",ABS(IFERROR(L26/K26,0))>=$D$21)),"是","否")
C27: DPCA | D27: 商业承兑汇票 | E27: M.02/ | H27: =F27+G27 | J27: =H27+I27 | K27: 0 | L27: =J27-K27 | M27: =IFERROR(L27/K27,1) | O27: =IF(AND(L27<>0,ABS(L27)>=$D$20,OR(M27="N/A",ABS(IFERROR(L27/K27,0))>=$D$21)),"是","否")
C28: DPCC | D28: 商业承兑汇票 | E28: M.02/ | H28: =F28+G28 | J28: =H28+I28 | K28: 0 | L28: =J28-K28 | M28: =IFERROR(L28/K28,1) | O28: =IF(AND(L28<>0,ABS(L28)>=$D$20,OR(M28="N/A",ABS(IFERROR(L28/K28,0))>=$D$21)),"是","否")
E29: 合计 | F29: =SUM(F25:F28) | G29: =SUM(G25:G28) | H29: =F29+G29 | I29: =SUM(I25:I28) | J29: =H29+I29 | K29: =SUM(K25:K28) | L29: =J29-K29 | M29: =IFERROR(L29/K29,1) | O29: =IF(AND(L29<>0,ABS(L29)>=$D$20,OR(M29="N/A",ABS(IFERROR(L29/K29,0))>=$D$21)),"是","否")
F30: RX | G30: RX | I30: RX | K30: RX
G31: A3
G32: Diff | H32: =H29-H31 | J32: =J29-J31 | K32: =K29-K31
C34: 波动说明
C35: [A]
C41: 调整汇总表（如不适用请删除）
C42: 调整类型

Sheet M.01 银承BKD
A1: 777ea5b4-12a4-4b4f-bd5a-60b7ed0d4f78
I2: 返回汇总页
B4: 目标
B5: 复核应付票据_银行承兑汇票金额、期限、担保品等支持性文件，并执行函证程序。
B7: 序号 | C7: 执行的程序 | F7: 程序表 | G7: 预审完成 | H7: 年审完成 | I7: 执行注意事项
B8: 1 | C8: 获取银行承兑汇票（含财务公司承兑汇票）明细表，将明细表期末总金额与银行承兑汇票总账核对一致。复核利息费用和应付利息计算的合理性（如适用）。 | F8: M.01&02.01明细账及表1
B9: 2 | C9: 检查银行承兑汇票协议或其他短期借款安排的文件，以确认银行承兑汇票的条款、限制、循环信用额和其他相关规定，选择需要进行函证的银行承兑汇票进行函证，并核对银行回函金额与账面金额一致。 | F9: 表2.1、表2.2及表2.3
B10: 3 | C10: 根据银行承兑汇票明细表，获取逾期银行承兑汇票的信息，对逾期银行承兑汇票未支付事项选取样本进行调查，查看逾期未支付的银行承兑汇票是否应当转入短期借款。（如适用） | F10: 表2.1及表2.2
B11: 4 | C11: 将银行承兑汇票金额与授信额度或担保金额、银承保证金、结构性存款、理财产品等开票担保品账面价值进行核对，选取样本验证银行承兑汇票期末余额合理性（如适用）。 | F11: 表2.1及表2.4
B14: 表1 将明细账与总账核对一致
B15: 账套名称/账套编码 | C15: 科目名称 | D15: Lead页余额 | E15: 索引号 | F15: 明细账余额 | G15: 明细账索引 | H15: 差异重新计算 （Note1）
D16: ='M.00 Lead'!F25 | E16: /M.00 | G16: /M.01&02.01明细账 | H16: =D16-F16
H17: =D17-F17
H18: =D18-F18
C20: 合计 | D20: =SUM(D16:D18) | F20: =SUM(F16:F18) | H20: =SUM(H16:H18)
D21: RX | F21: RX | H21: RX
B23: Note1：如果总账和明细账差异金额大于SAD请在以下解释差异并执行相应的程序：针对金额大于测试阈值及性质异常的项目我们需进一步进行测试。(如不适用请删除）
B28: EY 测试属性解释: | DW28: 使用授信额度
B29: 对于应付票据_银行承兑汇票，我们执行以下程序，以确保： | DW29: 保证金质押开票
B30: 1) 向承兑银行发函确认应付票据_银行承兑汇票的余额，核对账面金额与回函金额相符。 | DW30: 结构性存款质押开票
B31: 2) 根据应付票据_银行承兑汇票明细表，获取了逾期银行承兑汇票的信息；对逾期银行承兑汇票未支付事项进行了调查，逾期未支付的银行承兑汇票已转入短期借款。
B32: 3) 使用授信额度或其他担保方式开立银行承兑汇票的，已检查银行承兑汇票的协议或银行授信审批文件，未发现异常情况。 | DW32: 理财产品质押开票
B33: 4) 将相关质押品账面价值与应付票据_银行承兑汇票余额进行核对，计算质押品账面价值与相关债务的比例，质押水平符合合同或协议约定要求。 | DW33: 应收票据质押开票
DW34: 第三方担保方式开票
B35: 表2.1 项目组在下面记录选样策略与理由
B40: 表2.2 根据表2.1的选样策略，选取测试项目执行EY测试属性1和2，并记录测试结论于下表
N41: EY Works | P41: 函证索引号 | Q41: 逾期原因（如适用） | R41: 针对未回函的应付票据执行的替代程序及结论
B42: EY测试属性类别 | C42: 账套名称/账套编码 | D42: 供应商名称 | E42: 出票人 | F42: 收票人 | G42: 签发日期 | H42: 到期日 | I42: 票据票面金额 | J42: 票据号码 | K42: 承兑人名称 | L42: 开票保证方式 | M42: 约定利率 | N42: 1 | O42: 2
B51: 表2.3 核对银行回函金额（包括格式一与格式二）与账面金额是否一致
B52: 账套名称/账套编码 | C52: 承兑银行/回函银行 | D52: 回函金额 | E52: 账面金额 | F52: 索引号 | G52: 差异 | H52: 差异原因及解释
F53: /M.01&02.01明细账 | G53: =D53-E53
G54: =D54-E54
G55: =D55-E55
G56: =D56-E56
G57: =D57-E57
B59: 表2.4 对表2.2中测试项目涉及的承兑银行，执行EY测试属性3和4，并记录测试结论于下表
B60: EY测试属性类别 | C60: 账套名称/账套编码 | D60: 承兑银行/出具实体 | E60: 票据金额 | F60: 索引号 | G60: 开票方式 | H60: 授信额度或担保金额 | I60: 开票协议或抵质押协议约定的比例 | J60: 用于质押的资产账面价值 | P60: 质押水平是否符合约定 | Q60: EY Works | S60: 质押水平不符合约定的原因
J61: 用于质押开票的保证金账面价值 | K61: 用于质押开票的结构性存款账面价值 | L61: 用于质押开票的理财产品账面价值 | M61: 用于质押开票的应收票据账面价值 | N61: 其他 | O61: 小计 | Q61: 3 | R61: 4
J62: C 货币资金 | K62: 【/D200_结构性存款】 | L62: 【/D200_银行理财产品】 | M62: E2E3 | N62: 根据实际情况填列
F63: /M.01&02.01明细账 | O63: =SUM(J63:N63) | P63: =IF(B63=3,"不适用",IF(E63="","",IF(O63>=E63*I63,"是","否")))
...

Sheet M.02 商承BKD
A1: b6608b9d-b253-4083-acb9-34fceb03f01b
I2: 返回汇总页
B4: 目标
B5: 复核应付票据_商业承兑汇票金额、期限、抵押品等支持性文件，并执行函证程序。
B7: 序号 | C7: 执行的程序 | F7: 程序表 | G7: 预审完成 | H7: 年审完成 | I7: 执行注意事项
B8: 1 | C8: 取得商业承兑汇票明细表，将明细表期末总金额与商业承兑汇票总账核对一致。复核利息费用和应付利息计算的合理性（如适用）。 | F8: M.01&02.01明细账及表1
B9: 2 | C9: 通过中国人民银行指定的票据服务机构（如：上海票据交易所），选择"票据承兑人信用信息披露查询（查询字段为：承兑人名称/统一社会信用代码）"功能，查询资产负债表日的票据承兑人信用信息详情，检查承兑余额、逾期余额（如有），是否与商业承兑汇票总账金额一致，如有差异，调查差异原因。 | F9: 表2
B10: 3 | C10: 根据明细账（票据台账），选取重大或异常的单张票据，过中国人民银行指定的票据服务机构（如：上海票据交易所），选择"票据承兑信息披露查询（查询字段为：票据（包）号码）"功能，查询票据承兑信息详情，检查其是否与明细账（票据台账）信息一致，如有差异，调查差异原因。 | F10: 表3.1及表3.2
B11: 4 | C11: 根据应付票据_商业承兑汇票明细表，获取逾期商业承兑汇票的信息，选取样本对逾期商业承兑汇票未支付事项进行调查，查看逾期未支付的商业承兑汇票是否应当转入应付账款（如适用）。 | F11: 表3.1及表3.2
B14: 表1 将明细账与总账核对一致
B15: 账套名称/账套编码 | C15: 科目名称 | D15: Lead页余额 | E15: 索引号 | F15: 明细账余额 | G15: 明细账索引 | H15: 差异重新计算 （Note1）
D16: ='M.00 Lead'!F26 | E16: /M.00 | G16: /M.01&02.01明细账 | H16: =D16-F16
H17: =D17-F17
H18: =D18-F18
C20: 合计 | D20: =SUM(D16:D18) | F20: =SUM(F16:F18) | H20: =SUM(H16:H18)
D21: RX | F21: RX | H21: RX
B23: Note1：如果总账和明细账差异金额大于SAD请在以下解释差异并执行相应的程序：针对金额大于测试阈值及性质异常的项目我们需进一步进行测试。(如不适用请删除）
B28: 表2 将账面余额与票据服务机构披露的票据承兑人信用信息详情核对一致
B29: 票据服务机构披露的承兑信息 | E29: 账面余额 | F29: 差异 | G29: 差异原因及解释
B30: 承兑人名称 | C30: 承兑余额 | D30: 逾期余额 （如有）
F31: =C31-E31
F32: =C32-E32
F33: =C33-E33
B36: EY 测试属性解释:
B37: 对于应付票据_商业承兑汇票，我们执行以下程序，以确保：
B38: 1）检查重大或异常的单张票据是否与中国人民银行指定的票据服务机构（如：上海票据交易所）所披露的票据承兑信息详情一致。
B39: 2）根据应付票据_商业承兑汇票明细表，获取了逾期商业承兑汇票的信息；对逾期商业承兑汇票未支付事项进行了调查，逾期未支付的商业承兑汇票已转入应付账款。
B41: 表3.1 项目组在下面记录选样策略与理由
B46: 表3.2 根据表3.1中的选样策略，选取测试项目并记录测试结论于下表
L47: EY Works | N47: 逾期原因（如适用）
B48: EY测试属性类别 | C48: 账套名称/账套编码 | D48: 供应商名称 | E48: 出票人 | F48: 收票人 | G48: 签发日期 | H48: 到期日 | I48: 票据票面金额 | J48: 票据号码 | K48: 约定利率 | L48: 1 | M48: 2

Sheet M.01.01&02.01明细账
C3: M.01&02.01 获取应付票据明细账（台账）
M4: 返回汇总页

Sheet SkywindSettingSheet
A1: 39019de7-7877-4430-a150-03b245f0def3
