Workbook

Sheet 汇总
A1: V6 SWP
B2: VC&VD.00 | C2: VC&VD.00 Lead （认定：O、M、C、P&D） | F2: 程序页 | G2: 执行 | H2: 不执行的原因
B3: 1 | C3: 我们获取或编制了销售费用/管理费用重大账户的引导表，将本期金额与试算表核对一致，并将上期金额与最终的前期试算表核对一致（如适用）。 | F3: Uexp.00 Lead
B4: VC&VD.00 | C4: VC&VD.00 BKD（认定：O、M、C、P&D） | F4: 程序页 | G4: 执行 | H4: 不执行的原因
B5: 1 | C5: 我们记录了我们对期间内账户波动的预期以及做出这些预期的基础和理由。 对比当期金额和上期金额，调查变动大于范围或与预期不符的变动情况。并就异常事项检查记账凭证、合同等支持性证据，评估其发生的合理性。 | F5: VC.00 销售费用BKD
B6: 2 | F6: VD.00 管理费用BKD
B7: VC&VD.01.1 | C7: VC&VD.01.1 实质性分析程序SAP（认定：O、M、C、P&D） | F7: 程序页 | G7: 执行 | H7: 不执行的原因
B8: 1 | C8: 如执行分析性复核程序，则使用264GL完成相应记录。如不执行，可直接执行VC&VD.01.2 详细测试 TOD。 | F8: 如执行，请项目组添加底稿索引，如不执行请直接删除该程序。
B9: VC&VD.01.2 | C9: VC&VD.01.2 详细测试 TOD（认定：O、M、P&D） | F9: 程序页 | G9: 执行 | H9: 不执行的原因
B10: 1 | C10: 若通过实质分析性复核程序取得的证据不足以就账户余额得出结论，则执行详细测试。 | F10: VC&VD.01.2 详细测试 TOD
B11: VD.01.03 | C11: VD.01.03复核法律费用（认定：O、M、C、P&D） | F11: 程序页 | G11: 执行 | H11: 不执行的原因
B12: 1 | C12: 我们对金额大于测试阈值的法律费用相关账户进行复核（如有），查看其交易性质及发票金额是否与账面一致，同时对性质特殊（如诉讼等）的法律费用向律师发送审计询问函，对回函差异进行调查，对于未决诉讼应执行相关程序请检查勾稽到预期信用损失、预计负债等底稿。 | F12: VD.01.03复核法律费用
B13: VC&VD.01.4 | C13: VC&VD.01.4 截止性测试（认定：O、C） | F13: 程序页 | G13: 执行 | H13: 不执行的原因
B14: 1 | C14: 结合我们对于被审计单位费用确认时点的理解，考虑截止性测试的涵盖期间。 | F14: VC&VD.01.4 截止性测试
B15: 2 | C15: 记录确定截止性测试样本的策略。

Sheet Uexp.00 Lead
B1: 标准工作底稿: VC&VD SWP 销售费用&管理费用
B2: 客户名称 | D2: 此工作底稿需要与以下 Canvas PSP guided workflow forms一起使用： • VC&VD.00 销售费用&管理费用引导表 • VC&VD.01 销售费用&管理费用实质性程序 • 账户结论
B3: 期末 | C3: 46022
B4: 分析日期
B5: 可容忍误差(TE)
B6: 名义金额(SAD)
B7: 适用会计准则
B8: 记账本位币
B9: VC&VD.00 LEAD
A10: 62442a70-4601-4582-abe9-90996a0f33f2
B11: 返回汇总页
B13: 安永标记
B14: TB | C14: 已与科目余额表核对无误
B15: PY | C15: 与上年最终审定数核对一致
B16: A3 | C16: 与未审数、审定数核对一致
B17: A5 | C17: 与审计调整核对一致
B18: FS | C18: 与FS.0x与财务报表核对无误
B19: w | C19: 低于SAD的金额——放弃进一步调查
B20: Rx | C20: 重新计算，无异常
B21: m | C21: 余额/活动不符合测试范围–无需进一步调查
B22: SL | C22: 已与明细账核对无误
B24: 表1
B25: 科目名称 | C25: 索引号 | D25: 本期账面数 | E25: 账表调整数 | F25: 本期未审数 | G25: 审计调整数 | H25: 本期审定数 | I25: 上期审定数
B26: 销售费用 | C26: VC.00 销售费用BKD | D26: ='VC.00 销售费用BKD'!E35 -> 0 | E26: ='VC.00 销售费用BKD'!F35 -> 0 | F26: =SUM(D26:E26) -> 0 | G26: ='VC.00 销售费用BKD'!I35 -> 0 | H26: =SUM(F26:G26) -> 0 | I26: ='VC.00 销售费用BKD'!K35 -> 0
B27: 管理费用 | C27: VD.00 管理费用BKD | D27: ='VD.00 管理费用BKD'!E35 -> 0 | E27: ='VD.00 管理费用BKD'!F35 -> 0 | F27: =SUM(D27:E27) -> 0 | G27: ='VD.00 管理费用BKD'!I35 -> 0 | H27: =SUM(F27:G27) -> 0 | I27: ='VD.00 管理费用BKD'!K35 -> 0

Sheet VC.00 销售费用BKD
B1: 标准底稿: VC SWP 销售费用
B2: VC.00 编制汇总表并比较余额
B4: 返回汇总页
D6: Threshold(s)
B7: 认定 | C7: CRA | D7: 各项认定1 | E7: 所有相关认定 2
B8: 完整性 (C) | D8: =IF(C8="Minimal",'Uexp.00 Lead'!$C$5*50%,IF(C8="Low",'Uexp.00 Lead'!$C$5*25%,IF(C8="Moderate",'Uexp.00 Lead'!$C$5*15%,IF(C8="High",'Uexp.00 Lead'!$C$5*10%,IF(C8="N/A","-",))))) -> 0 | E8: =MIN($D$8:$D$11) -> 0
B9: 发生 (O) | D9: =IF(C9="Minimal",'Uexp.00 Lead'!$C$5*100%,IF(C9="Low",'Uexp.00 Lead'!$C$5*75%,IF(C9="Moderate",'Uexp.00 Lead'!$C$5*50%,IF(C9="High",'Uexp.00 Lead'!$C$5*25%,IF(C9="N/A","-",))))) -> 0
B10: 计量（M） | D10: =IF(C10="Minimal",'Uexp.00 Lead'!$C$5*100%,IF(C10="Low",'Uexp.00 Lead'!$C$5*75%,IF(C10="Moderate",'Uexp.00 Lead'!$C$5*50%,IF(C10="High",'Uexp.00 Lead'!$C$5*25%,IF(C10="N/A","-",))))) -> 0
B11: 列报和披露 (P&D) | D11: =IF(C11="Minimal",'Uexp.00 Lead'!$C$5*100%,IF(C11="Low",'Uexp.00 Lead'!$C$5*75%,IF(C11="Moderate",'Uexp.00 Lead'!$C$5*50%,IF(C11="High",'Uexp.00 Lead'!$C$5*25%,IF(C11="N/A","-",))))) -> 0
B12: 1 各项认定的测试阈值，是根据EY GAM SUBSTANTIVE DESIGN 2.2.1
B13: 中的示例测试阈值（用占TE的百分比表示）在相应风险等级（CRA）区间的上限计算得出的。
B14: 除负债/费用类别账户的完整性认定应当使用负债/费用账户表之外，其他类别账户和认定均可使用资产/收入账户表。
B15: 2 所有相关认定的测试阈值，是所有有效认定对应之测试阈值的最小值。我们在 Lead中使用该测试阈值：（a）作为选取总账账户进行测试的起点；（b）作为（需要进一步调查的）金额波动范围的起点。
B17: 在下文中描述我们当期对账户波动的预期，以及这些预期的理由。
B22: 波动范围
B23: ="波动幅度 ("&'Uexp.00 Lead'!$C$8&")" -> 波动幅度 () | C23: =E8 -> 0
B24: 波动幅度（%）： | C24: 0.1
E27: |--------- TB ---------| | K27: |------- PY -------|
B28: 表1 | E28: ="货币/单位: "&'Uexp.00 Lead'!C8 -> 货币/单位:
E29: ='Uexp.00 Lead'!C3 -> 46022 | K29: =DATE(YEAR($E$29)-1,12,31) -> 45657 | L29: 本期和上期发生额 | N29: For X-ref | O29: Notes | P29: 进一步调查基于波动幅度？ | Q29: 进一步调查基于定性考虑？
B30: 账套名称/账套编码 | C30: 总账科目编码 | D30: 科目名称 | E30: 本期账面数 | F30: 账表调整数 | G30: 本期未审数 | H30: 结构比 | I30: 审计调整数 | J30: 本期审定数 | K30: 上期审定数 | L30: 变动金额 | M30: 变动%
G31: =E31+F31 -> 0 | H31: =IF($G$35<>0,G31/$G$35,"") | J31: =G31+I31 -> 0 | L31: =J31-K31 -> 0 | M31: =IF(K31<>0,L31/K31,1) -> 1 | O31: [A] | P31: =IF(AND(ABS(L31)>=$C$23,ABS(M31)>=$C$24),"是","否") -> 是
G32: =E32+F32 -> 0 | H32: =IF($G$35<>0,G32/$G$35,"") | J32: =G32+I32 -> 0 | L32: =J32-K32 -> 0 | M32: =IF(K32<>0,L32/K32,1) -> 1 | P32: =IF(AND(ABS(L32)>=$C$23,ABS(M32)>=$C$24),"是","否") -> 是
G33: =E33+F33 -> 0 | H33: =IF($G$35<>0,G33/$G$35,"") | J33: =G33+I33 -> 0 | L33: =J33-K33 -> 0 | M33: =IF(K33<>0,L33/K33,1) -> 1 | P33: =IF(AND(ABS(L33)>=$C$23,ABS(M33)>=$C$24),"是","否") -> 是
D35: 合计 | E35: =SUM(E30:E34) -> 0 | F35: =SUM(F30:F34) -> 0 | G35: =SUM(G30:G34) -> 0 | H35: =SUM(H30:H34) -> 0 | I35: =SUM(I30:I34) -> 0 | J35: =SUM(J30:J34) -> 0 | K35: =SUM(K30:K34) -> 0 | L35: =J35-K35 -> 0 | M35: =IF(K35<>0,L35/K35,1) -> 1 | P35: =IF(AND(ABS(L35)>=$C$23,ABS(M35)>=$C$24),"是","否") -> 是
E36: Rx | F36: Rx | G36: Rx | I36: Rx | J36: Rx | K36: Rx
F37: A3
F38: Diff | G38: =G35-G37 -> 0 | J38: =J35-J37 -> 0 | K38: =K35-K37 -> 0
B40: 波动说明
B41: [A]
B46: 调整汇总表（如不适用请删除）
B47: 调整类型

Sheet VD.00 管理费用BKD
B1: 标准底稿: VD SWP 管理费用
B2: VD.00 编制汇总表并比较余额
B4: 返回汇总页
D6: Threshold(s)
B7: 认定 | C7: CRA | D7: 各项认定1 | E7: 所有相关认定 2
B8: 完整性 (C) | D8: =IF(C8="Minimal",'Uexp.00 Lead'!$C$5*50%,IF(C8="Low",'Uexp.00 Lead'!$C$5*25%,IF(C8="Moderate",'Uexp.00 Lead'!$C$5*15%,IF(C8="High",'Uexp.00 Lead'!$C$5*10%,IF(C8="N/A","-",))))) -> 0 | E8: =MIN($D$8:$D$11) -> 0
B9: 发生 (O) | D9: =IF(C9="Minimal",'Uexp.00 Lead'!$C$5*100%,IF(C9="Low",'Uexp.00 Lead'!$C$5*75%,IF(C9="Moderate",'Uexp.00 Lead'!$C$5*50%,IF(C9="High",'Uexp.00 Lead'!$C$5*25%,IF(C9="N/A","-",))))) -> 0
B10: 计量（M） | D10: =IF(C10="Minimal",'Uexp.00 Lead'!$C$5*100%,IF(C10="Low",'Uexp.00 Lead'!$C$5*75%,IF(C10="Moderate",'Uexp.00 Lead'!$C$5*50%,IF(C10="High",'Uexp.00 Lead'!$C$5*25%,IF(C10="N/A","-",))))) -> 0
B11: 列报和披露 (P&D) | D11: =IF(C11="Minimal",'Uexp.00 Lead'!$C$5*100%,IF(C11="Low",'Uexp.00 Lead'!$C$5*75%,IF(C11="Moderate",'Uexp.00 Lead'!$C$5*50%,IF(C11="High",'Uexp.00 Lead'!$C$5*25%,IF(C11="N/A","-",))))) -> 0
B12: 1 各项认定的测试阈值，是根据EY GAM SUBSTANTIVE DESIGN 2.2.1
B13: 中的示例测试阈值（用占TE的百分比表示）在相应风险等级（CRA）区间的上限计算得出的。
B14: 除负债/费用类别账户的完整性认定应当使用负债/费用账户表之外，其他类别账户和认定均可使用资产/收入账户表。
B15: 2 所有相关认定的测试阈值，是所有有效认定对应之测试阈值的最小值。我们在 Lead中使用该测试阈值：（a）作为选取总账账户进行测试的起点；（b）作为（需要进一步调查的）金额波动范围的起点。
B17: 在下文中描述我们当期对账户波动的预期，以及这些预期的理由。
B22: 波动范围
B23: ="波动幅度 ("&'Uexp.00 Lead'!$C$8&")" -> 波动幅度 () | C23: =E8 -> 0
B24: 波动幅度（%）： | C24: 0.1
E27: |------- TB -------| | K27: |------- PY -------|
B28: 表1 | E28: ="货币/单位: "&'Uexp.00 Lead'!C8 -> 货币/单位:
E29: ='Uexp.00 Lead'!C3 -> 46022 | K29: =DATE(YEAR($E$29)-1,12,31) -> 45657 | L29: 本期和上期发生额 | N29: For X-ref | O29: Notes | P29: 进一步调查基于波动幅度？ | Q29: 进一步调查基于定性考虑？
B30: 账套名称/账套编码 | C30: 总账科目编码 | D30: 科目名称 | E30: 本期账面数 | F30: 账表调整数 | G30: 本期未审数 | H30: 结构比 | I30: 审计调整数 | J30: 本期审定数 | K30: 上期审定数 | L30: 变动金额 | M30: 变动%
G31: =E31+F31 -> 0 | H31: =IF($G$35<>0,G31/$G$35,"") | J31: =G31+I31 -> 0 | L31: =J31-K31 -> 0 | M31: =IF(K31<>0,L31/K31,1) -> 1 | O31: [A] | P31: =IF(AND(ABS(L31)>=$C$23,ABS(M31)>=$C$24),"是","否") -> 是
G32: =E32+F32 -> 0 | H32: =IF($G$35<>0,G32/$G$35,"") | J32: =G32+I32 -> 0 | L32: =J32-K32 -> 0 | M32: =IF(K32<>0,L32/K32,1) -> 1 | P32: =IF(AND(ABS(L32)>=$C$23,ABS(M32)>=$C$24),"是","否") -> 是
G33: =E33+F33 -> 0 | H33: =IF($G$35<>0,G33/$G$35,"") | J33: =G33+I33 -> 0 | L33: =J33-K33 -> 0 | M33: =IF(K33<>0,L33/K33,1) -> 1 | P33: =IF(AND(ABS(L33)>=$C$23,ABS(M33)>=$C$24),"是","否") -> 是
E35: =SUM(E30:E34) -> 0 | F35: =SUM(F30:F34) -> 0 | G35: =SUM(G30:G34) -> 0 | H35: =SUM(H30:H34) -> 0 | I35: =SUM(I30:I34) -> 0 | J35: =SUM(J30:J34) -> 0 | K35: =SUM(K30:K34) -> 0 | L35: =J35-K35 -> 0 | M35: =IF(K35<>0,L35/K35,1) -> 1 | P35: =IF(AND(ABS(L35)>=$C$23,ABS(M35)>=$C$24),"是","否") -> 是
E36: Rx | F36: Rx | G36: Rx | I36: Rx | J36: Rx | K36: Rx
F37: A3
F38: Diff | G38: =G35-G37 -> 0 | J38: =J35-J37 -> 0 | K38: =K35-K37 -> 0
B40: 波动说明
B41: [A]
B46: 调整汇总表（如不适用请删除）
B47: 调整类型

Sheet VC&VD.01.2 TOD 年审
A1: V6 SWP
C2: 该底稿适用项目组年审时执行全年TOD程序。即不在预审分配样本执行TOD。
C3: 目标
C4: 通过在全年费用交易中选取关键项（key item）和代表性样本进行细节测试，确保对费用交易在本年度内准确记录并正确分类。
C5: 非同一重大交易类别且不具有类似特征(如不同CRA)的费用类型，应当分别进行TOD测试。
C9: 抽样策略
C10: 1 | D10: 确定样本总体和完整性测试
C11: 1.1 | D11: 总体名称 | E11: 数据来源 X-ref | F11: 金额
D15: 总体金额 | F15: =SUM(F12:F14) -> 0
F16: Rx
C17: 1.2 | D17: 剔除： | E17: 数据来源 X-ref | F17: 执行审计工作底稿X-ref | G17: 金额
D18: a. 在其他底稿中已执行程序项：(以下可由项目组自定义)
D19: 固定资产折旧费 | E19: eg.VC.00 | F19: eg.<固定资产折旧测算>
D20: 使用权资产折旧费
D21: 无形资产摊销费
D22: 长期待摊费用摊销费
D23: 工资薪酬
D24: 租赁费
D25: 预提费用（含预提和冲销）
D26: [其他剔除金额]
D27: b. 负值 | F27: 对于负值我们执行的审计工作详见以下表2
D29: 剔除样本合计 | G29: =SUM(G19:G27) -> 0
G30: Rx
D31: 扣除剔除项后样本总体金额： | G31: =F15-G29 -> 0
C34: 2 | D34: 确定关键项（key item） | E34: 数量 | F34: 金额
D35: 单笔发生额大于测试阈值
D36: 性质特殊[款项性质]
D37: [其他项目组认为存在风险的样本]
D39: 合计 | E39: =SUM(E35:E37) -> 0 | F39: =SUM(F35:F37) -> 0
E40: Rx | F40: Rx
C42: 3 | D42: 使用安永抽样工具对扣除关键项后的剩余样本总体抽取代表性样本
D44: 扣除剔除项和关键项后剩余样本总体： | E44: =G31-F39 -> 0
B48: 表1 | C48: 我们对抽出的关键项和代表性样本执行以下程序：
C49: 安永属性测试说明：获取相关支持性文件（如采购订单、发票、交货单、供应商合同、供应商借项通知单、结算单），检查了日记账分录，并得出结论：所记录的费用为：
C50: A | D50: 金额与支持性文件核对一致。
C51: B | D51: 记录在恰当的期间。
C52: C | D52: 分类恰当（即金额被记录至适当的账户，并包含在恰当的利润表项目中），这是基于费用的性质以及我们对该实体会计政策的理解。
P54: EY Works
C55: 抽样ID | D55: 样本类型 | E55: 凭证日期 | F55: 凭证号 | G55: 凭证摘要 | H55: 科目编码 | I55: 科目名称 | J55: 凭证金额 | K55: 供应商/分包商名称 | L55: 获得的支持性证据的名称及编号 | M55: 获得的交易凭据日期（费用实际发生日期） | N55: 获得的交易凭据金额（费用实际发生金额） | O55: 支持性证据金额与凭证金额之间的差异 | P55: A | Q55: B | R55: C | S55: 如有异常，请解释
O56: =J56-N56 -> 0
...

Sheet VC&VD.01.2 TOD 预审+剩余期间
C2: 该底稿适用项目组将TOD样本在年审预审中进行分配，并分别在预审和年审中执行TOD。
C3: 目标
C4: 通过在全年费用交易中选取关键项（key item）和代表性样本进行细节测试，确保对费用交易在本年度内准确记录并正确分类。
C5: 非同一重大交易类别且不具有类似特征(如不同CRA)的费用类型，应当分别进行TOD测试。
C8: 抽样策略
C9: 1 | D9: 确定样本总体和完整性测试
C10: 1.1 | D10: 总体名称 | E10: 数据来源 X-ref | F10: 预审期间（如1-9月份） | G10: 剩余期间（如10-12月份) | H10: 合计
H11: =F11+G11 -> 0
H12: =F12+G12 -> 0
H13: =F13+G13 -> 0
H14: =F14+G14 -> 0
D15: 总体金额 | F15: =SUM(F11:F14) -> 0 | G15: =SUM(G11:G14) -> 0 | H15: =F15+G15 -> 0
F16: Rx | G16: Rx
C17: 1.2 | D17: 剔除 | E17: 数据来源 X-ref | F17: 执行审计工作底稿X-ref | G17: 预审期间（如1-9月份） | H17: 剩余期间（如10-12月份) | I17: 合计
D18: a. 在其他底稿中已执行程序项：（以下可由项目组自定义）
D19: 固定资产折旧费 | E19: eg.VC.00 | F19: eg.<固定资产折旧测算> | I19: =G19+H19 -> 0
D20: 使用权资产折旧费 | I20: =G20+H20 -> 0
D21: 无形资产摊销费 | I21: =G21+H21 -> 0
D22: 长期待摊费用摊销费 | I22: =G22+H22 -> 0
D23: 工资薪酬 | I23: =G23+H23 -> 0
D24: 租赁费 | I24: =G24+H24 -> 0
D25: 预提费用（含预提和冲销） | I25: =G25+H25 -> 0
D26: [其他剔除金额] | I26: =G26+H26 -> 0
D27: b. 负值 | F27: 对于负值我们执行的审计工作详见以下表2 | I27: =G27+H27 -> 0
D29: 剔除样本合计 | G29: =SUM(G19:G27) -> 0 | H29: =SUM(H19:H27) -> 0 | I29: =SUM(I19:I27) -> 0
G30: Rx | H30: Rx | I30: Rx
D31: 扣除剔除项后样本总体金额： | G31: =F15-G29 -> 0 | H31: =G15-H29 -> 0 | I31: =H15-I29 -> 0
C34: 2 | D34: 确定关键项（key item） | E34: 预审期间（如1-9月份） | G34: 剩余期间（如10-12月份） | I34: 合计
E35: 数量 | F35: 金额 | G35: 数量 | H35: 金额 | I35: 数量 | J35: 金额
D36: 单笔发生额大于测试阈值 | I36: =G36+E36 -> 0 | J36: =H36+F36 -> 0
D37: 性质特殊[款项性质] | I37: =G37+E37 -> 0 | J37: =H37+F37 -> 0
D38: [其他项目组认为存在风险的样本] | I38: =G38+E38 -> 0 | J38: =H38+F38 -> 0
D40: 合计 | E40: =SUM(E36:E38) -> 0 | F40: =SUM(F36:F38) -> 0 | G40: =SUM(G36:G38) -> 0 | H40: =SUM(H36:H38) -> 0 | I40: =E40+G40 -> 0 | J40: =H40+F40 -> 0
E41: Rx | F41: Rx | G41: Rx | H41: Rx | I41: Rx | J41: Rx
C43: 3 | D43: 使用安永抽样工具对扣除关键项后的剩余样本总体抽取代表性样本
E44: 预审期间（如1-9月份） | F44: 剩余期间（如10-12月份) | G44: 合计
D45: 扣除剔除项和关键项后剩余样本总体： | E45: =G31-F40 -> 0 | F45: =H31-H40 -> 0 | G45: =I31-J40 -> 0
C47: 4 | D47: 请项目组在以下填写年审预审分配代表性样本的策略：
B53: 表1 | C53: 我们对抽出的关键项和代表性样本执行以下程序：
C54: 安永属性测试说明：获取相关支持性文件（如采购订单、发票、交货单、供应商合同、供应商借项通知单、结算单），检查了日记账分录，并得出结论：所记录的费用为：
...

Sheet VC&VD.01.2 TOD 抽样工具输出
A1: 804a7b04-c4dc-41ba-a745-4666c5f24f11
B3: 注： | C3: 请在此保留安永抽样工具输出的抽样结果底稿。如果未使用抽样工具，请删除该页，但项目组应在底稿中记录抽样过程。

Sheet VD.01.3 复核法律费用
B1: 标准工作底稿: VD SWP 管理费用
B2: VD.01.3 复核法律费用
B4: 复核法律费用
B6: 返回汇总页
B8: 安永属性测试说明:
B9: 我们对金额大于测试阈值的法律费用相关账户进行复核（如有），查看其交易性质及金额是否与账面一致，同时对性质特殊（如诉讼等）的法律费用向律师发送审计询问函，对回函差异进行调查，对于未决诉讼，应执行相关程序，请检查勾稽到预期信用损失、预计负债等底稿。
B11: 表1
B12: 账套名称/账套编码 | C12: 科目编码 | D12: 项目名称 | E12: 本期账面数 | F12: 服务性质/内容 | G12: 服务开始时间 | H12: 金额 | I12: 是否发函（如不发函请列示原因） | J12: 是否回函 | K12: 回函是否有差异 | L12: 差异原因(如适用) | M12: 是否涉及未决诉讼 | N12: For X-ref
D20: 合计 | E20: =SUM(E12:E18) -> 0 | H20: =SUM(H12:H18) -> 0
E21: Rx | H21: Rx
B23: Notes

Sheet VC&VD.01.4 截止性测试
B1: 标准工作底稿: VC&VD SWP 销售费用&管理费用
B2: VC&VD.01.4 截止性测试
B4: 执行截止性测试
B6: 返回汇总页
B8: 表1 确定截止性测试的涵盖期间
B9: 测试期间（输入前后天数） | C9: 测试期间确定依据/原因 | D9: 测试开始日期 | E9: 测试结束日期
C10: （测试期间项目组要结合被审计单位的费用从实际发生到入账的周期进行判断，并在此记录。） | D10: ='Uexp.00 Lead'!$C$3-'VC&VD.01.4 截止性测试'!B10 -> 46022 | E10: ='Uexp.00 Lead'!$C$3+'VC&VD.01.4 截止性测试'!B10 -> 46022
B12: 表2 记录确定截止性测试样本的策略：
B17: 表3 测试期间费用的截止性
B18: 安永属性测试说明：
B19: 根据支持性证据（例如：费用结算单等）确定所选交易已记录在适当会计期间。
B23: 入账凭证 | F23: 支持性证据信息 | I23: 金额涉及： | K23: EY Works | L23: 备注
F24: （确认控制权转移/接受服务的交易凭据） | I24: （用“√”标记）
B25: 凭证编号 | C25: 日期 | D25: 金额 | E25: 明细科目名称 | F25: 交易凭据名称 | G25: 交易凭据编号 | H25: 交易发生日期 | I25: 本期 | J25: 资产负债表日后期间 | K25: 1
B26: 本期资产负债表日前记录的交易
B32: 本期资产负债表日后记录的交易
B39: Notes
B40: *我们在注释框中包括我们认为有必要的任何附加评论，以使以前与本项目没有联系的有经验的审计师清楚地理解 1)我们所执行程序的性质、时间和范围; 2)我们执行的程序的结果; 3)获得的证据和得出的结论，包括我们考虑的任何不一致或相反的信息以及与该信息相关的结论; 4)确定的例外情况的细节，如果适用，以及如何解决这些问题，包括执行的其他实质性程序。

Sheet SkywindSettingSheet
A1: 6c62fc94-8360-45ff-b236-5283c3da78da
A3: {"Id":"2120093264","IsProject":false,"ProjectId":"2006600230","TempProjectName":"测试上数","TempType":2}
A4: TRUE
A5: 管理费用
