Workbook

Sheet 汇总
A1: b1f3f80b-0552-4a3d-a30b-8b045766af91
C3: 客户名称 | F3: 重要性水平(PM)
C5: 期末 | D5: 45657 | F5: 可容忍误差(TE)
C7: 记账本位币 | F7: 名义金额(SAD)
C9: 适用会计准则
C12: CRA | D12: %*
C13: High | D13: 0.1
C14: Moderate | D14: 0.15
C15: Low | D15: 0.25
C16: Minimal | D16: 0.5
C17: N/A
C18: *我们期望执行的基准实质性审计程序性质、时间和范围对应的CRA风险比例，此比例为上限，项目组应按照实际情况进行调整。
C20: 认定 | D20: CRA | E20: Threshold | F20: 所有相关认定*
B21: High | C21: 完整性（C） | E21: =IFERROR(VLOOKUP(D21,$C$13:$D$16,2,FALSE)*$G$5,"-") -> - | F21: =MIN($E$21:$E$24) -> 0
B22: Moderate | C22: 发生（O） | E22: =IFERROR(VLOOKUP(D22,$C$13:$D$16,2,FALSE)*$G$5,"-") -> -
B23: Low | C23: 计量（M） | E23: =IFERROR(VLOOKUP(D23,$C$13:$D$16,2,FALSE)*$G$5,"-") -> -
B24: Minimal | C24: 列报与披露（P&D） | E24: =IFERROR(VLOOKUP(D24,$C$13:$D$16,2,FALSE)*$G$5,"-") -> -
B25: N/A | C25: *使用所有相关认定中的最低阈值来计算该阈值。
C27: 该科目涉及OSP底稿可参考此链接 | E27: OSP SWP 研发费用 202YMMDD XYZ公司.xlsx
A29: P1 | C29: 序号 | D29: 报表科目 | E29: 执行实质性程序 | F29: 实质性程序类型 | G29: 认定 | H29: 程序描述 | I29: 执行 | J29: 索引 | K29: 如不执行PSP，原因需记录文字多于5个文字
C30: 1 | D30: 所有利润表科目（除收入和成本） | E30: VD-01.1-GL: 实质性程序{取得对账单并进行对比} | F30: PSP | G30: IS: O, M, C, P&D | H30: 取得所有利润表科目（除收入和成本外）金额。对比之前期间并调查异常或非预期变动或未发生预期变动的情况。调查任何异常交易，并基于综合风险评估和已确定的测试临界值测试交易。 | J30: Uexp_Lead
C31: 2 | D31: 制造费用 | E31: VD-01.1-GL: 实质性程序{取得对账单并进行对比} | F31: PSP | G31: IS: O, M, C, P&D | H31: 1.从管理层处取得各利润表类账户的明细账。 2.将明细账金额与总账及我们的导引表核对一致。对比当期金额和上期金额，调查异常或非预期变动或者预期变动不足的情况。 3.分析费用明细的变动，并就异常事项检查记账凭证、合同等支持性证据，评估其发生的合理性。 4调查任何异常交易，并基于综合风险评估和已确定的测试临界值测试交易。 | J31: Uexp制造费用BKD
C32: 3 | D32: 研发费用 | J32: Uexp研发费用BKD
C33: 4 | D33: 财务费用 | J33: Uexp财务费用BKD
C34: 5 | D34: 其他收益 | J34: Uexp其他收益BKD
C35: 6 | D35: 投资收益 | J35: Uexp投资收益BKD
C36: 7 | D36: 公允价值变动损益 | J36: Uexp公允价值变动损益BKD
C37: 8 | D37: 信用减值损失 | J37: Uexp信用减值损失BKD
C38: 9 | D38: 资产减值损失 | J38: Uexp资产减值损失BKD
C39: 10 | D39: 资产处置损益 | J39: Uexp资产处置损益BKD
C40: 11 | D40: 营业外收入 | J40: Uexp营业外收入BKD
C41: 12 | D41: 营业外支出 | J41: Uexp营业外支出BKD
C42: 13 | D42: 债务重组利得和损失 | J42: Uexp债务重组利得和损失BKD
C43: 14 | D43: 财务费用/投资收益 | E43: UC-01-GL: 利息和股息收入 | F43: PSP | G43: IS: O, M, C, P&D | H43: 测试重大投资的利息和股息收益，或通过与相关投资余额相比较来检查投资收益的合理性。 | J43: Uexp利息测试
C44: 15 | D44: 所有利润表科目（除收入和成本） | E44: VD-01.2-GL: 实质性程序{执行分析程序} | F44: PSP | G44: IS: O, M, C, P&D | H44: 确定我们对按类型、月份或其他适用期间分解的管理和其他营业费用的预期，使其精确到足以根据我们对业务的了解，识别出错报。 结合我们的预期和已识别出的精确度，确定我们的差异临界值（已入账费用与我们的可接受但尚无进一步调查的预期之间的金额差异）。 结合我们的差异临界值，识别我们的预期的差异。取得充足证据证明差异是适当的。记录我们如何就实质分析性复核程序中使用的相关数据的可靠性满足自身要求。确定是否执行实质分析性复核程序来测试相关账户。如执行，则使用264GL完成相应记录。
C45: 16 | D45: 费用科目（包括制造费用） | E45: VD-01.8-GL:执行截止程序 | F45: PSP | G45: IS: O, C | H45: 记录在账面的费用交易是否记录于正确期间 | J45: Uexp_Cutoff
C46: 17 | D46: 由审计团队确认执行TOD范围 | E46: VC/VD-01.3-01.6-GL: 实质性程序 详细测试(TOD） | F46: PSP | G46: IS: O, M, C, P&D | H46: 若通过实质分析性复核程序取得的证据不足以就账户余额得出结论，则执行详细测试。 | J46: Uexp_TOD
C48: IPE 考虑
A49: /P1 | C49: 18 | D49: IPE | H49: 执行IPE程序以评估客户提供的数据的准确性和完整性。可点击此处获取265 Form，获取后需更新链接至执行程序265GL 。
C51: 费用类账户总结陈述
...

Sheet Uexp_Lead
A1: c320deef-b651-4890-83c8-fa4b53e6fbdf
J2: 返回汇总页
C4: 目标
C5: 通过执行分析和调查两期的费用科目重大变动来确定费用科目是否合理。
C7: 序号 | D7: 执行的程序 | G7: 程序表 | H7: 预审完成 | I7: 年审完成 | J7: 执行注意事项
C8: 1 | D8: 我们获取费用科目余额表本期金额以及上年审定数。 | G8: 表1 | H8: 是
C9: 2 | D9: 我们将两期审定金额进行比对，对那些变动大于范围的事项，获得管理层解释并对解释是否合理进行调查。 | G9: 表1 | H9: 是
C12: 在下文中描述我们当期对账户波动的预期，以及这些预期的依据和理由。
C17: ="波动幅度 ("&汇总!D7&"):" -> 波动幅度 (): | D17: =汇总!$F$21 -> 0
C18: 波动幅度（%）：
E19: AA | F19: BB | G19: CC=AA+BB | H19: DD | I19: EE=CC+DD | J19: FF | K19: GG=EE-FF | L19: HH=GG/FF
K20: 本期审定数与上期审定数比较
B21: 表1 | C21: 科目名称 | D21: 索引号 | E21: 本期账面数 | F21: 本期账表调整数 | G21: 本期账面未审数 | H21: 本期审计调整金数 | I21: 本期账面审定数 | J21: 上期末审定数 | K21: 变动额 | L21: 变动率
C22: 制造费用 | D22: Uexp制造费用BKD | E22: =IFERROR(Uexp制造费用BKD!F35,"") -> 0 | F22: =IFERROR(Uexp制造费用BKD!H35,"") -> 0 | G22: =E22+F22 -> 0 | H22: =IFERROR(Uexp制造费用BKD!L35,"") -> 0 | I22: =G22+H22 -> 0 | J22: =IFERROR(Uexp制造费用BKD!N35,"") -> 0 | K22: =I22-J22 -> 0 | L22: =IF(J22<>0,K22/J22,1) -> 1
C23: 研发费用 | D23: Uexp研发费用BKD | E23: =IFERROR(Uexp研发费用BKD!F41,"") -> 0 | F23: =IFERROR(Uexp研发费用BKD!H41,"") -> 0 | G23: =E23+F23 -> 0 | H23: =IFERROR(Uexp研发费用BKD!L41,"") -> 0 | I23: =G23+H23 -> 0 | J23: =IFERROR(Uexp研发费用BKD!N41,"") -> 0 | K23: =I23-J23 -> 0 | L23: =IF(J23<>0,K23/J23,1) -> 1
C24: 财务费用 | D24: Uexp财务费用BKD | E24: =IFERROR(Uexp财务费用BKD!F35,"") -> 0 | F24: =IFERROR(Uexp财务费用BKD!H35,"") -> 0 | G24: =E24+F24 -> 0 | H24: =IFERROR(Uexp财务费用BKD!L35,"") -> 0 | I24: =G24+H24 -> 0 | J24: =IFERROR(Uexp财务费用BKD!N35,"") -> 0 | K24: =I24-J24 -> 0 | L24: =IF(J24<>0,K24/J24,1) -> 1
C25: 其他收益 | D25: Uexp其他收益BKD | E25: =IFERROR(Uexp其他收益BKD!F37,"") -> 0 | F25: =IFERROR(Uexp其他收益BKD!H37,"") -> 0 | G25: =E25+F25 -> 0 | H25: =IFERROR(Uexp其他收益BKD!L37,"") -> 0 | I25: =G25+H25 -> 0 | J25: =IFERROR(Uexp其他收益BKD!N37,"") -> 0 | K25: =I25-J25 -> 0 | L25: =IF(J25<>0,K25/J25,1) -> 1
C26: 投资收益 | D26: Uexp投资收益BKD | E26: =IFERROR(Uexp投资收益BKD!F37,"") -> 0 | F26: =IFERROR(Uexp投资收益BKD!H37,"") -> 0 | G26: =E26+F26 -> 0 | H26: =IFERROR(Uexp投资收益BKD!L37,"") -> 0 | I26: =G26+H26 -> 0 | J26: =IFERROR(Uexp投资收益BKD!N37,"") -> 0 | K26: =I26-J26 -> 0 | L26: =IF(J26<>0,K26/J26,1) -> 1
C27: 公允价值变动损益 | D27: Uexp公允价值变动损益BKD | E27: =IFERROR(Uexp公允价值变动损益BKD!F36,"") -> 0 | F27: =IFERROR(Uexp公允价值变动损益BKD!H36,"") -> 0 | G27: =E27+F27 -> 0 | H27: =IFERROR(Uexp公允价值变动损益BKD!L36,"") -> 0 | I27: =G27+H27 -> 0 | J27: =IFERROR(Uexp公允价值变动损益BKD!N36,"") -> 0 | K27: =I27-J27 -> 0 | L27: =IF(J27<>0,K27/J27,1) -> 1
C28: 信用减值损失 | D28: Uexp信用减值损失BKD | E28: =IFERROR(Uexp信用减值损失BKD!F35,"") -> 0 | F28: =IFERROR(Uexp信用减值损失BKD!H35,"") -> 0 | G28: =E28+F28 -> 0 | H28: =IFERROR(Uexp信用减值损失BKD!L35,"") -> 0 | I28: =G28+H28 -> 0 | J28: =IFERROR(Uexp信用减值损失BKD!N35,"") -> 0 | K28: =I28-J28 -> 0 | L28: =IF(J28<>0,K28/J28,1) -> 1
C29: 资产减值损失 | D29: Uexp资产减值损失BKD | E29: =IFERROR(Uexp资产减值损失BKD!F36,"") -> 0 | F29: =IFERROR(Uexp资产减值损失BKD!H36,"") -> 0 | G29: =E29+F29 -> 0 | H29: =IFERROR(Uexp资产减值损失BKD!L36,"") -> 0 | I29: =G29+H29 -> 0 | J29: =IFERROR(Uexp资产减值损失BKD!N36,"") -> 0 | K29: =I29-J29 -> 0 | L29: =IF(J29<>0,K29/J29,1) -> 1
C30: 资产处置损益 | D30: Uexp资产处置损益BKD | E30: =IFERROR(Uexp资产处置损益BKD!F36,"") -> 0 | F30: =IFERROR(Uexp资产处置损益BKD!H36,"") -> 0 | G30: =E30+F30 -> 0 | H30: =IFERROR(Uexp资产处置损益BKD!L36,"") -> 0 | I30: =G30+H30 -> 0 | J30: =IFERROR(Uexp资产处置损益BKD!N36,"") -> 0 | K30: =I30-J30 -> 0 | L30: =IF(J30<>0,K30/J30,1) -> 1
C31: 营业外收入 | D31: Uexp营业外收入BKD | E31: =IFERROR(Uexp营业外收入BKD!F36,"") -> 0 | F31: =IFERROR(Uexp营业外收入BKD!H36,"") -> 0 | G31: =E31+F31 -> 0 | H31: =IFERROR(Uexp营业外收入BKD!L36,"") -> 0 | I31: =G31+H31 -> 0 | J31: =IFERROR(Uexp营业外收入BKD!N36,"") -> 0 | K31: =I31-J31 -> 0 | L31: =IF(J31<>0,K31/J31,1) -> 1
C32: 营业外支出 | D32: Uexp营业外支出BKD | E32: =IFERROR(Uexp营业外支出BKD!F37,"") -> 0 | F32: =IFERROR(Uexp营业外支出BKD!H37,"") -> 0 | G32: =E32+F32 -> 0 | H32: =IFERROR(Uexp营业外支出BKD!L37,"") -> 0 | I32: =G32+H32 -> 0 | J32: =IFERROR(Uexp营业外支出BKD!N37,"") -> 0 | K32: =I32-J32 -> 0 | L32: =IF(J32<>0,K32/J32,1) -> 1
C33: 债务重组利得和损失 | D33: Uexp债务重组利得和损失BKD | E33: =IFERROR(Uexp债务重组利得和损失BKD!F37,"") -> 0 | F33: =IFERROR(Uexp债务重组利得和损失BKD!H37,"") -> 0 | G33: =E33+F33 -> 0 | H33: =IFERROR(Uexp债务重组利得和损失BKD!L37,"") -> 0 | I33: =G33+H33 -> 0 | J33: =IFERROR(Uexp债务重组利得和损失BKD!N37,"") -> 0 | K33: =I33-J33 -> 0 | L33: =IF(J33<>0,K33/J33,1) -> 1
B35: Notes
C40: 调整汇总表 | D40: 如不适用请删除

Sheet Uexp制造费用BKD
A1: 750d443c-76ce-4b04-9a77-da842ea2cc9b
J2: 返回汇总页
C4: 目标
C5: 1.通过执行分析和调查两期的制造费用重大变动来确定其变动是否合理。
C6: 2.明细账金额、科目余额表中的金额是否一致，对重大不一致调查其调节项的性质及原因。
C8: 序号 | D8: 执行的程序 | G8: 程序表 | H8: 预审完成 | I8: 年审完成 | J8: 执行注意事项
C9: 1 | D9: 从管理层处取得本期制造费用账户的明细。 | G9: 表1 | H9: 是
C10: 2 | D10: 对比当期金额和上期金额，调查变动大于范围或与预期不符的变动情况。并就异常事项检查记账凭证、合同等支持性证据，评估其发生的合理性。 | G10: 表1 | H10: 是
C11: 3 | D11: 将明细账与生产成本-制造费用进行核对，并对差异大于SAD的项目进行调查。 | G11: 表1 | H11: 是
C12: 4 | D12: 对于单项金额重大的制造费用，需要获取该单项费用的组成明细，需要获取支持性文件如合同等，在必要时进行费用测试。 | G12: TOD SWP U_Exp_Uexp.01 TOD年审 | H12: 是
C13: 5 | D13: 对调查任何异常交易，并基于综合风险评估和已确定的测试临界值测试交易。 | G13: 项目组自行设计 | H13: 是
C14: 6 | D14: 将费用科目中存在着勾稽关系的费用类型，同相应的其他科目金额进行核对X-ref | G14: 表1 | H14: 是
C18: 在下文中描述我们当期对账户波动的预期，以及这些预期的依据和理由。
C23: ="波动范围 ("&D11& "):" -> 波动范围 (将明细账与生产成本-制造费用进行核对，并对差异大于SAD的项目进行调查。): | D23: =汇总!$F$21 -> 0
C24: 波动范围 (%):
F26: AA | H26: BB | I26: CC=AA+BB | L26: DD | M26: EE=CC+DD | N26: FF | O26: GG=EE-FF | P26: HH=GG/FF
A27: T1 | C27: TB | D27: TB | E27: TB | F27: TB
I28: =F28+H28 -> 0 | J28: =IF($I$35<>0,I28/$I$35,"") | M28: =I28+L28 -> 0 | O28: =M28-N28 -> 0 | P28: =IF(N28<>0,O28/N28,1) -> 1
B29: 表1 | I29: 本期数 | N29: =DATE(YEAR(汇总!$D$5)-1,12,31) -> 45291 | O29: 本期审定数与上期审定数比较
C30: 账套名称/账套编码 | D30: 科目编码 | E30: 科目名称 | F30: 本期账面数 | G30: 本期账表调整编号 | H30: 本期账表调整数 | I30: 本期账面未审数 | J30: 结构比 | K30: 本期审计调整编号 | L30: 本期审计调整金数 | M30: 本期账面审定数 | N30: 上期末审定数 (PY) | O30: 变动额 | P30: 变动率% | Q30: For X-ref | R30: Notes
I31: =F31+H31 -> 0 | J31: =IF($I$35<>0,I31/$I$35,"") | M31: =I31+L31 -> 0 | O31: =M31-N31 -> 0 | P31: =IF(N31<>0,O31/N31,1) -> 1
I32: =F32+H32 -> 0 | J32: =IF($I$35<>0,I32/$I$35,"") | M32: =I32+L32 -> 0 | O32: =M32-N32 -> 0 | P32: =IF(N32<>0,O32/N32,1) -> 1
A33: /T1 | I33: =F33+H33 -> 0 | J33: =IF($I$35<>0,I33/$I$35,"") | M33: =I33+L33 -> 0 | O33: =M33-N33 -> 0 | P33: =IF(N33<>0,O33/N33,1) -> 1
E35: 合计 | F35: =SUM(F30:F34) -> 0 | H35: =SUM(H30:H34) -> 0 | I35: =SUM(I30:I34) -> 0 | J35: =SUM(J30:J34) -> 0 | L35: =SUM(L30:L34) -> 0 | M35: =SUM(M30:M34) -> 0 | N35: =SUM(N30:N34) -> 0 | O35: =M35-N35 -> 0 | P35: =IF(N35<>0,O35/N35,1) -> 1
F36: Rx | H36: Rx | I36: Rx | J36: Rx | L36: Rx | M36: Rx | N36: Rx
D38: 详细测试涵盖的总账账户 | E38: <Uexp.01 TOD预审+剩余期间>/<Uexp.01 TOD 年审>
B40: Notes | C40: 对变动不在范围内的项目进行调查，评估其合理性，并记录在“说明”中。对异常项目进行调查，并记录在“说明”中。
B47: 表3 | C47: 对于单项费用类别金额占整个制造费用比例达到一定比例查看J列，需要获取该单项费用的组成明细，需要获取支持性文件如合同等，在必要时进行费用测试。（表格请审计团队自行设计）

Sheet Uexp研发费用BKD
A1: 4cdc28c4-ea8a-467e-9b39-ede0a6875638
J2: 返回汇总页
C4: 目标
C5: 1.通过执行分析和调查两期的研发费用重大变动来确定其变动是否合理。
C6: 2.明细账金额、总账及报表金额是否一致，对重大不一致调查其调节项的性质及原因。
C8: 序号 | D8: 执行的程序 | G8: 程序表 | H8: 预审完成 | I8: 年审完成 | J8: 执行注意事项
C9: 1 | D9: 从管理层处取得本期研发费用账户的明细。 | G9: 表1 | H9: 是
C10: 2 | D10: 对比当期金额和上期金额，调查变动大于范围或与预期不符的变动情况。并就异常事项检查记账凭证、合同等支持性证据，评估其发生的合理性。 | G10: 表1 | H10: 是
C11: 3 | D11: 将明细账与管理层报表进行核对，并对差异大于SAD的项目进行调查。 | G11: 表1 | H11: 是
C12: 4 | D12: 对于单项金额重大的研发费用，需要获取该单项费用的组成明细，需要获取支持性文件如合同等，在必要时进行费用测试。 | G12: TOD SWP U_Exp_Uexp.01 TOD年审 | H12: 是
C13: 5 | D13: 调查任何异常交易，并基于综合风险评估和已确定的测试临界值测试交易。 | G13: 项目组自行设计 | H13: 是
C14: 6 | D14: 将费用科目中存在着勾稽关系的费用类型，同相应的其他科目金额进行核对X-ref | G14: 表1 | H14: 是 | J14: 注意：研发费用中的资本化部分与研发支出金额的资本化时点应当进行核对并标记交叉索引 注意：在建工程或借款底稿中的利息测试应当注意是否包括形成研发费用的部分交叉索引
C18: 在下文中描述我们当期对账户波动的预期，以及这些预期的依据和理由。
C23: ="波动范围 ("&D11& "):" -> 波动范围 (将明细账与管理层报表进行核对，并对差异大于SAD的项目进行调查。): | D23: =汇总!$F$21 -> 0
C24: 波动范围 (%):
F27: AA | H27: BB | I27: CC=AA+BB | L27: DD | M27: EE=CC+DD | N27: FF | O27: GG=EE-FF | P27: HH=GG/FF
A28: T1 | C28: TB | D28: TB | E28: TB | F28: TB
I29: =F29+H29 -> 0 | J29: =IF($I$41<>0,I29/$I$41,"") | M29: =I29+L29 -> 0 | O29: =M29-N29 -> 0 | P29: =IF(N29<>0,O29/N29,1) -> 1
B30: 表1 | I30: 本期数 | N30: =DATE(YEAR(汇总!$D$5)-1,12,31) -> 45291 | O30: 本期审定数与上期审定数比较
C31: 账套名称/账套编码 | D31: 科目编码 | E31: 科目名称 | F31: 本期账面数 | G31: 本期账表调整编号 | H31: 本期账表调整数 | I31: 本期账面未审数 | J31: 结构比 | K31: 本期审计调整编号 | L31: 本期审计调整金数 | M31: 本期账面审定数 | N31: 上期末审定数 (PY) | O31: 变动额 | P31: 变动率% | Q31: For X-ref | R31: Notes
I32: =F32+H32 -> 0 | J32: =IF($I$41<>0,I32/$I$41,"") | M32: =I32+L32 -> 0 | O32: =M32-N32 -> 0 | P32: =IF(N32<>0,O32/N32,1) -> 1
I33: =F33+H33 -> 0 | J33: =IF($I$41<>0,I33/$I$41,"") | M33: =I33+L33 -> 0 | O33: =M33-N33 -> 0 | P33: =IF(N33<>0,O33/N33,1) -> 1
I34: =F34+H34 -> 0 | J34: =IF($I$41<>0,I34/$I$41,"") | M34: =I34+L34 -> 0 | O34: =M34-N34 -> 0 | P34: =IF(N34<>0,O34/N34,1) -> 1
I35: =F35+H35 -> 0 | J35: =IF($I$41<>0,I35/$I$41,"") | M35: =I35+L35 -> 0 | O35: =M35-N35 -> 0 | P35: =IF(N35<>0,O35/N35,1) -> 1
I36: =F36+H36 -> 0 | J36: =IF($I$41<>0,I36/$I$41,"") | M36: =I36+L36 -> 0 | O36: =M36-N36 -> 0 | P36: =IF(N36<>0,O36/N36,1) -> 1
I37: =F37+H37 -> 0 | J37: =IF($I$41<>0,I37/$I$41,"") | M37: =I37+L37 -> 0 | O37: =M37-N37 -> 0 | P37: =IF(N37<>0,O37/N37,1) -> 1
I38: =F38+H38 -> 0 | J38: =IF($I$41<>0,I38/$I$41,"") | M38: =I38+L38 -> 0 | O38: =M38-N38 -> 0 | P38: =IF(N38<>0,O38/N38,1) -> 1
A39: /T1 | I39: =F39+H39 -> 0 | J39: =IF($I$41<>0,I39/$I$41,"") | M39: =I39+L39 -> 0 | O39: =M39-N39 -> 0 | P39: =IF(N39<>0,O39/N39,1) -> 1
E41: 合计 | F41: =SUM(F31:F40) -> 0 | H41: =SUM(H31:H40) -> 0 | I41: =SUM(I31:I40) -> 0 | J41: =SUM(J31:J40) -> 0 | L41: =SUM(L31:L40) -> 0 | M41: =SUM(M31:M40) -> 0 | N41: =SUM(N31:N40) -> 0 | O41: =M41-N41 -> 0 | P41: =IF(N41<>0,O41/N41,1) -> 1
F42: Rx | H42: ^ | I42: Rx | J42: Rx | L42: Rx | M42: Rx | N42: Rx
H43: A3
D44: 详细测试涵盖的总账账户 | E44: <Uexp.01 TOD预审+剩余期间>/<Uexp.01 TOD 年审> | H44: Diff | I44: =I41-I43 -> 0 | M44: =M41-M43 -> 0 | N44: =N41-N43 -> 0
B46: Notes | C46: 对变动不在范围内的项目进行调查，评估其合理性，并记录在“说明”中。对异常项目进行调查，并记录在“说明”中。

Sheet Uexp财务费用BKD
A1: ef949b77-f54f-447e-9d50-7c9f48bd6215
J2: 返回汇总页
C4: 目标
C5: 1.通过执行分析和调查两期的财务费用重大变动来确定其变动是否合理。
C6: 2.明细账金额、总账及报表金额是否一致，对重大不一致调查其调节项的性质及原因。
C8: 序号 | D8: 执行的程序 | G8: 程序表 | H8: 预审完成 | I8: 年审完成 | J8: 执行注意事项
C9: 1 | D9: 从管理层处取得本期财务费用账户的明细。 | G9: 表1 | H9: 是
C10: 2 | D10: 对比当期金额和上期金额，调查变动大于范围或与预期不符的变动情况。并就异常事项检查记账凭证、合同等支持性证据，评估其发生的合理性。 | G10: 表1 | H10: 是
C11: 3 | D11: 将明细账与管理层报表进行核对，并对差异大于SAD的项目进行调查。 | G11: 表1 | H11: 是
C12: 4 | D12: 对于单项金额重大的财务费用，需要获取该单项费用的组成明细，需要获取支持性文件如合同等，在必要时进行费用测试。 | G12: TOD SWP U_Exp_Uexp.01 TOD年审 | H12: 是
C13: 5 | D13: 我们对金额大于测试阈值或性质特殊的利息收入进行测试。 | G13: <Uexp利息测试>
C14: 6 | D14: 将费用科目中存在着勾稽关系的费用类型，同相应的其他科目金额进行核对X-ref | G14: 表1 | H14: 是
C18: 在下文中描述我们当期对账户波动的预期，以及这些预期的依据和理由。
C23: ="波动范围 ("&D11& "):" -> 波动范围 (将明细账与管理层报表进行核对，并对差异大于SAD的项目进行调查。): | D23: =汇总!$F$21 -> 0
C24: 波动范围 (%):
F26: AA | H26: BB | I26: CC=AA+BB | L26: DD | M26: EE=CC+DD | N26: FF | O26: GG=EE-FF | P26: HH=GG/FF
A27: T1 | C27: TB | D27: TB | E27: TB | F27: TB
I28: =F28+H28 -> 0 | J28: =IF($I$35<>0,I28/$I$35,"") | M28: =I28+L28 -> 0 | O28: =M28-N28 -> 0 | P28: =IF(N28<>0,O28/N28,1) -> 1
B29: 表1 | I29: 本期数 | N29: =DATE(YEAR(汇总!$D$5)-1,12,31) -> 45291 | O29: 本期审定数与上期审定数比较
C30: 账套名称/账套编码 | D30: 科目编码 | E30: 科目名称 | F30: 本期账面数 | G30: 本期账表调整编号 | H30: 本期账表调整数 | I30: 本期账面未审数 | J30: 结构比 | K30: 本期审计调整编号 | L30: 本期审计调整金数 | M30: 本期账面审定数 | N30: 上期末审定数 (PY) | O30: 变动额 | P30: 变动率% | Q30: For X-ref | R30: Notes
I31: =F31+H31 -> 0 | J31: =IF($I$35<>0,I31/$I$35,"") | M31: =I31+L31 -> 0 | O31: =M31-N31 -> 0 | P31: =IF(N31<>0,O31/N31,1) -> 1
I32: =F32+H32 -> 0 | J32: =IF($I$35<>0,I32/$I$35,"") | M32: =I32+L32 -> 0 | O32: =M32-N32 -> 0 | P32: =IF(N32<>0,O32/N32,1) -> 1
A33: /T1 | I33: =F33+H33 -> 0 | J33: =IF($I$35<>0,I33/$I$35,"") | M33: =I33+L33 -> 0 | O33: =M33-N33 -> 0 | P33: =IF(N33<>0,O33/N33,1) -> 1
E35: 合计 | F35: =SUM(F30:F34) -> 0 | H35: =SUM(H30:H34) -> 0 | I35: =SUM(I30:I34) -> 0 | J35: =SUM(J30:J34) -> 0 | L35: =SUM(L30:L34) -> 0 | M35: =SUM(M30:M34) -> 0 | N35: =SUM(N30:N34) -> 0 | O35: =M35-N35 -> 0 | P35: =IF(N35<>0,O35/N35,1) -> 1
F36: Rx | H36: Rx | I36: Rx | J36: Rx | L36: Rx | M36: Rx | N36: Rx
H37: A3
H38: Diff | I38: =I35-I37 -> 0 | M38: =M35-M37 -> 0 | N38: =N35-N37 -> 0
B40: Notes | C40: 对变动不在范围内的项目进行调查，评估其合理性，并记录在“说明”中。对异常项目进行调查，并记录在“说明”中。

Sheet Uexp利息测试
A1: 284a92ec-2ca6-4386-9d4e-e60c226247db
J2: 返回汇总页
C4: 必读！利息收入合理性测试适用范围：
C6: 目标
C7: 测试货币资金的利息收入并通过与相关余额进行比较来检查合理性。
C9: 序号 | D9: 执行的测试 | G9: 程序表 | H9: 预审完成 | I9: 年审完成 | J9: 执行注意事项
C10: 1 | D10: 活期存款 | G10: C_货币资金
C11: 1.1 | D11: 核对期末活期存款金额至公司期末银行存款明细清单。
C12: 1.2 | D12: 针对活期存款/协定存款/通知存款，使用期初、期末平均余额乘以适用的利率，测算本期利息收入。 | G12: 表1
C13: 1.3 | D13: 与财务费用底稿里的公司活期存款/协定存款/通知存款进行差异比较，若差异金额大于TT则调查原因及是否需要调整。必要时，采取月平均余额进行测算 | G13: 表1
C14: 2 | D14: 定期存款
C15: 2.1 | D15: 获取公司【20__年1月1日至20__年12月31日】的定期存款明细清单（包含期末已到期的定期存款）。 | G15: 表2
C16: 2.2 | D16: 核对期末尚未到期的定期存款金额至公司期末银行存款明细清单。 | G16: 表2
C17: 2.3 | D17: 针对定期存款，使用本金、利率、存款期限测算本期利息收入。 | G17: 表2
C18: 2.4 | D18: 与财务费用底稿里的公司定期存款利息收入进行差异比较，若差异金额大于TT则调查原因及是否需要调整。 | G18: 表2
C19: 3 | D19: 其他利息类型 | G19: 表3
B23: 表1 | C23: 对货币资金的利息收入进行测算——活期存款：
C24: |----------------------------------------C100 -----------------------------------------------------| | H24: AA | I24: BB | J24: CC=(AA+BB)/2 | K24: DD | L24: EE | M24: FF=CC*DD*EE
C25: 账套名称/账套编码 | D25: 末级科目 | E25: 账号 | F25: 账户名称 | G25: 原币币种 | H25: 期末原币 | I25: 期初原币金额 | J25: 本期原币平均余额 | K25: 适用活期利率 | L25: 汇率（如适用） | M25: 安永测算本期利息收入
J26: =(H26+I26)/2 -> 0 | M26: =J26*K26*L26 -> 0
J27: =(H27+I27)/2 -> 0 | M27: =J27*K27*L27 -> 0
J28: =(H28+I28)/2 -> 0 | M28: =J28*K28*L28 -> 0
J29: =(H29+I29)/2 -> 0 | M29: =J29*K29*L29 -> 0
F31: 合计 | H31: =SUM(H26:H29) -> 0 | M31: =SUM(M26:M29) -> 0
F32: C.01.1 | G32: 活期存款 | M32: Rx
G33: Diff | H33: =H31-H32 -> 0
B36: 表2 | C36: 对货币资金的利息收入进行测算——定期存款： | H36: AA | I36: BB | L36: CC | M36: DD | N36: EE=(AA*BB*CC/360)*DD
L37: =DATE(YEAR(汇总!D5)-1,12,31)+1 -> 45292
C38: 账套名称/账套编码 | D38: 末级科目 | E38: 账号 | F38: 账户名称 | G38: 原币币种 | H38: 期末原币 | I38: 年利率 | J38: 起息日 | K38: 到期日 | L38: 本年计息日 | M38: 汇率（如适用） | N38: 安永测算本期利息收入
L39: {=IFERROR(_xlfn.IFS((J39<$L$37)*(K39<汇总!$D$5),DATEDIF($L$37,K39,"D"),(J39<$L$37)*(K39>=汇总!$D$5),DATEDIF($L$37,汇总!$D$5,"D"),(J39>=$L$37)*(K39<汇总!$D$5),DATEDIF(J39,K39,"D"),(J39>=$L$37)*(K39>=汇总!$D$5),DATEDIF(J39,汇总!$D$5,"D"))+1,"")} | N39: =IFERROR(H39*I39*L39/360,0)*M39 -> 0
L40: {=IFERROR(_xlfn.IFS((J40<$L$37)*(K40<汇总!$D$5),DATEDIF($L$37,K40,"D"),(J40<$L$37)*(K40>=汇总!$D$5),DATEDIF($L$37,汇总!$D$5,"D"),(J40>=$L$37)*(K40<汇总!$D$5),DATEDIF(J40,K40,"D"),(J40>=$L$37)*(K40>=汇总!$D$5),DATEDIF(J40,汇总!$D$5,"D"))+1,"")} | N40: =IFERROR(H40*I40*L40/360,0)*M40 -> 0
L41: {=IFERROR(_xlfn.IFS((J41<$L$37)*(K41<汇总!$D$5),DATEDIF($L$37,K41,"D"),(J41<$L$37)*(K41>=汇总!$D$5),DATEDIF($L$37,汇总!$D$5,"D"),(J41>=$L$37)*(K41<汇总!$D$5),DATEDIF(J41,K41,"D"),(J41>=$L$37)*(K41>=汇总!$D$5),DATEDIF(J41,汇总!$D$5,"D"))+1,"")} | N41: =IFERROR(H41*I41*L41/360,0)*M41 -> 0
L42: {=IFERROR(_xlfn.IFS((J42<$L$37)*(K42<汇总!$D$5),DATEDIF($L$37,K42,"D"),(J42<$L$37)*(K42>=汇总!$D$5),DATEDIF($L$37,汇总!$D$5,"D"),(J42>=$L$37)*(K42<汇总!$D$5),DATEDIF(J42,K42,"D"),(J42>=$L$37)*(K42>=汇总!$D$5),DATEDIF(J42,汇总!$D$5,"D"))+1,"")} | N42: =IFERROR(H42*I42*L42/360,0)*M42 -> 0
L43: {=IFERROR(_xlfn.IFS((J43<$L$37)*(K43<汇总!$D$5),DATEDIF($L$37,K43,"D"),(J43<$L$37)*(K43>=汇总!$D$5),DATEDIF($L$37,汇总!$D$5,"D"),(J43>=$L$37)*(K43<汇总!$D$5),DATEDIF(J43,K43,"D"),(J43>=$L$37)*(K43>=汇总!$D$5),DATEDIF(J43,汇总!$D$5,"D"))+1,"")} | N43: =IFERROR(H43*I43*L43/360,0)*M43 -> 0
F45: 合计 | H45: =SUM(H39:H43) -> 0 | N45: =SUM(N39:N43) -> 0
F46: C.01.1 | G46: 定期存款 | N46: Rx
G47: Diff | H47: =H45-H46 -> 0 | L47: Uexp | M47: 财务费用-利息收入-活期
M48: 财务费用-利息收入-定期
M49: 财务费用-利息收入（其他）
M50: 合计 | N50: =SUM(N47:N49) -> 0
...

Sheet Uexp其他收益BKD
A1: d5aed963-ff0a-445a-8114-fb83b79025eb
J2: 返回汇总页
C4: 目标
C5: 1.通过执行分析和调查两期的其他收益重大变动来确定其变动是否合理。
C6: 2.明细账金额、总账及报表金额是否一致，对重大不一致调查其调节项的性质及原因。
C8: 序号 | D8: 执行的程序 | G8: 程序表 | H8: 预审完成 | I8: 年审完成 | J8: 执行注意事项
C9: 1 | D9: 获取本期其他收益的明细表，将本期金额与TB或报表数核对一致，上期数与上期管理层报表数或审计审定数核对一致。 | G9: 表1 | H9: 是
C10: 2 | D10: 对比当期金额和上期金额，调查变动大于范围或与预期不符的变动情况。并就异常事项检查记账凭证、合同等支持性证据，评估其发生的合理性。 | G10: 表1 | H10: 是
C11: 3 | D11: 将明细账与管理层报表进行核对，并对差异大于SAD的项目进行调查。 | G11: 表1 | H11: 是
C12: 4 | D12: 对于当期收到政府补助款项一次性计入其他收益的大额政府补助项目，获取并查看支持性文件和银行水单。 | G12: 表2 | H12: 是
C13: 5 | D13: 调查任何异常交易，并基于综合风险评估和已确定的测试临界值测试交易。 | G13: 项目组自行设计 | H13: 是
C14: 6 | D14: 将费用科目中存在着勾稽关系的费用类型，同相应的其他科目金额进行核对X-ref | G14: 表1 | H14: 是
C15: 7 | D15: 复核政府补助明细表（如有），对政府补助计入其他收益部分判断是否计入恰当的科目，管理层是否进行正确的会计处理。 | G15: 表2 | H15: 是
C19: 在下文中描述我们当期对账户波动的预期，以及这些预期的依据和理由。
C24: ="波动范围 ("&D12& "):" -> 波动范围 (对于当期收到政府补助款项一次性计入其他收益的大额政府补助项目，获取并查看支持性文件和银行水单。): | D24: =汇总!$F$21 -> 0
C25: 波动范围 (%):
F28: AA | H28: BB | I28: CC=AA+BB | L28: DD | M28: EE=CC+DD | N28: FF | O28: GG=EE-FF | P28: HH=GG/FF
A29: T1 | C29: TB | D29: TB | E29: TB | F29: TB
I30: =F30+H30 -> 0 | J30: =IF($I$37<>0,I30/$I$37,"") | M30: =I30+L30 -> 0 | O30: =M30-N30 -> 0 | P30: =IF(N30<>0,O30/N30,1) -> 1
B31: 表1 | I31: 本期数 | N31: =DATE(YEAR(汇总!$D$5)-1,12,31) -> 45291 | O31: 本期审定数与上期审定数比较
C32: 账套名称/账套编码 | D32: 科目编码 | E32: 科目名称 | F32: 本期账面数 | G32: 本期账表调整编号 | H32: 本期账表调整数 | I32: 本期账面未审数 | J32: 结构比 | K32: 本期审计调整编号 | L32: 本期审计调整金数 | M32: 本期账面审定数 | N32: 上期末审定数 (PY) | O32: 变动额 | P32: 变动率% | Q32: For X-ref | R32: Notes
I33: =F33+H33 -> 0 | J33: =IF($I$37<>0,I33/$I$37,"") | M33: =I33+L33 -> 0 | O33: =M33-N33 -> 0 | P33: =IF(N33<>0,O33/N33,1) -> 1
I34: =F34+H34 -> 0 | J34: =IF($I$37<>0,I34/$I$37,"") | M34: =I34+L34 -> 0 | O34: =M34-N34 -> 0 | P34: =IF(N34<>0,O34/N34,1) -> 1
A35: /T1 | I35: =F35+H35 -> 0 | J35: =IF($I$37<>0,I35/$I$37,"") | M35: =I35+L35 -> 0 | O35: =M35-N35 -> 0 | P35: =IF(N35<>0,O35/N35,1) -> 1
E37: 合计 | F37: =SUM(F32:F36) -> 0 | H37: =SUM(H32:H36) -> 0 | I37: =SUM(I32:I36) -> 0 | J37: =SUM(J32:J36) -> 0 | L37: =SUM(L32:L36) -> 0 | M37: =SUM(M32:M36) -> 0 | N37: =SUM(N32:N36) -> 0 | O37: =M37-N37 -> 0 | P37: =IF(N37<>0,O37/N37,1) -> 1
F38: Rx | H38: Rx | I38: Rx | J38: Rx | L38: Rx | M38: Rx | N38: Rx
H39: A3
H40: Diff | I40: =I37-I39 -> 0 | M40: =M37-M39 -> 0 | N40: =N37-N39 -> 0
B42: Notes | C42: 对变动不在范围内的项目进行调查，评估其合理性，并记录在“说明”中。对异常项目进行调查，并记录在“说明”中。
B50: 表2 | C50: 对于当期收到政府补助款项一次性计入其他收益的大额政府补助项目，获取并查看支持性文件和银行水单。
C51: 政府补助名称 | D51: 金额 | E51: 支持性文件 | F51: 银行 | G51: 检查的其他会计凭证（如有） | H51: 会计处理是否恰当 | I51: 是否需要进行调整 | J51: 调整金额

Sheet Uexp投资收益BKD
A1: 24c95553-06d4-415a-96fe-a3f6e73262de
J2: 返回汇总页
C4: 目标
C5: 1.通过执行分析和调查两期的投资收益重大变动来确定其变动是否合理。
C6: 2.明细账金额、总账及报表金额是否一致，对重大不一致调查其调节项的性质及原因。
C8: 序号 | D8: 执行的程序 | G8: 程序表 | H8: 预审完成 | I8: 年审完成 | J8: 执行注意事项
C9: 1 | D9: 从管理层处取得本期投资收益账户的明细。 | G9: 表1 | H9: 是
C10: 2 | D10: 对比当期金额和上期金额，调查变动大于范围或与预期不符的变动情况。并就异常事项检查记账凭证、合同等支持性证据，评估其发生的合理性。 | G10: 表1 | H10: 是
C11: 3 | D11: 将明细账与管理层报表进行核对，并对差异大于SAD的项目进行调查。 | G11: 表1 | H11: 是
C12: 4 | D12: 对于单项重大的投资收益，需要获取该单项收益的组成明细，需要获取支持性文件如合同等，在必要时进行收入测试。 | G12: TOD SWP U_Exp_Uexp.01 TOD年审 | H12: 是
C13: 5 | D13: 调查任何异常交易，并基于综合风险评估和已确定的测试临界值测试交易。 | G13: 项目组自行设计 | H13: 是
C14: 6 | D14: 将费用科目中存在着勾稽关系的费用类型，同相应的其他科目金额进行核对X-ref | G14: 表1 | H14: 是
C19: 在下文中描述我们当期对账户波动的预期，以及这些预期的依据和理由。
C24: ="波动范围 ("&D12& "):" -> 波动范围 (对于单项重大的投资收益，需要获取该单项收益的组成明细，需要获取支持性文件如合同等，在必要时进行收入测试。): | D24: =汇总!$F$21 -> 0
C25: 波动范围 (%):
F28: AA | H28: BB | I28: CC=AA+BB | L28: DD | M28: EE=CC+DD | N28: FF | O28: GG=EE-FF | P28: HH=GG/FF
A29: T1 | C29: TB | D29: TB | E29: TB | F29: TB
I30: =F30+H30 -> 0 | J30: =IF($I$37<>0,I30/$I$37,"") | M30: =I30+L30 -> 0 | O30: =M30-N30 -> 0 | P30: =IF(N30<>0,O30/N30,1) -> 1
B31: 表1 | I31: 本期数 | N31: =DATE(YEAR(汇总!$D$5)-1,12,31) -> 45291 | O31: 本期审定数与上期审定数比较
C32: 账套名称/账套编码 | D32: 科目编码 | E32: 科目名称 | F32: 本期账面数 | G32: 本期账表调整编号 | H32: 本期账表调整数 | I32: 本期账面未审数 | J32: 结构比 | K32: 本期审计调整编号 | L32: 本期审计调整金数 | M32: 本期账面审定数 | N32: 上期末审定数 (PY) | O32: 变动额 | P32: 变动率% | Q32: For X-ref | R32: Notes
I33: =F33+H33 -> 0 | J33: =IF($I$37<>0,I33/$I$37,"") | M33: =I33+L33 -> 0 | O33: =M33-N33 -> 0 | P33: =IF(N33<>0,O33/N33,1) -> 1
I34: =F34+H34 -> 0 | J34: =IF($I$37<>0,I34/$I$37,"") | M34: =I34+L34 -> 0 | O34: =M34-N34 -> 0 | P34: =IF(N34<>0,O34/N34,1) -> 1
A35: /T1 | I35: =F35+H35 -> 0 | J35: =IF($I$37<>0,I35/$I$37,"") | M35: =I35+L35 -> 0 | O35: =M35-N35 -> 0 | P35: =IF(N35<>0,O35/N35,1) -> 1
E37: 合计 | F37: =SUM(F32:F36) -> 0 | H37: =SUM(H32:H36) -> 0 | I37: =SUM(I32:I36) -> 0 | J37: =SUM(J32:J36) -> 0 | L37: =SUM(L32:L36) -> 0 | M37: =SUM(M32:M36) -> 0 | N37: =SUM(N32:N36) -> 0 | O37: =M37-N37 -> 0 | P37: =IF(N37<>0,O37/N37,1) -> 1
F38: Rx | H38: Rx | I38: Rx | J38: Rx | L38: Rx | M38: Rx | N38: Rx
H39: A3
H40: Diff | I40: =I37-I39 -> 0 | M40: =M37-M39 -> 0 | N40: =N37-N39 -> 0
B42: Notes | C42: 对变动不在范围内的项目进行调查，评估其合理性，并记录在“说明”中。对异常项目进行调查，并记录在“说明”中。
B49: 表2 | C49: 对于单项收入类别金额占整个投资收益比例达到一定比例查看J列，需要获取该单项收入的组成明细，需要获取支持性文件如合同等，在必要时进行收入测试。（表格请审计团队自行设计）

Sheet Uexp公允价值变动损益BKD
A1: 099b5e22-59e3-4498-8c64-7188848172a8
J2: 返回汇总页
C4: 目标
C5: 1.通过执行分析和调查两期的公允价值变动损益重大变动来确定其变动是否合理。
C6: 2.明细账金额、总账及报表金额是否一致，对重大不一致调查其调节项的性质及原因。
C8: 序号 | D8: 执行的程序 | G8: 程序表 | H8: 预审完成 | I8: 年审完成 | J8: 执行注意事项
C9: 1 | D9: 从管理层处取得本期公允价值变动损益账户的明细。 | G9: 表1 | H9: 是
C10: 2 | D10: 对比当期金额和上期金额，调查变动大于范围或与预期不符的变动情况。并就异常事项检查记账凭证、合同等支持性证据，评估其发生的合理性。 | G10: 表1 | H10: 是
C11: 3 | D11: 将明细账与管理层报表进行核对，并对差异大于SAD的项目进行调查。 | G11: 表1 | H11: 是
C12: 4 | D12: 对于单项重大的公允价值变动损益，需要获取该单项损益的组成明细，需要获取支持性文件如合同等，在必要时进行损益测试。 | G12: TOD SWP U_Exp_Uexp.01 TOD年审 | H12: 是
C13: 5 | D13: 调查任何异常交易，并基于综合风险评估和已确定的测试临界值测试交易。 | G13: 项目组自行设计 | H13: 是
C14: 6 | D14: 将费用科目中存在着勾稽关系的费用类型，同相应的其他科目金额进行核对X-ref | G14: 表1 | H14: 是 | J14: 已经在表1中执行X-REF程序的费用类型，无需再执行表3.
C19: 在下文中描述我们当期对账户波动的预期，以及这些预期的依据和理由。
C24: ="波动范围 ("&D13& "):" -> 波动范围 (调查任何异常交易，并基于综合风险评估和已确定的测试临界值测试交易。): | D24: =汇总!$F$21 -> 0
C25: 波动范围 (%):
F27: AA | H27: BB | I27: CC=AA+BB | L27: DD | M27: EE=CC+DD | N27: FF | O27: GG=EE-FF | P27: HH=GG/FF
A28: T1 | C28: TB | D28: TB | E28: TB | F28: TB
I29: =F29+H29 -> 0 | J29: =IF($I$36<>0,I29/$I$36,"") | M29: =I29+L29 -> 0 | O29: =M29-N29 -> 0 | P29: =IF(N29<>0,O29/N29,1) -> 1
B30: 表1 | I30: 本期数 | N30: =DATE(YEAR(汇总!$D$5)-1,12,31) -> 45291 | O30: 本期审定数与上期审定数比较
C31: 账套名称/账套编码 | D31: 科目编码 | E31: 科目名称 | F31: 本期账面数 | G31: 本期账表调整编号 | H31: 本期账表调整数 | I31: 本期账面未审数 | J31: 结构比 | K31: 本期审计调整编号 | L31: 本期审计调整金数 | M31: 本期账面审定数 | N31: 上期末审定数 (PY) | O31: 变动额 | P31: 变动率% | Q31: For X-ref | R31: Notes
I32: =F32+H32 -> 0 | J32: =IF($I$36<>0,I32/$I$36,"") | M32: =I32+L32 -> 0 | O32: =M32-N32 -> 0 | P32: =IF(N32<>0,O32/N32,1) -> 1
I33: =F33+H33 -> 0 | J33: =IF($I$36<>0,I33/$I$36,"") | M33: =I33+L33 -> 0 | O33: =M33-N33 -> 0 | P33: =IF(N33<>0,O33/N33,1) -> 1
A34: /T1 | I34: =F34+H34 -> 0 | J34: =IF($I$36<>0,I34/$I$36,"") | M34: =I34+L34 -> 0 | O34: =M34-N34 -> 0 | P34: =IF(N34<>0,O34/N34,1) -> 1
E36: 合计 | F36: =SUM(F31:F35) -> 0 | H36: =SUM(H31:H35) -> 0 | I36: =SUM(I31:I35) -> 0 | J36: =SUM(J31:J35) -> 0 | L36: =SUM(L31:L35) -> 0 | M36: =SUM(M31:M35) -> 0 | N36: =SUM(N31:N35) -> 0 | O36: =M36-N36 -> 0 | P36: =IF(N36<>0,O36/N36,1) -> 1
F37: Rx | H37: Rx | I37: Rx | J37: Rx | L37: Rx | M37: Rx | N37: Rx
H38: A3
H39: Diff | I39: =I36-I38 -> 0 | M39: =M36-M38 -> 0 | N39: =N36-N38 -> 0
B41: Notes | C41: 对变动不在范围内的项目进行调查，评估其合理性，并记录在“说明”中。对异常项目进行调查，并记录在“说明”中。
B49: 表2 | C49: 对于单项收入类别金额占整个投资收益比例达到一定比例查看J列，需要获取该单项收入的组成明细，需要获取支持性文件如合同等，在必要时进行收入测试。（表格请审计团队自行设计）

Sheet Uexp信用减值损失BKD
A1: 08d7c109-e271-44be-96d8-8a34f7c9239f
J2: 返回汇总页
C4: 目标
C5: 1.通过执行分析和调查两期的信用减值损失重大变动来确定其变动是否合理。
C6: 2.明细账金额、总账及报表金额是否一致，对重大不一致调查其调节项的性质及原因。
C8: 序号 | D8: 执行的程序 | G8: 程序表 | H8: 预审完成 | I8: 年审完成 | J8: 执行注意事项
C9: 1 | D9: 从管理层处取得本期信用减值损失账户的明细。 | G9: 表1 | H9: 是
C10: 2 | D10: 对比当期金额和上期金额，调查变动大于范围或与预期不符的变动情况。并就异常事项检查记账凭证、合同等支持性证据，评估其发生的合理性。 | G10: 表1 | H10: 是
C11: 3 | D11: 将明细账与管理层报表进行核对，并对差异大于SAD的项目进行调查。 | G11: 表1 | H11: 是
C12: 4 | D12: 对于单项重大的损失，需要获取该单项损失的组成明细，需要获取支持性文件如合同等，在必要时进行费用测试。 | G12: TOD SWP U_Exp_Uexp.01 TOD年审 | H12: 是
C13: 5 | D13: 调查任何异常交易，并基于综合风险评估和已确定的测试临界值测试交易。 | G13: 项目组自行设计 | H13: 是
C14: 6 | D14: 将费用科目中存在着勾稽关系的费用类型，同相应的其他科目金额进行核对X-ref | G14: 表1 | H14: 是 | J14: 已经在表1中执行X-REF程序的费用类型，无需再执行表3.
C18: 在下文中描述我们当期对账户波动的预期，以及这些预期的依据和理由。
C23: ="波动范围 ("&D12& "):" -> 波动范围 (对于单项重大的损失，需要获取该单项损失的组成明细，需要获取支持性文件如合同等，在必要时进行费用测试。): | D23: =汇总!$F$21 -> 0
C24: 波动范围 (%):
F26: AA | H26: BB | I26: CC=AA+BB | L26: DD | M26: EE=CC+DD | N26: FF | O26: GG=EE-FF | P26: HH=GG/FF
A27: T1 | C27: TB | D27: TB | E27: TB | F27: TB
I28: =F28+H28 -> 0 | J28: =IF($I$35<>0,I28/$I$35,"") | M28: =I28+L28 -> 0 | O28: =M28-N28 -> 0 | P28: =IF(N28<>0,O28/N28,1) -> 1
B29: 表1 | I29: 本期数 | N29: =DATE(YEAR(汇总!$D$5)-1,12,31) -> 45291 | O29: 本期审定数与上期审定数比较
C30: 账套名称/账套编码 | D30: 科目编码 | E30: 科目名称 | F30: 本期账面数 | G30: 本期账表调整编号 | H30: 本期账表调整数 | I30: 本期账面未审数 | J30: 结构比 | K30: 本期审计调整编号 | L30: 本期审计调整金数 | M30: 本期账面审定数 | N30: 上期末审定数 (PY) | O30: 变动额 | P30: 变动率% | Q30: For X-ref | R30: Notes
I31: =F31+H31 -> 0 | J31: =IF($I$35<>0,I31/$I$35,"") | M31: =I31+L31 -> 0 | O31: =M31-N31 -> 0 | P31: =IF(N31<>0,O31/N31,1) -> 1
I32: =F32+H32 -> 0 | J32: =IF($I$35<>0,I32/$I$35,"") | M32: =I32+L32 -> 0 | O32: =M32-N32 -> 0 | P32: =IF(N32<>0,O32/N32,1) -> 1
A33: /T1 | I33: =F33+H33 -> 0 | J33: =IF($I$35<>0,I33/$I$35,"") | M33: =I33+L33 -> 0 | O33: =M33-N33 -> 0 | P33: =IF(N33<>0,O33/N33,1) -> 1
E35: 合计 | F35: =SUM(F30:F34) -> 0 | H35: =SUM(H30:H34) -> 0 | I35: =SUM(I30:I34) -> 0 | J35: =SUM(J30:J34) -> 0 | L35: =SUM(L30:L34) -> 0 | M35: =SUM(M30:M34) -> 0 | N35: =SUM(N30:N34) -> 0 | O35: =M35-N35 -> 0 | P35: =IF(N35<>0,O35/N35,1) -> 1
F36: Rx | H36: Rx | I36: Rx | J36: Rx | L36: Rx | M36: Rx | N36: Rx
H37: A3
H38: Diff | I38: =I35-I37 -> 0 | M38: =M35-M37 -> 0 | N38: =N35-N37 -> 0
C42: 与财务报表核对如下：
C43: 交叉索引 | E43: 金额
D44: 应收票据坏账损失
D45: 应收账款坏账损失
D46: 其他应收款坏账损失
D47: 债权投资减值损失
D48: 其他债权投资减值损失
D49: 财务担保合同减值损失
D50: 长期应收款坏账损失
D51: 其他
D52: 差异 | E52: =SUM(E44:E51)-I35 -> 0
B56: Notes | C56: 对变动不在范围内的项目进行调查，评估其合理性，并记录在“说明”中。对异常项目进行调查，并记录在“说明”中。
B63: 表2 | C63: 对于单项费用类别金额占整个信用减值损失比例达到一定比例查看J列，需要获取该单项费用的组成明细，需要获取支持性文件如合同等，在必要时进行费用测试。（表格请审计团队自行设计）

Sheet Uexp资产减值损失BKD
A1: 40930b5d-0c3d-401d-8bf3-e5a34e5d8fd5
J2: 返回汇总页
C4: 目标
C5: 1.通过执行分析和调查两期的资产减值损失重大变动来确定其变动是否合理。
C6: 2.明细账金额、总账及报表金额是否一致，对重大不一致调查其调节项的性质及原因。
C8: 序号 | D8: 执行的程序 | G8: 程序表 | H8: 预审完成 | I8: 年审完成 | J8: 执行注意事项
C9: 1 | D9: 从管理层处取得本期资产减值损失账户的明细。 | G9: 表1 | H9: 是
C10: 2 | D10: 对比当期金额和上期金额，调查变动大于范围或与预期不符的变动情况。并就异常事项检查记账凭证、合同等支持性证据，评估其发生的合理性。 | G10: 表1 | H10: 是
C11: 3 | D11: 将明细账与管理层报表进行核对，并对差异大于SAD的项目进行调查。 | G11: 表1 | H11: 是
C12: 4 | D12: 对于单项重大的减值损失，需要获取该单项费用的组成明细，需要获取支持性文件如合同等，在必要时进行费用测试。 | G12: TOD SWP U_Exp_Uexp.01 TOD年审 | H12: 是
C13: 5 | D13: 调查任何异常交易，并基于综合风险评估和已确定的测试临界值测试交易。 | G13: 项目组自行设计 | H13: 是
C14: 6 | D14: 将费用科目中存在着勾稽关系的费用类型，同相应的其他科目金额进行核对X-ref | G14: 表1 | H14: 是 | J14: 已经在表1中执行X-REF程序的费用类型，无需再执行表3.
C18: 在下文中描述我们当期对账户波动的预期，以及这些预期的依据和理由。
C23: ="波动范围 ("&D12& "):" -> 波动范围 (对于单项重大的减值损失，需要获取该单项费用的组成明细，需要获取支持性文件如合同等，在必要时进行费用测试。): | D23: =汇总!$F$21 -> 0
C24: 波动范围 (%):
F27: AA | H27: BB | I27: CC=AA+BB | L27: DD | M27: EE=CC+DD | N27: FF | O27: GG=EE-FF | P27: HH=GG/FF
A28: T1 | C28: TB | D28: TB | E28: TB | F28: TB
I29: =F29+H29 -> 0 | J29: =IF($I$36<>0,I29/$I$36,"") | M29: =I29+L29 -> 0 | O29: =M29-N29 -> 0 | P29: =IF(N29<>0,O29/N29,1) -> 1
B30: 表1 | I30: 本期数 | N30: =DATE(YEAR(汇总!$D$5)-1,12,31) -> 45291 | O30: 本期审定数与上期审定数比较
C31: 账套名称/账套编码 | D31: 科目编码 | E31: 科目名称 | F31: 本期账面数 | G31: 本期账表调整编号 | H31: 本期账表调整数 | I31: 本期账面未审数 | J31: 结构比 | K31: 本期审计调整编号 | L31: 本期审计调整金数 | M31: 本期账面审定数 | N31: 上期末审定数 (PY) | O31: 变动额 | P31: 变动率% | Q31: For X-ref | R31: Notes
I32: =F32+H32 -> 0 | J32: =IF($I$36<>0,I32/$I$36,"") | M32: =I32+L32 -> 0 | O32: =M32-N32 -> 0 | P32: =IF(N32<>0,O32/N32,1) -> 1
I33: =F33+H33 -> 0 | J33: =IF($I$36<>0,I33/$I$36,"") | M33: =I33+L33 -> 0 | O33: =M33-N33 -> 0 | P33: =IF(N33<>0,O33/N33,1) -> 1
A34: /T1 | I34: =F34+H34 -> 0 | J34: =IF($I$36<>0,I34/$I$36,"") | M34: =I34+L34 -> 0 | O34: =M34-N34 -> 0 | P34: =IF(N34<>0,O34/N34,1) -> 1
E36: 合计 | F36: =SUM(F31:F35) -> 0 | H36: =SUM(H31:H35) -> 0 | I36: =SUM(I31:I35) -> 0 | J36: =SUM(J31:J35) -> 0 | L36: =SUM(L31:L35) -> 0 | M36: =SUM(M31:M35) -> 0 | N36: =SUM(N31:N35) -> 0 | O36: =M36-N36 -> 0 | P36: =IF(N36<>0,O36/N36,1) -> 1
F37: Rx | H37: Rx | I37: Rx | J37: Rx | L37: Rx | M37: Rx | N37: Rx
H38: A3
H39: Diff | I39: =I36-I38 -> 0 | M39: =M36-M38 -> 0 | N39: =N36-N38 -> 0
C42: 与资产负债表核对如下：
C43: 交叉索引 | D43: 账套名称/账套编码 | E43: 科目编码 | F43: 科目名称 | G43: 本年变动金额
F44: 固定资产减值准备本年变动额
F45: 无形资产减值准备本年变动额
F46: 在建工程减值准备本年变动额
F47: 投资性房地产减值准备本年变动额
F48: 长期股权投资减值准备本年变动额
F49: 【其他-可加行】
F50: 资产负债表科目金额小计 | G50: =SUM(G44:G49) -> 0
F51: 利润表资产减值损失金额 | G51: =$I$36 -> 0
F53: 差异 | G53: =G50-G51 -> 0
B59: Notes | C59: 对变动不在范围内的项目进行调查，评估其合理性，并记录在“说明”中。对异常项目进行调查，并记录在“说明”中。
B66: 表2 | C66: 对于单项费用类别金额占整个资产减值损失比例达到一定比例查看J列，需要获取该单项费用的组成明细，需要获取支持性文件如合同等，在必要时进行费用测试。（表格请审计团队自行设计）

Sheet Uexp资产处置损益BKD
A1: 9044ccd0-ddb8-4146-932f-064afb5425f6
J2: 返回汇总页
C4: 目标
C5: 1.通过执行分析和调查两期的资产处置损益重大变动来确定其变动是否合理。
C6: 2.明细账金额、总账及报表金额是否一致，对重大不一致调查其调节项的性质及原因。
C8: 序号 | D8: 执行的程序 | G8: 程序表 | H8: 预审完成 | I8: 年审完成 | J8: 执行注意事项
C9: 1 | D9: 从管理层处取得本期资产处置损益账户的明细。 | G9: 表1 | H9: 是
C10: 2 | D10: 对比当期金额和上期金额，调查变动大于范围或与预期不符的变动情况。并就异常事项检查记账凭证、合同等支持性证据，评估其发生的合理性。 | G10: 表1 | H10: 是
C11: 3 | D11: 将明细账与管理层报表进行核对，并对差异大于SAD的项目进行调查。 | G11: 表1 | H11: 是
C12: 4 | D12: 对于单项重大的资产处置损益，需要获取该单项费用的组成明细，需要获取支持性文件如合同等，在必要时进行费用测试。 | G12: TOD SWP U_Exp_Uexp.01 TOD年审 | H12: 是
C13: 5 | D13: 调查任何异常交易，并基于综合风险评估和已确定的测试临界值测试交易。 | G13: 项目组自行设计 | H13: 是
C14: 6 | D14: 将费用科目中存在着勾稽关系的费用类型，同相应的其他科目金额进行核对X-ref | G14: 表1 | H14: 是 | J14: 已经在表1中执行X-REF程序的费用类型，无需再执行表3.
C18: 在下文中描述我们当期对账户波动的预期，以及这些预期的依据和理由。
C23: ="波动范围 ("&D12& "):" -> 波动范围 (对于单项重大的资产处置损益，需要获取该单项费用的组成明细，需要获取支持性文件如合同等，在必要时进行费用测试。): | D23: =汇总!$F$21 -> 0
C24: 波动范围 (%):
F27: AA | H27: BB | I27: CC=AA+BB | L27: DD | M27: EE=CC+DD | N27: FF | O27: GG=EE-FF | P27: HH=GG/FF
A28: T1 | C28: TB | D28: TB | E28: TB | F28: TB
I29: =F29+H29 -> 0 | J29: =IF($I$36<>0,I29/$I$36,"") | M29: =I29+L29 -> 0 | O29: =M29-N29 -> 0 | P29: =IF(N29<>0,O29/N29,1) -> 1
B30: 表1 | I30: 本期数 | N30: =DATE(YEAR(汇总!$D$5)-1,12,31) -> 45291 | O30: 本期审定数与上期审定数比较
C31: 账套名称/账套编码 | D31: 科目编码 | E31: 科目名称 | F31: 本期账面数 | G31: 本期账表调整编号 | H31: 本期账表调整数 | I31: 本期账面未审数 | J31: 结构比 | K31: 本期审计调整编号 | L31: 本期审计调整金数 | M31: 本期账面审定数 | N31: 上期末审定数 (PY) | O31: 变动额 | P31: 变动率% | Q31: For X-ref | R31: Notes
I32: =F32+H32 -> 0 | J32: =IF($I$36<>0,I32/$I$36,"") | M32: =I32+L32 -> 0 | O32: =M32-N32 -> 0 | P32: =IF(N32<>0,O32/N32,1) -> 1
I33: =F33+H33 -> 0 | J33: =IF($I$36<>0,I33/$I$36,"") | M33: =I33+L33 -> 0 | O33: =M33-N33 -> 0 | P33: =IF(N33<>0,O33/N33,1) -> 1
A34: /T1 | I34: =F34+H34 -> 0 | J34: =IF($I$36<>0,I34/$I$36,"") | M34: =I34+L34 -> 0 | O34: =M34-N34 -> 0 | P34: =IF(N34<>0,O34/N34,1) -> 1
E36: 合计 | F36: =SUM(F31:F35) -> 0 | H36: =SUM(H31:H35) -> 0 | I36: =SUM(I31:I35) -> 0 | J36: =SUM(J31:J35) -> 0 | L36: =SUM(L31:L35) -> 0 | M36: =SUM(M31:M35) -> 0 | N36: =SUM(N31:N35) -> 0 | O36: =M36-N36 -> 0 | P36: =IF(N36<>0,O36/N36,1) -> 1
F37: Rx | H37: Rx | I37: Rx | J37: Rx | L37: Rx | M37: Rx | N37: Rx
H38: A3
H39: Diff | I39: =I36-I38 -> 0 | M39: =M36-M38 -> 0 | N39: =N36-N38 -> 0
C41: 与资产负债表核对如下：
C42: 交叉索引 | D42: 账套名称/账套编码 | E42: 科目编码 | F42: 科目名称 | G42: 处置损益
F43: 固定资产处置损益
F44: 无形资产处置损益
F45: 在建工程处置损益
F46: 【其他-可加行】
F47: 资产负债表科目金额小计 | G47: =SUM(G43:G46) -> 0
F48: 利润表资产处置损益金额 | G48: =$I$36 -> 0
F50: 差异 | G50: =G47-G48 -> 0
B55: Notes | C55: 对变动不在范围内的项目进行调查，评估其合理性，并记录在“说明”中。对异常项目进行调查，并记录在“说明”中。
B62: 表2 | C62: 对于单项费用类别金额占整个资产处置损益比例达到一定比例查看J列，需要获取该单项费用的组成明细，需要获取支持性文件如合同等，在必要时进行费用测试。（表格请审计团队自行设计）

Sheet Uexp营业外收入BKD
A1: 91604a69-e836-47f0-8f3a-ad5c01fa9c1f
J2: 返回汇总页
C4: 目标
C5: 1.通过执行分析和调查两期的营业外收入重大变动来确定其变动是否合理。
C6: 2.明细账金额、总账及报表金额是否一致，对重大不一致调查其调节项的性质及原因。
C8: 序号 | D8: 执行的程序 | G8: 程序表 | H8: 预审完成 | I8: 年审完成 | J8: 执行注意事项
C9: 1 | D9: 从管理层处取得本期营业外收入账户的明细。 | G9: 表1 | H9: 是
C10: 2 | D10: 对比当期金额和上期金额，调查变动大于范围或与预期不符的变动情况。并就异常事项检查记账凭证、合同等支持性证据，评估其发生的合理性。 | G10: 表1 | H10: 是
C11: 3 | D11: 将明细账与管理层报表进行核对，并对差异大于SAD的项目进行调查。 | G11: 表1 | H11: 是
C12: 4 | D12: 对于单项重大的利得，需要获取该单项利得的组成明细，需要获取支持性文件如合同等，在必要时进行利得测试。 | G12: TOD SWP U_Exp_Uexp.01 TOD年审 | H12: 是
C13: 5 | D13: 调查任何异常交易，并基于综合风险评估和已确定的测试临界值测试交易。 | G13: 项目组自行设计 | H13: 是
C14: 6 | D14: 将费用科目中存在着勾稽关系的费用类型，同相应的其他科目金额进行核对X-ref | G14: 表1 | H14: 是
C18: 在下文中描述我们当期对账户波动的预期，以及这些预期的依据和理由。
C23: ="波动范围 ("&D12& "):" -> 波动范围 (对于单项重大的利得，需要获取该单项利得的组成明细，需要获取支持性文件如合同等，在必要时进行利得测试。): | D23: =汇总!$F$21 -> 0
C24: 波动范围 (%):
F27: AA | H27: BB | I27: CC=AA+BB | L27: DD | M27: EE=CC+DD | N27: FF | O27: GG=EE-FF | P27: HH=GG/FF
A28: T1 | C28: TB | D28: TB | E28: TB | F28: TB
I29: =F29+H29 -> 0 | J29: =IF($I$36<>0,I29/$I$36,"") | M29: =I29+L29 -> 0 | O29: =M29-N29 -> 0 | P29: =IF(N29<>0,O29/N29,1) -> 1
B30: 表1 | I30: 本期数 | N30: =DATE(YEAR(汇总!$D$5)-1,12,31) -> 45291 | O30: 本期审定数与上期审定数比较
C31: 账套名称/账套编码 | D31: 科目编码 | E31: 科目名称 | F31: 本期账面数 | G31: 本期账表调整编号 | H31: 本期账表调整数 | I31: 本期账面未审数 | J31: 结构比 | K31: 本期审计调整编号 | L31: 本期审计调整金数 | M31: 本期账面审定数 | N31: 上期末审定数 (PY) | O31: 变动额 | P31: 变动率% | Q31: For X-ref | R31: Notes
I32: =F32+H32 -> 0 | J32: =IF($I$36<>0,I32/$I$36,"") | M32: =I32+L32 -> 0 | O32: =M32-N32 -> 0 | P32: =IF(N32<>0,O32/N32,1) -> 1
I33: =F33+H33 -> 0 | J33: =IF($I$36<>0,I33/$I$36,"") | M33: =I33+L33 -> 0 | O33: =M33-N33 -> 0 | P33: =IF(N33<>0,O33/N33,1) -> 1
A34: /T1 | I34: =F34+H34 -> 0 | J34: =IF($I$36<>0,I34/$I$36,"") | M34: =I34+L34 -> 0 | O34: =M34-N34 -> 0 | P34: =IF(N34<>0,O34/N34,1) -> 1
E36: 合计 | F36: =SUM(F31:F35) -> 0 | H36: =SUM(H31:H35) -> 0 | I36: =SUM(I31:I35) -> 0 | J36: =SUM(J31:J35) -> 0 | L36: =SUM(L31:L35) -> 0 | M36: =SUM(M31:M35) -> 0 | N36: =SUM(N31:N35) -> 0 | O36: =M36-N36 -> 0 | P36: =IF(N36<>0,O36/N36,1) -> 1
F37: Rx | H37: Rx | I37: Rx | J37: ^ | L37: Rx | M37: Rx | N37: Rx
H38: A3
H39: Diff | I39: =I36-I38 -> 0 | M39: =M36-M38 -> 0 | N39: =N36-N38 -> 0
B41: Notes | C41: 对变动不在范围内的项目进行调查，评估其合理性，并记录在“说明”中。对异常项目进行调查，并记录在“说明”中。
B48: 表2 | C48: 对于单项利得类别金额占整个营业外收入比例达到一定比例查看J列，需要获取该单项利得的组成明细，需要获取支持性文件如合同等，在必要时进行利得测试。（表格请审计团队自行设计）

Sheet Uexp营业外支出BKD
A1: 86864713-feda-4db1-b1c3-d36448fb3132
J2: 返回汇总页
C4: 目标
C5: 1.通过执行分析和调查两期的营业外支出重大变动来确定其变动是否合理。
C6: 2.明细账金额、总账及报表金额是否一致，对重大不一致调查其调节项的性质及原因。
C8: 序号 | D8: 执行的程序 | G8: 程序表 | H8: 预审完成 | I8: 年审完成 | J8: 执行注意事项
C9: 1 | D9: 从管理层处取得本期营业外支出账户的明细。 | G9: 表1 | H9: 是
C10: 2 | D10: 对比当期金额和上期金额，调查变动大于范围或与预期不符的变动情况。并就异常事项检查记账凭证、合同等支持性证据，评估其发生的合理性。 | G10: 表1 | H10: 是
C11: 3 | D11: 将明细账与管理层报表进行核对，并对差异大于SAD的项目进行调查。 | G11: 表1 | H11: 是
C12: 4 | D12: 对于单项重大损失，需要获取该单项损失的组成明细，需要获取支持性文件如合同等，在必要时进行损失测试。 | G12: TOD SWP U_Exp_Uexp.01 TOD年审 | H12: 是
C13: 5 | D13: 调查任何异常交易，并基于综合风险评估和已确定的测试临界值测试交易。 | G13: 项目组自行设计 | H13: 是
C14: 6 | D14: 将费用科目中存在着勾稽关系的费用类型，同相应的其他科目金额进行核对X-ref | G14: 表1 | H14: 是
C19: 在下文中描述我们当期对账户波动的预期，以及这些预期的依据和理由。
C24: ="波动范围 ("&D13& "):" -> 波动范围 (调查任何异常交易，并基于综合风险评估和已确定的测试临界值测试交易。): | D24: =汇总!$F$21 -> 0
C25: 波动范围 (%):
F28: AA | H28: BB | I28: CC=AA+BB | L28: DD | M28: EE=CC+DD | N28: FF | O28: GG=EE-FF | P28: HH=GG/FF
A29: T1 | C29: TB | D29: TB | E29: TB | F29: TB
I30: =F30+H30 -> 0 | J30: =IF($I$37<>0,I30/$I$37,"") | M30: =I30+L30 -> 0 | O30: =M30-N30 -> 0 | P30: =IF(N30<>0,O30/N30,1) -> 1
B31: 表1 | I31: 本期数 | N31: =DATE(YEAR(汇总!$D$5)-1,12,31) -> 45291 | O31: 本期审定数与上期审定数比较
C32: 账套名称/账套编码 | D32: 科目编码 | E32: 科目名称 | F32: 本期账面数 | G32: 本期账表调整编号 | H32: 本期账表调整数 | I32: 本期账面未审数 | J32: 结构比 | K32: 本期审计调整编号 | L32: 本期审计调整金数 | M32: 本期账面审定数 | N32: 上期末审定数 (PY) | O32: 变动额 | P32: 变动率% | Q32: For X-ref | R32: Notes
I33: =F33+H33 -> 0 | J33: =IF($I$37<>0,I33/$I$37,"") | M33: =I33+L33 -> 0 | O33: =M33-N33 -> 0 | P33: =IF(N33<>0,O33/N33,1) -> 1
I34: =F34+H34 -> 0 | J34: =IF($I$37<>0,I34/$I$37,"") | M34: =I34+L34 -> 0 | O34: =M34-N34 -> 0 | P34: =IF(N34<>0,O34/N34,1) -> 1
A35: /T1 | I35: =F35+H35 -> 0 | J35: =IF($I$37<>0,I35/$I$37,"") | M35: =I35+L35 -> 0 | O35: =M35-N35 -> 0 | P35: =IF(N35<>0,O35/N35,1) -> 1
E37: 合计 | F37: =SUM(F32:F36) -> 0 | H37: =SUM(H32:H36) -> 0 | I37: =SUM(I32:I36) -> 0 | J37: =SUM(J32:J36) -> 0 | L37: =SUM(L32:L36) -> 0 | M37: =SUM(M32:M36) -> 0 | N37: =SUM(N32:N36) -> 0 | O37: =M37-N37 -> 0 | P37: =IF(N37<>0,O37/N37,1) -> 1
F38: Rx | H38: Rx | I38: Rx | J38: ^ | L38: Rx | M38: Rx | N38: Rx
H39: A3
H40: Diff | I40: =I37-I39 -> 0 | M40: =M37-M39 -> 0 | N40: =N37-N39 -> 0
B42: Notes | C42: 对变动不在范围内的项目进行调查，评估其合理性，并记录在“说明”中。对异常项目进行调查，并记录在“说明”中。
B49: 表2 | C49: 对于单项损失类别金额占整个营业外支出达到一定比例查看J列，需要获取该单项损失的组成明细，需要获取支持性文件如合同等，在必要时进行损失测试。（表格请审计团队自行设计）

Sheet Uexp债务重组利得和损失BKD
A1: 28183d84-3dae-44d6-9b07-fad4d0edb8e4
J2: 返回汇总页
C4: 目标
C5: 1.通过执行分析和调查两期的债务重组利得和损失重大变动来确定其变动是否合理。
C6: 2.明细账金额、总账及报表金额是否一致，对重大不一致调查其调节项的性质及原因。
C8: 序号 | D8: 执行的程序 | G8: 程序表 | H8: 预审完成 | I8: 年审完成 | J8: 执行注意事项
C9: 1 | D9: 从管理层处取得本期债务重组利得和损失账户的明细。 | G9: 表1 | H9: 是
C10: 2 | D10: 对比当期金额和上期金额，调查变动大于范围或与预期不符的变动情况。并就异常事项检查记账凭证、合同等支持性证据，评估其发生的合理性。 | G10: 表1 | H10: 是
C11: 3 | D11: 将明细账与管理层报表进行核对，并对差异大于SAD的项目进行调查。 | G11: 表1 | H11: 是
C12: 4 | D12: 获取债务重组明细表，对当期确认债务重组利得/损益的时点进行判断，复核是否满足金融资产和金融负债终止确认条件，判断相关债务的现实义务已经解除的依据，包括但不限于查看债务重组协议的具体条款以及协议的执行情况，律师意见书、董事会决议、股东会决议等。 | G12: 项目组自行设计 | H12: 是
C13: 5 | D13: 调查任何异常交易，并基于综合风险评估和已确定的测试临界值测试交易。 | G13: 自行介绍 | H13: 是
C14: 6 | D14: 将费用科目中存在着勾稽关系的费用类型，同相应的其他科目金额进行核对X-ref | G14: 表1 | H14: 是
C19: 在下文中描述我们当期对账户波动的预期，以及这些预期的依据和理由。
C24: ="波动范围 ("&D13& "):" -> 波动范围 (调查任何异常交易，并基于综合风险评估和已确定的测试临界值测试交易。): | D24: =汇总!$F$21 -> 0
C25: 波动范围 (%):
F28: AA | H28: BB | I28: CC=AA+BB | L28: DD | M28: EE=CC+DD | N28: FF | O28: GG=EE-FF | P28: HH=GG/FF
A29: T1 | C29: TB | D29: TB | E29: TB | F29: TB
I30: =F30+H30 -> 0 | J30: =IF($I$37<>0,I30/$I$37,"") | M30: =I30+L30 -> 0 | O30: =M30-N30 -> 0 | P30: =IF(N30<>0,O30/N30,1) -> 1
B31: 表1 | I31: 本期数 | N31: =DATE(YEAR(汇总!$D$5)-1,12,31) -> 45291 | O31: 本期审定数与上期审定数比较
C32: 账套名称/账套编码 | D32: 科目编码 | E32: 科目名称 | F32: 本期账面数 | G32: 本期账表调整编号 | H32: 本期账表调整数 | I32: 本期账面未审数 | J32: 结构比 | K32: 本期审计调整编号 | L32: 本期审计调整金数 | M32: 本期账面审定数 | N32: 上期末审定数 (PY) | O32: 变动额 | P32: 变动率% | Q32: For X-ref | R32: Notes
I33: =F33+H33 -> 0 | J33: =IF($I$37<>0,I33/$I$37,"") | M33: =I33+L33 -> 0 | O33: =M33-N33 -> 0 | P33: =IF(N33<>0,O33/N33,1) -> 1
I34: =F34+H34 -> 0 | J34: =IF($I$37<>0,I34/$I$37,"") | M34: =I34+L34 -> 0 | O34: =M34-N34 -> 0 | P34: =IF(N34<>0,O34/N34,1) -> 1
A35: /T1 | I35: =F35+H35 -> 0 | J35: =IF($I$37<>0,I35/$I$37,"") | M35: =I35+L35 -> 0 | O35: =M35-N35 -> 0 | P35: =IF(N35<>0,O35/N35,1) -> 1
E37: 合计 | F37: =SUM(F32:F36) -> 0 | H37: =SUM(H32:H36) -> 0 | I37: =SUM(I32:I36) -> 0 | J37: =SUM(J32:J36) -> 0 | L37: =SUM(L32:L36) -> 0 | M37: =SUM(M32:M36) -> 0 | N37: =SUM(N32:N36) -> 0 | O37: =M37-N37 -> 0 | P37: =IF(N37<>0,O37/N37,1) -> 1
F38: Rx | H38: Rx | I38: Rx | J38: Rx | L38: Rx | M38: Rx | N38: Rx
H39: A3
H40: Diff | I40: =I37-I39 -> 0 | M40: =M37-M39 -> 0 | N40: =N37-N39 -> 0
B42: Notes | C42: 对变动不在范围内的项目进行调查，评估其合理性，并记录在“说明”中。对异常项目进行调查，并记录在“说明”中。
B50: 表2 | C50: 获取债务重组明细表，并检查相关支持性文件并记录检查结果，判断债务重组确认时点满足金融资产和金融负债终止确认的条件。（项目组请根据实际情况进行修改）
C52: 【测试表格由项目组自行设计】

Sheet Uexp_Cutoff
A1: 27072530-60da-4b5d-87b1-4357f8557a1f
J2: 返回汇总页
C5: 目标
C6: 测试记录在账面的费用交易是否记录于正确期间
C8: 序号 | D8: 执行的程序 | G8: 程序表 | H8: 预审完成 | I8: 年审完成 | J8: 执行注意事项
C9: 1 | D9: 结合我们对于被审计单位费用确认时点的理解，考虑截止性测试的涵盖期间。 | G9: 表1 | J9: 考虑我们从其他审计程序中获取的审计证据（例如，已测试过的折旧、摊销、职工薪酬、租赁费、保险费等），确认我们是否已经对全部期间费用的截止性执行了充分、适当的审计程序。
C10: 2 | D10: 获取截止测试涵盖期间内的期间费用明细账，并考虑IPE测试的结果。 | G10: 【请项目组更新底稿索引】
C11: 3 | D11: 获得测试期间内所选交易的支持文件，并确定它们是否记录在适当的期间。项目组可以检查发生额大于TE的交易，或项目组发现符合其他特定标准的交易作为关键项（key item）。如果关键项（key item）的检查不足以应对CRA的风险水平，项目组应当采取安永审计抽样工具抽取代表性样本。 | G11: 表2及表3
B15: 表1 | C15: 确定截止性测试的涵盖期间
C16: 测试期间（输入前后天数） | D16: 测试期间确定依据/原因 | E16: 测试开始日期 | F16: 测试结束日期
D17: （测试期间项目组要根据需要根据关账时间和发票入账频率进行判断，并在此记录。） | E17: =汇总!D5-C17 -> 45657 | F17: =汇总!D5+C17 -> 45657
B19: 表2 | C19: 记录确定截止性测试样本的策略
B23: 表3 | C23: 测试期间费用的截止性
C24: 记账日期 | D24: 交易事项描述 | E24: 发票日期 | F24: 交易金额 | G24: 发票号码 | H24: 业务发生日期 | I24: 交易是否被记录在正确的期间 | J24: 说明我们所执行的工作以及检查的外部审计证据。
C25: 本期资产负债表日前记录的交易
C36: 本期资产负债表日后记录的交易
C38: 已经在P_寻找未入账负债中包含期后费用入账时间是否合理的测试，此处不再赘述。
B43: Notes | C43: *我们在注释框中包括我们认为有必要的任何附加评论，以使以前与本项目没有联系的有经验的审计师清楚地理解 1)我们所执行程序的性质、时间和范围; 2)我们执行的程序的结果; 3)获得的证据和得出的结论，包括我们考虑的任何不一致或相反的信息以及与该信息相关的结论; 4)确定的例外情况的细节，如果适用，以及如何解决这些问题，包括执行的其他实质性程序。

Sheet Uexp_TOD
I2: 返回汇总页
C3: 请项目组使用以下链接获取标准底稿执行费用TOD程序：
C4: TOD SWP U_Exp 202YXXDD XYZ公司.xlsx

Sheet SkywindSettingSheet
A1: 4dc9ee5d-f2ce-45d3-9ab7-e53d6fd7e35c
A3: {"Id":"2120093264","IsProject":false,"ProjectId":"2006600230","TempProjectName":"测试上数","TempType":2}
A4: TRUE
A5: 管理费用
